Workbook

Sheet Instances
B1: clingo-5.8.0/one-as | I1: min | O1: median | U1: max
B2: error | C2: mem | D2: memout | E2: par2 | F2: rstatus | G2: time | H2: timeout | I2: error | J2: mem | K2: memout | L2: par2 | M2: time | N2: timeout | O2: error | P2: mem | Q2: memout | R2: par2 | S2: time | T2: timeout | U2: error | V2: mem | W2: memout | X2: par2 | Y2: time | Z2: timeout
A3: ./10-145162646848673 | B3: 1 | C3: 0 | D3: 0 | E3: 10000 | F3: ok | G3: 5000 | H3: 1 | I3: =MIN($B3) -> 0 | J3: =MIN($C3) -> 0 | K3: =MIN($D3) -> 0 | L3: =MIN($E3) -> 0 | M3: =MIN($G3) -> 0 | N3: =MIN($H3) -> 0 | O3: =MEDIAN($B3) -> 0 | P3: =MEDIAN($C3) -> 0 | Q3: =MEDIAN($D3) -> 0 | R3: =MEDIAN($E3) -> 0 | S3: =MEDIAN($G3) -> 0 | T3: =MEDIAN($H3) -> 0 | U3: =MAX($B3) -> 0 | V3: =MAX($C3) -> 0 | W3: =MAX($D3) -> 0 | X3: =MAX($E3) -> 0 | Y3: =MAX($G3) -> 0 | Z3: =MAX($H3) -> 0
A4: ./10-17630975493234 | B4: 1 | C4: 0 | D4: 0 | E4: 10000 | F4: ok | G4: 5000 | H4: 1 | I4: =MIN($B4) -> 0 | J4: =MIN($C4) -> 0 | K4: =MIN($D4) -> 0 | L4: =MIN($E4) -> 0 | M4: =MIN($G4) -> 0 | N4: =MIN($H4) -> 0 | O4: =MEDIAN($B4) -> 0 | P4: =MEDIAN($C4) -> 0 | Q4: =MEDIAN($D4) -> 0 | R4: =MEDIAN($E4) -> 0 | S4: =MEDIAN($G4) -> 0 | T4: =MEDIAN($H4) -> 0 | U4: =MAX($B4) -> 0 | V4: =MAX($C4) -> 0 | W4: =MAX($D4) -> 0 | X4: =MAX($E4) -> 0 | Y4: =MAX($G4) -> 0 | Z4: =MAX($H4) -> 0
A5: ./10-18708915822629 | B5: 1 | C5: 0 | D5: 0 | E5: 10000 | F5: ok | G5: 5000 | H5: 1 | I5: =MIN($B5) -> 0 | J5: =MIN($C5) -> 0 | K5: =MIN($D5) -> 0 | L5: =MIN($E5) -> 0 | M5: =MIN($G5) -> 0 | N5: =MIN($H5) -> 0 | O5: =MEDIAN($B5) -> 0 | P5: =MEDIAN($C5) -> 0 | Q5: =MEDIAN($D5) -> 0 | R5: =MEDIAN($E5) -> 0 | S5: =MEDIAN($G5) -> 0 | T5: =MEDIAN($H5) -> 0 | U5: =MAX($B5) -> 0 | V5: =MAX($C5) -> 0 | W5: =MAX($D5) -> 0 | X5: =MAX($E5) -> 0 | Y5: =MAX($G5) -> 0 | Z5: =MAX($H5) -> 0
A6: ./10-282093612040832 | B6: 1 | C6: 0 | D6: 0 | E6: 10000 | F6: ok | G6: 5000 | H6: 1 | I6: =MIN($B6) -> 0 | J6: =MIN($C6) -> 0 | K6: =MIN($D6) -> 0 | L6: =MIN($E6) -> 0 | M6: =MIN($G6) -> 0 | N6: =MIN($H6) -> 0 | O6: =MEDIAN($B6) -> 0 | P6: =MEDIAN($C6) -> 0 | Q6: =MEDIAN($D6) -> 0 | R6: =MEDIAN($E6) -> 0 | S6: =MEDIAN($G6) -> 0 | T6: =MEDIAN($H6) -> 0 | U6: =MAX($B6) -> 0 | V6: =MAX($C6) -> 0 | W6: =MAX($D6) -> 0 | X6: =MAX($E6) -> 0 | Y6: =MAX($G6) -> 0 | Z6: =MAX($H6) -> 0
A7: ./10-283712654672237 | B7: 1 | C7: 0 | D7: 0 | E7: 10000 | F7: ok | G7: 5000 | H7: 1 | I7: =MIN($B7) -> 0 | J7: =MIN($C7) -> 0 | K7: =MIN($D7) -> 0 | L7: =MIN($E7) -> 0 | M7: =MIN($G7) -> 0 | N7: =MIN($H7) -> 0 | O7: =MEDIAN($B7) -> 0 | P7: =MEDIAN($C7) -> 0 | Q7: =MEDIAN($D7) -> 0 | R7: =MEDIAN($E7) -> 0 | S7: =MEDIAN($G7) -> 0 | T7: =MEDIAN($H7) -> 0 | U7: =MAX($B7) -> 0 | V7: =MAX($C7) -> 0 | W7: =MAX($D7) -> 0 | X7: =MAX($E7) -> 0 | Y7: =MAX($G7) -> 0 | Z7: =MAX($H7) -> 0
A8: ./10-611399871496200 | B8: 1 | C8: 0 | D8: 0 | E8: 10000 | F8: ok | G8: 5000 | H8: 1 | I8: =MIN($B8) -> 0 | J8: =MIN($C8) -> 0 | K8: =MIN($D8) -> 0 | L8: =MIN($E8) -> 0 | M8: =MIN($G8) -> 0 | N8: =MIN($H8) -> 0 | O8: =MEDIAN($B8) -> 0 | P8: =MEDIAN($C8) -> 0 | Q8: =MEDIAN($D8) -> 0 | R8: =MEDIAN($E8) -> 0 | S8: =MEDIAN($G8) -> 0 | T8: =MEDIAN($H8) -> 0 | U8: =MAX($B8) -> 0 | V8: =MAX($C8) -> 0 | W8: =MAX($D8) -> 0 | X8: =MAX($E8) -> 0 | Y8: =MAX($G8) -> 0 | Z8: =MAX($H8) -> 0
A9: ./10-703945206928000 | B9: 1 | C9: 0 | D9: 0 | E9: 10000 | F9: ok | G9: 5000 | H9: 1 | I9: =MIN($B9) -> 0 | J9: =MIN($C9) -> 0 | K9: =MIN($D9) -> 0 | L9: =MIN($E9) -> 0 | M9: =MIN($G9) -> 0 | N9: =MIN($H9) -> 0 | O9: =MEDIAN($B9) -> 0 | P9: =MEDIAN($C9) -> 0 | Q9: =MEDIAN($D9) -> 0 | R9: =MEDIAN($E9) -> 0 | S9: =MEDIAN($G9) -> 0 | T9: =MEDIAN($H9) -> 0 | U9: =MAX($B9) -> 0 | V9: =MAX($C9) -> 0 | W9: =MAX($D9) -> 0 | X9: =MAX($E9) -> 0 | Y9: =MAX($G9) -> 0 | Z9: =MAX($H9) -> 0
A10: ./11-142936786347061 | B10: 1 | C10: 0 | D10: 0 | E10: 10000 | F10: ok | G10: 5000 | H10: 1 | I10: =MIN($B10) -> 0 | J10: =MIN($C10) -> 0 | K10: =MIN($D10) -> 0 | L10: =MIN($E10) -> 0 | M10: =MIN($G10) -> 0 | N10: =MIN($H10) -> 0 | O10: =MEDIAN($B10) -> 0 | P10: =MEDIAN($C10) -> 0 | Q10: =MEDIAN($D10) -> 0 | R10: =MEDIAN($E10) -> 0 | S10: =MEDIAN($G10) -> 0 | T10: =MEDIAN($H10) -> 0 | U10: =MAX($B10) -> 0 | V10: =MAX($C10) -> 0 | W10: =MAX($D10) -> 0 | X10: =MAX($E10) -> 0 | Y10: =MAX($G10) -> 0 | Z10: =MAX($H10) -> 0
A11: ./11-142992641884424 | B11: 1 | C11: 0 | D11: 0 | E11: 10000 | F11: ok | G11: 5000 | H11: 1 | I11: =MIN($B11) -> 0 | J11: =MIN($C11) -> 0 | K11: =MIN($D11) -> 0 | L11: =MIN($E11) -> 0 | M11: =MIN($G11) -> 0 | N11: =MIN($H11) -> 0 | O11: =MEDIAN($B11) -> 0 | P11: =MEDIAN($C11) -> 0 | Q11: =MEDIAN($D11) -> 0 | R11: =MEDIAN($E11) -> 0 | S11: =MEDIAN($G11) -> 0 | T11: =MEDIAN($H11) -> 0 | U11: =MAX($B11) -> 0 | V11: =MAX($C11) -> 0 | W11: =MAX($D11) -> 0 | X11: =MAX($E11) -> 0 | Y11: =MAX($G11) -> 0 | Z11: =MAX($H11) -> 0
A12: ./11-302094043054658 | B12: 1 | C12: 0 | D12: 0 | E12: 10000 | F12: ok | G12: 5000 | H12: 1 | I12: =MIN($B12) -> 0 | J12: =MIN($C12) -> 0 | K12: =MIN($D12) -> 0 | L12: =MIN($E12) -> 0 | M12: =MIN($G12) -> 0 | N12: =MIN($H12) -> 0 | O12: =MEDIAN($B12) -> 0 | P12: =MEDIAN($C12) -> 0 | Q12: =MEDIAN($D12) -> 0 | R12: =MEDIAN($E12) -> 0 | S12: =MEDIAN($G12) -> 0 | T12: =MEDIAN($H12) -> 0 | U12: =MAX($B12) -> 0 | V12: =MAX($C12) -> 0 | W12: =MAX($D12) -> 0 | X12: =MAX($E12) -> 0 | Y12: =MAX($G12) -> 0 | Z12: =MAX($H12) -> 0
A13: ./11-563345380114560 | B13: 1 | C13: 0 | D13: 0 | E13: 10000 | F13: ok | G13: 5000 | H13: 1 | I13: =MIN($B13) -> 0 | J13: =MIN($C13) -> 0 | K13: =MIN($D13) -> 0 | L13: =MIN($E13) -> 0 | M13: =MIN($G13) -> 0 | N13: =MIN($H13) -> 0 | O13: =MEDIAN($B13) -> 0 | P13: =MEDIAN($C13) -> 0 | Q13: =MEDIAN($D13) -> 0 | R13: =MEDIAN($E13) -> 0 | S13: =MEDIAN($G13) -> 0 | T13: =MEDIAN($H13) -> 0 | U13: =MAX($B13) -> 0 | V13: =MAX($C13) -> 0 | W13: =MAX($D13) -> 0 | X13: =MAX($E13) -> 0 | Y13: =MAX($G13) -> 0 | Z13: =MAX($H13) -> 0
A14: ./11-567405982269522 | B14: 1 | C14: 0 | D14: 0 | E14: 10000 | F14: ok | G14: 5000 | H14: 1 | I14: =MIN($B14) -> 0 | J14: =MIN($C14) -> 0 | K14: =MIN($D14) -> 0 | L14: =MIN($E14) -> 0 | M14: =MIN($G14) -> 0 | N14: =MIN($H14) -> 0 | O14: =MEDIAN($B14) -> 0 | P14: =MEDIAN($C14) -> 0 | Q14: =MEDIAN($D14) -> 0 | R14: =MEDIAN($E14) -> 0 | S14: =MEDIAN($G14) -> 0 | T14: =MEDIAN($H14) -> 0 | U14: =MAX($B14) -> 0 | V14: =MAX($C14) -> 0 | W14: =MAX($D14) -> 0 | X14: =MAX($E14) -> 0 | Y14: =MAX($G14) -> 0 | Z14: =MAX($H14) -> 0
... A186: ./manifest | B186: 1 | C186: 0 | D186: 0 | E186: 10000 | F186: ok | G186: 5000 | H186: 1 | I186: =MIN($B186) -> 0 | J186: =MIN($C186) -> 0 | K186: =MIN($D186) -> 0 | L186: =MIN($E186) -> 0 | M186: =MIN($G186) -> 0 | N186: =MIN($H186) -> 0 | O186: =MEDIAN($B186) -> 0 | P186: =MEDIAN($C186) -> 0 | Q186: =MEDIAN($D186) -> 0 | R186: =MEDIAN($E186) -> 0 | S186: =MEDIAN($G186) -> 0 | T186: =MEDIAN($H186) -> 0 | U186: =MAX($B186) -> 0 | V186: =MAX($C186) -> 0 | W186: =MAX($D186) -> 0 | X186: =MAX($E186) -> 0 | Y186: =MAX($G186) -> 0 | Z186: =MAX($H186) -> 0
A188: SUM | B188: =SUM(B$3:B$186) -> 0 | C188: =SUM(C$3:C$186) -> 0 | D188: =SUM(D$3:D$186) -> 0 | E188: =SUM(E$3:E$186) -> 0 | G188: =SUM(G$3:G$186) -> 0 | H188: =SUM(H$3:H$186) -> 0 | I188: =SUM(I$3:I$186) -> 0 | J188: =SUM(J$3:J$186) -> 0 | K188: =SUM(K$3:K$186) -> 0 | L188: =SUM(L$3:L$186) -> 0 | M188: =SUM(M$3:M$186) -> 0 | N188: =SUM(N$3:N$186) -> 0 | ... Z188: =SUM(Z$3:Z$186) -> 0
A189: AVG | B189: =AVERAGE(B$3:B$186) -> 0 | C189: =AVERAGE(C$3:C$186) -> 0 | D189: =AVERAGE(D$3:D$186) -> 0 | E189: =AVERAGE(E$3:E$186) -> 0 | G189: =AVERAGE(G$3:G$186) -> 0 | H189: =AVERAGE(H$3:H$186) -> 0 | I189: =AVERAGE(I$3:I$186) -> 0 | J189: =AVERAGE(J$3:J$186) -> 0 | K189: =AVERAGE(K$3:K$186) -> 0 | L189: =AVERAGE(L$3:L$186) -> 0 | M189: =AVERAGE(M$3:M$186) -> 0 | N189: =AVERAGE(N$3:N$186) -> 0 | ... Z189: =AVERAGE(Z$3:Z$186) -> 0
A190: DEV | B190: =STDEV(B$3:B$186) -> 0 | C190: =STDEV(C$3:C$186) -> 0 | D190: =STDEV(D$3:D$186) -> 0 | E190: =STDEV(E$3:E$186) -> 0 | G190: =STDEV(G$3:G$186) -> 0 | H190: =STDEV(H$3:H$186) -> 0 | I190: =STDEV(I$3:I$186) -> 0 | J190: =STDEV(J$3:J$186) -> 0 | K190: =STDEV(K$3:K$186) -> 0 | L190: =STDEV(L$3:L$186) -> 0 | M190: =STDEV(M$3:M$186) -> 0 | N190: =STDEV(N$3:N$186) -> 0 | ... Z190: =STDEV(Z$3:Z$186) -> 0
A191: DST | B191: =SUMPRODUCT(--(B$3:B$186-$I$3:$I$186)^2)^0.5 -> 0 | C191: =SUMPRODUCT(--(C$3:C$186-$J$3:$J$186)^2)^0.5 -> 0 | D191: =SUMPRODUCT(--(D$3:D$186-$K$3:$K$186)^2)^0.5 -> 0 | E191: =SUMPRODUCT(--(E$3:E$186-$L$3:$L$186)^2)^0.5 -> 0 | G191: =SUMPRODUCT(--(G$3:G$186-$M$3:$M$186)^2)^0.5 -> 0 | H191: =SUMPRODUCT(--(H$3:H$186-$N$3:$N$186)^2)^0.5 -> 0
A192: BEST | B192: =SUMPRODUCT(NOT(ISBLANK(B$3:B$186))*(B$3:B$186=$I$3:$I$186)) -> 0 | C192: =SUMPRODUCT(NOT(ISBLANK(C$3:C$186))*(C$3:C$186=$J$3:$J$186)) -> 0 | D192: =SUMPRODUCT(NOT(ISBLANK(D$3:D$186))*(D$3:D$186=$K$3:$K$186)) -> 0 | E192: =SUMPRODUCT(NOT(ISBLANK(E$3:E$186))*(E$3:E$186=$L$3:$L$186)) -> 0 | G192: =SUMPRODUCT(NOT(ISBLANK(G$3:G$186))*(G$3:G$186=$M$3:$M$186)) -> 0 | H192: =SUMPRODUCT(NOT(ISBLANK(H$3:H$186))*(H$3:H$186=$N$3:$N$186)) -> 0
A193: BETTER | B193: =SUMPRODUCT(NOT(ISBLANK(B$3:B$186))*(B$3:B$186<$O$3:$O$186)) -> 0 | C193: =SUMPRODUCT(NOT(ISBLANK(C$3:C$186))*(C$3:C$186<$P$3:$P$186)) -> 0 | D193: =SUMPRODUCT(NOT(ISBLANK(D$3:D$186))*(D$3:D$186<$Q$3:$Q$186)) -> 0 | E193: =SUMPRODUCT(NOT(ISBLANK(E$3:E$186))*(E$3:E$186<$R$3:$R$186)) -> 0 | G193: =SUMPRODUCT(NOT(ISBLANK(G$3:G$186))*(G$3:G$186<$S$3:$S$186)) -> 0 | H193: =SUMPRODUCT(NOT(ISBLANK(H$3:H$186))*(H$3:H$186<$T$3:$T$186)) -> 0
A194: WORSE | B194: =SUMPRODUCT((NOT(ISBLANK(B$3:B$186))*(B$3:B$186>$O$3:$O$186))+ISBLANK(B$3:B$186)) -> 0 | C194: =SUMPRODUCT((NOT(ISBLANK(C$3:C$186))*(C$3:C$186>$P$3:$P$186))+ISBLANK(C$3:C$186)) -> 0 | D194: =SUMPRODUCT((NOT(ISBLANK(D$3:D$186))*(D$3:D$186>$Q$3:$Q$186))+ISBLANK(D$3:D$186)) -> 0 | E194: =SUMPRODUCT((NOT(ISBLANK(E$3:E$186))*(E$3:E$186>$R$3:$R$186))+ISBLANK(E$3:E$186)) -> 0 | G194: =SUMPRODUCT((NOT(ISBLANK(G$3:G$186))*(G$3:G$186>$S$3:$S$186))+ISBLANK(G$3:G$186)) -> 0 | H194: =SUMPRODUCT((NOT(ISBLANK(H$3:H$186))*(H$3:H$186>$T$3:$T$186))+ISBLANK(H$3:H$186)) -> 0
A195: WORST | B195: =SUMPRODUCT((NOT(ISBLANK(B$3:B$186))*(B$3:B$186=$U$3:$U$186))+ISBLANK(B$3:B$186)) -> 0 | C195: =SUMPRODUCT((NOT(ISBLANK(C$3:C$186))*(C$3:C$186=$V$3:$V$186))+ISBLANK(C$3:C$186)) -> 0 | D195: =SUMPRODUCT((NOT(ISBLANK(D$3:D$186))*(D$3:D$186=$W$3:$W$186))+ISBLANK(D$3:D$186)) -> 0 | E195: =SUMPRODUCT((NOT(ISBLANK(E$3:E$186))*(E$3:E$186=$X$3:$X$186))+ISBLANK(E$3:E$186)) -> 0 | G195: =SUMPRODUCT((NOT(ISBLANK(G$3:G$186))*(G$3:G$186=$Y$3:$Y$186))+ISBLANK(G$3:G$186)) -> 0 | H195: =SUMPRODUCT((NOT(ISBLANK(H$3:H$186))*(H$3:H$186=$Z$3:$Z$186))+ISBLANK(H$3:H$186)) -> 0

Sheet Merged Runs
A1: Merge criteria: | B1: clingo-5.8.0/one-as | I1: min | O1: median | U1: max
A2: median | B2: error | C2: mem | D2: memout | E2: par2 | F2: rstatus | G2: time | H2: timeout | I2: error | J2: mem | K2: memout | L2: par2 | M2: time | N2: timeout | O2: error | P2: mem | Q2: memout | R2: par2 | S2: time | T2: timeout | U2: error | V2: mem | W2: memout | X2: par2 | Y2: time | Z2: timeout
A3: ./10-145162646848673 | B3: {=_xlfn.SWITCH($A$2,"average", AVERAGE(Instances!B3:Instances!B3),"median", MEDIAN(Instances!B3:Instances!B3),"min", MIN(Instances!B3:Instances!B3),"max", MAX(Instances!B3:Instances!B3),"diff", MAX(Instances!B3:Instances!B3)-MIN(Instances!B3:Instances!B3))} -> 0 | C3: {=_xlfn.SWITCH($A$2,"average", AVERAGE(Instances!C3:Instances!C3),"median", MEDIAN(Instances!C3:Instances!C3),"min", MIN(Instances!C3:Instances!C3),"max", MAX(Instances!C3:Instances!C3),"diff", MAX(Instances!C3:Instances!C3)-MIN(Instances!C3:Instances!C3))} -> 0 | D3: {=_xlfn.SWITCH($A$2,"average", AVERAGE(Instances!D3:Instances!D3),"median", MEDIAN(Instances!D3:Instances!D3),"min", MIN(Instances!D3:Instances!D3),"max", MAX(Instances!D3:Instances!D3),"diff", MAX(Instances!D3:Instances!D3)-MIN(Instances!D3:Instances!D3))} -> 0 | E3: {=_xlfn.SWITCH($A$2,"average", AVERAGE(Instances!E3:Instances!E3),"median", MEDIAN(Instances!E3:Instances!E3),"min", MIN(Instances!E3:Instances!E3),"max", MAX(Instances!E3:Instances!E3),"diff", MAX(Instances!E3:Instances!E3)-MIN(Instances!E3:Instances!E3))} -> 0 | G3: {=_xlfn.SWITCH($A$2,"average", AVERAGE(Instances!G3:Instances!G3),"median", MEDIAN(Instances!G3:Instances!G3),"min", MIN(Instances!G3:Instances!G3),"max", MAX(Instances!G3:Instances!G3),"diff", MAX(Instances!G3:Instances!G3)-MIN(Instances!G3:Instances!G3))} -> 0 | H3: {=_xlfn.SWITCH($A$2,"average", AVERAGE(Instances!H3:Instances!H3),"median", MEDIAN(Instances!H3:Instances!H3),"min", MIN(Instances!H3:Instances!H3),"max", MAX(Instances!H3:Instances!H3),"diff", MAX(Instances!H3:Instances!H3)-MIN(Instances!H3:Instances!H3))} -> 0 | I3: =MIN($B3) -> 0 | J3: =MIN($C3) -> 0 | K3: =MIN($D3) -> 0 | L3: =MIN($E3) -> 0 | M3: =MIN($G3) -> 0 | N3: =MIN($H3) -> 0 | O3: =MEDIAN($B3) -> 0 | P3: =MEDIAN($C3) -> 0 | Q3: =MEDIAN($D3) -> 0 | R3: =MEDIAN($E3) -> 0 | S3: =MEDIAN($G3) -> 0 | T3: =MEDIAN($H3) -> 0 | U3: =MAX($B3) -> 0 | V3: =MAX($C3) -> 0 | W3: =MAX($D3) -> 0 | X3: =MAX($E3) -> 0 | Y3: =MAX($G3) -> 0 | Z3: =MAX($H3) -> 0
A4: ./10-17630975493234 | B4: {=_xlfn.SWITCH($A$2,"average", AVERAGE(Instances!B4:Instances!B4),"median", MEDIAN(Instances!B4:Instances!B4),"min", MIN(Instances!B4:Instances!B4),"max", MAX(Instances!B4:Instances!B4),"diff", MAX(Instances!B4:Instances!B4)-MIN(Instances!B4:Instances!B4))} -> 0 | C4: {=_xlfn.SWITCH($A$2,"average", AVERAGE(Instances!C4:Instances!C4),"median", MEDIAN(Instances!C4:Instances!C4),"min", MIN(Instances!C4:Instances!C4),"max", MAX(Instances!C4:Instances!C4),"diff", MAX(Instances!C4:Instances!C4)-MIN(Instances!C4:Instances!C4))} -> 0 | D4: {=_xlfn.SWITCH($A$2,"average", AVERAGE(Instances!D4:Instances!D4),"median", MEDIAN(Instances!D4:Instances!D4),"min", MIN(Instances!D4:Instances!D4),"max", MAX(Instances!D4:Instances!D4),"diff", MAX(Instances!D4:Instances!D4)-MIN(Instances!D4:Instances!D4))} -> 0 | E4: {=_xlfn.SWITCH($A$2,"average", AVERAGE(Instances!E4:Instances!E4),"median", MEDIAN(Instances!E4:Instances!E4),"min", MIN(Instances!E4:Instances!E4),"max", MAX(Instances!E4:Instances!E4),"diff", MAX(Instances!E4:Instances!E4)-MIN(Instances!E4:Instances!E4))} -> 0 | G4: {=_xlfn.SWITCH($A$2,"average", AVERAGE(Instances!G4:Instances!G4),"median", MEDIAN(Instances!G4:Instances!G4),"min", MIN(Instances!G4:Instances!G4),"max", MAX(Instances!G4:Instances!G4),"diff", MAX(Instances!G4:Instances!G4)-MIN(Instances!G4:Instances!G4))} -> 0 | H4: {=_xlfn.SWITCH($A$2,"average", AVERAGE(Instances!H4:Instances!H4),"median", MEDIAN(Instances!H4:Instances!H4),"min", MIN(Instances!H4:Instances!H4),"max", MAX(Instances!H4:Instances!H4),"diff", MAX(Instances!H4:Instances!H4)-MIN(Instances!H4:Instances!H4))} -> 0 | I4: =MIN($B4) -> 0 | J4: =MIN($C4) -> 0 | K4: =MIN($D4) -> 0 | L4: =MIN($E4) -> 0 | M4: =MIN($G4) -> 0 | N4: =MIN($H4) -> 0 | O4: =MEDIAN($B4) -> 0 | P4: =MEDIAN($C4) -> 0 | Q4: =MEDIAN($D4) -> 0 | R4: =MEDIAN($E4) -> 0 | S4: =MEDIAN($G4) -> 0 | T4: =MEDIAN($H4) -> 0 | U4: =MAX($B4) -> 0 | V4: =MAX($C4) -> 0 | W4: =MAX($D4) -> 0 | X4: =MAX($E4) -> 0 | Y4: =MAX($G4) -> 0 | Z4: =MAX($H4) -> 0
A5: ./10-18708915822629 | B5: {=_xlfn.SWITCH($A$2,"average", AVERAGE(Instances!B5:Instances!B5),"median", MEDIAN(Instances!B5:Instances!B5),"min", MIN(Instances!B5:Instances!B5),"max", MAX(Instances!B5:Instances!B5),"diff", MAX(Instances!B5:Instances!B5)-MIN(Instances!B5:Instances!B5))} -> 0 | C5: {=_xlfn.SWITCH($A$2,"average", AVERAGE(Instances!C5:Instances!C5),"median", MEDIAN(Instances!C5:Instances!C5),"min", MIN(Instances!C5:Instances!C5),"max", MAX(Instances!C5:Instances!C5),"diff", MAX(Instances!C5:Instances!C5)-MIN(Instances!C5:Instances!C5))} -> 0 | D5: {=_xlfn.SWITCH($A$2,"average", AVERAGE(Instances!D5:Instances!D5),"median", MEDIAN(Instances!D5:Instances!D5),"min", MIN(Instances!D5:Instances!D5),"max", MAX(Instances!D5:Instances!D5),"diff", MAX(Instances!D5:Instances!D5)-MIN(Instances!D5:Instances!D5))} -> 0 | E5: {=_xlfn.SWITCH($A$2,"average", AVERAGE(Instances!E5:Instances!E5),"median", MEDIAN(Instances!E5:Instances!E5),"min", MIN(Instances!E5:Instances!E5),"max", MAX(Instances!E5:Instances!E5),"diff", MAX(Instances!E5:Instances!E5)-MIN(Instances!E5:Instances!E5))} -> 0 | G5: {=_xlfn.SWITCH($A$2,"average", AVERAGE(Instances!G5:Instances!G5),"median", MEDIAN(Instances!G5:Instances!G5),"min", MIN(Instances!G5:Instances!G5),"max", MAX(Instances!G5:Instances!G5),"diff", MAX(Instances!G5:Instances!G5)-MIN(Instances!G5:Instances!G5))} -> 0 | H5: {=_xlfn.SWITCH($A$2,"average", AVERAGE(Instances!H5:Instances!H5),"median", MEDIAN(Instances!H5:Instances!H5),"min", MIN(Instances!H5:Instances!H5),"max", MAX(Instances!H5:Instances!H5),"diff", MAX(Instances!H5:Instances!H5)-MIN(Instances!H5:Instances!H5))} -> 0 | I5: =MIN($B5) -> 0 | J5: =MIN($C5) -> 0 | K5: =MIN($D5) -> 0 | L5: =MIN($E5) -> 0 | M5: =MIN($G5) -> 0 | N5: =MIN($H5) -> 0 | O5: =MEDIAN($B5) -> 0 | P5: =MEDIAN($C5) -> 0 | Q5: =MEDIAN($D5) -> 0 | R5: =MEDIAN($E5) -> 0 | S5: =MEDIAN($G5) -> 0 | T5: =MEDIAN($H5) -> 0 | U5: =MAX($B5) -> 0 | V5: =MAX($C5) -> 0 | W5: =MAX($D5) -> 0 | X5: =MAX($E5) -> 0 | Y5: =MAX($G5) -> 0 | Z5: =MAX($H5) -> 0
A6: ./10-282093612040832 | B6: {=_xlfn.SWITCH($A$2,"average", AVERAGE(Instances!B6:Instances!B6),"median", MEDIAN(Instances!B6:Instances!B6),"min", MIN(Instances!B6:Instances!B6),"max", MAX(Instances!B6:Instances!B6),"diff", MAX(Instances!B6:Instances!B6)-MIN(Instances!B6:Instances!B6))} -> 0 | C6: {=_xlfn.SWITCH($A$2,"average", AVERAGE(Instances!C6:Instances!C6),"median", MEDIAN(Instances!C6:Instances!C6),"min", MIN(Instances!C6:Instances!C6),"max", MAX(Instances!C6:Instances!C6),"diff", MAX(Instances!C6:Instances!C6)-MIN(Instances!C6:Instances!C6))} -> 0 | D6: {=_xlfn.SWITCH($A$2,"average", AVERAGE(Instances!D6:Instances!D6),"median", MEDIAN(Instances!D6:Instances!D6),"min", MIN(Instances!D6:Instances!D6),"max", MAX(Instances!D6:Instances!D6),"diff", MAX(Instances!D6:Instances!D6)-MIN(Instances!D6:Instances!D6))} -> 0 | E6: {=_xlfn.SWITCH($A$2,"average", AVERAGE(Instances!E6:Instances!E6),"median", MEDIAN(Instances!E6:Instances!E6),"min", MIN(Instances!E6:Instances!E6),"max", MAX(Instances!E6:Instances!E6),"diff", MAX(Instances!E6:Instances!E6)-MIN(Instances!E6:Instances!E6))} -> 0 | G6: {=_xlfn.SWITCH($A$2,"average", AVERAGE(Instances!G6:Instances!G6),"median", MEDIAN(Instances!G6:Instances!G6),"min", MIN(Instances!G6:Instances!G6),"max", MAX(Instances!G6:Instances!G6),"diff", MAX(Instances!G6:Instances!G6)-MIN(Instances!G6:Instances!G6))} -> 0 | H6: {=_xlfn.SWITCH($A$2,"average", AVERAGE(Instances!H6:Instances!H6),"median", MEDIAN(Instances!H6:Instances!H6),"min", MIN(Instances!H6:Instances!H6),"max", MAX(Instances!H6:Instances!H6),"diff", MAX(Instances!H6:Instances!H6)-MIN(Instances!H6:Instances!H6))} -> 0 | I6: =MIN($B6) -> 0 | J6: =MIN($C6) -> 0 | K6: =MIN($D6) -> 0 | L6: =MIN($E6) -> 0 | M6: =MIN($G6) -> 0 | N6: =MIN($H6) -> 0 | O6: =MEDIAN($B6) -> 0 | P6: =MEDIAN($C6) -> 0 | Q6: =MEDIAN($D6) -> 0 | R6: =MEDIAN($E6) -> 0 | S6: =MEDIAN($G6) -> 0 | T6: =MEDIAN($H6) -> 0 | U6: =MAX($B6) -> 0 | V6: =MAX($C6) -> 0 | W6: =MAX($D6) -> 0 | X6: =MAX($E6) -> 0 | Y6: =MAX($G6) -> 0 | Z6: =MAX($H6) -> 0
A7: ./10-283712654672237 | B7: {=_xlfn.SWITCH($A$2,"average", AVERAGE(Instances!B7:Instances!B7),"median", MEDIAN(Instances!B7:Instances!B7),"min", MIN(Instances!B7:Instances!B7),"max", MAX(Instances!B7:Instances!B7),"diff", MAX(Instances!B7:Instances!B7)-MIN(Instances!B7:Instances!B7))} -> 0 | C7: {=_xlfn.SWITCH($A$2,"average", AVERAGE(Instances!C7:Instances!C7),"median", MEDIAN(Instances!C7:Instances!C7),"min", MIN(Instances!C7:Instances!C7),"max", MAX(Instances!C7:Instances!C7),"diff", MAX(Instances!C7:Instances!C7)-MIN(Instances!C7:Instances!C7))} -> 0 | D7: {=_xlfn.SWITCH($A$2,"average", AVERAGE(Instances!D7:Instances!D7),"median", MEDIAN(Instances!D7:Instances!D7),"min", MIN(Instances!D7:Instances!D7),"max", MAX(Instances!D7:Instances!D7),"diff", MAX(Instances!D7:Instances!D7)-MIN(Instances!D7:Instances!D7))} -> 0 | E7: {=_xlfn.SWITCH($A$2,"average", AVERAGE(Instances!E7:Instances!E7),"median", MEDIAN(Instances!E7:Instances!E7),"min", MIN(Instances!E7:Instances!E7),"max", MAX(Instances!E7:Instances!E7),"diff", MAX(Instances!E7:Instances!E7)-MIN(Instances!E7:Instances!E7))} -> 0 | G7: {=_xlfn.SWITCH($A$2,"average", AVERAGE(Instances!G7:Instances!G7),"median", MEDIAN(Instances!G7:Instances!G7),"min", MIN(Instances!G7:Instances!G7),"max", MAX(Instances!G7:Instances!G7),"diff", MAX(Instances!G7:Instances!G7)-MIN(Instances!G7:Instances!G7))} -> 0 | H7: {=_xlfn.SWITCH($A$2,"average", AVERAGE(Instances!H7:Instances!H7),"median", MEDIAN(Instances!H7:Instances!H7),"min", MIN(Instances!H7:Instances!H7),"max", MAX(Instances!H7:Instances!H7),"diff", MAX(Instances!H7:Instances!H7)-MIN(Instances!H7:Instances!H7))} -> 0 | I7: =MIN($B7) -> 0 | J7: =MIN($C7) -> 0 | K7: =MIN($D7) -> 0 | L7: =MIN($E7) -> 0 | M7: =MIN($G7) -> 0 | N7: =MIN($H7) -> 0 | O7: =MEDIAN($B7) -> 0 | P7: =MEDIAN($C7) -> 0 | Q7: =MEDIAN($D7) -> 0 | R7: =MEDIAN($E7) -> 0 | S7: =MEDIAN($G7) -> 0 | T7: =MEDIAN($H7) -> 0 | U7: =MAX($B7) -> 0 | V7: =MAX($C7) -> 0 | W7: =MAX($D7) -> 0 | X7: =MAX($E7) -> 0 | Y7: =MAX($G7) -> 0 | Z7: =MAX($H7) -> 0
A8: ./10-611399871496200 | B8: {=_xlfn.SWITCH($A$2,"average", AVERAGE(Instances!B8:Instances!B8),"median", MEDIAN(Instances!B8:Instances!B8),"min", MIN(Instances!B8:Instances!B8),"max", MAX(Instances!B8:Instances!B8),"diff", MAX(Instances!B8:Instances!B8)-MIN(Instances!B8:Instances!B8))} -> 0 | C8: {=_xlfn.SWITCH($A$2,"average", AVERAGE(Instances!C8:Instances!C8),"median", MEDIAN(Instances!C8:Instances!C8),"min", MIN(Instances!C8:Instances!C8),"max", MAX(Instances!C8:Instances!C8),"diff", MAX(Instances!C8:Instances!C8)-MIN(Instances!C8:Instances!C8))} -> 0 | D8: {=_xlfn.SWITCH($A$2,"average", AVERAGE(Instances!D8:Instances!D8),"median", MEDIAN(Instances!D8:Instances!D8),"min", MIN(Instances!D8:Instances!D8),"max", MAX(Instances!D8:Instances!D8),"diff", MAX(Instances!D8:Instances!D8)-MIN(Instances!D8:Instances!D8))} -> 0 | E8: {=_xlfn.SWITCH($A$2,"average", AVERAGE(Instances!E8:Instances!E8),"median", MEDIAN(Instances!E8:Instances!E8),"min", MIN(Instances!E8:Instances!E8),"max", MAX(Instances!E8:Instances!E8),"diff", MAX(Instances!E8:Instances!E8)-MIN(Instances!E8:Instances!E8))} -> 0 | G8: {=_xlfn.SWITCH($A$2,"average", AVERAGE(Instances!G8:Instances!G8),"median", MEDIAN(Instances!G8:Instances!G8),"min", MIN(Instances!G8:Instances!G8),"max", MAX(Instances!G8:Instances!G8),"diff", MAX(Instances!G8:Instances!G8)-MIN(Instances!G8:Instances!G8))} -> 0 | H8: {=_xlfn.SWITCH($A$2,"average", AVERAGE(Instances!H8:Instances!H8),"median", MEDIAN(Instances!H8:Instances!H8),"min", MIN(Instances!H8:Instances!H8),"max", MAX(Instances!H8:Instances!H8),"diff", MAX(Instances!H8:Instances!H8)-MIN(Instances!H8:Instances!H8))} -> 0 | I8: =MIN($B8) -> 0 | J8: =MIN($C8) -> 0 | K8: =MIN($D8) -> 0 | L8: =MIN($E8) -> 0 | M8: =MIN($G8) -> 0 | N8: =MIN($H8) -> 0 | O8: =MEDIAN($B8) -> 0 | P8: =MEDIAN($C8) -> 0 | Q8: =MEDIAN($D8) -> 0 | R8: =MEDIAN($E8) -> 0 | S8: =MEDIAN($G8) -> 0 | T8: =MEDIAN($H8) -> 0 | U8: =MAX($B8) -> 0 | V8: =MAX($C8) -> 0 | W8: =MAX($D8) -> 0 | X8: =MAX($E8) -> 0 | Y8: =MAX($G8) -> 0 | Z8: =MAX($H8) -> 0
A9: ./10-703945206928000 | B9: {=_xlfn.SWITCH($A$2,"average", AVERAGE(Instances!B9:Instances!B9),"median", MEDIAN(Instances!B9:Instances!B9),"min", MIN(Instances!B9:Instances!B9),"max", MAX(Instances!B9:Instances!B9),"diff", MAX(Instances!B9:Instances!B9)-MIN(Instances!B9:Instances!B9))} -> 0 | C9: {=_xlfn.SWITCH($A$2,"average", AVERAGE(Instances!C9:Instances!C9),"median", MEDIAN(Instances!C9:Instances!C9),"min", MIN(Instances!C9:Instances!C9),"max", MAX(Instances!C9:Instances!C9),"diff", MAX(Instances!C9:Instances!C9)-MIN(Instances!C9:Instances!C9))} -> 0 | D9: {=_xlfn.SWITCH($A$2,"average", AVERAGE(Instances!D9:Instances!D9),"median", MEDIAN(Instances!D9:Instances!D9),"min", MIN(Instances!D9:Instances!D9),"max", MAX(Instances!D9:Instances!D9),"diff", MAX(Instances!D9:Instances!D9)-MIN(Instances!D9:Instances!D9))} -> 0 | E9: {=_xlfn.SWITCH($A$2,"average", AVERAGE(Instances!E9:Instances!E9),"median", MEDIAN(Instances!E9:Instances!E9),"min", MIN(Instances!E9:Instances!E9),"max", MAX(Instances!E9:Instances!E9),"diff", MAX(Instances!E9:Instances!E9)-MIN(Instances!E9:Instances!E9))} -> 0 | G9: {=_xlfn.SWITCH($A$2,"average", AVERAGE(Instances!G9:Instances!G9),"median", MEDIAN(Instances!G9:Instances!G9),"min", MIN(Instances!G9:Instances!G9),"max", MAX(Instances!G9:Instances!G9),"diff", MAX(Instances!G9:Instances!G9)-MIN(Instances!G9:Instances!G9))} -> 0 | H9: {=_xlfn.SWITCH($A$2,"average", AVERAGE(Instances!H9:Instances!H9),"median", MEDIAN(Instances!H9:Instances!H9),"min", MIN(Instances!H9:Instances!H9),"max", MAX(Instances!H9:Instances!H9),"diff", MAX(Instances!H9:Instances!H9)-MIN(Instances!H9:Instances!H9))} -> 0 | I9: =MIN($B9) -> 0 | J9: =MIN($C9) -> 0 | K9: =MIN($D9) -> 0 | L9: =MIN($E9) -> 0 | M9: =MIN($G9) -> 0 | N9: =MIN($H9) -> 0 | O9: =MEDIAN($B9) -> 0 | P9: =MEDIAN($C9) -> 0 | Q9: =MEDIAN($D9) -> 0 | R9: =MEDIAN($E9) -> 0 | S9: =MEDIAN($G9) -> 0 | T9: =MEDIAN($H9) -> 0 | U9: =MAX($B9) -> 0 | V9: =MAX($C9) -> 0 | W9: =MAX($D9) -> 0 | X9: =MAX($E9) -> 0 | Y9: =MAX($G9) -> 0 | Z9: =MAX($H9) -> 0
A10: ./11-142936786347061 | B10: {=_xlfn.SWITCH($A$2,"average", AVERAGE(Instances!B10:Instances!B10),"median", MEDIAN(Instances!B10:Instances!B10),"min", MIN(Instances!B10:Instances!B10),"max", MAX(Instances!B10:Instances!B10),"diff", MAX(Instances!B10:Instances!B10)-MIN(Instances!B10:Instances!B10))} -> 0 | C10: {=_xlfn.SWITCH($A$2,"average", AVERAGE(Instances!C10:Instances!C10),"median", MEDIAN(Instances!C10:Instances!C10),"min", MIN(Instances!C10:Instances!C10),"max", MAX(Instances!C10:Instances!C10),"diff", MAX(Instances!C10:Instances!C10)-MIN(Instances!C10:Instances!C10))} -> 0 | D10: {=_xlfn.SWITCH($A$2,"average", AVERAGE(Instances!D10:Instances!D10),"median", MEDIAN(Instances!D10:Instances!D10),"min", MIN(Instances!D10:Instances!D10),"max", MAX(Instances!D10:Instances!D10),"diff", MAX(Instances!D10:Instances!D10)-MIN(Instances!D10:Instances!D10))} -> 0 | E10: {=_xlfn.SWITCH($A$2,"average", AVERAGE(Instances!E10:Instances!E10),"median", MEDIAN(Instances!E10:Instances!E10),"min", MIN(Instances!E10:Instances!E10),"max", MAX(Instances!E10:Instances!E10),"diff", MAX(Instances!E10:Instances!E10)-MIN(Instances!E10:Instances!E10))} -> 0 | G10: {=_xlfn.SWITCH($A$2,"average", AVERAGE(Instances!G10:Instances!G10),"median", MEDIAN(Instances!G10:Instances!G10),"min", MIN(Instances!G10:Instances!G10),"max", MAX(Instances!G10:Instances!G10),"diff", MAX(Instances!G10:Instances!G10)-MIN(Instances!G10:Instances!G10))} -> 0 | H10: {=_xlfn.SWITCH($A$2,"average", AVERAGE(Instances!H10:Instances!H10),"median", MEDIAN(Instances!H10:Instances!H10),"min", MIN(Instances!H10:Instances!H10),"max", MAX(Instances!H10:Instances!H10),"diff", MAX(Instances!H10:Instances!H10)-MIN(Instances!H10:Instances!H10))} -> 0 | I10: =MIN($B10) -> 0 | J10: =MIN($C10) -> 0 | K10: =MIN($D10) -> 0 | L10: =MIN($E10) -> 0 | M10: =MIN($G10) -> 0 | N10: =MIN($H10) -> 0 | O10: =MEDIAN($B10) -> 0 | P10: =MEDIAN($C10) -> 0 | Q10: =MEDIAN($D10) -> 0 | R10: =MEDIAN($E10) -> 0 | S10: =MEDIAN($G10) -> 0 | T10: =MEDIAN($H10) -> 0 | U10: =MAX($B10) -> 0 | V10: =MAX($C10) -> 0 | W10: =MAX($D10) -> 0 | X10: =MAX($E10) -> 0 | Y10: =MAX($G10) -> 0 | Z10: =MAX($H10) -> 0
A11: ./11-142992641884424 | B11: {=_xlfn.SWITCH($A$2,"average", AVERAGE(Instances!B11:Instances!B11),"median", MEDIAN(Instances!B11:Instances!B11),"min", MIN(Instances!B11:Instances!B11),"max", MAX(Instances!B11:Instances!B11),"diff", MAX(Instances!B11:Instances!B11)-MIN(Instances!B11:Instances!B11))} -> 0 | C11: {=_xlfn.SWITCH($A$2,"average", AVERAGE(Instances!C11:Instances!C11),"median", MEDIAN(Instances!C11:Instances!C11),"min", MIN(Instances!C11:Instances!C11),"max", MAX(Instances!C11:Instances!C11),"diff", MAX(Instances!C11:Instances!C11)-MIN(Instances!C11:Instances!C11))} -> 0 | D11: {=_xlfn.SWITCH($A$2,"average", AVERAGE(Instances!D11:Instances!D11),"median", MEDIAN(Instances!D11:Instances!D11),"min", MIN(Instances!D11:Instances!D11),"max", MAX(Instances!D11:Instances!D11),"diff", MAX(Instances!D11:Instances!D11)-MIN(Instances!D11:Instances!D11))} -> 0 | E11: {=_xlfn.SWITCH($A$2,"average", AVERAGE(Instances!E11:Instances!E11),"median", MEDIAN(Instances!E11:Instances!E11),"min", MIN(Instances!E11:Instances!E11),"max", MAX(Instances!E11:Instances!E11),"diff", MAX(Instances!E11:Instances!E11)-MIN(Instances!E11:Instances!E11))} -> 0 | G11: {=_xlfn.SWITCH($A$2,"average", AVERAGE(Instances!G11:Instances!G11),"median", MEDIAN(Instances!G11:Instances!G11),"min", MIN(Instances!G11:Instances!G11),"max", MAX(Instances!G11:Instances!G11),"diff", MAX(Instances!G11:Instances!G11)-MIN(Instances!G11:Instances!G11))} -> 0 | H11: {=_xlfn.SWITCH($A$2,"average", AVERAGE(Instances!H11:Instances!H11),"median", MEDIAN(Instances!H11:Instances!H11),"min", MIN(Instances!H11:Instances!H11),"max", MAX(Instances!H11:Instances!H11),"diff", MAX(Instances!H11:Instances!H11)-MIN(Instances!H11:Instances!H11))} -> 0 | I11: =MIN($B11) -> 0 | J11: =MIN($C11) -> 0 | K11: =MIN($D11) -> 0 | L11: =MIN($E11) -> 0 | M11: =MIN($G11) -> 0 | N11: =MIN($H11) -> 0 | O11: =MEDIAN($B11) -> 0 | P11: =MEDIAN($C11) -> 0 | Q11: =MEDIAN($D11) -> 0 | R11: =MEDIAN($E11) -> 0 | S11: =MEDIAN($G11) -> 0 | T11: =MEDIAN($H11) -> 0 | U11: =MAX($B11) -> 0 | V11: =MAX($C11) -> 0 | W11: =MAX($D11) -> 0 | X11: =MAX($E11) -> 0 | Y11: =MAX($G11) -> 0 | Z11: =MAX($H11) -> 0
A12: ./11-302094043054658 | B12: {=_xlfn.SWITCH($A$2,"average", AVERAGE(Instances!B12:Instances!B12),"median", MEDIAN(Instances!B12:Instances!B12),"min", MIN(Instances!B12:Instances!B12),"max", MAX(Instances!B12:Instances!B12),"diff", MAX(Instances!B12:Instances!B12)-MIN(Instances!B12:Instances!B12))} -> 0 | C12: {=_xlfn.SWITCH($A$2,"average", AVERAGE(Instances!C12:Instances!C12),"median", MEDIAN(Instances!C12:Instances!C12),"min", MIN(Instances!C12:Instances!C12),"max", MAX(Instances!C12:Instances!C12),"diff", MAX(Instances!C12:Instances!C12)-MIN(Instances!C12:Instances!C12))} -> 0 | D12: {=_xlfn.SWITCH($A$2,"average", AVERAGE(Instances!D12:Instances!D12),"median", MEDIAN(Instances!D12:Instances!D12),"min", MIN(Instances!D12:Instances!D12),"max", MAX(Instances!D12:Instances!D12),"diff", MAX(Instances!D12:Instances!D12)-MIN(Instances!D12:Instances!D12))} -> 0 | E12: {=_xlfn.SWITCH($A$2,"average", AVERAGE(Instances!E12:Instances!E12),"median", MEDIAN(Instances!E12:Instances!E12),"min", MIN(Instances!E12:Instances!E12),"max", MAX(Instances!E12:Instances!E12),"diff", MAX(Instances!E12:Instances!E12)-MIN(Instances!E12:Instances!E12))} -> 0 | G12: {=_xlfn.SWITCH($A$2,"average", AVERAGE(Instances!G12:Instances!G12),"median", MEDIAN(Instances!G12:Instances!G12),"min", MIN(Instances!G12:Instances!G12),"max", MAX(Instances!G12:Instances!G12),"diff", MAX(Instances!G12:Instances!G12)-MIN(Instances!G12:Instances!G12))} -> 0 | H12: {=_xlfn.SWITCH($A$2,"average", AVERAGE(Instances!H12:Instances!H12),"median", MEDIAN(Instances!H12:Instances!H12),"min", MIN(Instances!H12:Instances!H12),"max", MAX(Instances!H12:Instances!H12),"diff", MAX(Instances!H12:Instances!H12)-MIN(Instances!H12:Instances!H12))} -> 0 | I12: =MIN($B12) -> 0 | J12: =MIN($C12) -> 0 | K12: =MIN($D12) -> 0 | L12: =MIN($E12) -> 0 | M12: =MIN($G12) -> 0 | N12: =MIN($H12) -> 0 | O12: =MEDIAN($B12) -> 0 | P12: =MEDIAN($C12) -> 0 | Q12: =MEDIAN($D12) -> 0 | R12: =MEDIAN($E12) -> 0 | S12: =MEDIAN($G12) -> 0 | T12: =MEDIAN($H12) -> 0 | U12: =MAX($B12) -> 0 | V12: =MAX($C12) -> 0 | W12: =MAX($D12) -> 0 | X12: =MAX($E12) -> 0 | Y12: =MAX($G12) -> 0 | Z12: =MAX($H12) -> 0
A13: ./11-563345380114560 | B13: {=_xlfn.SWITCH($A$2,"average", AVERAGE(Instances!B13:Instances!B13),"median", MEDIAN(Instances!B13:Instances!B13),"min", MIN(Instances!B13:Instances!B13),"max", MAX(Instances!B13:Instances!B13),"diff", MAX(Instances!B13:Instances!B13)-MIN(Instances!B13:Instances!B13))} -> 0 | C13: {=_xlfn.SWITCH($A$2,"average", AVERAGE(Instances!C13:Instances!C13),"median", MEDIAN(Instances!C13:Instances!C13),"min", MIN(Instances!C13:Instances!C13),"max", MAX(Instances!C13:Instances!C13),"diff", MAX(Instances!C13:Instances!C13)-MIN(Instances!C13:Instances!C13))} -> 0 | D13: {=_xlfn.SWITCH($A$2,"average", AVERAGE(Instances!D13:Instances!D13),"median", MEDIAN(Instances!D13:Instances!D13),"min", MIN(Instances!D13:Instances!D13),"max", MAX(Instances!D13:Instances!D13),"diff", MAX(Instances!D13:Instances!D13)-MIN(Instances!D13:Instances!D13))} -> 0 | E13: {=_xlfn.SWITCH($A$2,"average", AVERAGE(Instances!E13:Instances!E13),"median", MEDIAN(Instances!E13:Instances!E13),"min", MIN(Instances!E13:Instances!E13),"max", MAX(Instances!E13:Instances!E13),"diff", MAX(Instances!E13:Instances!E13)-MIN(Instances!E13:Instances!E13))} -> 0 | G13: {=_xlfn.SWITCH($A$2,"average", AVERAGE(Instances!G13:Instances!G13),"median", MEDIAN(Instances!G13:Instances!G13),"min", MIN(Instances!G13:Instances!G13),"max", MAX(Instances!G13:Instances!G13),"diff", MAX(Instances!G13:Instances!G13)-MIN(Instances!G13:Instances!G13))} -> 0 | H13: {=_xlfn.SWITCH($A$2,"average", AVERAGE(Instances!H13:Instances!H13),"median", MEDIAN(Instances!H13:Instances!H13),"min", MIN(Instances!H13:Instances!H13),"max", MAX(Instances!H13:Instances!H13),"diff", MAX(Instances!H13:Instances!H13)-MIN(Instances!H13:Instances!H13))} -> 0 | I13: =MIN($B13) -> 0 | J13: =MIN($C13) -> 0 | K13: =MIN($D13) -> 0 | L13: =MIN($E13) -> 0 | M13: =MIN($G13) -> 0 | N13: =MIN($H13) -> 0 | O13: =MEDIAN($B13) -> 0 | P13: =MEDIAN($C13) -> 0 | Q13: =MEDIAN($D13) -> 0 | R13: =MEDIAN($E13) -> 0 | S13: =MEDIAN($G13) -> 0 | T13: =MEDIAN($H13) -> 0 | U13: =MAX($B13) -> 0 | V13: =MAX($C13) -> 0 | W13: =MAX($D13) -> 0 | X13: =MAX($E13) -> 0 | Y13: =MAX($G13) -> 0 | Z13: =MAX($H13) -> 0
A14: ./11-567405982269522 | B14: {=_xlfn.SWITCH($A$2,"average", AVERAGE(Instances!B14:Instances!B14),"median", MEDIAN(Instances!B14:Instances!B14),"min", MIN(Instances!B14:Instances!B14),"max", MAX(Instances!B14:Instances!B14),"diff", MAX(Instances!B14:Instances!B14)-MIN(Instances!B14:Instances!B14))} -> 0 | C14: {=_xlfn.SWITCH($A$2,"average", AVERAGE(Instances!C14:Instances!C14),"median", MEDIAN(Instances!C14:Instances!C14),"min", MIN(Instances!C14:Instances!C14),"max", MAX(Instances!C14:Instances!C14),"diff", MAX(Instances!C14:Instances!C14)-MIN(Instances!C14:Instances!C14))} -> 0 | D14: {=_xlfn.SWITCH($A$2,"average", AVERAGE(Instances!D14:Instances!D14),"median", MEDIAN(Instances!D14:Instances!D14),"min", MIN(Instances!D14:Instances!D14),"max", MAX(Instances!D14:Instances!D14),"diff", MAX(Instances!D14:Instances!D14)-MIN(Instances!D14:Instances!D14))} -> 0 | E14: {=_xlfn.SWITCH($A$2,"average", AVERAGE(Instances!E14:Instances!E14),"median", MEDIAN(Instances!E14:Instances!E14),"min", MIN(Instances!E14:Instances!E14),"max", MAX(Instances!E14:Instances!E14),"diff", MAX(Instances!E14:Instances!E14)-MIN(Instances!E14:Instances!E14))} -> 0 | G14: {=_xlfn.SWITCH($A$2,"average", AVERAGE(Instances!G14:Instances!G14),"median", MEDIAN(Instances!G14:Instances!G14),"min", MIN(Instances!G14:Instances!G14),"max", MAX(Instances!G14:Instances!G14),"diff", MAX(Instances!G14:Instances!G14)-MIN(Instances!G14:Instances!G14))} -> 0 | H14: {=_xlfn.SWITCH($A$2,"average", AVERAGE(Instances!H14:Instances!H14),"median", MEDIAN(Instances!H14:Instances!H14),"min", MIN(Instances!H14:Instances!H14),"max", MAX(Instances!H14:Instances!H14),"diff", MAX(Instances!H14:Instances!H14)-MIN(Instances!H14:Instances!H14))} -> 0 | I14: =MIN($B14) -> 0 | J14: =MIN($C14) -> 0 | K14: =MIN($D14) -> 0 | L14: =MIN($E14) -> 0 | M14: =MIN($G14) -> 0 | N14: =MIN($H14) -> 0 | O14: =MEDIAN($B14) -> 0 | P14: =MEDIAN($C14) -> 0 | Q14: =MEDIAN($D14) -> 0 | R14: =MEDIAN($E14) -> 0 | S14: =MEDIAN($G14) -> 0 | T14: =MEDIAN($H14) -> 0 | U14: =MAX($B14) -> 0 | V14: =MAX($C14) -> 0 | W14: =MAX($D14) -> 0 | X14: =MAX($E14) -> 0 | Y14: =MAX($G14) -> 0 | Z14: =MAX($H14) -> 0
... A186: ./manifest | B186: {=_xlfn.SWITCH($A$2,"average", AVERAGE(Instances!B186:Instances!B186),"median", MEDIAN(Instances!B186:Instances!B186),"min", MIN(Instances!B186:Instances!B186),"max", MAX(Instances!B186:Instances!B186),"diff", MAX(Instances!B186:Instances!B186)-MIN(Instances!B186:Instances!B186))} -> 0 | C186: {=_xlfn.SWITCH($A$2,"average", AVERAGE(Instances!C186:Instances!C186),"median", MEDIAN(Instances!C186:Instances!C186),"min", MIN(Instances!C186:Instances!C186),"max", MAX(Instances!C186:Instances!C186),"diff", MAX(Instances!C186:Instances!C186)-MIN(Instances!C186:Instances!C186))} -> 0 | D186: {=_xlfn.SWITCH($A$2,"average", AVERAGE(Instances!D186:Instances!D186),"median", MEDIAN(Instances!D186:Instances!D186),"min", MIN(Instances!D186:Instances!D186),"max", MAX(Instances!D186:Instances!D186),"diff", MAX(Instances!D186:Instances!D186)-MIN(Instances!D186:Instances!D186))} -> 0 | E186: {=_xlfn.SWITCH($A$2,"average", AVERAGE(Instances!E186:Instances!E186),"median", MEDIAN(Instances!E186:Instances!E186),"min", MIN(Instances!E186:Instances!E186),"max", MAX(Instances!E186:Instances!E186),"diff", MAX(Instances!E186:Instances!E186)-MIN(Instances!E186:Instances!E186))} -> 0 | G186: {=_xlfn.SWITCH($A$2,"average", AVERAGE(Instances!G186:Instances!G186),"median", MEDIAN(Instances!G186:Instances!G186),"min", MIN(Instances!G186:Instances!G186),"max", MAX(Instances!G186:Instances!G186),"diff", MAX(Instances!G186:Instances!G186)-MIN(Instances!G186:Instances!G186))} -> 0 | H186: {=_xlfn.SWITCH($A$2,"average", AVERAGE(Instances!H186:Instances!H186),"median", MEDIAN(Instances!H186:Instances!H186),"min", MIN(Instances!H186:Instances!H186),"max", MAX(Instances!H186:Instances!H186),"diff", MAX(Instances!H186:Instances!H186)-MIN(Instances!H186:Instances!H186))} -> 0 | I186: =MIN($B186) -> 0 | J186: =MIN($C186) -> 0 | K186: =MIN($D186) -> 0 | L186: =MIN($E186) -> 0 | M186: =MIN($G186) -> 0 | N186: =MIN($H186) -> 0 | O186: =MEDIAN($B186) -> 0 | P186: =MEDIAN($C186) -> 0 | Q186: =MEDIAN($D186) -> 0 | R186: =MEDIAN($E186) -> 0 | S186: =MEDIAN($G186) -> 0 | T186: =MEDIAN($H186) -> 0 | U186: =MAX($B186) -> 0 | V186: =MAX($C186) -> 0 | W186: =MAX($D186) -> 0 | X186: =MAX($E186) -> 0 | Y186: =MAX($G186) -> 0 | Z186: =MAX($H186) -> 0
A188: SUM | B188: =SUM(B$3:B$186) -> 0 | C188: =SUM(C$3:C$186) -> 0 | D188: =SUM(D$3:D$186) -> 0 | E188: =SUM(E$3:E$186) -> 0 | G188: =SUM(G$3:G$186) -> 0 | H188: =SUM(H$3:H$186) -> 0 | I188: =SUM(I$3:I$186) -> 0 | J188: =SUM(J$3:J$186) -> 0 | K188: =SUM(K$3:K$186) -> 0 | L188: =SUM(L$3:L$186) -> 0 | M188: =SUM(M$3:M$186) -> 0 | N188: =SUM(N$3:N$186) -> 0 | ... Z188: =SUM(Z$3:Z$186) -> 0
A189: AVG | B189: =AVERAGE(B$3:B$186) -> 0 | C189: =AVERAGE(C$3:C$186) -> 0 | D189: =AVERAGE(D$3:D$186) -> 0 | E189: =AVERAGE(E$3:E$186) -> 0 | G189: =AVERAGE(G$3:G$186) -> 0 | H189: =AVERAGE(H$3:H$186) -> 0 | I189: =AVERAGE(I$3:I$186) -> 0 | J189: =AVERAGE(J$3:J$186) -> 0 | K189: =AVERAGE(K$3:K$186) -> 0 | L189: =AVERAGE(L$3:L$186) -> 0 | M189: =AVERAGE(M$3:M$186) -> 0 | N189: =AVERAGE(N$3:N$186) -> 0 | ... Z189: =AVERAGE(Z$3:Z$186) -> 0
A190: DEV | B190: =STDEV(B$3:B$186) -> 0 | C190: =STDEV(C$3:C$186) -> 0 | D190: =STDEV(D$3:D$186) -> 0 | E190: =STDEV(E$3:E$186) -> 0 | G190: =STDEV(G$3:G$186) -> 0 | H190: =STDEV(H$3:H$186) -> 0 | I190: =STDEV(I$3:I$186) -> 0 | J190: =STDEV(J$3:J$186) -> 0 | K190: =STDEV(K$3:K$186) -> 0 | L190: =STDEV(L$3:L$186) -> 0 | M190: =STDEV(M$3:M$186) -> 0 | N190: =STDEV(N$3:N$186) -> 0 | ... Z190: =STDEV(Z$3:Z$186) -> 0
A191: DST | B191: =SUMPRODUCT(--(B$3:B$186-$I$3:$I$186)^2)^0.5 -> 0 | C191: =SUMPRODUCT(--(C$3:C$186-$J$3:$J$186)^2)^0.5 -> 0 | D191: =SUMPRODUCT(--(D$3:D$186-$K$3:$K$186)^2)^0.5 -> 0 | E191: =SUMPRODUCT(--(E$3:E$186-$L$3:$L$186)^2)^0.5 -> 0 | G191: =SUMPRODUCT(--(G$3:G$186-$M$3:$M$186)^2)^0.5 -> 0 | H191: =SUMPRODUCT(--(H$3:H$186-$N$3:$N$186)^2)^0.5 -> 0
A192: BEST | B192: =SUMPRODUCT(NOT(ISBLANK(B$3:B$186))*(B$3:B$186=$I$3:$I$186)) -> 0 | C192: =SUMPRODUCT(NOT(ISBLANK(C$3:C$186))*(C$3:C$186=$J$3:$J$186)) -> 0 | D192: =SUMPRODUCT(NOT(ISBLANK(D$3:D$186))*(D$3:D$186=$K$3:$K$186)) -> 0 | E192: =SUMPRODUCT(NOT(ISBLANK(E$3:E$186))*(E$3:E$186=$L$3:$L$186)) -> 0 | G192: =SUMPRODUCT(NOT(ISBLANK(G$3:G$186))*(G$3:G$186=$M$3:$M$186)) -> 0 | H192: =SUMPRODUCT(NOT(ISBLANK(H$3:H$186))*(H$3:H$186=$N$3:$N$186)) -> 0
A193: BETTER | B193: =SUMPRODUCT(NOT(ISBLANK(B$3:B$186))*(B$3:B$186<$O$3:$O$186)) -> 0 | C193: =SUMPRODUCT(NOT(ISBLANK(C$3:C$186))*(C$3:C$186<$P$3:$P$186)) -> 0 | D193: =SUMPRODUCT(NOT(ISBLANK(D$3:D$186))*(D$3:D$186<$Q$3:$Q$186)) -> 0 | E193: =SUMPRODUCT(NOT(ISBLANK(E$3:E$186))*(E$3:E$186<$R$3:$R$186)) -> 0 | G193: =SUMPRODUCT(NOT(ISBLANK(G$3:G$186))*(G$3:G$186<$S$3:$S$186)) -> 0 | H193: =SUMPRODUCT(NOT(ISBLANK(H$3:H$186))*(H$3:H$186<$T$3:$T$186)) -> 0
A194: WORSE | B194: =SUMPRODUCT((NOT(ISBLANK(B$3:B$186))*(B$3:B$186>$O$3:$O$186))+ISBLANK(B$3:B$186)) -> 0 | C194: =SUMPRODUCT((NOT(ISBLANK(C$3:C$186))*(C$3:C$186>$P$3:$P$186))+ISBLANK(C$3:C$186)) -> 0 | D194: =SUMPRODUCT((NOT(ISBLANK(D$3:D$186))*(D$3:D$186>$Q$3:$Q$186))+ISBLANK(D$3:D$186)) -> 0 | E194: =SUMPRODUCT((NOT(ISBLANK(E$3:E$186))*(E$3:E$186>$R$3:$R$186))+ISBLANK(E$3:E$186)) -> 0 | G194: =SUMPRODUCT((NOT(ISBLANK(G$3:G$186))*(G$3:G$186>$S$3:$S$186))+ISBLANK(G$3:G$186)) -> 0 | H194: =SUMPRODUCT((NOT(ISBLANK(H$3:H$186))*(H$3:H$186>$T$3:$T$186))+ISBLANK(H$3:H$186)) -> 0
A195: WORST | B195: =SUMPRODUCT((NOT(ISBLANK(B$3:B$186))*(B$3:B$186=$U$3:$U$186))+ISBLANK(B$3:B$186)) -> 0 | C195: =SUMPRODUCT((NOT(ISBLANK(C$3:C$186))*(C$3:C$186=$V$3:$V$186))+ISBLANK(C$3:C$186)) -> 0 | D195: =SUMPRODUCT((NOT(ISBLANK(D$3:D$186))*(D$3:D$186=$W$3:$W$186))+ISBLANK(D$3:D$186)) -> 0 | E195: =SUMPRODUCT((NOT(ISBLANK(E$3:E$186))*(E$3:E$186=$X$3:$X$186))+ISBLANK(E$3:E$186)) -> 0 | G195: =SUMPRODUCT((NOT(ISBLANK(G$3:G$186))*(G$3:G$186=$Y$3:$Y$186))+ISBLANK(G$3:G$186)) -> 0 | H195: =SUMPRODUCT((NOT(ISBLANK(H$3:H$186))*(H$3:H$186=$Z$3:$Z$186))+ISBLANK(H$3:H$186)) -> 0

Sheet Classes
B1: clingo-5.8.0/one-as | I1: min | O1: median | U1: max
B2: error | C2: mem | D2: memout | E2: par2 | F2: rstatus | G2: time | H2: timeout | I2: error | J2: mem | K2: memout | L2: par2 | M2: time | N2: timeout | O2: error | P2: mem | Q2: memout | R2: par2 | S2: time | T2: timeout | U2: error | V2: mem | W2: memout | X2: par2 | Y2: time | Z2: timeout
A3: . | B3: =AVERAGE(Instances!B3:Instances!B94) -> 0 | C3: =AVERAGE(Instances!C3:Instances!C94) -> 0 | D3: =AVERAGE(Instances!D3:Instances!D94) -> 0 | E3: =AVERAGE(Instances!E3:Instances!E94) -> 0 | G3: =AVERAGE(Instances!G3:Instances!G94) -> 0 | H3: =SUM(Instances!H3:Instances!H94) -> 0 | I3: =MIN($B3) -> 0 | J3: =MIN($C3) -> 0 | K3: =MIN($D3) -> 0 | L3: =MIN($E3) -> 0 | M3: =MIN($G3) -> 0 | N3: =MIN($H3) -> 0 | O3: =MEDIAN($B3) -> 0 | P3: =MEDIAN($C3) -> 0 | Q3: =MEDIAN($D3) -> 0 | R3: =MEDIAN($E3) -> 0 | S3: =MEDIAN($G3) -> 0 | T3: =MEDIAN($H3) -> 0 | U3: =MAX($B3) -> 0 | V3: =MAX($C3) -> 0 | W3: =MAX($D3) -> 0 | X3: =MAX($E3) -> 0 | Y3: =MAX($G3) -> 0 | Z3: =MAX($H3) -> 0
A4: . | B4: =AVERAGE(Instances!B95:Instances!B186) -> 0 | C4: =AVERAGE(Instances!C95:Instances!C186) -> 0 | D4: =AVERAGE(Instances!D95:Instances!D186) -> 0 | E4: =AVERAGE(Instances!E95:Instances!E186) -> 0 | G4: =AVERAGE(Instances!G95:Instances!G186) -> 0 | H4: =SUM(Instances!H95:Instances!H186) -> 0 | I4: =MIN($B4) -> 0 | J4: =MIN($C4) -> 0 | K4: =MIN($D4) -> 0 | L4: =MIN($E4) -> 0 | M4: =MIN($G4) -> 0 | N4: =MIN($H4) -> 0 | O4: =MEDIAN($B4) -> 0 | P4: =MEDIAN($C4) -> 0 | Q4: =MEDIAN($D4) -> 0 | R4: =MEDIAN($E4) -> 0 | S4: =MEDIAN($G4) -> 0 | T4: =MEDIAN($H4) -> 0 | U4: =MAX($B4) -> 0 | V4: =MAX($C4) -> 0 | W4: =MAX($D4) -> 0 | X4: =MAX($E4) -> 0 | Y4: =MAX($G4) -> 0 | Z4: =MAX($H4) -> 0
A6: SUM | B6: =SUM(B$3:B$4) -> 0 | C6: =SUM(C$3:C$4) -> 0 | D6: =SUM(D$3:D$4) -> 0 | E6: =SUM(E$3:E$4) -> 0 | G6: =SUM(G$3:G$4) -> 0 | H6: =SUM(H$3:H$4) -> 0 | I6: =SUM(I$3:I$4) -> 0 | J6: =SUM(J$3:J$4) -> 0 | K6: =SUM(K$3:K$4) -> 0 | L6: =SUM(L$3:L$4) -> 0 | M6: =SUM(M$3:M$4) -> 0 | N6: =SUM(N$3:N$4) -> 0 | ... Z6: =SUM(Z$3:Z$4) -> 0
A7: AVG | B7: =AVERAGE(B$3:B$4) -> 0 | C7: =AVERAGE(C$3:C$4) -> 0 | D7: =AVERAGE(D$3:D$4) -> 0 | E7: =AVERAGE(E$3:E$4) -> 0 | G7: =AVERAGE(G$3:G$4) -> 0 | H7: =AVERAGE(H$3:H$4) -> 0 | I7: =AVERAGE(I$3:I$4) -> 0 | J7: =AVERAGE(J$3:J$4) -> 0 | K7: =AVERAGE(K$3:K$4) -> 0 | L7: =AVERAGE(L$3:L$4) -> 0 | M7: =AVERAGE(M$3:M$4) -> 0 | N7: =AVERAGE(N$3:N$4) -> 0 | ... Z7: =AVERAGE(Z$3:Z$4) -> 0
A8: DEV | B8: =STDEV(B$3:B$4) -> 0 | C8: =STDEV(C$3:C$4) -> 0 | D8: =STDEV(D$3:D$4) -> 0 | E8: =STDEV(E$3:E$4) -> 0 | G8: =STDEV(G$3:G$4) -> 0 | H8: =STDEV(H$3:H$4) -> 0 | I8: =STDEV(I$3:I$4) -> 0 | J8: =STDEV(J$3:J$4) -> 0 | K8: =STDEV(K$3:K$4) -> 0 | L8: =STDEV(L$3:L$4) -> 0 | M8: =STDEV(M$3:M$4) -> 0 | N8: =STDEV(N$3:N$4) -> 0 | ... Z8: =STDEV(Z$3:Z$4) -> 0
A9: DST | B9: =SUMPRODUCT(--(B$3:B$4-$I$3:$I$4)^2)^0.5 -> 0 | C9: =SUMPRODUCT(--(C$3:C$4-$J$3:$J$4)^2)^0.5 -> 0 | D9: =SUMPRODUCT(--(D$3:D$4-$K$3:$K$4)^2)^0.5 -> 0 | E9: =SUMPRODUCT(--(E$3:E$4-$L$3:$L$4)^2)^0.5 -> 0 | G9: =SUMPRODUCT(--(G$3:G$4-$M$3:$M$4)^2)^0.5 -> 0 | H9: =SUMPRODUCT(--(H$3:H$4-$N$3:$N$4)^2)^0.5 -> 0
A10: BEST | B10: =SUMPRODUCT(NOT(ISBLANK(B$3:B$4))*(B$3:B$4=$I$3:$I$4)) -> 0 | C10: =SUMPRODUCT(NOT(ISBLANK(C$3:C$4))*(C$3:C$4=$J$3:$J$4)) -> 0 | D10: =SUMPRODUCT(NOT(ISBLANK(D$3:D$4))*(D$3:D$4=$K$3:$K$4)) -> 0 | E10: =SUMPRODUCT(NOT(ISBLANK(E$3:E$4))*(E$3:E$4=$L$3:$L$4)) -> 0 | G10: =SUMPRODUCT(NOT(ISBLANK(G$3:G$4))*(G$3:G$4=$M$3:$M$4)) -> 0 | H10: =SUMPRODUCT(NOT(ISBLANK(H$3:H$4))*(H$3:H$4=$N$3:$N$4)) -> 0
A11: BETTER | B11: =SUMPRODUCT(NOT(ISBLANK(B$3:B$4))*(B$3:B$4<$O$3:$O$4)) -> 0 | C11: =SUMPRODUCT(NOT(ISBLANK(C$3:C$4))*(C$3:C$4<$P$3:$P$4)) -> 0 | D11: =SUMPRODUCT(NOT(ISBLANK(D$3:D$4))*(D$3:D$4<$Q$3:$Q$4)) -> 0 | E11: =SUMPRODUCT(NOT(ISBLANK(E$3:E$4))*(E$3:E$4<$R$3:$R$4)) -> 0 | G11: =SUMPRODUCT(NOT(ISBLANK(G$3:G$4))*(G$3:G$4<$S$3:$S$4)) -> 0 | H11: =SUMPRODUCT(NOT(ISBLANK(H$3:H$4))*(H$3:H$4<$T$3:$T$4)) -> 0
A12: WORSE | B12: =SUMPRODUCT((NOT(ISBLANK(B$3:B$4))*(B$3:B$4>$O$3:$O$4))+ISBLANK(B$3:B$4)) -> 0 | C12: =SUMPRODUCT((NOT(ISBLANK(C$3:C$4))*(C$3:C$4>$P$3:$P$4))+ISBLANK(C$3:C$4)) -> 0 | D12: =SUMPRODUCT((NOT(ISBLANK(D$3:D$4))*(D$3:D$4>$Q$3:$Q$4))+ISBLANK(D$3:D$4)) -> 0 | E12: =SUMPRODUCT((NOT(ISBLANK(E$3:E$4))*(E$3:E$4>$R$3:$R$4))+ISBLANK(E$3:E$4)) -> 0 | G12: =SUMPRODUCT((NOT(ISBLANK(G$3:G$4))*(G$3:G$4>$S$3:$S$4))+ISBLANK(G$3:G$4)) -> 0 | H12: =SUMPRODUCT((NOT(ISBLANK(H$3:H$4))*(H$3:H$4>$T$3:$T$4))+ISBLANK(H$3:H$4)) -> 0
A13: WORST | B13: =SUMPRODUCT((NOT(ISBLANK(B$3:B$4))*(B$3:B$4=$U$3:$U$4))+ISBLANK(B$3:B$4)) -> 0 | C13: =SUMPRODUCT((NOT(ISBLANK(C$3:C$4))*(C$3:C$4=$V$3:$V$4))+ISBLANK(C$3:C$4)) -> 0 | D13: =SUMPRODUCT((NOT(ISBLANK(D$3:D$4))*(D$3:D$4=$W$3:$W$4))+ISBLANK(D$3:D$4)) -> 0 | E13: =SUMPRODUCT((NOT(ISBLANK(E$3:E$4))*(E$3:E$4=$X$3:$X$4))+ISBLANK(E$3:E$4)) -> 0 | G13: =SUMPRODUCT((NOT(ISBLANK(G$3:G$4))*(G$3:G$4=$Y$3:$Y$4))+ISBLANK(G$3:G$4)) -> 0 | H13: =SUMPRODUCT((NOT(ISBLANK(H$3:H$4))*(H$3:H$4=$Z$3:$Z$4))+ISBLANK(H$3:H$4)) -> 0

Sheet Helper
A2: error | B2: 1 | E2: =VLOOKUP(Charts!$F$3,A2:B7,2,FALSE) -> 0 | K2: =E2 -> 0 | Q2: =VLOOKUP(Charts!$F$3,A2:B7,2,FALSE) -> 0
A3: mem | B3: 2 | D3: data | E3: =Instances!B1 -> 0 | J3: data | K3: =E3 -> 0 | Q3: =Instances!B1 -> 0
A4: memout | B4: 3 | D4: index | E4: values | F4: sorted | H4: aggregated | J4: index | K4: values | L4: sorted | N4: aggregated | P4: plot | Q4: index | R4: sorted | S4: index | T4: aggregated
A5: par2 | B5: 4 | D5: 1 | E5: =IF(INDIRECT(ADDRESS($D5+2,E$2+1,,,"Instances"))="","",INDIRECT(ADDRESS($D5+2,E$2+1,,,"Instances"))) -> 0 | F5: =IFERROR(SMALL(E5:E188,ROW()-ROW($F$5)+1),"") -> 0 | H5: =IFERROR(SUM(F5:F5),"") -> 0 | J5: 1 | K5: {=_xlfn.SWITCH(Charts!$B$3,"average", AVERAGE(INDIRECT(ADDRESS(0+3,K$2+1,,,"Instances") & ":" & ADDRESS(0+3,K$2+1))),"median", MEDIAN(INDIRECT(ADDRESS(0+3,K$2+1,,,"Instances") & ":" & ADDRESS(0+3,K$2+1))),"min", MIN(INDIRECT(ADDRESS(0+3,K$2+1,,,"Instances") & ":" & ADDRESS(0+3,K$2+1))),"max", MAX(INDIRECT(ADDRESS(0+3,K$2+1,,,"Instances") & ":" & ADDRESS(0+3,K$2+1))),"diff", MAX(INDIRECT(ADDRESS(0+3,K$2+1,,,"Instances") & ":" & ADDRESS(0+3,K$2+1)))-MIN(INDIRECT(ADDRESS(0+3,K$2+1,,,"Instances") & ":" & ADDRESS(0+3,K$2+1))))} -> 0 | L5: =IFERROR(SMALL(K5:K188,ROW()-ROW($L$5)+1),"") -> 0 | N5: =IFERROR(SUM(L5:L5),"") -> 0 | Q5: =IF(Charts!$B$3="none",E932,IF(K932="",NA(),K932)) -> 0 | R5: =IF(Charts!$B$3="none",F932,IF(L932="",NA(),L932)) -> 0 | S5: =IF(Charts!$B$3="none",G932,IF(M932="",NA(),M932)) -> 0 | T5: =IF(Charts!$B$3="none",H932,IF(N932="",NA(),N932)) -> 0
A6: time | B6: 6 | D6: 2 | E6: =IF(INDIRECT(ADDRESS($D6+2,E$2+1,,,"Instances"))="","",INDIRECT(ADDRESS($D6+2,E$2+1,,,"Instances"))) -> 0 | F6: =IFERROR(SMALL(E5:E188,ROW()-ROW($F$5)+1),"") -> 0 | H6: =IFERROR(SUM(F5:F6),"") -> 0 | J6: 2 | K6: {=_xlfn.SWITCH(Charts!$B$3,"average", AVERAGE(INDIRECT(ADDRESS(1+3,K$2+1,,,"Instances") & ":" & ADDRESS(1+3,K$2+1))),"median", MEDIAN(INDIRECT(ADDRESS(1+3,K$2+1,,,"Instances") & ":" & ADDRESS(1+3,K$2+1))),"min", MIN(INDIRECT(ADDRESS(1+3,K$2+1,,,"Instances") & ":" & ADDRESS(1+3,K$2+1))),"max", MAX(INDIRECT(ADDRESS(1+3,K$2+1,,,"Instances") & ":" & ADDRESS(1+3,K$2+1))),"diff", MAX(INDIRECT(ADDRESS(1+3,K$2+1,,,"Instances") & ":" & ADDRESS(1+3,K$2+1)))-MIN(INDIRECT(ADDRESS(1+3,K$2+1,,,"Instances") & ":" & ADDRESS(1+3,K$2+1))))} -> 0 | L6: =IFERROR(SMALL(K5:K188,ROW()-ROW($L$5)+1),"") -> 0 | N6: =IFERROR(SUM(L5:L6),"") -> 0 | Q6: =IF(Charts!$B$3="none",E933,IF(K933="",NA(),K933)) -> 0 | R6: =IF(Charts!$B$3="none",F933,IF(L933="",NA(),L933)) -> 0 | S6: =IF(Charts!$B$3="none",G933,IF(M933="",NA(),M933)) -> 0 | T6: =IF(Charts!$B$3="none",H933,IF(N933="",NA(),N933)) -> 0
A7: timeout | B7: 7 | D7: 3 | E7: =IF(INDIRECT(ADDRESS($D7+2,E$2+1,,,"Instances"))="","",INDIRECT(ADDRESS($D7+2,E$2+1,,,"Instances"))) -> 0 | F7: =IFERROR(SMALL(E5:E188,ROW()-ROW($F$5)+1),"") -> 0 | H7: =IFERROR(SUM(F5:F7),"") -> 0 | J7: 3 | K7: {=_xlfn.SWITCH(Charts!$B$3,"average", AVERAGE(INDIRECT(ADDRESS(2+3,K$2+1,,,"Instances") & ":" & ADDRESS(2+3,K$2+1))),"median", MEDIAN(INDIRECT(ADDRESS(2+3,K$2+1,,,"Instances") & ":" & ADDRESS(2+3,K$2+1))),"min", MIN(INDIRECT(ADDRESS(2+3,K$2+1,,,"Instances") & ":" & ADDRESS(2+3,K$2+1))),"max", MAX(INDIRECT(ADDRESS(2+3,K$2+1,,,"Instances") & ":" & ADDRESS(2+3,K$2+1))),"diff", MAX(INDIRECT(ADDRESS(2+3,K$2+1,,,"Instances") & ":" & ADDRESS(2+3,K$2+1)))-MIN(INDIRECT(ADDRESS(2+3,K$2+1,,,"Instances") & ":" & ADDRESS(2+3,K$2+1))))} -> 0 | L7: =IFERROR(SMALL(K5:K188,ROW()-ROW($L$5)+1),"") -> 0 | N7: =IFERROR(SUM(L5:L7),"") -> 0 | Q7: =IF(Charts!$B$3="none",E934,IF(K934="",NA(),K934)) -> 0 | R7: =IF(Charts!$B$3="none",F934,IF(L934="",NA(),L934)) -> 0 | S7: =IF(Charts!$B$3="none",G934,IF(M934="",NA(),M934)) -> 0 | T7: =IF(Charts!$B$3="none",H934,IF(N934="",NA(),N934)) -> 0
D8: 4 | E8: =IF(INDIRECT(ADDRESS($D8+2,E$2+1,,,"Instances"))="","",INDIRECT(ADDRESS($D8+2,E$2+1,,,"Instances"))) -> 0 | F8: =IFERROR(SMALL(E5:E188,ROW()-ROW($F$5)+1),"") -> 0 | H8: =IFERROR(SUM(F5:F8),"") -> 0 | J8: 4 | K8: {=_xlfn.SWITCH(Charts!$B$3,"average", AVERAGE(INDIRECT(ADDRESS(3+3,K$2+1,,,"Instances") & ":" & ADDRESS(3+3,K$2+1))),"median", MEDIAN(INDIRECT(ADDRESS(3+3,K$2+1,,,"Instances") & ":" & ADDRESS(3+3,K$2+1))),"min", MIN(INDIRECT(ADDRESS(3+3,K$2+1,,,"Instances") & ":" & ADDRESS(3+3,K$2+1))),"max", MAX(INDIRECT(ADDRESS(3+3,K$2+1,,,"Instances") & ":" & ADDRESS(3+3,K$2+1))),"diff", MAX(INDIRECT(ADDRESS(3+3,K$2+1,,,"Instances") & ":" & ADDRESS(3+3,K$2+1)))-MIN(INDIRECT(ADDRESS(3+3,K$2+1,,,"Instances") & ":" & ADDRESS(3+3,K$2+1))))} -> 0 | L8: =IFERROR(SMALL(K5:K188,ROW()-ROW($L$5)+1),"") -> 0 | N8: =IFERROR(SUM(L5:L8),"") -> 0 | Q8: =IF(Charts!$B$3="none",E935,IF(K935="",NA(),K935)) -> 0 | R8: =IF(Charts!$B$3="none",F935,IF(L935="",NA(),L935)) -> 0 | S8: =IF(Charts!$B$3="none",G935,IF(M935="",NA(),M935)) -> 0 | T8: =IF(Charts!$B$3="none",H935,IF(N935="",NA(),N935)) -> 0
D9: 5 | E9: =IF(INDIRECT(ADDRESS($D9+2,E$2+1,,,"Instances"))="","",INDIRECT(ADDRESS($D9+2,E$2+1,,,"Instances"))) -> 0 | F9: =IFERROR(SMALL(E5:E188,ROW()-ROW($F$5)+1),"") -> 0 | H9: =IFERROR(SUM(F5:F9),"") -> 0 | J9: 5 | K9: {=_xlfn.SWITCH(Charts!$B$3,"average", AVERAGE(INDIRECT(ADDRESS(4+3,K$2+1,,,"Instances") & ":" & ADDRESS(4+3,K$2+1))),"median", MEDIAN(INDIRECT(ADDRESS(4+3,K$2+1,,,"Instances") & ":" & ADDRESS(4+3,K$2+1))),"min", MIN(INDIRECT(ADDRESS(4+3,K$2+1,,,"Instances") & ":" & ADDRESS(4+3,K$2+1))),"max", MAX(INDIRECT(ADDRESS(4+3,K$2+1,,,"Instances") & ":" & ADDRESS(4+3,K$2+1))),"diff", MAX(INDIRECT(ADDRESS(4+3,K$2+1,,,"Instances") & ":" & ADDRESS(4+3,K$2+1)))-MIN(INDIRECT(ADDRESS(4+3,K$2+1,,,"Instances") & ":" & ADDRESS(4+3,K$2+1))))} -> 0 | L9: =IFERROR(SMALL(K5:K188,ROW()-ROW($L$5)+1),"") -> 0 | N9: =IFERROR(SUM(L5:L9),"") -> 0 | Q9: =IF(Charts!$B$3="none",E936,IF(K936="",NA(),K936)) -> 0 | R9: =IF(Charts!$B$3="none",F936,IF(L936="",NA(),L936)) -> 0 | S9: =IF(Charts!$B$3="none",G936,IF(M936="",NA(),M936)) -> 0 | T9: =IF(Charts!$B$3="none",H936,IF(N936="",NA(),N936)) -> 0
D10: 6 | E10: =IF(INDIRECT(ADDRESS($D10+2,E$2+1,,,"Instances"))="","",INDIRECT(ADDRESS($D10+2,E$2+1,,,"Instances"))) -> 0 | F10: =IFERROR(SMALL(E5:E188,ROW()-ROW($F$5)+1),"") -> 0 | H10: =IFERROR(SUM(F5:F10),"") -> 0 | J10: 6 | K10: {=_xlfn.SWITCH(Charts!$B$3,"average", AVERAGE(INDIRECT(ADDRESS(5+3,K$2+1,,,"Instances") & ":" & ADDRESS(5+3,K$2+1))),"median", MEDIAN(INDIRECT(ADDRESS(5+3,K$2+1,,,"Instances") & ":" & ADDRESS(5+3,K$2+1))),"min", MIN(INDIRECT(ADDRESS(5+3,K$2+1,,,"Instances") & ":" & ADDRESS(5+3,K$2+1))),"max", MAX(INDIRECT(ADDRESS(5+3,K$2+1,,,"Instances") & ":" & ADDRESS(5+3,K$2+1))),"diff", MAX(INDIRECT(ADDRESS(5+3,K$2+1,,,"Instances") & ":" & ADDRESS(5+3,K$2+1)))-MIN(INDIRECT(ADDRESS(5+3,K$2+1,,,"Instances") & ":" & ADDRESS(5+3,K$2+1))))} -> 0 | L10: =IFERROR(SMALL(K5:K188,ROW()-ROW($L$5)+1),"") -> 0 | N10: =IFERROR(SUM(L5:L10),"") -> 0 | Q10: =IF(Charts!$B$3="none",E937,IF(K937="",NA(),K937)) -> 0 | R10: =IF(Charts!$B$3="none",F937,IF(L937="",NA(),L937)) -> 0 | S10: =IF(Charts!$B$3="none",G937,IF(M937="",NA(),M937)) -> 0 | T10: =IF(Charts!$B$3="none",H937,IF(N937="",NA(),N937)) -> 0
D11: 7 | E11: =IF(INDIRECT(ADDRESS($D11+2,E$2+1,,,"Instances"))="","",INDIRECT(ADDRESS($D11+2,E$2+1,,,"Instances"))) -> 0 | F11: =IFERROR(SMALL(E5:E188,ROW()-ROW($F$5)+1),"") -> 0 | H11: =IFERROR(SUM(F5:F11),"") -> 0 | J11: 7 | K11: {=_xlfn.SWITCH(Charts!$B$3,"average", AVERAGE(INDIRECT(ADDRESS(6+3,K$2+1,,,"Instances") & ":" & ADDRESS(6+3,K$2+1))),"median", MEDIAN(INDIRECT(ADDRESS(6+3,K$2+1,,,"Instances") & ":" & ADDRESS(6+3,K$2+1))),"min", MIN(INDIRECT(ADDRESS(6+3,K$2+1,,,"Instances") & ":" & ADDRESS(6+3,K$2+1))),"max", MAX(INDIRECT(ADDRESS(6+3,K$2+1,,,"Instances") & ":" & ADDRESS(6+3,K$2+1))),"diff", MAX(INDIRECT(ADDRESS(6+3,K$2+1,,,"Instances") & ":" & ADDRESS(6+3,K$2+1)))-MIN(INDIRECT(ADDRESS(6+3,K$2+1,,,"Instances") & ":" & ADDRESS(6+3,K$2+1))))} -> 0 | L11: =IFERROR(SMALL(K5:K188,ROW()-ROW($L$5)+1),"") -> 0 | N11: =IFERROR(SUM(L5:L11),"") -> 0 | Q11: =IF(Charts!$B$3="none",E938,IF(K938="",NA(),K938)) -> 0 | R11: =IF(Charts!$B$3="none",F938,IF(L938="",NA(),L938)) -> 0 | S11: =IF(Charts!$B$3="none",G938,IF(M938="",NA(),M938)) -> 0 | T11: =IF(Charts!$B$3="none",H938,IF(N938="",NA(),N938)) -> 0
D12: 8 | E12: =IF(INDIRECT(ADDRESS($D12+2,E$2+1,,,"Instances"))="","",INDIRECT(ADDRESS($D12+2,E$2+1,,,"Instances"))) -> 0 | F12: =IFERROR(SMALL(E5:E188,ROW()-ROW($F$5)+1),"") -> 0 | H12: =IFERROR(SUM(F5:F12),"") -> 0 | J12: 8 | K12: {=_xlfn.SWITCH(Charts!$B$3,"average", AVERAGE(INDIRECT(ADDRESS(7+3,K$2+1,,,"Instances") & ":" & ADDRESS(7+3,K$2+1))),"median", MEDIAN(INDIRECT(ADDRESS(7+3,K$2+1,,,"Instances") & ":" & ADDRESS(7+3,K$2+1))),"min", MIN(INDIRECT(ADDRESS(7+3,K$2+1,,,"Instances") & ":" & ADDRESS(7+3,K$2+1))),"max", MAX(INDIRECT(ADDRESS(7+3,K$2+1,,,"Instances") & ":" & ADDRESS(7+3,K$2+1))),"diff", MAX(INDIRECT(ADDRESS(7+3,K$2+1,,,"Instances") & ":" & ADDRESS(7+3,K$2+1)))-MIN(INDIRECT(ADDRESS(7+3,K$2+1,,,"Instances") & ":" & ADDRESS(7+3,K$2+1))))} -> 0 | L12: =IFERROR(SMALL(K5:K188,ROW()-ROW($L$5)+1),"") -> 0 | N12: =IFERROR(SUM(L5:L12),"") -> 0 | Q12: =IF(Charts!$B$3="none",E939,IF(K939="",NA(),K939)) -> 0 | R12: =IF(Charts!$B$3="none",F939,IF(L939="",NA(),L939)) -> 0 | S12: =IF(Charts!$B$3="none",G939,IF(M939="",NA(),M939)) -> 0 | T12: =IF(Charts!$B$3="none",H939,IF(N939="",NA(),N939)) -> 0
D13: 9 | E13: =IF(INDIRECT(ADDRESS($D13+2,E$2+1,,,"Instances"))="","",INDIRECT(ADDRESS($D13+2,E$2+1,,,"Instances"))) -> 0 | F13: =IFERROR(SMALL(E5:E188,ROW()-ROW($F$5)+1),"") -> 0 | H13: =IFERROR(SUM(F5:F13),"") -> 0 | J13: 9 | K13: {=_xlfn.SWITCH(Charts!$B$3,"average", AVERAGE(INDIRECT(ADDRESS(8+3,K$2+1,,,"Instances") & ":" & ADDRESS(8+3,K$2+1))),"median", MEDIAN(INDIRECT(ADDRESS(8+3,K$2+1,,,"Instances") & ":" & ADDRESS(8+3,K$2+1))),"min", MIN(INDIRECT(ADDRESS(8+3,K$2+1,,,"Instances") & ":" & ADDRESS(8+3,K$2+1))),"max", MAX(INDIRECT(ADDRESS(8+3,K$2+1,,,"Instances") & ":" & ADDRESS(8+3,K$2+1))),"diff", MAX(INDIRECT(ADDRESS(8+3,K$2+1,,,"Instances") & ":" & ADDRESS(8+3,K$2+1)))-MIN(INDIRECT(ADDRESS(8+3,K$2+1,,,"Instances") & ":" & ADDRESS(8+3,K$2+1))))} -> 0 | L13: =IFERROR(SMALL(K5:K188,ROW()-ROW($L$5)+1),"") -> 0 | N13: =IFERROR(SUM(L5:L13),"") -> 0 | Q13: =IF(Charts!$B$3="none",E940,IF(K940="",NA(),K940)) -> 0 | R13: =IF(Charts!$B$3="none",F940,IF(L940="",NA(),L940)) -> 0 | S13: =IF(Charts!$B$3="none",G940,IF(M940="",NA(),M940)) -> 0 | T13: =IF(Charts!$B$3="none",H940,IF(N940="",NA(),N940)) -> 0
D14: 10 | E14: =IF(INDIRECT(ADDRESS($D14+2,E$2+1,,,"Instances"))="","",INDIRECT(ADDRESS($D14+2,E$2+1,,,"Instances"))) -> 0 | F14: =IFERROR(SMALL(E5:E188,ROW()-ROW($F$5)+1),"") -> 0 | H14: =IFERROR(SUM(F5:F14),"") -> 0 | J14: 10 | K14: {=_xlfn.SWITCH(Charts!$B$3,"average", AVERAGE(INDIRECT(ADDRESS(9+3,K$2+1,,,"Instances") & ":" & ADDRESS(9+3,K$2+1))),"median", MEDIAN(INDIRECT(ADDRESS(9+3,K$2+1,,,"Instances") & ":" & ADDRESS(9+3,K$2+1))),"min", MIN(INDIRECT(ADDRESS(9+3,K$2+1,,,"Instances") & ":" & ADDRESS(9+3,K$2+1))),"max", MAX(INDIRECT(ADDRESS(9+3,K$2+1,,,"Instances") & ":" & ADDRESS(9+3,K$2+1))),"diff", MAX(INDIRECT(ADDRESS(9+3,K$2+1,,,"Instances") & ":" & ADDRESS(9+3,K$2+1)))-MIN(INDIRECT(ADDRESS(9+3,K$2+1,,,"Instances") & ":" & ADDRESS(9+3,K$2+1))))} -> 0 | L14: =IFERROR(SMALL(K5:K188,ROW()-ROW($L$5)+1),"") -> 0 | N14: =IFERROR(SUM(L5:L14),"") -> 0 | Q14: =IF(Charts!$B$3="none",E941,IF(K941="",NA(),K941)) -> 0 | R14: =IF(Charts!$B$3="none",F941,IF(L941="",NA(),L941)) -> 0 | S14: =IF(Charts!$B$3="none",G941,IF(M941="",NA(),M941)) -> 0 | T14: =IF(Charts!$B$3="none",H941,IF(N941="",NA(),N941)) -> 0
D15: 11 | E15: =IF(INDIRECT(ADDRESS($D15+2,E$2+1,,,"Instances"))="","",INDIRECT(ADDRESS($D15+2,E$2+1,,,"Instances"))) -> 0 | F15: =IFERROR(SMALL(E5:E188,ROW()-ROW($F$5)+1),"") -> 0 | H15: =IFERROR(SUM(F5:F15),"") -> 0 | J15: 11 | K15: {=_xlfn.SWITCH(Charts!$B$3,"average", AVERAGE(INDIRECT(ADDRESS(10+3,K$2+1,,,"Instances") & ":" & ADDRESS(10+3,K$2+1))),"median", MEDIAN(INDIRECT(ADDRESS(10+3,K$2+1,,,"Instances") & ":" & ADDRESS(10+3,K$2+1))),"min", MIN(INDIRECT(ADDRESS(10+3,K$2+1,,,"Instances") & ":" & ADDRESS(10+3,K$2+1))),"max", MAX(INDIRECT(ADDRESS(10+3,K$2+1,,,"Instances") & ":" & ADDRESS(10+3,K$2+1))),"diff", MAX(INDIRECT(ADDRESS(10+3,K$2+1,,,"Instances") & ":" & ADDRESS(10+3,K$2+1)))-MIN(INDIRECT(ADDRESS(10+3,K$2+1,,,"Instances") & ":" & ADDRESS(10+3,K$2+1))))} -> 0 | L15: =IFERROR(SMALL(K5:K188,ROW()-ROW($L$5)+1),"") -> 0 | N15: =IFERROR(SUM(L5:L15),"") -> 0 | Q15: =IF(Charts!$B$3="none",E942,IF(K942="",NA(),K942)) -> 0 | R15: =IF(Charts!$B$3="none",F942,IF(L942="",NA(),L942)) -> 0 | S15: =IF(Charts!$B$3="none",G942,IF(M942="",NA(),M942)) -> 0 | T15: =IF(Charts!$B$3="none",H942,IF(N942="",NA(),N942)) -> 0
