Workbook

Sheet Instances
B1: clingo-5.8.0/one-as | S1: min | AH1: median | AW1: max
B2: choices | C2: conflicts | D2: constraints | E2: error | F2: mem | G2: memout | H2: models | I2: overall-time | J2: par2 | K2: restarts | L2: rstatus | M2: rules | N2: solving-time | O2: status | P2: time | Q2: timeout | R2: variables | S2: choices | T2: conflicts | U2: constraints | V2: error | W2: mem | X2: memout | Y2: models | Z2: overall-time | AA2: par2 | AB2: restarts | AC2: rules | AD2: solving-time | AE2: time | AF2: timeout | AG2: variables | AH2: choices | AI2: conflicts | AJ2: constraints | AK2: error | AL2: mem | AM2: memout | AN2: models | AO2: overall-time | AP2: par2 | AQ2: restarts | AR2: rules | AS2: solving-time | AT2: time | AU2: timeout | AV2: variables | AW2: choices | AX2: conflicts | AY2: constraints | AZ2: error | BA2: mem | BB2: memout | BC2: models | BD2: overall-time | BE2: par2 | BF2: restarts | BG2: rules | BH2: solving-time | BI2: time | BJ2: timeout | BK2: variables
A3: /Level_0 | B3: 0 | C3: 0 | D3: 0 | E3: 0 | F3: 15006 | G3: 1 | H3: 0 | I3: 161.105 | J3: 3000 | K3: 0 | L3: out of memory | M3: 0 | N3: 0 | O3: UNKNOWN | P3: 1500 | Q3: 1 | R3: 0 | S3: =MIN($B3) -> 0 | T3: =MIN($C3) -> 0 | U3: =MIN($D3) -> 0 | V3: =MIN($E3) -> 0 | W3: =MIN($F3) -> 0 | X3: =MIN($G3) -> 0 | Y3: =MIN($H3) -> 0 | Z3: =MIN($I3) -> 0 | AA3: =MIN($J3) -> 0 | AB3: =MIN($K3) -> 0 | AC3: =MIN($M3) -> 0 | AD3: =MIN($N3) -> 0 | AE3: =MIN($P3) -> 0 | AF3: =MIN($Q3) -> 0 | AG3: =MIN($R3) -> 0 | AH3: =MEDIAN($B3) -> 0 | AI3: =MEDIAN($C3) -> 0 | AJ3: =MEDIAN($D3) -> 0 | AK3: =MEDIAN($E3) -> 0 | AL3: =MEDIAN($F3) -> 0 | AM3: =MEDIAN($G3) -> 0 | AN3: =MEDIAN($H3) -> 0 | AO3: =MEDIAN($I3) -> 0 | AP3: =MEDIAN($J3) -> 0 | AQ3: =MEDIAN($K3) -> 0 | AR3: =MEDIAN($M3) -> 0 | AS3: =MEDIAN($N3) -> 0 | AT3: =MEDIAN($P3) -> 0 | AU3: =MEDIAN($Q3) -> 0 | AV3: =MEDIAN($R3) -> 0 | AW3: =MAX($B3) -> 0 | AX3: =MAX($C3) -> 0 | AY3: =MAX($D3) -> 0 | AZ3: =MAX($E3) -> 0 | BA3: =MAX($F3) -> 0 | BB3: =MAX($G3) -> 0 | BC3: =MAX($H3) -> 0 | BD3: =MAX($I3) -> 0 | BE3: =MAX($J3) -> 0 | BF3: =MAX($K3) -> 0 | BG3: =MAX($M3) -> 0 | BH3: =MAX($N3) -> 0 | BI3: =MAX($P3) -> 0 | BJ3: =MAX($Q3) -> 0 | BK3: =MAX($R3) -> 0
A4: /Level_1 | B4: 0 | C4: 0 | D4: 0 | E4: 0 | F4: 15006 | G4: 1 | H4: 0 | I4: 161.705 | J4: 3000 | K4: 0 | L4: out of memory | M4: 0 | N4: 0 | O4: UNKNOWN | P4: 1500 | Q4: 1 | R4: 0 | S4: =MIN($B4) -> 0 | T4: =MIN($C4) -> 0 | U4: =MIN($D4) -> 0 | V4: =MIN($E4) -> 0 | W4: =MIN($F4) -> 0 | X4: =MIN($G4) -> 0 | Y4: =MIN($H4) -> 0 | Z4: =MIN($I4) -> 0 | AA4: =MIN($J4) -> 0 | AB4: =MIN($K4) -> 0 | AC4: =MIN($M4) -> 0 | AD4: =MIN($N4) -> 0 | AE4: =MIN($P4) -> 0 | AF4: =MIN($Q4) -> 0 | AG4: =MIN($R4) -> 0 | AH4: =MEDIAN($B4) -> 0 | AI4: =MEDIAN($C4) -> 0 | AJ4: =MEDIAN($D4) -> 0 | AK4: =MEDIAN($E4) -> 0 | AL4: =MEDIAN($F4) -> 0 | AM4: =MEDIAN($G4) -> 0 | AN4: =MEDIAN($H4) -> 0 | AO4: =MEDIAN($I4) -> 0 | AP4: =MEDIAN($J4) -> 0 | AQ4: =MEDIAN($K4) -> 0 | AR4: =MEDIAN($M4) -> 0 | AS4: =MEDIAN($N4) -> 0 | AT4: =MEDIAN($P4) -> 0 | AU4: =MEDIAN($Q4) -> 0 | AV4: =MEDIAN($R4) -> 0 | AW4: =MAX($B4) -> 0 | AX4: =MAX($C4) -> 0 | AY4: =MAX($D4) -> 0 | AZ4: =MAX($E4) -> 0 | BA4: =MAX($F4) -> 0 | BB4: =MAX($G4) -> 0 | BC4: =MAX($H4) -> 0 | BD4: =MAX($I4) -> 0 | BE4: =MAX($J4) -> 0 | BF4: =MAX($K4) -> 0 | BG4: =MAX($M4) -> 0 | BH4: =MAX($N4) -> 0 | BI4: =MAX($P4) -> 0 | BJ4: =MAX($Q4) -> 0 | BK4: =MAX($R4) -> 0
A5: /Level_2 | B5: 0 | C5: 0 | D5: 0 | E5: 0 | F5: 15008 | G5: 1 | H5: 0 | I5: 162.406 | J5: 3000 | K5: 0 | L5: out of memory | M5: 0 | N5: 0 | O5: UNKNOWN | P5: 1500 | Q5: 1 | R5: 0 | S5: =MIN($B5) -> 0 | T5: =MIN($C5) -> 0 | U5: =MIN($D5) -> 0 | V5: =MIN($E5) -> 0 | W5: =MIN($F5) -> 0 | X5: =MIN($G5) -> 0 | Y5: =MIN($H5) -> 0 | Z5: =MIN($I5) -> 0 | AA5: =MIN($J5) -> 0 | AB5: =MIN($K5) -> 0 | AC5: =MIN($M5) -> 0 | AD5: =MIN($N5) -> 0 | AE5: =MIN($P5) -> 0 | AF5: =MIN($Q5) -> 0 | AG5: =MIN($R5) -> 0 | AH5: =MEDIAN($B5) -> 0 | AI5: =MEDIAN($C5) -> 0 | AJ5: =MEDIAN($D5) -> 0 | AK5: =MEDIAN($E5) -> 0 | AL5: =MEDIAN($F5) -> 0 | AM5: =MEDIAN($G5) -> 0 | AN5: =MEDIAN($H5) -> 0 | AO5: =MEDIAN($I5) -> 0 | AP5: =MEDIAN($J5) -> 0 | AQ5: =MEDIAN($K5) -> 0 | AR5: =MEDIAN($M5) -> 0 | AS5: =MEDIAN($N5) -> 0 | AT5: =MEDIAN($P5) -> 0 | AU5: =MEDIAN($Q5) -> 0 | AV5: =MEDIAN($R5) -> 0 | AW5: =MAX($B5) -> 0 | AX5: =MAX($C5) -> 0 | AY5: =MAX($D5) -> 0 | AZ5: =MAX($E5) -> 0 | BA5: =MAX($F5) -> 0 | BB5: =MAX($G5) -> 0 | BC5: =MAX($H5) -> 0 | BD5: =MAX($I5) -> 0 | BE5: =MAX($J5) -> 0 | BF5: =MAX($K5) -> 0 | BG5: =MAX($M5) -> 0 | BH5: =MAX($N5) -> 0 | BI5: =MAX($P5) -> 0 | BJ5: =MAX($Q5) -> 0 | BK5: =MAX($R5) -> 0
A6: /Level_3 | B6: 0 | C6: 0 | D6: 0 | E6: 0 | F6: 15012 | G6: 1 | H6: 0 | I6: 161.305 | J6: 3000 | K6: 0 | L6: out of memory | M6: 0 | N6: 0 | O6: UNKNOWN | P6: 1500 | Q6: 1 | R6: 0 | S6: =MIN($B6) -> 0 | T6: =MIN($C6) -> 0 | U6: =MIN($D6) -> 0 | V6: =MIN($E6) -> 0 | W6: =MIN($F6) -> 0 | X6: =MIN($G6) -> 0 | Y6: =MIN($H6) -> 0 | Z6: =MIN($I6) -> 0 | AA6: =MIN($J6) -> 0 | AB6: =MIN($K6) -> 0 | AC6: =MIN($M6) -> 0 | AD6: =MIN($N6) -> 0 | AE6: =MIN($P6) -> 0 | AF6: =MIN($Q6) -> 0 | AG6: =MIN($R6) -> 0 | AH6: =MEDIAN($B6) -> 0 | AI6: =MEDIAN($C6) -> 0 | AJ6: =MEDIAN($D6) -> 0 | AK6: =MEDIAN($E6) -> 0 | AL6: =MEDIAN($F6) -> 0 | AM6: =MEDIAN($G6) -> 0 | AN6: =MEDIAN($H6) -> 0 | AO6: =MEDIAN($I6) -> 0 | AP6: =MEDIAN($J6) -> 0 | AQ6: =MEDIAN($K6) -> 0 | AR6: =MEDIAN($M6) -> 0 | AS6: =MEDIAN($N6) -> 0 | AT6: =MEDIAN($P6) -> 0 | AU6: =MEDIAN($Q6) -> 0 | AV6: =MEDIAN($R6) -> 0 | AW6: =MAX($B6) -> 0 | AX6: =MAX($C6) -> 0 | AY6: =MAX($D6) -> 0 | AZ6: =MAX($E6) -> 0 | BA6: =MAX($F6) -> 0 | BB6: =MAX($G6) -> 0 | BC6: =MAX($H6) -> 0 | BD6: =MAX($I6) -> 0 | BE6: =MAX($J6) -> 0 | BF6: =MAX($K6) -> 0 | BG6: =MAX($M6) -> 0 | BH6: =MAX($N6) -> 0 | BI6: =MAX($P6) -> 0 | BJ6: =MAX($Q6) -> 0 | BK6: =MAX($R6) -> 0
A7: /Level_4 | B7: 0 | C7: 0 | D7: 0 | E7: 0 | F7: 15005 | G7: 1 | H7: 0 | I7: 160.705 | J7: 3000 | K7: 0 | L7: out of memory | M7: 0 | N7: 0 | O7: UNKNOWN | P7: 1500 | Q7: 1 | R7: 0 | S7: =MIN($B7) -> 0 | T7: =MIN($C7) -> 0 | U7: =MIN($D7) -> 0 | V7: =MIN($E7) -> 0 | W7: =MIN($F7) -> 0 | X7: =MIN($G7) -> 0 | Y7: =MIN($H7) -> 0 | Z7: =MIN($I7) -> 0 | AA7: =MIN($J7) -> 0 | AB7: =MIN($K7) -> 0 | AC7: =MIN($M7) -> 0 | AD7: =MIN($N7) -> 0 | AE7: =MIN($P7) -> 0 | AF7: =MIN($Q7) -> 0 | AG7: =MIN($R7) -> 0 | AH7: =MEDIAN($B7) -> 0 | AI7: =MEDIAN($C7) -> 0 | AJ7: =MEDIAN($D7) -> 0 | AK7: =MEDIAN($E7) -> 0 | AL7: =MEDIAN($F7) -> 0 | AM7: =MEDIAN($G7) -> 0 | AN7: =MEDIAN($H7) -> 0 | AO7: =MEDIAN($I7) -> 0 | AP7: =MEDIAN($J7) -> 0 | AQ7: =MEDIAN($K7) -> 0 | AR7: =MEDIAN($M7) -> 0 | AS7: =MEDIAN($N7) -> 0 | AT7: =MEDIAN($P7) -> 0 | AU7: =MEDIAN($Q7) -> 0 | AV7: =MEDIAN($R7) -> 0 | AW7: =MAX($B7) -> 0 | AX7: =MAX($C7) -> 0 | AY7: =MAX($D7) -> 0 | AZ7: =MAX($E7) -> 0 | BA7: =MAX($F7) -> 0 | BB7: =MAX($G7) -> 0 | BC7: =MAX($H7) -> 0 | BD7: =MAX($I7) -> 0 | BE7: =MAX($J7) -> 0 | BF7: =MAX($K7) -> 0 | BG7: =MAX($M7) -> 0 | BH7: =MAX($N7) -> 0 | BI7: =MAX($P7) -> 0 | BJ7: =MAX($Q7) -> 0 | BK7: =MAX($R7) -> 0
A8: /Level_5 | B8: 0 | C8: 0 | D8: 0 | E8: 0 | F8: 15011 | G8: 1 | H8: 0 | I8: 161.406 | J8: 3000 | K8: 0 | L8: out of memory | M8: 0 | N8: 0 | O8: UNKNOWN | P8: 1500 | Q8: 1 | R8: 0 | S8: =MIN($B8) -> 0 | T8: =MIN($C8) -> 0 | U8: =MIN($D8) -> 0 | V8: =MIN($E8) -> 0 | W8: =MIN($F8) -> 0 | X8: =MIN($G8) -> 0 | Y8: =MIN($H8) -> 0 | Z8: =MIN($I8) -> 0 | AA8: =MIN($J8) -> 0 | AB8: =MIN($K8) -> 0 | AC8: =MIN($M8) -> 0 | AD8: =MIN($N8) -> 0 | AE8: =MIN($P8) -> 0 | AF8: =MIN($Q8) -> 0 | AG8: =MIN($R8) -> 0 | AH8: =MEDIAN($B8) -> 0 | AI8: =MEDIAN($C8) -> 0 | AJ8: =MEDIAN($D8) -> 0 | AK8: =MEDIAN($E8) -> 0 | AL8: =MEDIAN($F8) -> 0 | AM8: =MEDIAN($G8) -> 0 | AN8: =MEDIAN($H8) -> 0 | AO8: =MEDIAN($I8) -> 0 | AP8: =MEDIAN($J8) -> 0 | AQ8: =MEDIAN($K8) -> 0 | AR8: =MEDIAN($M8) -> 0 | AS8: =MEDIAN($N8) -> 0 | AT8: =MEDIAN($P8) -> 0 | AU8: =MEDIAN($Q8) -> 0 | AV8: =MEDIAN($R8) -> 0 | AW8: =MAX($B8) -> 0 | AX8: =MAX($C8) -> 0 | AY8: =MAX($D8) -> 0 | AZ8: =MAX($E8) -> 0 | BA8: =MAX($F8) -> 0 | BB8: =MAX($G8) -> 0 | BC8: =MAX($H8) -> 0 | BD8: =MAX($I8) -> 0 | BE8: =MAX($J8) -> 0 | BF8: =MAX($K8) -> 0 | BG8: =MAX($M8) -> 0 | BH8: =MAX($N8) -> 0 | BI8: =MAX($P8) -> 0 | BJ8: =MAX($Q8) -> 0 | BK8: =MAX($R8) -> 0
A9: /Level_6 | B9: 0 | C9: 0 | D9: 0 | E9: 0 | F9: 15007 | G9: 1 | H9: 0 | I9: 161.406 | J9: 3000 | K9: 0 | L9: out of memory | M9: 0 | N9: 0 | O9: UNKNOWN | P9: 1500 | Q9: 1 | R9: 0 | S9: =MIN($B9) -> 0 | T9: =MIN($C9) -> 0 | U9: =MIN($D9) -> 0 | V9: =MIN($E9) -> 0 | W9: =MIN($F9) -> 0 | X9: =MIN($G9) -> 0 | Y9: =MIN($H9) -> 0 | Z9: =MIN($I9) -> 0 | AA9: =MIN($J9) -> 0 | AB9: =MIN($K9) -> 0 | AC9: =MIN($M9) -> 0 | AD9: =MIN($N9) -> 0 | AE9: =MIN($P9) -> 0 | AF9: =MIN($Q9) -> 0 | AG9: =MIN($R9) -> 0 | AH9: =MEDIAN($B9) -> 0 | AI9: =MEDIAN($C9) -> 0 | AJ9: =MEDIAN($D9) -> 0 | AK9: =MEDIAN($E9) -> 0 | AL9: =MEDIAN($F9) -> 0 | AM9: =MEDIAN($G9) -> 0 | AN9: =MEDIAN($H9) -> 0 | AO9: =MEDIAN($I9) -> 0 | AP9: =MEDIAN($J9) -> 0 | AQ9: =MEDIAN($K9) -> 0 | AR9: =MEDIAN($M9) -> 0 | AS9: =MEDIAN($N9) -> 0 | AT9: =MEDIAN($P9) -> 0 | AU9: =MEDIAN($Q9) -> 0 | AV9: =MEDIAN($R9) -> 0 | AW9: =MAX($B9) -> 0 | AX9: =MAX($C9) -> 0 | AY9: =MAX($D9) -> 0 | AZ9: =MAX($E9) -> 0 | BA9: =MAX($F9) -> 0 | BB9: =MAX($G9) -> 0 | BC9: =MAX($H9) -> 0 | BD9: =MAX($I9) -> 0 | BE9: =MAX($J9) -> 0 | BF9: =MAX($K9) -> 0 | BG9: =MAX($M9) -> 0 | BH9: =MAX($N9) -> 0 | BI9: =MAX($P9) -> 0 | BJ9: =MAX($Q9) -> 0 | BK9: =MAX($R9) -> 0
A10: /Level_7 | B10: 0 | C10: 0 | D10: 0 | E10: 0 | F10: 15007 | G10: 1 | H10: 0 | I10: 162.005 | J10: 3000 | K10: 0 | L10: out of memory | M10: 0 | N10: 0 | O10: UNKNOWN | P10: 1500 | Q10: 1 | R10: 0 | S10: =MIN($B10) -> 0 | T10: =MIN($C10) -> 0 | U10: =MIN($D10) -> 0 | V10: =MIN($E10) -> 0 | W10: =MIN($F10) -> 0 | X10: =MIN($G10) -> 0 | Y10: =MIN($H10) -> 0 | Z10: =MIN($I10) -> 0 | AA10: =MIN($J10) -> 0 | AB10: =MIN($K10) -> 0 | AC10: =MIN($M10) -> 0 | AD10: =MIN($N10) -> 0 | AE10: =MIN($P10) -> 0 | AF10: =MIN($Q10) -> 0 | AG10: =MIN($R10) -> 0 | AH10: =MEDIAN($B10) -> 0 | AI10: =MEDIAN($C10) -> 0 | AJ10: =MEDIAN($D10) -> 0 | AK10: =MEDIAN($E10) -> 0 | AL10: =MEDIAN($F10) -> 0 | AM10: =MEDIAN($G10) -> 0 | AN10: =MEDIAN($H10) -> 0 | AO10: =MEDIAN($I10) -> 0 | AP10: =MEDIAN($J10) -> 0 | AQ10: =MEDIAN($K10) -> 0 | AR10: =MEDIAN($M10) -> 0 | AS10: =MEDIAN($N10) -> 0 | AT10: =MEDIAN($P10) -> 0 | AU10: =MEDIAN($Q10) -> 0 | AV10: =MEDIAN($R10) -> 0 | AW10: =MAX($B10) -> 0 | AX10: =MAX($C10) -> 0 | AY10: =MAX($D10) -> 0 | AZ10: =MAX($E10) -> 0 | BA10: =MAX($F10) -> 0 | BB10: =MAX($G10) -> 0 | BC10: =MAX($H10) -> 0 | BD10: =MAX($I10) -> 0 | BE10: =MAX($J10) -> 0 | BF10: =MAX($K10) -> 0 | BG10: =MAX($M10) -> 0 | BH10: =MAX($N10) -> 0 | BI10: =MAX($P10) -> 0 | BJ10: =MAX($Q10) -> 0 | BK10: =MAX($R10) -> 0
A11: /Level_8 | B11: 0 | C11: 0 | D11: 0 | E11: 0 | F11: 15007 | G11: 1 | H11: 0 | I11: 161.806 | J11: 3000 | K11: 0 | L11: out of memory | M11: 0 | N11: 0 | O11: UNKNOWN | P11: 1500 | Q11: 1 | R11: 0 | S11: =MIN($B11) -> 0 | T11: =MIN($C11) -> 0 | U11: =MIN($D11) -> 0 | V11: =MIN($E11) -> 0 | W11: =MIN($F11) -> 0 | X11: =MIN($G11) -> 0 | Y11: =MIN($H11) -> 0 | Z11: =MIN($I11) -> 0 | AA11: =MIN($J11) -> 0 | AB11: =MIN($K11) -> 0 | AC11: =MIN($M11) -> 0 | AD11: =MIN($N11) -> 0 | AE11: =MIN($P11) -> 0 | AF11: =MIN($Q11) -> 0 | AG11: =MIN($R11) -> 0 | AH11: =MEDIAN($B11) -> 0 | AI11: =MEDIAN($C11) -> 0 | AJ11: =MEDIAN($D11) -> 0 | AK11: =MEDIAN($E11) -> 0 | AL11: =MEDIAN($F11) -> 0 | AM11: =MEDIAN($G11) -> 0 | AN11: =MEDIAN($H11) -> 0 | AO11: =MEDIAN($I11) -> 0 | AP11: =MEDIAN($J11) -> 0 | AQ11: =MEDIAN($K11) -> 0 | AR11: =MEDIAN($M11) -> 0 | AS11: =MEDIAN($N11) -> 0 | AT11: =MEDIAN($P11) -> 0 | AU11: =MEDIAN($Q11) -> 0 | AV11: =MEDIAN($R11) -> 0 | AW11: =MAX($B11) -> 0 | AX11: =MAX($C11) -> 0 | AY11: =MAX($D11) -> 0 | AZ11: =MAX($E11) -> 0 | BA11: =MAX($F11) -> 0 | BB11: =MAX($G11) -> 0 | BC11: =MAX($H11) -> 0 | BD11: =MAX($I11) -> 0 | BE11: =MAX($J11) -> 0 | BF11: =MAX($K11) -> 0 | BG11: =MAX($M11) -> 0 | BH11: =MAX($N11) -> 0 | BI11: =MAX($P11) -> 0 | BJ11: =MAX($Q11) -> 0 | BK11: =MAX($R11) -> 0
A12: /Level_9 | B12: 0 | C12: 0 | D12: 0 | E12: 0 | F12: 15004 | G12: 1 | H12: 0 | I12: 156.339 | J12: 3000 | K12: 0 | L12: out of memory | M12: 0 | N12: 0 | O12: UNKNOWN | P12: 1500 | Q12: 1 | R12: 0 | S12: =MIN($B12) -> 0 | T12: =MIN($C12) -> 0 | U12: =MIN($D12) -> 0 | V12: =MIN($E12) -> 0 | W12: =MIN($F12) -> 0 | X12: =MIN($G12) -> 0 | Y12: =MIN($H12) -> 0 | Z12: =MIN($I12) -> 0 | AA12: =MIN($J12) -> 0 | AB12: =MIN($K12) -> 0 | AC12: =MIN($M12) -> 0 | AD12: =MIN($N12) -> 0 | AE12: =MIN($P12) -> 0 | AF12: =MIN($Q12) -> 0 | AG12: =MIN($R12) -> 0 | AH12: =MEDIAN($B12) -> 0 | AI12: =MEDIAN($C12) -> 0 | AJ12: =MEDIAN($D12) -> 0 | AK12: =MEDIAN($E12) -> 0 | AL12: =MEDIAN($F12) -> 0 | AM12: =MEDIAN($G12) -> 0 | AN12: =MEDIAN($H12) -> 0 | AO12: =MEDIAN($I12) -> 0 | AP12: =MEDIAN($J12) -> 0 | AQ12: =MEDIAN($K12) -> 0 | AR12: =MEDIAN($M12) -> 0 | AS12: =MEDIAN($N12) -> 0 | AT12: =MEDIAN($P12) -> 0 | AU12: =MEDIAN($Q12) -> 0 | AV12: =MEDIAN($R12) -> 0 | AW12: =MAX($B12) -> 0 | AX12: =MAX($C12) -> 0 | AY12: =MAX($D12) -> 0 | AZ12: =MAX($E12) -> 0 | BA12: =MAX($F12) -> 0 | BB12: =MAX($G12) -> 0 | BC12: =MAX($H12) -> 0 | BD12: =MAX($I12) -> 0 | BE12: =MAX($J12) -> 0 | BF12: =MAX($K12) -> 0 | BG12: =MAX($M12) -> 0 | BH12: =MAX($N12) -> 0 | BI12: =MAX($P12) -> 0 | BJ12: =MAX($Q12) -> 0 | BK12: =MAX($R12) -> 0
A13: /Level_0 | B13: 0 | C13: 0 | D13: 0 | E13: 0 | F13: 15007 | G13: 1 | H13: 0 | I13: 162.106 | J13: 3000 | K13: 0 | L13: out of memory | M13: 0 | N13: 0 | O13: UNKNOWN | P13: 1500 | Q13: 1 | R13: 0 | S13: =MIN($B13) -> 0 | T13: =MIN($C13) -> 0 | U13: =MIN($D13) -> 0 | V13: =MIN($E13) -> 0 | W13: =MIN($F13) -> 0 | X13: =MIN($G13) -> 0 | Y13: =MIN($H13) -> 0 | Z13: =MIN($I13) -> 0 | AA13: =MIN($J13) -> 0 | AB13: =MIN($K13) -> 0 | AC13: =MIN($M13) -> 0 | AD13: =MIN($N13) -> 0 | AE13: =MIN($P13) -> 0 | AF13: =MIN($Q13) -> 0 | AG13: =MIN($R13) -> 0 | AH13: =MEDIAN($B13) -> 0 | AI13: =MEDIAN($C13) -> 0 | AJ13: =MEDIAN($D13) -> 0 | AK13: =MEDIAN($E13) -> 0 | AL13: =MEDIAN($F13) -> 0 | AM13: =MEDIAN($G13) -> 0 | AN13: =MEDIAN($H13) -> 0 | AO13: =MEDIAN($I13) -> 0 | AP13: =MEDIAN($J13) -> 0 | AQ13: =MEDIAN($K13) -> 0 | AR13: =MEDIAN($M13) -> 0 | AS13: =MEDIAN($N13) -> 0 | AT13: =MEDIAN($P13) -> 0 | AU13: =MEDIAN($Q13) -> 0 | AV13: =MEDIAN($R13) -> 0 | AW13: =MAX($B13) -> 0 | AX13: =MAX($C13) -> 0 | AY13: =MAX($D13) -> 0 | AZ13: =MAX($E13) -> 0 | BA13: =MAX($F13) -> 0 | BB13: =MAX($G13) -> 0 | BC13: =MAX($H13) -> 0 | BD13: =MAX($I13) -> 0 | BE13: =MAX($J13) -> 0 | BF13: =MAX($K13) -> 0 | BG13: =MAX($M13) -> 0 | BH13: =MAX($N13) -> 0 | BI13: =MAX($P13) -> 0 | BJ13: =MAX($Q13) -> 0 | BK13: =MAX($R13) -> 0
A14: /Level_1 | B14: 0 | C14: 0 | D14: 0 | E14: 0 | F14: 15007 | G14: 1 | H14: 0 | I14: 161.706 | J14: 3000 | K14: 0 | L14: out of memory | M14: 0 | N14: 0 | O14: UNKNOWN | P14: 1500 | Q14: 1 | R14: 0 | S14: =MIN($B14) -> 0 | T14: =MIN($C14) -> 0 | U14: =MIN($D14) -> 0 | V14: =MIN($E14) -> 0 | W14: =MIN($F14) -> 0 | X14: =MIN($G14) -> 0 | Y14: =MIN($H14) -> 0 | Z14: =MIN($I14) -> 0 | AA14: =MIN($J14) -> 0 | AB14: =MIN($K14) -> 0 | AC14: =MIN($M14) -> 0 | AD14: =MIN($N14) -> 0 | AE14: =MIN($P14) -> 0 | AF14: =MIN($Q14) -> 0 | AG14: =MIN($R14) -> 0 | AH14: =MEDIAN($B14) -> 0 | AI14: =MEDIAN($C14) -> 0 | AJ14: =MEDIAN($D14) -> 0 | AK14: =MEDIAN($E14) -> 0 | AL14: =MEDIAN($F14) -> 0 | AM14: =MEDIAN($G14) -> 0 | AN14: =MEDIAN($H14) -> 0 | AO14: =MEDIAN($I14) -> 0 | AP14: =MEDIAN($J14) -> 0 | AQ14: =MEDIAN($K14) -> 0 | AR14: =MEDIAN($M14) -> 0 | AS14: =MEDIAN($N14) -> 0 | AT14: =MEDIAN($P14) -> 0 | AU14: =MEDIAN($Q14) -> 0 | AV14: =MEDIAN($R14) -> 0 | AW14: =MAX($B14) -> 0 | AX14: =MAX($C14) -> 0 | AY14: =MAX($D14) -> 0 | AZ14: =MAX($E14) -> 0 | BA14: =MAX($F14) -> 0 | BB14: =MAX($G14) -> 0 | BC14: =MAX($H14) -> 0 | BD14: =MAX($I14) -> 0 | BE14: =MAX($J14) -> 0 | BF14: =MAX($K14) -> 0 | BG14: =MAX($M14) -> 0 | BH14: =MAX($N14) -> 0 | BI14: =MAX($P14) -> 0 | BJ14: =MAX($Q14) -> 0 | BK14: =MAX($R14) -> 0
... A32: /Level_9 | B32: 0 | C32: 0 | D32: 0 | E32: 0 | F32: 15003 | G32: 1 | H32: 0 | I32: 162.006 | J32: 3000 | K32: 0 | L32: out of memory | M32: 0 | N32: 0 | O32: UNKNOWN | P32: 1500 | Q32: 1 | R32: 0 | S32: =MIN($B32) -> 0 | T32: =MIN($C32) -> 0 | U32: =MIN($D32) -> 0 | V32: =MIN($E32) -> 0 | W32: =MIN($F32) -> 0 | X32: =MIN($G32) -> 0 | Y32: =MIN($H32) -> 0 | Z32: =MIN($I32) -> 0 | AA32: =MIN($J32) -> 0 | AB32: =MIN($K32) -> 0 | AC32: =MIN($M32) -> 0 | AD32: =MIN($N32) -> 0 | AE32: =MIN($P32) -> 0 | AF32: =MIN($Q32) -> 0 | AG32: =MIN($R32) -> 0 | AH32: =MEDIAN($B32) -> 0 | AI32: =MEDIAN($C32) -> 0 | AJ32: =MEDIAN($D32) -> 0 | AK32: =MEDIAN($E32) -> 0 | AL32: =MEDIAN($F32) -> 0 | AM32: =MEDIAN($G32) -> 0 | AN32: =MEDIAN($H32) -> 0 | AO32: =MEDIAN($I32) -> 0 | AP32: =MEDIAN($J32) -> 0 | AQ32: =MEDIAN($K32) -> 0 | AR32: =MEDIAN($M32) -> 0 | AS32: =MEDIAN($N32) -> 0 | AT32: =MEDIAN($P32) -> 0 | AU32: =MEDIAN($Q32) -> 0 | AV32: =MEDIAN($R32) -> 0 | AW32: =MAX($B32) -> 0 | AX32: =MAX($C32) -> 0 | AY32: =MAX($D32) -> 0 | AZ32: =MAX($E32) -> 0 | BA32: =MAX($F32) -> 0 | BB32: =MAX($G32) -> 0 | BC32: =MAX($H32) -> 0 | BD32: =MAX($I32) -> 0 | BE32: =MAX($J32) -> 0 | BF32: =MAX($K32) -> 0 | BG32: =MAX($M32) -> 0 | BH32: =MAX($N32) -> 0 | BI32: =MAX($P32) -> 0 | BJ32: =MAX($Q32) -> 0 | BK32: =MAX($R32) -> 0
A34: SUM | B34: =SUM(B$3:B$32) -> 0 | C34: =SUM(C$3:C$32) -> 0 | D34: =SUM(D$3:D$32) -> 0 | E34: =SUM(E$3:E$32) -> 0 | F34: =SUM(F$3:F$32) -> 0 | G34: =SUM(G$3:G$32) -> 0 | H34: =SUM(H$3:H$32) -> 0 | I34: =SUM(I$3:I$32) -> 0 | ... K34: =SUM(K$3:K$32) -> 0 | M34: =SUM(M$3:M$32) -> 0 | N34: =SUM(N$3:N$32) -> 0 | P34: =SUM(P$3:P$32) -> 0 | Q34: =SUM(Q$3:Q$32) -> 0 | R34: =SUM(R$3:R$32) -> 0 | S34: =SUM(S$3:S$32) -> 0 | T34: =SUM(T$3:T$32) -> 0 | U34: =SUM(U$3:U$32) -> 0 | V34: =SUM(V$3:V$32) -> 0 | W34: =SUM(W$3:W$32) -> 0 | ... BK34: =SUM(BK$3:BK$32) -> 0
A35: AVG | B35: =AVERAGE(B$3:B$32) -> 0 | C35: =AVERAGE(C$3:C$32) -> 0 | D35: =AVERAGE(D$3:D$32) -> 0 | E35: =AVERAGE(E$3:E$32) -> 0 | F35: =AVERAGE(F$3:F$32) -> 0 | G35: =AVERAGE(G$3:G$32) -> 0 | H35: =AVERAGE(H$3:H$32) -> 0 | I35: =AVERAGE(I$3:I$32) -> 0 | ... K35: =AVERAGE(K$3:K$32) -> 0 | M35: =AVERAGE(M$3:M$32) -> 0 | N35: =AVERAGE(N$3:N$32) -> 0 | P35: =AVERAGE(P$3:P$32) -> 0 | Q35: =AVERAGE(Q$3:Q$32) -> 0 | R35: =AVERAGE(R$3:R$32) -> 0 | S35: =AVERAGE(S$3:S$32) -> 0 | T35: =AVERAGE(T$3:T$32) -> 0 | U35: =AVERAGE(U$3:U$32) -> 0 | V35: =AVERAGE(V$3:V$32) -> 0 | W35: =AVERAGE(W$3:W$32) -> 0 | ... BK35: =AVERAGE(BK$3:BK$32) -> 0
A36: DEV | B36: =STDEV(B$3:B$32) -> 0 | C36: =STDEV(C$3:C$32) -> 0 | D36: =STDEV(D$3:D$32) -> 0 | E36: =STDEV(E$3:E$32) -> 0 | F36: =STDEV(F$3:F$32) -> 0 | G36: =STDEV(G$3:G$32) -> 0 | H36: =STDEV(H$3:H$32) -> 0 | I36: =STDEV(I$3:I$32) -> 0 | ... K36: =STDEV(K$3:K$32) -> 0 | M36: =STDEV(M$3:M$32) -> 0 | N36: =STDEV(N$3:N$32) -> 0 | P36: =STDEV(P$3:P$32) -> 0 | Q36: =STDEV(Q$3:Q$32) -> 0 | R36: =STDEV(R$3:R$32) -> 0 | S36: =STDEV(S$3:S$32) -> 0 | T36: =STDEV(T$3:T$32) -> 0 | U36: =STDEV(U$3:U$32) -> 0 | V36: =STDEV(V$3:V$32) -> 0 | W36: =STDEV(W$3:W$32) -> 0 | ... BK36: =STDEV(BK$3:BK$32) -> 0
A37: DST | B37: =SUMPRODUCT(--(B$3:B$32-$S$3:$S$32)^2)^0.5 -> 0 | C37: =SUMPRODUCT(--(C$3:C$32-$T$3:$T$32)^2)^0.5 -> 0 | D37: =SUMPRODUCT(--(D$3:D$32-$U$3:$U$32)^2)^0.5 -> 0 | E37: =SUMPRODUCT(--(E$3:E$32-$V$3:$V$32)^2)^0.5 -> 0 | F37: =SUMPRODUCT(--(F$3:F$32-$W$3:$W$32)^2)^0.5 -> 0 | G37: =SUMPRODUCT(--(G$3:G$32-$X$3:$X$32)^2)^0.5 -> 0 | H37: =SUMPRODUCT(--(H$3:H$32-$Y$3:$Y$32)^2)^0.5 -> 0 | I37: =SUMPRODUCT(--(I$3:I$32-$Z$3:$Z$32)^2)^0.5 -> 0 | J37: =SUMPRODUCT(--(J$3:J$32-$AA$3:$AA$32)^2)^0.5 -> 0 | K37: =SUMPRODUCT(--(K$3:K$32-$AB$3:$AB$32)^2)^0.5 -> 0 | M37: =SUMPRODUCT(--(M$3:M$32-$AC$3:$AC$32)^2)^0.5 -> 0 | N37: =SUMPRODUCT(--(N$3:N$32-$AD$3:$AD$32)^2)^0.5 -> 0 | P37: =SUMPRODUCT(--(P$3:P$32-$AE$3:$AE$32)^2)^0.5 -> 0 | Q37: =SUMPRODUCT(--(Q$3:Q$32-$AF$3:$AF$32)^2)^0.5 -> 0 | R37: =SUMPRODUCT(--(R$3:R$32-$AG$3:$AG$32)^2)^0.5 -> 0
A38: BEST | B38: =SUMPRODUCT(NOT(ISBLANK(B$3:B$32))*(B$3:B$32=$S$3:$S$32)) -> 0 | C38: =SUMPRODUCT(NOT(ISBLANK(C$3:C$32))*(C$3:C$32=$T$3:$T$32)) -> 0 | D38: =SUMPRODUCT(NOT(ISBLANK(D$3:D$32))*(D$3:D$32=$U$3:$U$32)) -> 0 | E38: =SUMPRODUCT(NOT(ISBLANK(E$3:E$32))*(E$3:E$32=$V$3:$V$32)) -> 0 | F38: =SUMPRODUCT(NOT(ISBLANK(F$3:F$32))*(F$3:F$32=$W$3:$W$32)) -> 0 | G38: =SUMPRODUCT(NOT(ISBLANK(G$3:G$32))*(G$3:G$32=$X$3:$X$32)) -> 0 | H38: =SUMPRODUCT(NOT(ISBLANK(H$3:H$32))*(H$3:H$32=$Y$3:$Y$32)) -> 0 | I38: =SUMPRODUCT(NOT(ISBLANK(I$3:I$32))*(I$3:I$32=$Z$3:$Z$32)) -> 0 | J38: =SUMPRODUCT(NOT(ISBLANK(J$3:J$32))*(J$3:J$32=$AA$3:$AA$32)) -> 0 | K38: =SUMPRODUCT(NOT(ISBLANK(K$3:K$32))*(K$3:K$32=$AB$3:$AB$32)) -> 0 | M38: =SUMPRODUCT(NOT(ISBLANK(M$3:M$32))*(M$3:M$32=$AC$3:$AC$32)) -> 0 | N38: =SUMPRODUCT(NOT(ISBLANK(N$3:N$32))*(N$3:N$32=$AD$3:$AD$32)) -> 0 | P38: =SUMPRODUCT(NOT(ISBLANK(P$3:P$32))*(P$3:P$32=$AE$3:$AE$32)) -> 0 | Q38: =SUMPRODUCT(NOT(ISBLANK(Q$3:Q$32))*(Q$3:Q$32=$AF$3:$AF$32)) -> 0 | R38: =SUMPRODUCT(NOT(ISBLANK(R$3:R$32))*(R$3:R$32=$AG$3:$AG$32)) -> 0
A39: BETTER | B39: =SUMPRODUCT(NOT(ISBLANK(B$3:B$32))*(B$3:B$32<$AH$3:$AH$32)) -> 0 | C39: =SUMPRODUCT(NOT(ISBLANK(C$3:C$32))*(C$3:C$32<$AI$3:$AI$32)) -> 0 | D39: =SUMPRODUCT(NOT(ISBLANK(D$3:D$32))*(D$3:D$32<$AJ$3:$AJ$32)) -> 0 | E39: =SUMPRODUCT(NOT(ISBLANK(E$3:E$32))*(E$3:E$32<$AK$3:$AK$32)) -> 0 | F39: =SUMPRODUCT(NOT(ISBLANK(F$3:F$32))*(F$3:F$32<$AL$3:$AL$32)) -> 0 | G39: =SUMPRODUCT(NOT(ISBLANK(G$3:G$32))*(G$3:G$32<$AM$3:$AM$32)) -> 0 | H39: =SUMPRODUCT(NOT(ISBLANK(H$3:H$32))*(H$3:H$32<$AN$3:$AN$32)) -> 0 | I39: =SUMPRODUCT(NOT(ISBLANK(I$3:I$32))*(I$3:I$32<$AO$3:$AO$32)) -> 0 | J39: =SUMPRODUCT(NOT(ISBLANK(J$3:J$32))*(J$3:J$32<$AP$3:$AP$32)) -> 0 | K39: =SUMPRODUCT(NOT(ISBLANK(K$3:K$32))*(K$3:K$32<$AQ$3:$AQ$32)) -> 0 | M39: =SUMPRODUCT(NOT(ISBLANK(M$3:M$32))*(M$3:M$32<$AR$3:$AR$32)) -> 0 | N39: =SUMPRODUCT(NOT(ISBLANK(N$3:N$32))*(N$3:N$32<$AS$3:$AS$32)) -> 0 | P39: =SUMPRODUCT(NOT(ISBLANK(P$3:P$32))*(P$3:P$32<$AT$3:$AT$32)) -> 0 | Q39: =SUMPRODUCT(NOT(ISBLANK(Q$3:Q$32))*(Q$3:Q$32<$AU$3:$AU$32)) -> 0 | R39: =SUMPRODUCT(NOT(ISBLANK(R$3:R$32))*(R$3:R$32<$AV$3:$AV$32)) -> 0
A40: WORSE | B40: =SUMPRODUCT((NOT(ISBLANK(B$3:B$32))*(B$3:B$32>$AH$3:$AH$32))+ISBLANK(B$3:B$32)) -> 0 | C40: =SUMPRODUCT((NOT(ISBLANK(C$3:C$32))*(C$3:C$32>$AI$3:$AI$32))+ISBLANK(C$3:C$32)) -> 0 | D40: =SUMPRODUCT((NOT(ISBLANK(D$3:D$32))*(D$3:D$32>$AJ$3:$AJ$32))+ISBLANK(D$3:D$32)) -> 0 | E40: =SUMPRODUCT((NOT(ISBLANK(E$3:E$32))*(E$3:E$32>$AK$3:$AK$32))+ISBLANK(E$3:E$32)) -> 0 | F40: =SUMPRODUCT((NOT(ISBLANK(F$3:F$32))*(F$3:F$32>$AL$3:$AL$32))+ISBLANK(F$3:F$32)) -> 0 | G40: =SUMPRODUCT((NOT(ISBLANK(G$3:G$32))*(G$3:G$32>$AM$3:$AM$32))+ISBLANK(G$3:G$32)) -> 0 | H40: =SUMPRODUCT((NOT(ISBLANK(H$3:H$32))*(H$3:H$32>$AN$3:$AN$32))+ISBLANK(H$3:H$32)) -> 0 | I40: =SUMPRODUCT((NOT(ISBLANK(I$3:I$32))*(I$3:I$32>$AO$3:$AO$32))+ISBLANK(I$3:I$32)) -> 0 | J40: =SUMPRODUCT((NOT(ISBLANK(J$3:J$32))*(J$3:J$32>$AP$3:$AP$32))+ISBLANK(J$3:J$32)) -> 0 | K40: =SUMPRODUCT((NOT(ISBLANK(K$3:K$32))*(K$3:K$32>$AQ$3:$AQ$32))+ISBLANK(K$3:K$32)) -> 0 | M40: =SUMPRODUCT((NOT(ISBLANK(M$3:M$32))*(M$3:M$32>$AR$3:$AR$32))+ISBLANK(M$3:M$32)) -> 0 | N40: =SUMPRODUCT((NOT(ISBLANK(N$3:N$32))*(N$3:N$32>$AS$3:$AS$32))+ISBLANK(N$3:N$32)) -> 0 | P40: =SUMPRODUCT((NOT(ISBLANK(P$3:P$32))*(P$3:P$32>$AT$3:$AT$32))+ISBLANK(P$3:P$32)) -> 0 | Q40: =SUMPRODUCT((NOT(ISBLANK(Q$3:Q$32))*(Q$3:Q$32>$AU$3:$AU$32))+ISBLANK(Q$3:Q$32)) -> 0 | R40: =SUMPRODUCT((NOT(ISBLANK(R$3:R$32))*(R$3:R$32>$AV$3:$AV$32))+ISBLANK(R$3:R$32)) -> 0
A41: WORST | B41: =SUMPRODUCT((NOT(ISBLANK(B$3:B$32))*(B$3:B$32=$AW$3:$AW$32))+ISBLANK(B$3:B$32)) -> 0 | C41: =SUMPRODUCT((NOT(ISBLANK(C$3:C$32))*(C$3:C$32=$AX$3:$AX$32))+ISBLANK(C$3:C$32)) -> 0 | D41: =SUMPRODUCT((NOT(ISBLANK(D$3:D$32))*(D$3:D$32=$AY$3:$AY$32))+ISBLANK(D$3:D$32)) -> 0 | E41: =SUMPRODUCT((NOT(ISBLANK(E$3:E$32))*(E$3:E$32=$AZ$3:$AZ$32))+ISBLANK(E$3:E$32)) -> 0 | F41: =SUMPRODUCT((NOT(ISBLANK(F$3:F$32))*(F$3:F$32=$BA$3:$BA$32))+ISBLANK(F$3:F$32)) -> 0 | G41: =SUMPRODUCT((NOT(ISBLANK(G$3:G$32))*(G$3:G$32=$BB$3:$BB$32))+ISBLANK(G$3:G$32)) -> 0 | H41: =SUMPRODUCT((NOT(ISBLANK(H$3:H$32))*(H$3:H$32=$BC$3:$BC$32))+ISBLANK(H$3:H$32)) -> 0 | I41: =SUMPRODUCT((NOT(ISBLANK(I$3:I$32))*(I$3:I$32=$BD$3:$BD$32))+ISBLANK(I$3:I$32)) -> 0 | J41: =SUMPRODUCT((NOT(ISBLANK(J$3:J$32))*(J$3:J$32=$BE$3:$BE$32))+ISBLANK(J$3:J$32)) -> 0 | K41: =SUMPRODUCT((NOT(ISBLANK(K$3:K$32))*(K$3:K$32=$BF$3:$BF$32))+ISBLANK(K$3:K$32)) -> 0 | M41: =SUMPRODUCT((NOT(ISBLANK(M$3:M$32))*(M$3:M$32=$BG$3:$BG$32))+ISBLANK(M$3:M$32)) -> 0 | N41: =SUMPRODUCT((NOT(ISBLANK(N$3:N$32))*(N$3:N$32=$BH$3:$BH$32))+ISBLANK(N$3:N$32)) -> 0 | P41: =SUMPRODUCT((NOT(ISBLANK(P$3:P$32))*(P$3:P$32=$BI$3:$BI$32))+ISBLANK(P$3:P$32)) -> 0 | Q41: =SUMPRODUCT((NOT(ISBLANK(Q$3:Q$32))*(Q$3:Q$32=$BJ$3:$BJ$32))+ISBLANK(Q$3:Q$32)) -> 0 | R41: =SUMPRODUCT((NOT(ISBLANK(R$3:R$32))*(R$3:R$32=$BK$3:$BK$32))+ISBLANK(R$3:R$32)) -> 0

Sheet Merged Runs
A1: Merge criteria: | B1: clingo-5.8.0/one-as | S1: min | AH1: median | AW1: max
A2: median | B2: choices | C2: conflicts | D2: constraints | E2: error | F2: mem | G2: memout | H2: models | I2: overall-time | J2: par2 | K2: restarts | L2: rstatus | M2: rules | N2: solving-time | O2: status | P2: time | Q2: timeout | R2: variables | S2: choices | T2: conflicts | U2: constraints | V2: error | W2: mem | X2: memout | Y2: models | Z2: overall-time | AA2: par2 | AB2: restarts | AC2: rules | AD2: solving-time | AE2: time | AF2: timeout | AG2: variables | AH2: choices | AI2: conflicts | AJ2: constraints | AK2: error | AL2: mem | AM2: memout | AN2: models | AO2: overall-time | AP2: par2 | AQ2: restarts | AR2: rules | AS2: solving-time | AT2: time | AU2: timeout | AV2: variables | AW2: choices | AX2: conflicts | AY2: constraints | AZ2: error | BA2: mem | BB2: memout | BC2: models | BD2: overall-time | BE2: par2 | BF2: restarts | BG2: rules | BH2: solving-time | BI2: time | BJ2: timeout | BK2: variables
A3: /Level_0 | B3: {=_xlfn.SWITCH($A$2,"average", AVERAGE(Instances!B3:Instances!B3),"median", MEDIAN(Instances!B3:Instances!B3),"min", MIN(Instances!B3:Instances!B3),"max", MAX(Instances!B3:Instances!B3),"diff", MAX(Instances!B3:Instances!B3)-MIN(Instances!B3:Instances!B3))} -> 0 | C3: {=_xlfn.SWITCH($A$2,"average", AVERAGE(Instances!C3:Instances!C3),"median", MEDIAN(Instances!C3:Instances!C3),"min", MIN(Instances!C3:Instances!C3),"max", MAX(Instances!C3:Instances!C3),"diff", MAX(Instances!C3:Instances!C3)-MIN(Instances!C3:Instances!C3))} -> 0 | D3: {=_xlfn.SWITCH($A$2,"average", AVERAGE(Instances!D3:Instances!D3),"median", MEDIAN(Instances!D3:Instances!D3),"min", MIN(Instances!D3:Instances!D3),"max", MAX(Instances!D3:Instances!D3),"diff", MAX(Instances!D3:Instances!D3)-MIN(Instances!D3:Instances!D3))} -> 0 | E3: {=_xlfn.SWITCH($A$2,"average", AVERAGE(Instances!E3:Instances!E3),"median", MEDIAN(Instances!E3:Instances!E3),"min", MIN(Instances!E3:Instances!E3),"max", MAX(Instances!E3:Instances!E3),"diff", MAX(Instances!E3:Instances!E3)-MIN(Instances!E3:Instances!E3))} -> 0 | F3: {=_xlfn.SWITCH($A$2,"average", AVERAGE(Instances!F3:Instances!F3),"median", MEDIAN(Instances!F3:Instances!F3),"min", MIN(Instances!F3:Instances!F3),"max", MAX(Instances!F3:Instances!F3),"diff", MAX(Instances!F3:Instances!F3)-MIN(Instances!F3:Instances!F3))} -> 0 | G3: {=_xlfn.SWITCH($A$2,"average", AVERAGE(Instances!G3:Instances!G3),"median", MEDIAN(Instances!G3:Instances!G3),"min", MIN(Instances!G3:Instances!G3),"max", MAX(Instances!G3:Instances!G3),"diff", MAX(Instances!G3:Instances!G3)-MIN(Instances!G3:Instances!G3))} -> 0 | H3: {=_xlfn.SWITCH($A$2,"average", AVERAGE(Instances!H3:Instances!H3),"median", MEDIAN(Instances!H3:Instances!H3),"min", MIN(Instances!H3:Instances!H3),"max", MAX(Instances!H3:Instances!H3),"diff", MAX(Instances!H3:Instances!H3)-MIN(Instances!H3:Instances!H3))} -> 0 | I3: {=_xlfn.SWITCH($A$2,"average", AVERAGE(Instances!I3:Instances!I3),"median", MEDIAN(Instances!I3:Instances!I3),"min", MIN(Instances!I3:Instances!I3),"max", MAX(Instances!I3:Instances!I3),"diff", MAX(Instances!I3:Instances!I3)-MIN(Instances!I3:Instances!I3))} -> 0 | ... K3: {=_xlfn.SWITCH($A$2,"average", AVERAGE(Instances!K3:Instances!K3),"median", MEDIAN(Instances!K3:Instances!K3),"min", MIN(Instances!K3:Instances!K3),"max", MAX(Instances!K3:Instances!K3),"diff", MAX(Instances!K3:Instances!K3)-MIN(Instances!K3:Instances!K3))} -> 0 | M3: {=_xlfn.SWITCH($A$2,"average", AVERAGE(Instances!M3:Instances!M3),"median", MEDIAN(Instances!M3:Instances!M3),"min", MIN(Instances!M3:Instances!M3),"max", MAX(Instances!M3:Instances!M3),"diff", MAX(Instances!M3:Instances!M3)-MIN(Instances!M3:Instances!M3))} -> 0 | N3: {=_xlfn.SWITCH($A$2,"average", AVERAGE(Instances!N3:Instances!N3),"median", MEDIAN(Instances!N3:Instances!N3),"min", MIN(Instances!N3:Instances!N3),"max", MAX(Instances!N3:Instances!N3),"diff", MAX(Instances!N3:Instances!N3)-MIN(Instances!N3:Instances!N3))} -> 0 | P3: {=_xlfn.SWITCH($A$2,"average", AVERAGE(Instances!P3:Instances!P3),"median", MEDIAN(Instances!P3:Instances!P3),"min", MIN(Instances!P3:Instances!P3),"max", MAX(Instances!P3:Instances!P3),"diff", MAX(Instances!P3:Instances!P3)-MIN(Instances!P3:Instances!P3))} -> 0 | Q3: {=_xlfn.SWITCH($A$2,"average", AVERAGE(Instances!Q3:Instances!Q3),"median", MEDIAN(Instances!Q3:Instances!Q3),"min", MIN(Instances!Q3:Instances!Q3),"max", MAX(Instances!Q3:Instances!Q3),"diff", MAX(Instances!Q3:Instances!Q3)-MIN(Instances!Q3:Instances!Q3))} -> 0 | R3: {=_xlfn.SWITCH($A$2,"average", AVERAGE(Instances!R3:Instances!R3),"median", MEDIAN(Instances!R3:Instances!R3),"min", MIN(Instances!R3:Instances!R3),"max", MAX(Instances!R3:Instances!R3),"diff", MAX(Instances!R3:Instances!R3)-MIN(Instances!R3:Instances!R3))} -> 0 | S3: =MIN($B3) -> 0 | T3: =MIN($C3) -> 0 | U3: =MIN($D3) -> 0 | V3: =MIN($E3) -> 0 | W3: =MIN($F3) -> 0 | X3: =MIN($G3) -> 0 | Y3: =MIN($H3) -> 0 | Z3: =MIN($I3) -> 0 | AA3: =MIN($J3) -> 0 | AB3: =MIN($K3) -> 0 | AC3: =MIN($M3) -> 0 | AD3: =MIN($N3) -> 0 | AE3: =MIN($P3) -> 0 | AF3: =MIN($Q3) -> 0 | AG3: =MIN($R3) -> 0 | AH3: =MEDIAN($B3) -> 0 | AI3: =MEDIAN($C3) -> 0 | AJ3: =MEDIAN($D3) -> 0 | AK3: =MEDIAN($E3) -> 0 | AL3: =MEDIAN($F3) -> 0 | AM3: =MEDIAN($G3) -> 0 | AN3: =MEDIAN($H3) -> 0 | AO3: =MEDIAN($I3) -> 0 | AP3: =MEDIAN($J3) -> 0 | AQ3: =MEDIAN($K3) -> 0 | AR3: =MEDIAN($M3) -> 0 | AS3: =MEDIAN($N3) -> 0 | AT3: =MEDIAN($P3) -> 0 | AU3: =MEDIAN($Q3) -> 0 | AV3: =MEDIAN($R3) -> 0 | AW3: =MAX($B3) -> 0 | AX3: =MAX($C3) -> 0 | AY3: =MAX($D3) -> 0 | AZ3: =MAX($E3) -> 0 | BA3: =MAX($F3) -> 0 | BB3: =MAX($G3) -> 0 | BC3: =MAX($H3) -> 0 | BD3: =MAX($I3) -> 0 | BE3: =MAX($J3) -> 0 | BF3: =MAX($K3) -> 0 | BG3: =MAX($M3) -> 0 | BH3: =MAX($N3) -> 0 | BI3: =MAX($P3) -> 0 | BJ3: =MAX($Q3) -> 0 | BK3: =MAX($R3) -> 0
A4: /Level_1 | B4: {=_xlfn.SWITCH($A$2,"average", AVERAGE(Instances!B4:Instances!B4),"median", MEDIAN(Instances!B4:Instances!B4),"min", MIN(Instances!B4:Instances!B4),"max", MAX(Instances!B4:Instances!B4),"diff", MAX(Instances!B4:Instances!B4)-MIN(Instances!B4:Instances!B4))} -> 0 | C4: {=_xlfn.SWITCH($A$2,"average", AVERAGE(Instances!C4:Instances!C4),"median", MEDIAN(Instances!C4:Instances!C4),"min", MIN(Instances!C4:Instances!C4),"max", MAX(Instances!C4:Instances!C4),"diff", MAX(Instances!C4:Instances!C4)-MIN(Instances!C4:Instances!C4))} -> 0 | D4: {=_xlfn.SWITCH($A$2,"average", AVERAGE(Instances!D4:Instances!D4),"median", MEDIAN(Instances!D4:Instances!D4),"min", MIN(Instances!D4:Instances!D4),"max", MAX(Instances!D4:Instances!D4),"diff", MAX(Instances!D4:Instances!D4)-MIN(Instances!D4:Instances!D4))} -> 0 | E4: {=_xlfn.SWITCH($A$2,"average", AVERAGE(Instances!E4:Instances!E4),"median", MEDIAN(Instances!E4:Instances!E4),"min", MIN(Instances!E4:Instances!E4),"max", MAX(Instances!E4:Instances!E4),"diff", MAX(Instances!E4:Instances!E4)-MIN(Instances!E4:Instances!E4))} -> 0 | F4: {=_xlfn.SWITCH($A$2,"average", AVERAGE(Instances!F4:Instances!F4),"median", MEDIAN(Instances!F4:Instances!F4),"min", MIN(Instances!F4:Instances!F4),"max", MAX(Instances!F4:Instances!F4),"diff", MAX(Instances!F4:Instances!F4)-MIN(Instances!F4:Instances!F4))} -> 0 | G4: {=_xlfn.SWITCH($A$2,"average", AVERAGE(Instances!G4:Instances!G4),"median", MEDIAN(Instances!G4:Instances!G4),"min", MIN(Instances!G4:Instances!G4),"max", MAX(Instances!G4:Instances!G4),"diff", MAX(Instances!G4:Instances!G4)-MIN(Instances!G4:Instances!G4))} -> 0 | H4: {=_xlfn.SWITCH($A$2,"average", AVERAGE(Instances!H4:Instances!H4),"median", MEDIAN(Instances!H4:Instances!H4),"min", MIN(Instances!H4:Instances!H4),"max", MAX(Instances!H4:Instances!H4),"diff", MAX(Instances!H4:Instances!H4)-MIN(Instances!H4:Instances!H4))} -> 0 | I4: {=_xlfn.SWITCH($A$2,"average", AVERAGE(Instances!I4:Instances!I4),"median", MEDIAN(Instances!I4:Instances!I4),"min", MIN(Instances!I4:Instances!I4),"max", MAX(Instances!I4:Instances!I4),"diff", MAX(Instances!I4:Instances!I4)-MIN(Instances!I4:Instances!I4))} -> 0 | ... K4: {=_xlfn.SWITCH($A$2,"average", AVERAGE(Instances!K4:Instances!K4),"median", MEDIAN(Instances!K4:Instances!K4),"min", MIN(Instances!K4:Instances!K4),"max", MAX(Instances!K4:Instances!K4),"diff", MAX(Instances!K4:Instances!K4)-MIN(Instances!K4:Instances!K4))} -> 0 | M4: {=_xlfn.SWITCH($A$2,"average", AVERAGE(Instances!M4:Instances!M4),"median", MEDIAN(Instances!M4:Instances!M4),"min", MIN(Instances!M4:Instances!M4),"max", MAX(Instances!M4:Instances!M4),"diff", MAX(Instances!M4:Instances!M4)-MIN(Instances!M4:Instances!M4))} -> 0 | N4: {=_xlfn.SWITCH($A$2,"average", AVERAGE(Instances!N4:Instances!N4),"median", MEDIAN(Instances!N4:Instances!N4),"min", MIN(Instances!N4:Instances!N4),"max", MAX(Instances!N4:Instances!N4),"diff", MAX(Instances!N4:Instances!N4)-MIN(Instances!N4:Instances!N4))} -> 0 | P4: {=_xlfn.SWITCH($A$2,"average", AVERAGE(Instances!P4:Instances!P4),"median", MEDIAN(Instances!P4:Instances!P4),"min", MIN(Instances!P4:Instances!P4),"max", MAX(Instances!P4:Instances!P4),"diff", MAX(Instances!P4:Instances!P4)-MIN(Instances!P4:Instances!P4))} -> 0 | Q4: {=_xlfn.SWITCH($A$2,"average", AVERAGE(Instances!Q4:Instances!Q4),"median", MEDIAN(Instances!Q4:Instances!Q4),"min", MIN(Instances!Q4:Instances!Q4),"max", MAX(Instances!Q4:Instances!Q4),"diff", MAX(Instances!Q4:Instances!Q4)-MIN(Instances!Q4:Instances!Q4))} -> 0 | R4: {=_xlfn.SWITCH($A$2,"average", AVERAGE(Instances!R4:Instances!R4),"median", MEDIAN(Instances!R4:Instances!R4),"min", MIN(Instances!R4:Instances!R4),"max", MAX(Instances!R4:Instances!R4),"diff", MAX(Instances!R4:Instances!R4)-MIN(Instances!R4:Instances!R4))} -> 0 | S4: =MIN($B4) -> 0 | T4: =MIN($C4) -> 0 | U4: =MIN($D4) -> 0 | V4: =MIN($E4) -> 0 | W4: =MIN($F4) -> 0 | X4: =MIN($G4) -> 0 | Y4: =MIN($H4) -> 0 | Z4: =MIN($I4) -> 0 | AA4: =MIN($J4) -> 0 | AB4: =MIN($K4) -> 0 | AC4: =MIN($M4) -> 0 | AD4: =MIN($N4) -> 0 | AE4: =MIN($P4) -> 0 | AF4: =MIN($Q4) -> 0 | AG4: =MIN($R4) -> 0 | AH4: =MEDIAN($B4) -> 0 | AI4: =MEDIAN($C4) -> 0 | AJ4: =MEDIAN($D4) -> 0 | AK4: =MEDIAN($E4) -> 0 | AL4: =MEDIAN($F4) -> 0 | AM4: =MEDIAN($G4) -> 0 | AN4: =MEDIAN($H4) -> 0 | AO4: =MEDIAN($I4) -> 0 | AP4: =MEDIAN($J4) -> 0 | AQ4: =MEDIAN($K4) -> 0 | AR4: =MEDIAN($M4) -> 0 | AS4: =MEDIAN($N4) -> 0 | AT4: =MEDIAN($P4) -> 0 | AU4: =MEDIAN($Q4) -> 0 | AV4: =MEDIAN($R4) -> 0 | AW4: =MAX($B4) -> 0 | AX4: =MAX($C4) -> 0 | AY4: =MAX($D4) -> 0 | AZ4: =MAX($E4) -> 0 | BA4: =MAX($F4) -> 0 | BB4: =MAX($G4) -> 0 | BC4: =MAX($H4) -> 0 | BD4: =MAX($I4) -> 0 | BE4: =MAX($J4) -> 0 | BF4: =MAX($K4) -> 0 | BG4: =MAX($M4) -> 0 | BH4: =MAX($N4) -> 0 | BI4: =MAX($P4) -> 0 | BJ4: =MAX($Q4) -> 0 | BK4: =MAX($R4) -> 0
A5: /Level_2 | B5: {=_xlfn.SWITCH($A$2,"average", AVERAGE(Instances!B5:Instances!B5),"median", MEDIAN(Instances!B5:Instances!B5),"min", MIN(Instances!B5:Instances!B5),"max", MAX(Instances!B5:Instances!B5),"diff", MAX(Instances!B5:Instances!B5)-MIN(Instances!B5:Instances!B5))} -> 0 | C5: {=_xlfn.SWITCH($A$2,"average", AVERAGE(Instances!C5:Instances!C5),"median", MEDIAN(Instances!C5:Instances!C5),"min", MIN(Instances!C5:Instances!C5),"max", MAX(Instances!C5:Instances!C5),"diff", MAX(Instances!C5:Instances!C5)-MIN(Instances!C5:Instances!C5))} -> 0 | D5: {=_xlfn.SWITCH($A$2,"average", AVERAGE(Instances!D5:Instances!D5),"median", MEDIAN(Instances!D5:Instances!D5),"min", MIN(Instances!D5:Instances!D5),"max", MAX(Instances!D5:Instances!D5),"diff", MAX(Instances!D5:Instances!D5)-MIN(Instances!D5:Instances!D5))} -> 0 | E5: {=_xlfn.SWITCH($A$2,"average", AVERAGE(Instances!E5:Instances!E5),"median", MEDIAN(Instances!E5:Instances!E5),"min", MIN(Instances!E5:Instances!E5),"max", MAX(Instances!E5:Instances!E5),"diff", MAX(Instances!E5:Instances!E5)-MIN(Instances!E5:Instances!E5))} -> 0 | F5: {=_xlfn.SWITCH($A$2,"average", AVERAGE(Instances!F5:Instances!F5),"median", MEDIAN(Instances!F5:Instances!F5),"min", MIN(Instances!F5:Instances!F5),"max", MAX(Instances!F5:Instances!F5),"diff", MAX(Instances!F5:Instances!F5)-MIN(Instances!F5:Instances!F5))} -> 0 | G5: {=_xlfn.SWITCH($A$2,"average", AVERAGE(Instances!G5:Instances!G5),"median", MEDIAN(Instances!G5:Instances!G5),"min", MIN(Instances!G5:Instances!G5),"max", MAX(Instances!G5:Instances!G5),"diff", MAX(Instances!G5:Instances!G5)-MIN(Instances!G5:Instances!G5))} -> 0 | H5: {=_xlfn.SWITCH($A$2,"average", AVERAGE(Instances!H5:Instances!H5),"median", MEDIAN(Instances!H5:Instances!H5),"min", MIN(Instances!H5:Instances!H5),"max", MAX(Instances!H5:Instances!H5),"diff", MAX(Instances!H5:Instances!H5)-MIN(Instances!H5:Instances!H5))} -> 0 | I5: {=_xlfn.SWITCH($A$2,"average", AVERAGE(Instances!I5:Instances!I5),"median", MEDIAN(Instances!I5:Instances!I5),"min", MIN(Instances!I5:Instances!I5),"max", MAX(Instances!I5:Instances!I5),"diff", MAX(Instances!I5:Instances!I5)-MIN(Instances!I5:Instances!I5))} -> 0 | ... K5: {=_xlfn.SWITCH($A$2,"average", AVERAGE(Instances!K5:Instances!K5),"median", MEDIAN(Instances!K5:Instances!K5),"min", MIN(Instances!K5:Instances!K5),"max", MAX(Instances!K5:Instances!K5),"diff", MAX(Instances!K5:Instances!K5)-MIN(Instances!K5:Instances!K5))} -> 0 | M5: {=_xlfn.SWITCH($A$2,"average", AVERAGE(Instances!M5:Instances!M5),"median", MEDIAN(Instances!M5:Instances!M5),"min", MIN(Instances!M5:Instances!M5),"max", MAX(Instances!M5:Instances!M5),"diff", MAX(Instances!M5:Instances!M5)-MIN(Instances!M5:Instances!M5))} -> 0 | N5: {=_xlfn.SWITCH($A$2,"average", AVERAGE(Instances!N5:Instances!N5),"median", MEDIAN(Instances!N5:Instances!N5),"min", MIN(Instances!N5:Instances!N5),"max", MAX(Instances!N5:Instances!N5),"diff", MAX(Instances!N5:Instances!N5)-MIN(Instances!N5:Instances!N5))} -> 0 | P5: {=_xlfn.SWITCH($A$2,"average", AVERAGE(Instances!P5:Instances!P5),"median", MEDIAN(Instances!P5:Instances!P5),"min", MIN(Instances!P5:Instances!P5),"max", MAX(Instances!P5:Instances!P5),"diff", MAX(Instances!P5:Instances!P5)-MIN(Instances!P5:Instances!P5))} -> 0 | Q5: {=_xlfn.SWITCH($A$2,"average", AVERAGE(Instances!Q5:Instances!Q5),"median", MEDIAN(Instances!Q5:Instances!Q5),"min", MIN(Instances!Q5:Instances!Q5),"max", MAX(Instances!Q5:Instances!Q5),"diff", MAX(Instances!Q5:Instances!Q5)-MIN(Instances!Q5:Instances!Q5))} -> 0 | R5: {=_xlfn.SWITCH($A$2,"average", AVERAGE(Instances!R5:Instances!R5),"median", MEDIAN(Instances!R5:Instances!R5),"min", MIN(Instances!R5:Instances!R5),"max", MAX(Instances!R5:Instances!R5),"diff", MAX(Instances!R5:Instances!R5)-MIN(Instances!R5:Instances!R5))} -> 0 | S5: =MIN($B5) -> 0 | T5: =MIN($C5) -> 0 | U5: =MIN($D5) -> 0 | V5: =MIN($E5) -> 0 | W5: =MIN($F5) -> 0 | X5: =MIN($G5) -> 0 | Y5: =MIN($H5) -> 0 | Z5: =MIN($I5) -> 0 | AA5: =MIN($J5) -> 0 | AB5: =MIN($K5) -> 0 | AC5: =MIN($M5) -> 0 | AD5: =MIN($N5) -> 0 | AE5: =MIN($P5) -> 0 | AF5: =MIN($Q5) -> 0 | AG5: =MIN($R5) -> 0 | AH5: =MEDIAN($B5) -> 0 | AI5: =MEDIAN($C5) -> 0 | AJ5: =MEDIAN($D5) -> 0 | AK5: =MEDIAN($E5) -> 0 | AL5: =MEDIAN($F5) -> 0 | AM5: =MEDIAN($G5) -> 0 | AN5: =MEDIAN($H5) -> 0 | AO5: =MEDIAN($I5) -> 0 | AP5: =MEDIAN($J5) -> 0 | AQ5: =MEDIAN($K5) -> 0 | AR5: =MEDIAN($M5) -> 0 | AS5: =MEDIAN($N5) -> 0 | AT5: =MEDIAN($P5) -> 0 | AU5: =MEDIAN($Q5) -> 0 | AV5: =MEDIAN($R5) -> 0 | AW5: =MAX($B5) -> 0 | AX5: =MAX($C5) -> 0 | AY5: =MAX($D5) -> 0 | AZ5: =MAX($E5) -> 0 | BA5: =MAX($F5) -> 0 | BB5: =MAX($G5) -> 0 | BC5: =MAX($H5) -> 0 | BD5: =MAX($I5) -> 0 | BE5: =MAX($J5) -> 0 | BF5: =MAX($K5) -> 0 | BG5: =MAX($M5) -> 0 | BH5: =MAX($N5) -> 0 | BI5: =MAX($P5) -> 0 | BJ5: =MAX($Q5) -> 0 | BK5: =MAX($R5) -> 0
A6: /Level_3 | B6: {=_xlfn.SWITCH($A$2,"average", AVERAGE(Instances!B6:Instances!B6),"median", MEDIAN(Instances!B6:Instances!B6),"min", MIN(Instances!B6:Instances!B6),"max", MAX(Instances!B6:Instances!B6),"diff", MAX(Instances!B6:Instances!B6)-MIN(Instances!B6:Instances!B6))} -> 0 | C6: {=_xlfn.SWITCH($A$2,"average", AVERAGE(Instances!C6:Instances!C6),"median", MEDIAN(Instances!C6:Instances!C6),"min", MIN(Instances!C6:Instances!C6),"max", MAX(Instances!C6:Instances!C6),"diff", MAX(Instances!C6:Instances!C6)-MIN(Instances!C6:Instances!C6))} -> 0 | D6: {=_xlfn.SWITCH($A$2,"average", AVERAGE(Instances!D6:Instances!D6),"median", MEDIAN(Instances!D6:Instances!D6),"min", MIN(Instances!D6:Instances!D6),"max", MAX(Instances!D6:Instances!D6),"diff", MAX(Instances!D6:Instances!D6)-MIN(Instances!D6:Instances!D6))} -> 0 | E6: {=_xlfn.SWITCH($A$2,"average", AVERAGE(Instances!E6:Instances!E6),"median", MEDIAN(Instances!E6:Instances!E6),"min", MIN(Instances!E6:Instances!E6),"max", MAX(Instances!E6:Instances!E6),"diff", MAX(Instances!E6:Instances!E6)-MIN(Instances!E6:Instances!E6))} -> 0 | F6: {=_xlfn.SWITCH($A$2,"average", AVERAGE(Instances!F6:Instances!F6),"median", MEDIAN(Instances!F6:Instances!F6),"min", MIN(Instances!F6:Instances!F6),"max", MAX(Instances!F6:Instances!F6),"diff", MAX(Instances!F6:Instances!F6)-MIN(Instances!F6:Instances!F6))} -> 0 | G6: {=_xlfn.SWITCH($A$2,"average", AVERAGE(Instances!G6:Instances!G6),"median", MEDIAN(Instances!G6:Instances!G6),"min", MIN(Instances!G6:Instances!G6),"max", MAX(Instances!G6:Instances!G6),"diff", MAX(Instances!G6:Instances!G6)-MIN(Instances!G6:Instances!G6))} -> 0 | H6: {=_xlfn.SWITCH($A$2,"average", AVERAGE(Instances!H6:Instances!H6),"median", MEDIAN(Instances!H6:Instances!H6),"min", MIN(Instances!H6:Instances!H6),"max", MAX(Instances!H6:Instances!H6),"diff", MAX(Instances!H6:Instances!H6)-MIN(Instances!H6:Instances!H6))} -> 0 | I6: {=_xlfn.SWITCH($A$2,"average", AVERAGE(Instances!I6:Instances!I6),"median", MEDIAN(Instances!I6:Instances!I6),"min", MIN(Instances!I6:Instances!I6),"max", MAX(Instances!I6:Instances!I6),"diff", MAX(Instances!I6:Instances!I6)-MIN(Instances!I6:Instances!I6))} -> 0 | ... K6: {=_xlfn.SWITCH($A$2,"average", AVERAGE(Instances!K6:Instances!K6),"median", MEDIAN(Instances!K6:Instances!K6),"min", MIN(Instances!K6:Instances!K6),"max", MAX(Instances!K6:Instances!K6),"diff", MAX(Instances!K6:Instances!K6)-MIN(Instances!K6:Instances!K6))} -> 0 | M6: {=_xlfn.SWITCH($A$2,"average", AVERAGE(Instances!M6:Instances!M6),"median", MEDIAN(Instances!M6:Instances!M6),"min", MIN(Instances!M6:Instances!M6),"max", MAX(Instances!M6:Instances!M6),"diff", MAX(Instances!M6:Instances!M6)-MIN(Instances!M6:Instances!M6))} -> 0 | N6: {=_xlfn.SWITCH($A$2,"average", AVERAGE(Instances!N6:Instances!N6),"median", MEDIAN(Instances!N6:Instances!N6),"min", MIN(Instances!N6:Instances!N6),"max", MAX(Instances!N6:Instances!N6),"diff", MAX(Instances!N6:Instances!N6)-MIN(Instances!N6:Instances!N6))} -> 0 | P6: {=_xlfn.SWITCH($A$2,"average", AVERAGE(Instances!P6:Instances!P6),"median", MEDIAN(Instances!P6:Instances!P6),"min", MIN(Instances!P6:Instances!P6),"max", MAX(Instances!P6:Instances!P6),"diff", MAX(Instances!P6:Instances!P6)-MIN(Instances!P6:Instances!P6))} -> 0 | Q6: {=_xlfn.SWITCH($A$2,"average", AVERAGE(Instances!Q6:Instances!Q6),"median", MEDIAN(Instances!Q6:Instances!Q6),"min", MIN(Instances!Q6:Instances!Q6),"max", MAX(Instances!Q6:Instances!Q6),"diff", MAX(Instances!Q6:Instances!Q6)-MIN(Instances!Q6:Instances!Q6))} -> 0 | R6: {=_xlfn.SWITCH($A$2,"average", AVERAGE(Instances!R6:Instances!R6),"median", MEDIAN(Instances!R6:Instances!R6),"min", MIN(Instances!R6:Instances!R6),"max", MAX(Instances!R6:Instances!R6),"diff", MAX(Instances!R6:Instances!R6)-MIN(Instances!R6:Instances!R6))} -> 0 | S6: =MIN($B6) -> 0 | T6: =MIN($C6) -> 0 | U6: =MIN($D6) -> 0 | V6: =MIN($E6) -> 0 | W6: =MIN($F6) -> 0 | X6: =MIN($G6) -> 0 | Y6: =MIN($H6) -> 0 | Z6: =MIN($I6) -> 0 | AA6: =MIN($J6) -> 0 | AB6: =MIN($K6) -> 0 | AC6: =MIN($M6) -> 0 | AD6: =MIN($N6) -> 0 | AE6: =MIN($P6) -> 0 | AF6: =MIN($Q6) -> 0 | AG6: =MIN($R6) -> 0 | AH6: =MEDIAN($B6) -> 0 | AI6: =MEDIAN($C6) -> 0 | AJ6: =MEDIAN($D6) -> 0 | AK6: =MEDIAN($E6) -> 0 | AL6: =MEDIAN($F6) -> 0 | AM6: =MEDIAN($G6) -> 0 | AN6: =MEDIAN($H6) -> 0 | AO6: =MEDIAN($I6) -> 0 | AP6: =MEDIAN($J6) -> 0 | AQ6: =MEDIAN($K6) -> 0 | AR6: =MEDIAN($M6) -> 0 | AS6: =MEDIAN($N6) -> 0 | AT6: =MEDIAN($P6) -> 0 | AU6: =MEDIAN($Q6) -> 0 | AV6: =MEDIAN($R6) -> 0 | AW6: =MAX($B6) -> 0 | AX6: =MAX($C6) -> 0 | AY6: =MAX($D6) -> 0 | AZ6: =MAX($E6) -> 0 | BA6: =MAX($F6) -> 0 | BB6: =MAX($G6) -> 0 | BC6: =MAX($H6) -> 0 | BD6: =MAX($I6) -> 0 | BE6: =MAX($J6) -> 0 | BF6: =MAX($K6) -> 0 | BG6: =MAX($M6) -> 0 | BH6: =MAX($N6) -> 0 | BI6: =MAX($P6) -> 0 | BJ6: =MAX($Q6) -> 0 | BK6: =MAX($R6) -> 0
A7: /Level_4 | B7: {=_xlfn.SWITCH($A$2,"average", AVERAGE(Instances!B7:Instances!B7),"median", MEDIAN(Instances!B7:Instances!B7),"min", MIN(Instances!B7:Instances!B7),"max", MAX(Instances!B7:Instances!B7),"diff", MAX(Instances!B7:Instances!B7)-MIN(Instances!B7:Instances!B7))} -> 0 | C7: {=_xlfn.SWITCH($A$2,"average", AVERAGE(Instances!C7:Instances!C7),"median", MEDIAN(Instances!C7:Instances!C7),"min", MIN(Instances!C7:Instances!C7),"max", MAX(Instances!C7:Instances!C7),"diff", MAX(Instances!C7:Instances!C7)-MIN(Instances!C7:Instances!C7))} -> 0 | D7: {=_xlfn.SWITCH($A$2,"average", AVERAGE(Instances!D7:Instances!D7),"median", MEDIAN(Instances!D7:Instances!D7),"min", MIN(Instances!D7:Instances!D7),"max", MAX(Instances!D7:Instances!D7),"diff", MAX(Instances!D7:Instances!D7)-MIN(Instances!D7:Instances!D7))} -> 0 | E7: {=_xlfn.SWITCH($A$2,"average", AVERAGE(Instances!E7:Instances!E7),"median", MEDIAN(Instances!E7:Instances!E7),"min", MIN(Instances!E7:Instances!E7),"max", MAX(Instances!E7:Instances!E7),"diff", MAX(Instances!E7:Instances!E7)-MIN(Instances!E7:Instances!E7))} -> 0 | F7: {=_xlfn.SWITCH($A$2,"average", AVERAGE(Instances!F7:Instances!F7),"median", MEDIAN(Instances!F7:Instances!F7),"min", MIN(Instances!F7:Instances!F7),"max", MAX(Instances!F7:Instances!F7),"diff", MAX(Instances!F7:Instances!F7)-MIN(Instances!F7:Instances!F7))} -> 0 | G7: {=_xlfn.SWITCH($A$2,"average", AVERAGE(Instances!G7:Instances!G7),"median", MEDIAN(Instances!G7:Instances!G7),"min", MIN(Instances!G7:Instances!G7),"max", MAX(Instances!G7:Instances!G7),"diff", MAX(Instances!G7:Instances!G7)-MIN(Instances!G7:Instances!G7))} -> 0 | H7: {=_xlfn.SWITCH($A$2,"average", AVERAGE(Instances!H7:Instances!H7),"median", MEDIAN(Instances!H7:Instances!H7),"min", MIN(Instances!H7:Instances!H7),"max", MAX(Instances!H7:Instances!H7),"diff", MAX(Instances!H7:Instances!H7)-MIN(Instances!H7:Instances!H7))} -> 0 | I7: {=_xlfn.SWITCH($A$2,"average", AVERAGE(Instances!I7:Instances!I7),"median", MEDIAN(Instances!I7:Instances!I7),"min", MIN(Instances!I7:Instances!I7),"max", MAX(Instances!I7:Instances!I7),"diff", MAX(Instances!I7:Instances!I7)-MIN(Instances!I7:Instances!I7))} -> 0 | ... K7: {=_xlfn.SWITCH($A$2,"average", AVERAGE(Instances!K7:Instances!K7),"median", MEDIAN(Instances!K7:Instances!K7),"min", MIN(Instances!K7:Instances!K7),"max", MAX(Instances!K7:Instances!K7),"diff", MAX(Instances!K7:Instances!K7)-MIN(Instances!K7:Instances!K7))} -> 0 | M7: {=_xlfn.SWITCH($A$2,"average", AVERAGE(Instances!M7:Instances!M7),"median", MEDIAN(Instances!M7:Instances!M7),"min", MIN(Instances!M7:Instances!M7),"max", MAX(Instances!M7:Instances!M7),"diff", MAX(Instances!M7:Instances!M7)-MIN(Instances!M7:Instances!M7))} -> 0 | N7: {=_xlfn.SWITCH($A$2,"average", AVERAGE(Instances!N7:Instances!N7),"median", MEDIAN(Instances!N7:Instances!N7),"min", MIN(Instances!N7:Instances!N7),"max", MAX(Instances!N7:Instances!N7),"diff", MAX(Instances!N7:Instances!N7)-MIN(Instances!N7:Instances!N7))} -> 0 | P7: {=_xlfn.SWITCH($A$2,"average", AVERAGE(Instances!P7:Instances!P7),"median", MEDIAN(Instances!P7:Instances!P7),"min", MIN(Instances!P7:Instances!P7),"max", MAX(Instances!P7:Instances!P7),"diff", MAX(Instances!P7:Instances!P7)-MIN(Instances!P7:Instances!P7))} -> 0 | Q7: {=_xlfn.SWITCH($A$2,"average", AVERAGE(Instances!Q7:Instances!Q7),"median", MEDIAN(Instances!Q7:Instances!Q7),"min", MIN(Instances!Q7:Instances!Q7),"max", MAX(Instances!Q7:Instances!Q7),"diff", MAX(Instances!Q7:Instances!Q7)-MIN(Instances!Q7:Instances!Q7))} -> 0 | R7: {=_xlfn.SWITCH($A$2,"average", AVERAGE(Instances!R7:Instances!R7),"median", MEDIAN(Instances!R7:Instances!R7),"min", MIN(Instances!R7:Instances!R7),"max", MAX(Instances!R7:Instances!R7),"diff", MAX(Instances!R7:Instances!R7)-MIN(Instances!R7:Instances!R7))} -> 0 | S7: =MIN($B7) -> 0 | T7: =MIN($C7) -> 0 | U7: =MIN($D7) -> 0 | V7: =MIN($E7) -> 0 | W7: =MIN($F7) -> 0 | X7: =MIN($G7) -> 0 | Y7: =MIN($H7) -> 0 | Z7: =MIN($I7) -> 0 | AA7: =MIN($J7) -> 0 | AB7: =MIN($K7) -> 0 | AC7: =MIN($M7) -> 0 | AD7: =MIN($N7) -> 0 | AE7: =MIN($P7) -> 0 | AF7: =MIN($Q7) -> 0 | AG7: =MIN($R7) -> 0 | AH7: =MEDIAN($B7) -> 0 | AI7: =MEDIAN($C7) -> 0 | AJ7: =MEDIAN($D7) -> 0 | AK7: =MEDIAN($E7) -> 0 | AL7: =MEDIAN($F7) -> 0 | AM7: =MEDIAN($G7) -> 0 | AN7: =MEDIAN($H7) -> 0 | AO7: =MEDIAN($I7) -> 0 | AP7: =MEDIAN($J7) -> 0 | AQ7: =MEDIAN($K7) -> 0 | AR7: =MEDIAN($M7) -> 0 | AS7: =MEDIAN($N7) -> 0 | AT7: =MEDIAN($P7) -> 0 | AU7: =MEDIAN($Q7) -> 0 | AV7: =MEDIAN($R7) -> 0 | AW7: =MAX($B7) -> 0 | AX7: =MAX($C7) -> 0 | AY7: =MAX($D7) -> 0 | AZ7: =MAX($E7) -> 0 | BA7: =MAX($F7) -> 0 | BB7: =MAX($G7) -> 0 | BC7: =MAX($H7) -> 0 | BD7: =MAX($I7) -> 0 | BE7: =MAX($J7) -> 0 | BF7: =MAX($K7) -> 0 | BG7: =MAX($M7) -> 0 | BH7: =MAX($N7) -> 0 | BI7: =MAX($P7) -> 0 | BJ7: =MAX($Q7) -> 0 | BK7: =MAX($R7) -> 0
A8: /Level_5 | B8: {=_xlfn.SWITCH($A$2,"average", AVERAGE(Instances!B8:Instances!B8),"median", MEDIAN(Instances!B8:Instances!B8),"min", MIN(Instances!B8:Instances!B8),"max", MAX(Instances!B8:Instances!B8),"diff", MAX(Instances!B8:Instances!B8)-MIN(Instances!B8:Instances!B8))} -> 0 | C8: {=_xlfn.SWITCH($A$2,"average", AVERAGE(Instances!C8:Instances!C8),"median", MEDIAN(Instances!C8:Instances!C8),"min", MIN(Instances!C8:Instances!C8),"max", MAX(Instances!C8:Instances!C8),"diff", MAX(Instances!C8:Instances!C8)-MIN(Instances!C8:Instances!C8))} -> 0 | D8: {=_xlfn.SWITCH($A$2,"average", AVERAGE(Instances!D8:Instances!D8),"median", MEDIAN(Instances!D8:Instances!D8),"min", MIN(Instances!D8:Instances!D8),"max", MAX(Instances!D8:Instances!D8),"diff", MAX(Instances!D8:Instances!D8)-MIN(Instances!D8:Instances!D8))} -> 0 | E8: {=_xlfn.SWITCH($A$2,"average", AVERAGE(Instances!E8:Instances!E8),"median", MEDIAN(Instances!E8:Instances!E8),"min", MIN(Instances!E8:Instances!E8),"max", MAX(Instances!E8:Instances!E8),"diff", MAX(Instances!E8:Instances!E8)-MIN(Instances!E8:Instances!E8))} -> 0 | F8: {=_xlfn.SWITCH($A$2,"average", AVERAGE(Instances!F8:Instances!F8),"median", MEDIAN(Instances!F8:Instances!F8),"min", MIN(Instances!F8:Instances!F8),"max", MAX(Instances!F8:Instances!F8),"diff", MAX(Instances!F8:Instances!F8)-MIN(Instances!F8:Instances!F8))} -> 0 | G8: {=_xlfn.SWITCH($A$2,"average", AVERAGE(Instances!G8:Instances!G8),"median", MEDIAN(Instances!G8:Instances!G8),"min", MIN(Instances!G8:Instances!G8),"max", MAX(Instances!G8:Instances!G8),"diff", MAX(Instances!G8:Instances!G8)-MIN(Instances!G8:Instances!G8))} -> 0 | H8: {=_xlfn.SWITCH($A$2,"average", AVERAGE(Instances!H8:Instances!H8),"median", MEDIAN(Instances!H8:Instances!H8),"min", MIN(Instances!H8:Instances!H8),"max", MAX(Instances!H8:Instances!H8),"diff", MAX(Instances!H8:Instances!H8)-MIN(Instances!H8:Instances!H8))} -> 0 | I8: {=_xlfn.SWITCH($A$2,"average", AVERAGE(Instances!I8:Instances!I8),"median", MEDIAN(Instances!I8:Instances!I8),"min", MIN(Instances!I8:Instances!I8),"max", MAX(Instances!I8:Instances!I8),"diff", MAX(Instances!I8:Instances!I8)-MIN(Instances!I8:Instances!I8))} -> 0 | ... K8: {=_xlfn.SWITCH($A$2,"average", AVERAGE(Instances!K8:Instances!K8),"median", MEDIAN(Instances!K8:Instances!K8),"min", MIN(Instances!K8:Instances!K8),"max", MAX(Instances!K8:Instances!K8),"diff", MAX(Instances!K8:Instances!K8)-MIN(Instances!K8:Instances!K8))} -> 0 | M8: {=_xlfn.SWITCH($A$2,"average", AVERAGE(Instances!M8:Instances!M8),"median", MEDIAN(Instances!M8:Instances!M8),"min", MIN(Instances!M8:Instances!M8),"max", MAX(Instances!M8:Instances!M8),"diff", MAX(Instances!M8:Instances!M8)-MIN(Instances!M8:Instances!M8))} -> 0 | N8: {=_xlfn.SWITCH($A$2,"average", AVERAGE(Instances!N8:Instances!N8),"median", MEDIAN(Instances!N8:Instances!N8),"min", MIN(Instances!N8:Instances!N8),"max", MAX(Instances!N8:Instances!N8),"diff", MAX(Instances!N8:Instances!N8)-MIN(Instances!N8:Instances!N8))} -> 0 | P8: {=_xlfn.SWITCH($A$2,"average", AVERAGE(Instances!P8:Instances!P8),"median", MEDIAN(Instances!P8:Instances!P8),"min", MIN(Instances!P8:Instances!P8),"max", MAX(Instances!P8:Instances!P8),"diff", MAX(Instances!P8:Instances!P8)-MIN(Instances!P8:Instances!P8))} -> 0 | Q8: {=_xlfn.SWITCH($A$2,"average", AVERAGE(Instances!Q8:Instances!Q8),"median", MEDIAN(Instances!Q8:Instances!Q8),"min", MIN(Instances!Q8:Instances!Q8),"max", MAX(Instances!Q8:Instances!Q8),"diff", MAX(Instances!Q8:Instances!Q8)-MIN(Instances!Q8:Instances!Q8))} -> 0 | R8: {=_xlfn.SWITCH($A$2,"average", AVERAGE(Instances!R8:Instances!R8),"median", MEDIAN(Instances!R8:Instances!R8),"min", MIN(Instances!R8:Instances!R8),"max", MAX(Instances!R8:Instances!R8),"diff", MAX(Instances!R8:Instances!R8)-MIN(Instances!R8:Instances!R8))} -> 0 | S8: =MIN($B8) -> 0 | T8: =MIN($C8) -> 0 | U8: =MIN($D8) -> 0 | V8: =MIN($E8) -> 0 | W8: =MIN($F8) -> 0 | X8: =MIN($G8) -> 0 | Y8: =MIN($H8) -> 0 | Z8: =MIN($I8) -> 0 | AA8: =MIN($J8) -> 0 | AB8: =MIN($K8) -> 0 | AC8: =MIN($M8) -> 0 | AD8: =MIN($N8) -> 0 | AE8: =MIN($P8) -> 0 | AF8: =MIN($Q8) -> 0 | AG8: =MIN($R8) -> 0 | AH8: =MEDIAN($B8) -> 0 | AI8: =MEDIAN($C8) -> 0 | AJ8: =MEDIAN($D8) -> 0 | AK8: =MEDIAN($E8) -> 0 | AL8: =MEDIAN($F8) -> 0 | AM8: =MEDIAN($G8) -> 0 | AN8: =MEDIAN($H8) -> 0 | AO8: =MEDIAN($I8) -> 0 | AP8: =MEDIAN($J8) -> 0 | AQ8: =MEDIAN($K8) -> 0 | AR8: =MEDIAN($M8) -> 0 | AS8: =MEDIAN($N8) -> 0 | AT8: =MEDIAN($P8) -> 0 | AU8: =MEDIAN($Q8) -> 0 | AV8: =MEDIAN($R8) -> 0 | AW8: =MAX($B8) -> 0 | AX8: =MAX($C8) -> 0 | AY8: =MAX($D8) -> 0 | AZ8: =MAX($E8) -> 0 | BA8: =MAX($F8) -> 0 | BB8: =MAX($G8) -> 0 | BC8: =MAX($H8) -> 0 | BD8: =MAX($I8) -> 0 | BE8: =MAX($J8) -> 0 | BF8: =MAX($K8) -> 0 | BG8: =MAX($M8) -> 0 | BH8: =MAX($N8) -> 0 | BI8: =MAX($P8) -> 0 | BJ8: =MAX($Q8) -> 0 | BK8: =MAX($R8) -> 0
A9: /Level_6 | B9: {=_xlfn.SWITCH($A$2,"average", AVERAGE(Instances!B9:Instances!B9),"median", MEDIAN(Instances!B9:Instances!B9),"min", MIN(Instances!B9:Instances!B9),"max", MAX(Instances!B9:Instances!B9),"diff", MAX(Instances!B9:Instances!B9)-MIN(Instances!B9:Instances!B9))} -> 0 | C9: {=_xlfn.SWITCH($A$2,"average", AVERAGE(Instances!C9:Instances!C9),"median", MEDIAN(Instances!C9:Instances!C9),"min", MIN(Instances!C9:Instances!C9),"max", MAX(Instances!C9:Instances!C9),"diff", MAX(Instances!C9:Instances!C9)-MIN(Instances!C9:Instances!C9))} -> 0 | D9: {=_xlfn.SWITCH($A$2,"average", AVERAGE(Instances!D9:Instances!D9),"median", MEDIAN(Instances!D9:Instances!D9),"min", MIN(Instances!D9:Instances!D9),"max", MAX(Instances!D9:Instances!D9),"diff", MAX(Instances!D9:Instances!D9)-MIN(Instances!D9:Instances!D9))} -> 0 | E9: {=_xlfn.SWITCH($A$2,"average", AVERAGE(Instances!E9:Instances!E9),"median", MEDIAN(Instances!E9:Instances!E9),"min", MIN(Instances!E9:Instances!E9),"max", MAX(Instances!E9:Instances!E9),"diff", MAX(Instances!E9:Instances!E9)-MIN(Instances!E9:Instances!E9))} -> 0 | F9: {=_xlfn.SWITCH($A$2,"average", AVERAGE(Instances!F9:Instances!F9),"median", MEDIAN(Instances!F9:Instances!F9),"min", MIN(Instances!F9:Instances!F9),"max", MAX(Instances!F9:Instances!F9),"diff", MAX(Instances!F9:Instances!F9)-MIN(Instances!F9:Instances!F9))} -> 0 | G9: {=_xlfn.SWITCH($A$2,"average", AVERAGE(Instances!G9:Instances!G9),"median", MEDIAN(Instances!G9:Instances!G9),"min", MIN(Instances!G9:Instances!G9),"max", MAX(Instances!G9:Instances!G9),"diff", MAX(Instances!G9:Instances!G9)-MIN(Instances!G9:Instances!G9))} -> 0 | H9: {=_xlfn.SWITCH($A$2,"average", AVERAGE(Instances!H9:Instances!H9),"median", MEDIAN(Instances!H9:Instances!H9),"min", MIN(Instances!H9:Instances!H9),"max", MAX(Instances!H9:Instances!H9),"diff", MAX(Instances!H9:Instances!H9)-MIN(Instances!H9:Instances!H9))} -> 0 | I9: {=_xlfn.SWITCH($A$2,"average", AVERAGE(Instances!I9:Instances!I9),"median", MEDIAN(Instances!I9:Instances!I9),"min", MIN(Instances!I9:Instances!I9),"max", MAX(Instances!I9:Instances!I9),"diff", MAX(Instances!I9:Instances!I9)-MIN(Instances!I9:Instances!I9))} -> 0 | ... K9: {=_xlfn.SWITCH($A$2,"average", AVERAGE(Instances!K9:Instances!K9),"median", MEDIAN(Instances!K9:Instances!K9),"min", MIN(Instances!K9:Instances!K9),"max", MAX(Instances!K9:Instances!K9),"diff", MAX(Instances!K9:Instances!K9)-MIN(Instances!K9:Instances!K9))} -> 0 | M9: {=_xlfn.SWITCH($A$2,"average", AVERAGE(Instances!M9:Instances!M9),"median", MEDIAN(Instances!M9:Instances!M9),"min", MIN(Instances!M9:Instances!M9),"max", MAX(Instances!M9:Instances!M9),"diff", MAX(Instances!M9:Instances!M9)-MIN(Instances!M9:Instances!M9))} -> 0 | N9: {=_xlfn.SWITCH($A$2,"average", AVERAGE(Instances!N9:Instances!N9),"median", MEDIAN(Instances!N9:Instances!N9),"min", MIN(Instances!N9:Instances!N9),"max", MAX(Instances!N9:Instances!N9),"diff", MAX(Instances!N9:Instances!N9)-MIN(Instances!N9:Instances!N9))} -> 0 | P9: {=_xlfn.SWITCH($A$2,"average", AVERAGE(Instances!P9:Instances!P9),"median", MEDIAN(Instances!P9:Instances!P9),"min", MIN(Instances!P9:Instances!P9),"max", MAX(Instances!P9:Instances!P9),"diff", MAX(Instances!P9:Instances!P9)-MIN(Instances!P9:Instances!P9))} -> 0 | Q9: {=_xlfn.SWITCH($A$2,"average", AVERAGE(Instances!Q9:Instances!Q9),"median", MEDIAN(Instances!Q9:Instances!Q9),"min", MIN(Instances!Q9:Instances!Q9),"max", MAX(Instances!Q9:Instances!Q9),"diff", MAX(Instances!Q9:Instances!Q9)-MIN(Instances!Q9:Instances!Q9))} -> 0 | R9: {=_xlfn.SWITCH($A$2,"average", AVERAGE(Instances!R9:Instances!R9),"median", MEDIAN(Instances!R9:Instances!R9),"min", MIN(Instances!R9:Instances!R9),"max", MAX(Instances!R9:Instances!R9),"diff", MAX(Instances!R9:Instances!R9)-MIN(Instances!R9:Instances!R9))} -> 0 | S9: =MIN($B9) -> 0 | T9: =MIN($C9) -> 0 | U9: =MIN($D9) -> 0 | V9: =MIN($E9) -> 0 | W9: =MIN($F9) -> 0 | X9: =MIN($G9) -> 0 | Y9: =MIN($H9) -> 0 | Z9: =MIN($I9) -> 0 | AA9: =MIN($J9) -> 0 | AB9: =MIN($K9) -> 0 | AC9: =MIN($M9) -> 0 | AD9: =MIN($N9) -> 0 | AE9: =MIN($P9) -> 0 | AF9: =MIN($Q9) -> 0 | AG9: =MIN($R9) -> 0 | AH9: =MEDIAN($B9) -> 0 | AI9: =MEDIAN($C9) -> 0 | AJ9: =MEDIAN($D9) -> 0 | AK9: =MEDIAN($E9) -> 0 | AL9: =MEDIAN($F9) -> 0 | AM9: =MEDIAN($G9) -> 0 | AN9: =MEDIAN($H9) -> 0 | AO9: =MEDIAN($I9) -> 0 | AP9: =MEDIAN($J9) -> 0 | AQ9: =MEDIAN($K9) -> 0 | AR9: =MEDIAN($M9) -> 0 | AS9: =MEDIAN($N9) -> 0 | AT9: =MEDIAN($P9) -> 0 | AU9: =MEDIAN($Q9) -> 0 | AV9: =MEDIAN($R9) -> 0 | AW9: =MAX($B9) -> 0 | AX9: =MAX($C9) -> 0 | AY9: =MAX($D9) -> 0 | AZ9: =MAX($E9) -> 0 | BA9: =MAX($F9) -> 0 | BB9: =MAX($G9) -> 0 | BC9: =MAX($H9) -> 0 | BD9: =MAX($I9) -> 0 | BE9: =MAX($J9) -> 0 | BF9: =MAX($K9) -> 0 | BG9: =MAX($M9) -> 0 | BH9: =MAX($N9) -> 0 | BI9: =MAX($P9) -> 0 | BJ9: =MAX($Q9) -> 0 | BK9: =MAX($R9) -> 0
