Workbook

Sheet Instances
B1: clingo-5.8.0/default | S1: min | AH1: median | AW1: max
B2: choices | C2: conflicts | D2: constraints | E2: error | F2: mem | G2: memout | H2: models | I2: overall-time | J2: par2 | K2: restarts | L2: rstatus | M2: rules | N2: solving-time | O2: status | P2: time | Q2: timeout | R2: variables | S2: choices | T2: conflicts | U2: constraints | V2: error | W2: mem | X2: memout | Y2: models | Z2: overall-time | AA2: par2 | AB2: restarts | AC2: rules | AD2: solving-time | AE2: time | AF2: timeout | AG2: variables | AH2: choices | AI2: conflicts | AJ2: constraints | AK2: error | AL2: mem | AM2: memout | AN2: models | AO2: overall-time | AP2: par2 | AQ2: restarts | AR2: rules | AS2: solving-time | AT2: time | AU2: timeout | AV2: variables | AW2: choices | AX2: conflicts | AY2: constraints | AZ2: error | BA2: mem | BB2: memout | BC2: models | BD2: overall-time | BE2: par2 | BF2: restarts | BG2: rules | BH2: solving-time | BI2: time | BJ2: timeout | BK2: variables
A3: /Level_0 | B3: 570267 | C3: 35341 | D3: 32870440 | E3: 0 | F3: 5594 | G3: 0 | H3: 1 | I3: 257.593 | J3: 259.43 | K3: 122 | L3: ok | M3: 30901515 | N3: 76.71 | O3: SATISFIABLE | P3: 259.43 | Q3: 0 | R3: 1233449 | S3: =MIN($B3) -> 0 | T3: =MIN($C3) -> 0 | U3: =MIN($D3) -> 0 | V3: =MIN($E3) -> 0 | W3: =MIN($F3) -> 0 | X3: =MIN($G3) -> 0 | Y3: =MIN($H3) -> 0 | Z3: =MIN($I3) -> 0 | AA3: =MIN($J3) -> 0 | AB3: =MIN($K3) -> 0 | AC3: =MIN($M3) -> 0 | AD3: =MIN($N3) -> 0 | AE3: =MIN($P3) -> 0 | AF3: =MIN($Q3) -> 0 | AG3: =MIN($R3) -> 0 | AH3: =MEDIAN($B3) -> 0 | AI3: =MEDIAN($C3) -> 0 | AJ3: =MEDIAN($D3) -> 0 | AK3: =MEDIAN($E3) -> 0 | AL3: =MEDIAN($F3) -> 0 | AM3: =MEDIAN($G3) -> 0 | AN3: =MEDIAN($H3) -> 0 | AO3: =MEDIAN($I3) -> 0 | AP3: =MEDIAN($J3) -> 0 | AQ3: =MEDIAN($K3) -> 0 | AR3: =MEDIAN($M3) -> 0 | AS3: =MEDIAN($N3) -> 0 | AT3: =MEDIAN($P3) -> 0 | AU3: =MEDIAN($Q3) -> 0 | AV3: =MEDIAN($R3) -> 0 | AW3: =MAX($B3) -> 0 | AX3: =MAX($C3) -> 0 | AY3: =MAX($D3) -> 0 | AZ3: =MAX($E3) -> 0 | BA3: =MAX($F3) -> 0 | BB3: =MAX($G3) -> 0 | BC3: =MAX($H3) -> 0 | BD3: =MAX($I3) -> 0 | BE3: =MAX($J3) -> 0 | BF3: =MAX($K3) -> 0 | BG3: =MAX($M3) -> 0 | BH3: =MAX($N3) -> 0 | BI3: =MAX($P3) -> 0 | BJ3: =MAX($Q3) -> 0 | BK3: =MAX($R3) -> 0
A4: /Level_1 | B4: 155097 | C4: 10950 | D4: 33163011 | E4: 0 | F4: 5647 | G4: 0 | H4: 1 | I4: 199.271 | J4: 200.74 | K4: 45 | L4: ok | M4: 31240755 | N4: 22.57 | O4: SATISFIABLE | P4: 200.74 | Q4: 0 | R4: 1158173 | S4: =MIN($B4) -> 0 | T4: =MIN($C4) -> 0 | U4: =MIN($D4) -> 0 | V4: =MIN($E4) -> 0 | W4: =MIN($F4) -> 0 | X4: =MIN($G4) -> 0 | Y4: =MIN($H4) -> 0 | Z4: =MIN($I4) -> 0 | AA4: =MIN($J4) -> 0 | AB4: =MIN($K4) -> 0 | AC4: =MIN($M4) -> 0 | AD4: =MIN($N4) -> 0 | AE4: =MIN($P4) -> 0 | AF4: =MIN($Q4) -> 0 | AG4: =MIN($R4) -> 0 | AH4: =MEDIAN($B4) -> 0 | AI4: =MEDIAN($C4) -> 0 | AJ4: =MEDIAN($D4) -> 0 | AK4: =MEDIAN($E4) -> 0 | AL4: =MEDIAN($F4) -> 0 | AM4: =MEDIAN($G4) -> 0 | AN4: =MEDIAN($H4) -> 0 | AO4: =MEDIAN($I4) -> 0 | AP4: =MEDIAN($J4) -> 0 | AQ4: =MEDIAN($K4) -> 0 | AR4: =MEDIAN($M4) -> 0 | AS4: =MEDIAN($N4) -> 0 | AT4: =MEDIAN($P4) -> 0 | AU4: =MEDIAN($Q4) -> 0 | AV4: =MEDIAN($R4) -> 0 | AW4: =MAX($B4) -> 0 | AX4: =MAX($C4) -> 0 | AY4: =MAX($D4) -> 0 | AZ4: =MAX($E4) -> 0 | BA4: =MAX($F4) -> 0 | BB4: =MAX($G4) -> 0 | BC4: =MAX($H4) -> 0 | BD4: =MAX($I4) -> 0 | BE4: =MAX($J4) -> 0 | BF4: =MAX($K4) -> 0 | BG4: =MAX($M4) -> 0 | BH4: =MAX($N4) -> 0 | BI4: =MAX($P4) -> 0 | BJ4: =MAX($Q4) -> 0 | BK4: =MAX($R4) -> 0
A5: /Level_2 | E5: 1 | F5: 8575 | G5: 0 | J5: 3600 | L5: signal(9) | P5: 1800 | Q5: 1 | V5: =MIN($E5) -> 0 | W5: =MIN($F5) -> 0 | X5: =MIN($G5) -> 0 | AA5: =MIN($J5) -> 0 | AE5: =MIN($P5) -> 0 | AF5: =MIN($Q5) -> 0 | AK5: =MEDIAN($E5) -> 0 | AL5: =MEDIAN($F5) -> 0 | AM5: =MEDIAN($G5) -> 0 | AP5: =MEDIAN($J5) -> 0 | AT5: =MEDIAN($P5) -> 0 | AU5: =MEDIAN($Q5) -> 0 | AZ5: =MAX($E5) -> 0 | BA5: =MAX($F5) -> 0 | BB5: =MAX($G5) -> 0 | BE5: =MAX($J5) -> 0 | BI5: =MAX($P5) -> 0 | BJ5: =MAX($Q5) -> 0
A6: /Level_3 | E6: 1 | F6: 9833 | G6: 0 | J6: 3600 | L6: signal(9) | P6: 1800 | Q6: 1 | V6: =MIN($E6) -> 0 | W6: =MIN($F6) -> 0 | X6: =MIN($G6) -> 0 | AA6: =MIN($J6) -> 0 | AE6: =MIN($P6) -> 0 | AF6: =MIN($Q6) -> 0 | AK6: =MEDIAN($E6) -> 0 | AL6: =MEDIAN($F6) -> 0 | AM6: =MEDIAN($G6) -> 0 | AP6: =MEDIAN($J6) -> 0 | AT6: =MEDIAN($P6) -> 0 | AU6: =MEDIAN($Q6) -> 0 | AZ6: =MAX($E6) -> 0 | BA6: =MAX($F6) -> 0 | BB6: =MAX($G6) -> 0 | BE6: =MAX($J6) -> 0 | BI6: =MAX($P6) -> 0 | BJ6: =MAX($Q6) -> 0
A7: /Level_4 | B7: 2101514 | C7: 283007 | D7: 30308585 | E7: 0 | F7: 5080 | G7: 0 | H7: 1 | I7: 551.252 | J7: 553.8 | K7: 637 | L7: ok | M7: 27903586 | N7: 386.74 | O7: SATISFIABLE | P7: 553.8 | Q7: 0 | R7: 1119738 | S7: =MIN($B7) -> 0 | T7: =MIN($C7) -> 0 | U7: =MIN($D7) -> 0 | V7: =MIN($E7) -> 0 | W7: =MIN($F7) -> 0 | X7: =MIN($G7) -> 0 | Y7: =MIN($H7) -> 0 | Z7: =MIN($I7) -> 0 | AA7: =MIN($J7) -> 0 | AB7: =MIN($K7) -> 0 | AC7: =MIN($M7) -> 0 | AD7: =MIN($N7) -> 0 | AE7: =MIN($P7) -> 0 | AF7: =MIN($Q7) -> 0 | AG7: =MIN($R7) -> 0 | AH7: =MEDIAN($B7) -> 0 | AI7: =MEDIAN($C7) -> 0 | AJ7: =MEDIAN($D7) -> 0 | AK7: =MEDIAN($E7) -> 0 | AL7: =MEDIAN($F7) -> 0 | AM7: =MEDIAN($G7) -> 0 | AN7: =MEDIAN($H7) -> 0 | AO7: =MEDIAN($I7) -> 0 | AP7: =MEDIAN($J7) -> 0 | AQ7: =MEDIAN($K7) -> 0 | AR7: =MEDIAN($M7) -> 0 | AS7: =MEDIAN($N7) -> 0 | AT7: =MEDIAN($P7) -> 0 | AU7: =MEDIAN($Q7) -> 0 | AV7: =MEDIAN($R7) -> 0 | AW7: =MAX($B7) -> 0 | AX7: =MAX($C7) -> 0 | AY7: =MAX($D7) -> 0 | AZ7: =MAX($E7) -> 0 | BA7: =MAX($F7) -> 0 | BB7: =MAX($G7) -> 0 | BC7: =MAX($H7) -> 0 | BD7: =MAX($I7) -> 0 | BE7: =MAX($J7) -> 0 | BF7: =MAX($K7) -> 0 | BG7: =MAX($M7) -> 0 | BH7: =MAX($N7) -> 0 | BI7: =MAX($P7) -> 0 | BJ7: =MAX($Q7) -> 0 | BK7: =MAX($R7) -> 0
A8: /Level_5 | B8: 567246 | C8: 48096 | D8: 40876397 | E8: 0 | F8: 6983 | G8: 0 | H8: 1 | I8: 337.089 | J8: 339.69 | K8: 141 | L8: ok | M8: 39189548 | N8: 100.31 | O8: SATISFIABLE | P8: 339.69 | Q8: 0 | R8: 1506064 | S8: =MIN($B8) -> 0 | T8: =MIN($C8) -> 0 | U8: =MIN($D8) -> 0 | V8: =MIN($E8) -> 0 | W8: =MIN($F8) -> 0 | X8: =MIN($G8) -> 0 | Y8: =MIN($H8) -> 0 | Z8: =MIN($I8) -> 0 | AA8: =MIN($J8) -> 0 | AB8: =MIN($K8) -> 0 | AC8: =MIN($M8) -> 0 | AD8: =MIN($N8) -> 0 | AE8: =MIN($P8) -> 0 | AF8: =MIN($Q8) -> 0 | AG8: =MIN($R8) -> 0 | AH8: =MEDIAN($B8) -> 0 | AI8: =MEDIAN($C8) -> 0 | AJ8: =MEDIAN($D8) -> 0 | AK8: =MEDIAN($E8) -> 0 | AL8: =MEDIAN($F8) -> 0 | AM8: =MEDIAN($G8) -> 0 | AN8: =MEDIAN($H8) -> 0 | AO8: =MEDIAN($I8) -> 0 | AP8: =MEDIAN($J8) -> 0 | AQ8: =MEDIAN($K8) -> 0 | AR8: =MEDIAN($M8) -> 0 | AS8: =MEDIAN($N8) -> 0 | AT8: =MEDIAN($P8) -> 0 | AU8: =MEDIAN($Q8) -> 0 | AV8: =MEDIAN($R8) -> 0 | AW8: =MAX($B8) -> 0 | AX8: =MAX($C8) -> 0 | AY8: =MAX($D8) -> 0 | AZ8: =MAX($E8) -> 0 | BA8: =MAX($F8) -> 0 | BB8: =MAX($G8) -> 0 | BC8: =MAX($H8) -> 0 | BD8: =MAX($I8) -> 0 | BE8: =MAX($J8) -> 0 | BF8: =MAX($K8) -> 0 | BG8: =MAX($M8) -> 0 | BH8: =MAX($N8) -> 0 | BI8: =MAX($P8) -> 0 | BJ8: =MAX($Q8) -> 0 | BK8: =MAX($R8) -> 0
A9: /Level_6 | B9: 2248583 | C9: 233999 | D9: 50592044 | E9: 0 | F9: 8179 | G9: 0 | H9: 1 | I9: 1223.592 | J9: 1231.84 | K9: 569 | L9: ok | M9: 45051637 | N9: 948.55 | O9: SATISFIABLE | P9: 1231.84 | Q9: 0 | R9: 2568549 | S9: =MIN($B9) -> 0 | T9: =MIN($C9) -> 0 | U9: =MIN($D9) -> 0 | V9: =MIN($E9) -> 0 | W9: =MIN($F9) -> 0 | X9: =MIN($G9) -> 0 | Y9: =MIN($H9) -> 0 | Z9: =MIN($I9) -> 0 | AA9: =MIN($J9) -> 0 | AB9: =MIN($K9) -> 0 | AC9: =MIN($M9) -> 0 | AD9: =MIN($N9) -> 0 | AE9: =MIN($P9) -> 0 | AF9: =MIN($Q9) -> 0 | AG9: =MIN($R9) -> 0 | AH9: =MEDIAN($B9) -> 0 | AI9: =MEDIAN($C9) -> 0 | AJ9: =MEDIAN($D9) -> 0 | AK9: =MEDIAN($E9) -> 0 | AL9: =MEDIAN($F9) -> 0 | AM9: =MEDIAN($G9) -> 0 | AN9: =MEDIAN($H9) -> 0 | AO9: =MEDIAN($I9) -> 0 | AP9: =MEDIAN($J9) -> 0 | AQ9: =MEDIAN($K9) -> 0 | AR9: =MEDIAN($M9) -> 0 | AS9: =MEDIAN($N9) -> 0 | AT9: =MEDIAN($P9) -> 0 | AU9: =MEDIAN($Q9) -> 0 | AV9: =MEDIAN($R9) -> 0 | AW9: =MAX($B9) -> 0 | AX9: =MAX($C9) -> 0 | AY9: =MAX($D9) -> 0 | AZ9: =MAX($E9) -> 0 | BA9: =MAX($F9) -> 0 | BB9: =MAX($G9) -> 0 | BC9: =MAX($H9) -> 0 | BD9: =MAX($I9) -> 0 | BE9: =MAX($J9) -> 0 | BF9: =MAX($K9) -> 0 | BG9: =MAX($M9) -> 0 | BH9: =MAX($N9) -> 0 | BI9: =MAX($P9) -> 0 | BJ9: =MAX($Q9) -> 0 | BK9: =MAX($R9) -> 0
A10: /Level_7 | E10: 1 | F10: 10128 | G10: 0 | J10: 3600 | L10: signal(9) | P10: 1800 | Q10: 1 | V10: =MIN($E10) -> 0 | W10: =MIN($F10) -> 0 | X10: =MIN($G10) -> 0 | AA10: =MIN($J10) -> 0 | AE10: =MIN($P10) -> 0 | AF10: =MIN($Q10) -> 0 | AK10: =MEDIAN($E10) -> 0 | AL10: =MEDIAN($F10) -> 0 | AM10: =MEDIAN($G10) -> 0 | AP10: =MEDIAN($J10) -> 0 | AT10: =MEDIAN($P10) -> 0 | AU10: =MEDIAN($Q10) -> 0 | AZ10: =MAX($E10) -> 0 | BA10: =MAX($F10) -> 0 | BB10: =MAX($G10) -> 0 | BE10: =MAX($J10) -> 0 | BI10: =MAX($P10) -> 0 | BJ10: =MAX($Q10) -> 0
A11: /Level_8 | B11: 6824492 | C11: 690817 | D11: 40033348 | E11: 0 | F11: 6954 | G11: 0 | H11: 1 | I11: 1543.118 | J11: 1546.11 | K11: 1480 | L11: ok | M11: 37432639 | N11: 1319.15 | O11: SATISFIABLE | P11: 1546.11 | Q11: 0 | R11: 2089703 | S11: =MIN($B11) -> 0 | T11: =MIN($C11) -> 0 | U11: =MIN($D11) -> 0 | V11: =MIN($E11) -> 0 | W11: =MIN($F11) -> 0 | X11: =MIN($G11) -> 0 | Y11: =MIN($H11) -> 0 | Z11: =MIN($I11) -> 0 | AA11: =MIN($J11) -> 0 | AB11: =MIN($K11) -> 0 | AC11: =MIN($M11) -> 0 | AD11: =MIN($N11) -> 0 | AE11: =MIN($P11) -> 0 | AF11: =MIN($Q11) -> 0 | AG11: =MIN($R11) -> 0 | AH11: =MEDIAN($B11) -> 0 | AI11: =MEDIAN($C11) -> 0 | AJ11: =MEDIAN($D11) -> 0 | AK11: =MEDIAN($E11) -> 0 | AL11: =MEDIAN($F11) -> 0 | AM11: =MEDIAN($G11) -> 0 | AN11: =MEDIAN($H11) -> 0 | AO11: =MEDIAN($I11) -> 0 | AP11: =MEDIAN($J11) -> 0 | AQ11: =MEDIAN($K11) -> 0 | AR11: =MEDIAN($M11) -> 0 | AS11: =MEDIAN($N11) -> 0 | AT11: =MEDIAN($P11) -> 0 | AU11: =MEDIAN($Q11) -> 0 | AV11: =MEDIAN($R11) -> 0 | AW11: =MAX($B11) -> 0 | AX11: =MAX($C11) -> 0 | AY11: =MAX($D11) -> 0 | AZ11: =MAX($E11) -> 0 | BA11: =MAX($F11) -> 0 | BB11: =MAX($G11) -> 0 | BC11: =MAX($H11) -> 0 | BD11: =MAX($I11) -> 0 | BE11: =MAX($J11) -> 0 | BF11: =MAX($K11) -> 0 | BG11: =MAX($M11) -> 0 | BH11: =MAX($N11) -> 0 | BI11: =MAX($P11) -> 0 | BJ11: =MAX($Q11) -> 0 | BK11: =MAX($R11) -> 0
A12: /Level_9 | E12: 1 | F12: 9581 | G12: 0 | J12: 3600 | L12: signal(9) | P12: 1800 | Q12: 1 | V12: =MIN($E12) -> 0 | W12: =MIN($F12) -> 0 | X12: =MIN($G12) -> 0 | AA12: =MIN($J12) -> 0 | AE12: =MIN($P12) -> 0 | AF12: =MIN($Q12) -> 0 | AK12: =MEDIAN($E12) -> 0 | AL12: =MEDIAN($F12) -> 0 | AM12: =MEDIAN($G12) -> 0 | AP12: =MEDIAN($J12) -> 0 | AT12: =MEDIAN($P12) -> 0 | AU12: =MEDIAN($Q12) -> 0 | AZ12: =MAX($E12) -> 0 | BA12: =MAX($F12) -> 0 | BB12: =MAX($G12) -> 0 | BE12: =MAX($J12) -> 0 | BI12: =MAX($P12) -> 0 | BJ12: =MAX($Q12) -> 0
A13: /Level_0 | E13: 1 | F13: 10004 | G13: 0 | J13: 3600 | L13: signal(9) | P13: 1800 | Q13: 1 | V13: =MIN($E13) -> 0 | W13: =MIN($F13) -> 0 | X13: =MIN($G13) -> 0 | AA13: =MIN($J13) -> 0 | AE13: =MIN($P13) -> 0 | AF13: =MIN($Q13) -> 0 | AK13: =MEDIAN($E13) -> 0 | AL13: =MEDIAN($F13) -> 0 | AM13: =MEDIAN($G13) -> 0 | AP13: =MEDIAN($J13) -> 0 | AT13: =MEDIAN($P13) -> 0 | AU13: =MEDIAN($Q13) -> 0 | AZ13: =MAX($E13) -> 0 | BA13: =MAX($F13) -> 0 | BB13: =MAX($G13) -> 0 | BE13: =MAX($J13) -> 0 | BI13: =MAX($P13) -> 0 | BJ13: =MAX($Q13) -> 0
A14: /Level_1 | E14: 1 | F14: 10542 | G14: 0 | J14: 3600 | L14: signal(9) | P14: 1800 | Q14: 1 | V14: =MIN($E14) -> 0 | W14: =MIN($F14) -> 0 | X14: =MIN($G14) -> 0 | AA14: =MIN($J14) -> 0 | AE14: =MIN($P14) -> 0 | AF14: =MIN($Q14) -> 0 | AK14: =MEDIAN($E14) -> 0 | AL14: =MEDIAN($F14) -> 0 | AM14: =MEDIAN($G14) -> 0 | AP14: =MEDIAN($J14) -> 0 | AT14: =MEDIAN($P14) -> 0 | AU14: =MEDIAN($Q14) -> 0 | AZ14: =MAX($E14) -> 0 | BA14: =MAX($F14) -> 0 | BB14: =MAX($G14) -> 0 | BE14: =MAX($J14) -> 0 | BI14: =MAX($P14) -> 0 | BJ14: =MAX($Q14) -> 0
A15: /Level_2 | E15: 1 | F15: 9788 | G15: 0 | J15: 3600 | L15: signal(9) | P15: 1800 | Q15: 1 | V15: =MIN($E15) -> 0 | W15: =MIN($F15) -> 0 | X15: =MIN($G15) -> 0 | AA15: =MIN($J15) -> 0 | AE15: =MIN($P15) -> 0 | AF15: =MIN($Q15) -> 0 | AK15: =MEDIAN($E15) -> 0 | AL15: =MEDIAN($F15) -> 0 | AM15: =MEDIAN($G15) -> 0 | AP15: =MEDIAN($J15) -> 0 | AT15: =MEDIAN($P15) -> 0 | AU15: =MEDIAN($Q15) -> 0 | AZ15: =MAX($E15) -> 0 | BA15: =MAX($F15) -> 0 | BB15: =MAX($G15) -> 0 | BE15: =MAX($J15) -> 0 | BI15: =MAX($P15) -> 0 | BJ15: =MAX($Q15) -> 0
A16: /Level_3 | E16: 1 | F16: 12215 | G16: 0 | J16: 3600 | L16: signal(9) | P16: 1800 | Q16: 1 | V16: =MIN($E16) -> 0 | W16: =MIN($F16) -> 0 | X16: =MIN($G16) -> 0 | AA16: =MIN($J16) -> 0 | AE16: =MIN($P16) -> 0 | AF16: =MIN($Q16) -> 0 | AK16: =MEDIAN($E16) -> 0 | AL16: =MEDIAN($F16) -> 0 | AM16: =MEDIAN($G16) -> 0 | AP16: =MEDIAN($J16) -> 0 | AT16: =MEDIAN($P16) -> 0 | AU16: =MEDIAN($Q16) -> 0 | AZ16: =MAX($E16) -> 0 | BA16: =MAX($F16) -> 0 | BB16: =MAX($G16) -> 0 | BE16: =MAX($J16) -> 0 | BI16: =MAX($P16) -> 0 | BJ16: =MAX($Q16) -> 0
A17: /Level_4 | E17: 1 | F17: 9983 | G17: 0 | J17: 3600 | L17: signal(9) | P17: 1800 | Q17: 1 | V17: =MIN($E17) -> 0 | W17: =MIN($F17) -> 0 | X17: =MIN($G17) -> 0 | AA17: =MIN($J17) -> 0 | AE17: =MIN($P17) -> 0 | AF17: =MIN($Q17) -> 0 | AK17: =MEDIAN($E17) -> 0 | AL17: =MEDIAN($F17) -> 0 | AM17: =MEDIAN($G17) -> 0 | AP17: =MEDIAN($J17) -> 0 | AT17: =MEDIAN($P17) -> 0 | AU17: =MEDIAN($Q17) -> 0 | AZ17: =MAX($E17) -> 0 | BA17: =MAX($F17) -> 0 | BB17: =MAX($G17) -> 0 | BE17: =MAX($J17) -> 0 | BI17: =MAX($P17) -> 0 | BJ17: =MAX($Q17) -> 0
A18: /Level_5 | E18: 1 | F18: 10213 | G18: 0 | J18: 3600 | L18: signal(9) | P18: 1800 | Q18: 1 | V18: =MIN($E18) -> 0 | W18: =MIN($F18) -> 0 | X18: =MIN($G18) -> 0 | AA18: =MIN($J18) -> 0 | AE18: =MIN($P18) -> 0 | AF18: =MIN($Q18) -> 0 | AK18: =MEDIAN($E18) -> 0 | AL18: =MEDIAN($F18) -> 0 | AM18: =MEDIAN($G18) -> 0 | AP18: =MEDIAN($J18) -> 0 | AT18: =MEDIAN($P18) -> 0 | AU18: =MEDIAN($Q18) -> 0 | AZ18: =MAX($E18) -> 0 | BA18: =MAX($F18) -> 0 | BB18: =MAX($G18) -> 0 | BE18: =MAX($J18) -> 0 | BI18: =MAX($P18) -> 0 | BJ18: =MAX($Q18) -> 0
A19: /Level_6 | E19: 1 | F19: 9003 | G19: 0 | J19: 3600 | L19: signal(9) | P19: 1800 | Q19: 1 | V19: =MIN($E19) -> 0 | W19: =MIN($F19) -> 0 | X19: =MIN($G19) -> 0 | AA19: =MIN($J19) -> 0 | AE19: =MIN($P19) -> 0 | AF19: =MIN($Q19) -> 0 | AK19: =MEDIAN($E19) -> 0 | AL19: =MEDIAN($F19) -> 0 | AM19: =MEDIAN($G19) -> 0 | AP19: =MEDIAN($J19) -> 0 | AT19: =MEDIAN($P19) -> 0 | AU19: =MEDIAN($Q19) -> 0 | AZ19: =MAX($E19) -> 0 | BA19: =MAX($F19) -> 0 | BB19: =MAX($G19) -> 0 | BE19: =MAX($J19) -> 0 | BI19: =MAX($P19) -> 0 | BJ19: =MAX($Q19) -> 0
A20: /Level_7 | E20: 1 | F20: 9617 | G20: 0 | J20: 3600 | L20: signal(9) | P20: 1800 | Q20: 1 | V20: =MIN($E20) -> 0 | W20: =MIN($F20) -> 0 | X20: =MIN($G20) -> 0 | AA20: =MIN($J20) -> 0 | AE20: =MIN($P20) -> 0 | AF20: =MIN($Q20) -> 0 | AK20: =MEDIAN($E20) -> 0 | AL20: =MEDIAN($F20) -> 0 | AM20: =MEDIAN($G20) -> 0 | AP20: =MEDIAN($J20) -> 0 | AT20: =MEDIAN($P20) -> 0 | AU20: =MEDIAN($Q20) -> 0 | AZ20: =MAX($E20) -> 0 | BA20: =MAX($F20) -> 0 | BB20: =MAX($G20) -> 0 | BE20: =MAX($J20) -> 0 | BI20: =MAX($P20) -> 0 | BJ20: =MAX($Q20) -> 0
A21: /Level_8 | E21: 1 | F21: 9089 | G21: 0 | J21: 3600 | L21: signal(9) | P21: 1800 | Q21: 1 | V21: =MIN($E21) -> 0 | W21: =MIN($F21) -> 0 | X21: =MIN($G21) -> 0 | AA21: =MIN($J21) -> 0 | AE21: =MIN($P21) -> 0 | AF21: =MIN($Q21) -> 0 | AK21: =MEDIAN($E21) -> 0 | AL21: =MEDIAN($F21) -> 0 | AM21: =MEDIAN($G21) -> 0 | AP21: =MEDIAN($J21) -> 0 | AT21: =MEDIAN($P21) -> 0 | AU21: =MEDIAN($Q21) -> 0 | AZ21: =MAX($E21) -> 0 | BA21: =MAX($F21) -> 0 | BB21: =MAX($G21) -> 0 | BE21: =MAX($J21) -> 0 | BI21: =MAX($P21) -> 0 | BJ21: =MAX($Q21) -> 0
A22: /Level_9 | E22: 1 | F22: 9351 | G22: 0 | J22: 3600 | L22: signal(9) | P22: 1800 | Q22: 1 | V22: =MIN($E22) -> 0 | W22: =MIN($F22) -> 0 | X22: =MIN($G22) -> 0 | AA22: =MIN($J22) -> 0 | AE22: =MIN($P22) -> 0 | AF22: =MIN($Q22) -> 0 | AK22: =MEDIAN($E22) -> 0 | AL22: =MEDIAN($F22) -> 0 | AM22: =MEDIAN($G22) -> 0 | AP22: =MEDIAN($J22) -> 0 | AT22: =MEDIAN($P22) -> 0 | AU22: =MEDIAN($Q22) -> 0 | AZ22: =MAX($E22) -> 0 | BA22: =MAX($F22) -> 0 | BB22: =MAX($G22) -> 0 | BE22: =MAX($J22) -> 0 | BI22: =MAX($P22) -> 0 | BJ22: =MAX($Q22) -> 0
A23: /Level_0 | E23: 1 | F23: 15904 | G23: 0 | J23: 3600 | L23: signal(9) | P23: 1800 | Q23: 1 | V23: =MIN($E23) -> 0 | W23: =MIN($F23) -> 0 | X23: =MIN($G23) -> 0 | AA23: =MIN($J23) -> 0 | AE23: =MIN($P23) -> 0 | AF23: =MIN($Q23) -> 0 | AK23: =MEDIAN($E23) -> 0 | AL23: =MEDIAN($F23) -> 0 | AM23: =MEDIAN($G23) -> 0 | AP23: =MEDIAN($J23) -> 0 | AT23: =MEDIAN($P23) -> 0 | AU23: =MEDIAN($Q23) -> 0 | AZ23: =MAX($E23) -> 0 | BA23: =MAX($F23) -> 0 | BB23: =MAX($G23) -> 0 | BE23: =MAX($J23) -> 0 | BI23: =MAX($P23) -> 0 | BJ23: =MAX($Q23) -> 0
... A28: /Level_5 | E28: 1 | F28: 10697 | G28: 0 | J28: 3600 | L28: signal(9) | P28: 1800 | Q28: 1 | V28: =MIN($E28) -> 0 | W28: =MIN($F28) -> 0 | X28: =MIN($G28) -> 0 | AA28: =MIN($J28) -> 0 | AE28: =MIN($P28) -> 0 | AF28: =MIN($Q28) -> 0 | AK28: =MEDIAN($E28) -> 0 | AL28: =MEDIAN($F28) -> 0 | AM28: =MEDIAN($G28) -> 0 | AP28: =MEDIAN($J28) -> 0 | AT28: =MEDIAN($P28) -> 0 | AU28: =MEDIAN($Q28) -> 0 | AZ28: =MAX($E28) -> 0 | BA28: =MAX($F28) -> 0 | BB28: =MAX($G28) -> 0 | BE28: =MAX($J28) -> 0 | BI28: =MAX($P28) -> 0 | BJ28: =MAX($Q28) -> 0
A29: /Level_6 | B29: 0 | C29: 0 | D29: 0 | E29: 0 | F29: 20002 | G29: 1 | H29: 0 | I29: 645.031 | J29: 3600 | K29: 0 | L29: out of memory | M29: 0 | N29: 0 | O29: UNKNOWN | P29: 1800 | Q29: 1 | R29: 0 | S29: =MIN($B29) -> 0 | T29: =MIN($C29) -> 0 | U29: =MIN($D29) -> 0 | V29: =MIN($E29) -> 0 | W29: =MIN($F29) -> 0 | X29: =MIN($G29) -> 0 | Y29: =MIN($H29) -> 0 | Z29: =MIN($I29) -> 0 | AA29: =MIN($J29) -> 0 | AB29: =MIN($K29) -> 0 | AC29: =MIN($M29) -> 0 | AD29: =MIN($N29) -> 0 | AE29: =MIN($P29) -> 0 | AF29: =MIN($Q29) -> 0 | AG29: =MIN($R29) -> 0 | AH29: =MEDIAN($B29) -> 0 | AI29: =MEDIAN($C29) -> 0 | AJ29: =MEDIAN($D29) -> 0 | AK29: =MEDIAN($E29) -> 0 | AL29: =MEDIAN($F29) -> 0 | AM29: =MEDIAN($G29) -> 0 | AN29: =MEDIAN($H29) -> 0 | AO29: =MEDIAN($I29) -> 0 | AP29: =MEDIAN($J29) -> 0 | AQ29: =MEDIAN($K29) -> 0 | AR29: =MEDIAN($M29) -> 0 | AS29: =MEDIAN($N29) -> 0 | AT29: =MEDIAN($P29) -> 0 | AU29: =MEDIAN($Q29) -> 0 | AV29: =MEDIAN($R29) -> 0 | AW29: =MAX($B29) -> 0 | AX29: =MAX($C29) -> 0 | AY29: =MAX($D29) -> 0 | AZ29: =MAX($E29) -> 0 | BA29: =MAX($F29) -> 0 | BB29: =MAX($G29) -> 0 | BC29: =MAX($H29) -> 0 | BD29: =MAX($I29) -> 0 | BE29: =MAX($J29) -> 0 | BF29: =MAX($K29) -> 0 | BG29: =MAX($M29) -> 0 | BH29: =MAX($N29) -> 0 | BI29: =MAX($P29) -> 0 | BJ29: =MAX($Q29) -> 0 | BK29: =MAX($R29) -> 0
A30: /Level_7 | B30: 0 | C30: 0 | D30: 0 | E30: 0 | F30: 20006 | G30: 1 | H30: 0 | I30: 837.029 | J30: 3600 | K30: 0 | L30: out of memory | M30: 0 | N30: 0 | O30: UNKNOWN | P30: 1800 | Q30: 1 | R30: 0 | S30: =MIN($B30) -> 0 | T30: =MIN($C30) -> 0 | U30: =MIN($D30) -> 0 | V30: =MIN($E30) -> 0 | W30: =MIN($F30) -> 0 | X30: =MIN($G30) -> 0 | Y30: =MIN($H30) -> 0 | Z30: =MIN($I30) -> 0 | AA30: =MIN($J30) -> 0 | AB30: =MIN($K30) -> 0 | AC30: =MIN($M30) -> 0 | AD30: =MIN($N30) -> 0 | AE30: =MIN($P30) -> 0 | AF30: =MIN($Q30) -> 0 | AG30: =MIN($R30) -> 0 | AH30: =MEDIAN($B30) -> 0 | AI30: =MEDIAN($C30) -> 0 | AJ30: =MEDIAN($D30) -> 0 | AK30: =MEDIAN($E30) -> 0 | AL30: =MEDIAN($F30) -> 0 | AM30: =MEDIAN($G30) -> 0 | AN30: =MEDIAN($H30) -> 0 | AO30: =MEDIAN($I30) -> 0 | AP30: =MEDIAN($J30) -> 0 | AQ30: =MEDIAN($K30) -> 0 | AR30: =MEDIAN($M30) -> 0 | AS30: =MEDIAN($N30) -> 0 | AT30: =MEDIAN($P30) -> 0 | AU30: =MEDIAN($Q30) -> 0 | AV30: =MEDIAN($R30) -> 0 | AW30: =MAX($B30) -> 0 | AX30: =MAX($C30) -> 0 | AY30: =MAX($D30) -> 0 | AZ30: =MAX($E30) -> 0 | BA30: =MAX($F30) -> 0 | BB30: =MAX($G30) -> 0 | BC30: =MAX($H30) -> 0 | BD30: =MAX($I30) -> 0 | BE30: =MAX($J30) -> 0 | BF30: =MAX($K30) -> 0 | BG30: =MAX($M30) -> 0 | BH30: =MAX($N30) -> 0 | BI30: =MAX($P30) -> 0 | BJ30: =MAX($Q30) -> 0 | BK30: =MAX($R30) -> 0
A31: /Level_8 | E31: 1 | F31: 14426 | G31: 0 | J31: 3600 | L31: signal(9) | P31: 1800 | Q31: 1 | V31: =MIN($E31) -> 0 | W31: =MIN($F31) -> 0 | X31: =MIN($G31) -> 0 | AA31: =MIN($J31) -> 0 | AE31: =MIN($P31) -> 0 | AF31: =MIN($Q31) -> 0 | AK31: =MEDIAN($E31) -> 0 | AL31: =MEDIAN($F31) -> 0 | AM31: =MEDIAN($G31) -> 0 | AP31: =MEDIAN($J31) -> 0 | AT31: =MEDIAN($P31) -> 0 | AU31: =MEDIAN($Q31) -> 0 | AZ31: =MAX($E31) -> 0 | BA31: =MAX($F31) -> 0 | BB31: =MAX($G31) -> 0 | BE31: =MAX($J31) -> 0 | BI31: =MAX($P31) -> 0 | BJ31: =MAX($Q31) -> 0
A32: /Level_9 | B32: 0 | C32: 0 | D32: 0 | E32: 0 | F32: 20003 | G32: 1 | H32: 0 | I32: 299.228 | J32: 3600 | K32: 0 | L32: out of memory | M32: 0 | N32: 0 | O32: UNKNOWN | P32: 1800 | Q32: 1 | R32: 0 | S32: =MIN($B32) -> 0 | T32: =MIN($C32) -> 0 | U32: =MIN($D32) -> 0 | V32: =MIN($E32) -> 0 | W32: =MIN($F32) -> 0 | X32: =MIN($G32) -> 0 | Y32: =MIN($H32) -> 0 | Z32: =MIN($I32) -> 0 | AA32: =MIN($J32) -> 0 | AB32: =MIN($K32) -> 0 | AC32: =MIN($M32) -> 0 | AD32: =MIN($N32) -> 0 | AE32: =MIN($P32) -> 0 | AF32: =MIN($Q32) -> 0 | AG32: =MIN($R32) -> 0 | AH32: =MEDIAN($B32) -> 0 | AI32: =MEDIAN($C32) -> 0 | AJ32: =MEDIAN($D32) -> 0 | AK32: =MEDIAN($E32) -> 0 | AL32: =MEDIAN($F32) -> 0 | AM32: =MEDIAN($G32) -> 0 | AN32: =MEDIAN($H32) -> 0 | AO32: =MEDIAN($I32) -> 0 | AP32: =MEDIAN($J32) -> 0 | AQ32: =MEDIAN($K32) -> 0 | AR32: =MEDIAN($M32) -> 0 | AS32: =MEDIAN($N32) -> 0 | AT32: =MEDIAN($P32) -> 0 | AU32: =MEDIAN($Q32) -> 0 | AV32: =MEDIAN($R32) -> 0 | AW32: =MAX($B32) -> 0 | AX32: =MAX($C32) -> 0 | AY32: =MAX($D32) -> 0 | AZ32: =MAX($E32) -> 0 | BA32: =MAX($F32) -> 0 | BB32: =MAX($G32) -> 0 | BC32: =MAX($H32) -> 0 | BD32: =MAX($I32) -> 0 | BE32: =MAX($J32) -> 0 | BF32: =MAX($K32) -> 0 | BG32: =MAX($M32) -> 0 | BH32: =MAX($N32) -> 0 | BI32: =MAX($P32) -> 0 | BJ32: =MAX($Q32) -> 0 | BK32: =MAX($R32) -> 0
A34: SUM | B34: =SUM(B$3:B$32) -> 0 | C34: =SUM(C$3:C$32) -> 0 | D34: =SUM(D$3:D$32) -> 0 | E34: =SUM(E$3:E$32) -> 0 | F34: =SUM(F$3:F$32) -> 0 | G34: =SUM(G$3:G$32) -> 0 | H34: =SUM(H$3:H$32) -> 0 | I34: =SUM(I$3:I$32) -> 0 | ... K34: =SUM(K$3:K$32) -> 0 | M34: =SUM(M$3:M$32) -> 0 | N34: =SUM(N$3:N$32) -> 0 | P34: =SUM(P$3:P$32) -> 0 | Q34: =SUM(Q$3:Q$32) -> 0 | R34: =SUM(R$3:R$32) -> 0 | S34: =SUM(S$3:S$32) -> 0 | T34: =SUM(T$3:T$32) -> 0 | U34: =SUM(U$3:U$32) -> 0 | V34: =SUM(V$3:V$32) -> 0 | W34: =SUM(W$3:W$32) -> 0 | ... BK34: =SUM(BK$3:BK$32) -> 0
A35: AVG | B35: =AVERAGE(B$3:B$32) -> 0 | C35: =AVERAGE(C$3:C$32) -> 0 | D35: =AVERAGE(D$3:D$32) -> 0 | E35: =AVERAGE(E$3:E$32) -> 0 | F35: =AVERAGE(F$3:F$32) -> 0 | G35: =AVERAGE(G$3:G$32) -> 0 | H35: =AVERAGE(H$3:H$32) -> 0 | I35: =AVERAGE(I$3:I$32) -> 0 | ... K35: =AVERAGE(K$3:K$32) -> 0 | M35: =AVERAGE(M$3:M$32) -> 0 | N35: =AVERAGE(N$3:N$32) -> 0 | P35: =AVERAGE(P$3:P$32) -> 0 | Q35: =AVERAGE(Q$3:Q$32) -> 0 | R35: =AVERAGE(R$3:R$32) -> 0 | S35: =AVERAGE(S$3:S$32) -> 0 | T35: =AVERAGE(T$3:T$32) -> 0 | U35: =AVERAGE(U$3:U$32) -> 0 | V35: =AVERAGE(V$3:V$32) -> 0 | W35: =AVERAGE(W$3:W$32) -> 0 | ... BK35: =AVERAGE(BK$3:BK$32) -> 0
A36: DEV | B36: =STDEV(B$3:B$32) -> 0 | C36: =STDEV(C$3:C$32) -> 0 | D36: =STDEV(D$3:D$32) -> 0 | E36: =STDEV(E$3:E$32) -> 0 | F36: =STDEV(F$3:F$32) -> 0 | G36: =STDEV(G$3:G$32) -> 0 | H36: =STDEV(H$3:H$32) -> 0 | I36: =STDEV(I$3:I$32) -> 0 | ... K36: =STDEV(K$3:K$32) -> 0 | M36: =STDEV(M$3:M$32) -> 0 | N36: =STDEV(N$3:N$32) -> 0 | P36: =STDEV(P$3:P$32) -> 0 | Q36: =STDEV(Q$3:Q$32) -> 0 | R36: =STDEV(R$3:R$32) -> 0 | S36: =STDEV(S$3:S$32) -> 0 | T36: =STDEV(T$3:T$32) -> 0 | U36: =STDEV(U$3:U$32) -> 0 | V36: =STDEV(V$3:V$32) -> 0 | W36: =STDEV(W$3:W$32) -> 0 | ... BK36: =STDEV(BK$3:BK$32) -> 0
A37: DST | B37: =SUMPRODUCT(--(B$3:B$32-$S$3:$S$32)^2)^0.5 -> 0 | C37: =SUMPRODUCT(--(C$3:C$32-$T$3:$T$32)^2)^0.5 -> 0 | D37: =SUMPRODUCT(--(D$3:D$32-$U$3:$U$32)^2)^0.5 -> 0 | E37: =SUMPRODUCT(--(E$3:E$32-$V$3:$V$32)^2)^0.5 -> 0 | F37: =SUMPRODUCT(--(F$3:F$32-$W$3:$W$32)^2)^0.5 -> 0 | G37: =SUMPRODUCT(--(G$3:G$32-$X$3:$X$32)^2)^0.5 -> 0 | H37: =SUMPRODUCT(--(H$3:H$32-$Y$3:$Y$32)^2)^0.5 -> 0 | I37: =SUMPRODUCT(--(I$3:I$32-$Z$3:$Z$32)^2)^0.5 -> 0 | J37: =SUMPRODUCT(--(J$3:J$32-$AA$3:$AA$32)^2)^0.5 -> 0 | K37: =SUMPRODUCT(--(K$3:K$32-$AB$3:$AB$32)^2)^0.5 -> 0 | M37: =SUMPRODUCT(--(M$3:M$32-$AC$3:$AC$32)^2)^0.5 -> 0 | N37: =SUMPRODUCT(--(N$3:N$32-$AD$3:$AD$32)^2)^0.5 -> 0 | P37: =SUMPRODUCT(--(P$3:P$32-$AE$3:$AE$32)^2)^0.5 -> 0 | Q37: =SUMPRODUCT(--(Q$3:Q$32-$AF$3:$AF$32)^2)^0.5 -> 0 | R37: =SUMPRODUCT(--(R$3:R$32-$AG$3:$AG$32)^2)^0.5 -> 0
A38: BEST | B38: =SUMPRODUCT(NOT(ISBLANK(B$3:B$32))*(B$3:B$32=$S$3:$S$32)) -> 0 | C38: =SUMPRODUCT(NOT(ISBLANK(C$3:C$32))*(C$3:C$32=$T$3:$T$32)) -> 0 | D38: =SUMPRODUCT(NOT(ISBLANK(D$3:D$32))*(D$3:D$32=$U$3:$U$32)) -> 0 | E38: =SUMPRODUCT(NOT(ISBLANK(E$3:E$32))*(E$3:E$32=$V$3:$V$32)) -> 0 | F38: =SUMPRODUCT(NOT(ISBLANK(F$3:F$32))*(F$3:F$32=$W$3:$W$32)) -> 0 | G38: =SUMPRODUCT(NOT(ISBLANK(G$3:G$32))*(G$3:G$32=$X$3:$X$32)) -> 0 | H38: =SUMPRODUCT(NOT(ISBLANK(H$3:H$32))*(H$3:H$32=$Y$3:$Y$32)) -> 0 | I38: =SUMPRODUCT(NOT(ISBLANK(I$3:I$32))*(I$3:I$32=$Z$3:$Z$32)) -> 0 | J38: =SUMPRODUCT(NOT(ISBLANK(J$3:J$32))*(J$3:J$32=$AA$3:$AA$32)) -> 0 | K38: =SUMPRODUCT(NOT(ISBLANK(K$3:K$32))*(K$3:K$32=$AB$3:$AB$32)) -> 0 | M38: =SUMPRODUCT(NOT(ISBLANK(M$3:M$32))*(M$3:M$32=$AC$3:$AC$32)) -> 0 | N38: =SUMPRODUCT(NOT(ISBLANK(N$3:N$32))*(N$3:N$32=$AD$3:$AD$32)) -> 0 | P38: =SUMPRODUCT(NOT(ISBLANK(P$3:P$32))*(P$3:P$32=$AE$3:$AE$32)) -> 0 | Q38: =SUMPRODUCT(NOT(ISBLANK(Q$3:Q$32))*(Q$3:Q$32=$AF$3:$AF$32)) -> 0 | R38: =SUMPRODUCT(NOT(ISBLANK(R$3:R$32))*(R$3:R$32=$AG$3:$AG$32)) -> 0
A39: BETTER | B39: =SUMPRODUCT(NOT(ISBLANK(B$3:B$32))*(B$3:B$32<$AH$3:$AH$32)) -> 0 | C39: =SUMPRODUCT(NOT(ISBLANK(C$3:C$32))*(C$3:C$32<$AI$3:$AI$32)) -> 0 | D39: =SUMPRODUCT(NOT(ISBLANK(D$3:D$32))*(D$3:D$32<$AJ$3:$AJ$32)) -> 0 | E39: =SUMPRODUCT(NOT(ISBLANK(E$3:E$32))*(E$3:E$32<$AK$3:$AK$32)) -> 0 | F39: =SUMPRODUCT(NOT(ISBLANK(F$3:F$32))*(F$3:F$32<$AL$3:$AL$32)) -> 0 | G39: =SUMPRODUCT(NOT(ISBLANK(G$3:G$32))*(G$3:G$32<$AM$3:$AM$32)) -> 0 | H39: =SUMPRODUCT(NOT(ISBLANK(H$3:H$32))*(H$3:H$32<$AN$3:$AN$32)) -> 0 | I39: =SUMPRODUCT(NOT(ISBLANK(I$3:I$32))*(I$3:I$32<$AO$3:$AO$32)) -> 0 | J39: =SUMPRODUCT(NOT(ISBLANK(J$3:J$32))*(J$3:J$32<$AP$3:$AP$32)) -> 0 | K39: =SUMPRODUCT(NOT(ISBLANK(K$3:K$32))*(K$3:K$32<$AQ$3:$AQ$32)) -> 0 | M39: =SUMPRODUCT(NOT(ISBLANK(M$3:M$32))*(M$3:M$32<$AR$3:$AR$32)) -> 0 | N39: =SUMPRODUCT(NOT(ISBLANK(N$3:N$32))*(N$3:N$32<$AS$3:$AS$32)) -> 0 | P39: =SUMPRODUCT(NOT(ISBLANK(P$3:P$32))*(P$3:P$32<$AT$3:$AT$32)) -> 0 | Q39: =SUMPRODUCT(NOT(ISBLANK(Q$3:Q$32))*(Q$3:Q$32<$AU$3:$AU$32)) -> 0 | R39: =SUMPRODUCT(NOT(ISBLANK(R$3:R$32))*(R$3:R$32<$AV$3:$AV$32)) -> 0
A40: WORSE | B40: =SUMPRODUCT((NOT(ISBLANK(B$3:B$32))*(B$3:B$32>$AH$3:$AH$32))+ISBLANK(B$3:B$32)) -> 0 | C40: =SUMPRODUCT((NOT(ISBLANK(C$3:C$32))*(C$3:C$32>$AI$3:$AI$32))+ISBLANK(C$3:C$32)) -> 0 | D40: =SUMPRODUCT((NOT(ISBLANK(D$3:D$32))*(D$3:D$32>$AJ$3:$AJ$32))+ISBLANK(D$3:D$32)) -> 0 | E40: =SUMPRODUCT((NOT(ISBLANK(E$3:E$32))*(E$3:E$32>$AK$3:$AK$32))+ISBLANK(E$3:E$32)) -> 0 | F40: =SUMPRODUCT((NOT(ISBLANK(F$3:F$32))*(F$3:F$32>$AL$3:$AL$32))+ISBLANK(F$3:F$32)) -> 0 | G40: =SUMPRODUCT((NOT(ISBLANK(G$3:G$32))*(G$3:G$32>$AM$3:$AM$32))+ISBLANK(G$3:G$32)) -> 0 | H40: =SUMPRODUCT((NOT(ISBLANK(H$3:H$32))*(H$3:H$32>$AN$3:$AN$32))+ISBLANK(H$3:H$32)) -> 0 | I40: =SUMPRODUCT((NOT(ISBLANK(I$3:I$32))*(I$3:I$32>$AO$3:$AO$32))+ISBLANK(I$3:I$32)) -> 0 | J40: =SUMPRODUCT((NOT(ISBLANK(J$3:J$32))*(J$3:J$32>$AP$3:$AP$32))+ISBLANK(J$3:J$32)) -> 0 | K40: =SUMPRODUCT((NOT(ISBLANK(K$3:K$32))*(K$3:K$32>$AQ$3:$AQ$32))+ISBLANK(K$3:K$32)) -> 0 | M40: =SUMPRODUCT((NOT(ISBLANK(M$3:M$32))*(M$3:M$32>$AR$3:$AR$32))+ISBLANK(M$3:M$32)) -> 0 | N40: =SUMPRODUCT((NOT(ISBLANK(N$3:N$32))*(N$3:N$32>$AS$3:$AS$32))+ISBLANK(N$3:N$32)) -> 0 | P40: =SUMPRODUCT((NOT(ISBLANK(P$3:P$32))*(P$3:P$32>$AT$3:$AT$32))+ISBLANK(P$3:P$32)) -> 0 | Q40: =SUMPRODUCT((NOT(ISBLANK(Q$3:Q$32))*(Q$3:Q$32>$AU$3:$AU$32))+ISBLANK(Q$3:Q$32)) -> 0 | R40: =SUMPRODUCT((NOT(ISBLANK(R$3:R$32))*(R$3:R$32>$AV$3:$AV$32))+ISBLANK(R$3:R$32)) -> 0
A41: WORST | B41: =SUMPRODUCT((NOT(ISBLANK(B$3:B$32))*(B$3:B$32=$AW$3:$AW$32))+ISBLANK(B$3:B$32)) -> 0 | C41: =SUMPRODUCT((NOT(ISBLANK(C$3:C$32))*(C$3:C$32=$AX$3:$AX$32))+ISBLANK(C$3:C$32)) -> 0 | D41: =SUMPRODUCT((NOT(ISBLANK(D$3:D$32))*(D$3:D$32=$AY$3:$AY$32))+ISBLANK(D$3:D$32)) -> 0 | E41: =SUMPRODUCT((NOT(ISBLANK(E$3:E$32))*(E$3:E$32=$AZ$3:$AZ$32))+ISBLANK(E$3:E$32)) -> 0 | F41: =SUMPRODUCT((NOT(ISBLANK(F$3:F$32))*(F$3:F$32=$BA$3:$BA$32))+ISBLANK(F$3:F$32)) -> 0 | G41: =SUMPRODUCT((NOT(ISBLANK(G$3:G$32))*(G$3:G$32=$BB$3:$BB$32))+ISBLANK(G$3:G$32)) -> 0 | H41: =SUMPRODUCT((NOT(ISBLANK(H$3:H$32))*(H$3:H$32=$BC$3:$BC$32))+ISBLANK(H$3:H$32)) -> 0 | I41: =SUMPRODUCT((NOT(ISBLANK(I$3:I$32))*(I$3:I$32=$BD$3:$BD$32))+ISBLANK(I$3:I$32)) -> 0 | J41: =SUMPRODUCT((NOT(ISBLANK(J$3:J$32))*(J$3:J$32=$BE$3:$BE$32))+ISBLANK(J$3:J$32)) -> 0 | K41: =SUMPRODUCT((NOT(ISBLANK(K$3:K$32))*(K$3:K$32=$BF$3:$BF$32))+ISBLANK(K$3:K$32)) -> 0 | M41: =SUMPRODUCT((NOT(ISBLANK(M$3:M$32))*(M$3:M$32=$BG$3:$BG$32))+ISBLANK(M$3:M$32)) -> 0 | N41: =SUMPRODUCT((NOT(ISBLANK(N$3:N$32))*(N$3:N$32=$BH$3:$BH$32))+ISBLANK(N$3:N$32)) -> 0 | P41: =SUMPRODUCT((NOT(ISBLANK(P$3:P$32))*(P$3:P$32=$BI$3:$BI$32))+ISBLANK(P$3:P$32)) -> 0 | Q41: =SUMPRODUCT((NOT(ISBLANK(Q$3:Q$32))*(Q$3:Q$32=$BJ$3:$BJ$32))+ISBLANK(Q$3:Q$32)) -> 0 | R41: =SUMPRODUCT((NOT(ISBLANK(R$3:R$32))*(R$3:R$32=$BK$3:$BK$32))+ISBLANK(R$3:R$32)) -> 0

Sheet Merged Runs
A1: Merge criteria: | B1: clingo-5.8.0/default | S1: min | AH1: median | AW1: max
A2: median | B2: choices | C2: conflicts | D2: constraints | E2: error | F2: mem | G2: memout | H2: models | I2: overall-time | J2: par2 | K2: restarts | L2: rstatus | M2: rules | N2: solving-time | O2: status | P2: time | Q2: timeout | R2: variables | S2: choices | T2: conflicts | U2: constraints | V2: error | W2: mem | X2: memout | Y2: models | Z2: overall-time | AA2: par2 | AB2: restarts | AC2: rules | AD2: solving-time | AE2: time | AF2: timeout | AG2: variables | AH2: choices | AI2: conflicts | AJ2: constraints | AK2: error | AL2: mem | AM2: memout | AN2: models | AO2: overall-time | AP2: par2 | AQ2: restarts | AR2: rules | AS2: solving-time | AT2: time | AU2: timeout | AV2: variables | AW2: choices | AX2: conflicts | AY2: constraints | AZ2: error | BA2: mem | BB2: memout | BC2: models | BD2: overall-time | BE2: par2 | BF2: restarts | BG2: rules | BH2: solving-time | BI2: time | BJ2: timeout | BK2: variables
A3: /Level_0 | B3: {=_xlfn.SWITCH($A$2,"average", AVERAGE(Instances!B3:Instances!B3),"median", MEDIAN(Instances!B3:Instances!B3),"min", MIN(Instances!B3:Instances!B3),"max", MAX(Instances!B3:Instances!B3),"diff", MAX(Instances!B3:Instances!B3)-MIN(Instances!B3:Instances!B3))} -> 0 | C3: {=_xlfn.SWITCH($A$2,"average", AVERAGE(Instances!C3:Instances!C3),"median", MEDIAN(Instances!C3:Instances!C3),"min", MIN(Instances!C3:Instances!C3),"max", MAX(Instances!C3:Instances!C3),"diff", MAX(Instances!C3:Instances!C3)-MIN(Instances!C3:Instances!C3))} -> 0 | D3: {=_xlfn.SWITCH($A$2,"average", AVERAGE(Instances!D3:Instances!D3),"median", MEDIAN(Instances!D3:Instances!D3),"min", MIN(Instances!D3:Instances!D3),"max", MAX(Instances!D3:Instances!D3),"diff", MAX(Instances!D3:Instances!D3)-MIN(Instances!D3:Instances!D3))} -> 0 | E3: {=_xlfn.SWITCH($A$2,"average", AVERAGE(Instances!E3:Instances!E3),"median", MEDIAN(Instances!E3:Instances!E3),"min", MIN(Instances!E3:Instances!E3),"max", MAX(Instances!E3:Instances!E3),"diff", MAX(Instances!E3:Instances!E3)-MIN(Instances!E3:Instances!E3))} -> 0 | F3: {=_xlfn.SWITCH($A$2,"average", AVERAGE(Instances!F3:Instances!F3),"median", MEDIAN(Instances!F3:Instances!F3),"min", MIN(Instances!F3:Instances!F3),"max", MAX(Instances!F3:Instances!F3),"diff", MAX(Instances!F3:Instances!F3)-MIN(Instances!F3:Instances!F3))} -> 0 | G3: {=_xlfn.SWITCH($A$2,"average", AVERAGE(Instances!G3:Instances!G3),"median", MEDIAN(Instances!G3:Instances!G3),"min", MIN(Instances!G3:Instances!G3),"max", MAX(Instances!G3:Instances!G3),"diff", MAX(Instances!G3:Instances!G3)-MIN(Instances!G3:Instances!G3))} -> 0 | H3: {=_xlfn.SWITCH($A$2,"average", AVERAGE(Instances!H3:Instances!H3),"median", MEDIAN(Instances!H3:Instances!H3),"min", MIN(Instances!H3:Instances!H3),"max", MAX(Instances!H3:Instances!H3),"diff", MAX(Instances!H3:Instances!H3)-MIN(Instances!H3:Instances!H3))} -> 0 | I3: {=_xlfn.SWITCH($A$2,"average", AVERAGE(Instances!I3:Instances!I3),"median", MEDIAN(Instances!I3:Instances!I3),"min", MIN(Instances!I3:Instances!I3),"max", MAX(Instances!I3:Instances!I3),"diff", MAX(Instances!I3:Instances!I3)-MIN(Instances!I3:Instances!I3))} -> 0 | ... K3: {=_xlfn.SWITCH($A$2,"average", AVERAGE(Instances!K3:Instances!K3),"median", MEDIAN(Instances!K3:Instances!K3),"min", MIN(Instances!K3:Instances!K3),"max", MAX(Instances!K3:Instances!K3),"diff", MAX(Instances!K3:Instances!K3)-MIN(Instances!K3:Instances!K3))} -> 0 | M3: {=_xlfn.SWITCH($A$2,"average", AVERAGE(Instances!M3:Instances!M3),"median", MEDIAN(Instances!M3:Instances!M3),"min", MIN(Instances!M3:Instances!M3),"max", MAX(Instances!M3:Instances!M3),"diff", MAX(Instances!M3:Instances!M3)-MIN(Instances!M3:Instances!M3))} -> 0 | N3: {=_xlfn.SWITCH($A$2,"average", AVERAGE(Instances!N3:Instances!N3),"median", MEDIAN(Instances!N3:Instances!N3),"min", MIN(Instances!N3:Instances!N3),"max", MAX(Instances!N3:Instances!N3),"diff", MAX(Instances!N3:Instances!N3)-MIN(Instances!N3:Instances!N3))} -> 0 | P3: {=_xlfn.SWITCH($A$2,"average", AVERAGE(Instances!P3:Instances!P3),"median", MEDIAN(Instances!P3:Instances!P3),"min", MIN(Instances!P3:Instances!P3),"max", MAX(Instances!P3:Instances!P3),"diff", MAX(Instances!P3:Instances!P3)-MIN(Instances!P3:Instances!P3))} -> 0 | Q3: {=_xlfn.SWITCH($A$2,"average", AVERAGE(Instances!Q3:Instances!Q3),"median", MEDIAN(Instances!Q3:Instances!Q3),"min", MIN(Instances!Q3:Instances!Q3),"max", MAX(Instances!Q3:Instances!Q3),"diff", MAX(Instances!Q3:Instances!Q3)-MIN(Instances!Q3:Instances!Q3))} -> 0 | R3: {=_xlfn.SWITCH($A$2,"average", AVERAGE(Instances!R3:Instances!R3),"median", MEDIAN(Instances!R3:Instances!R3),"min", MIN(Instances!R3:Instances!R3),"max", MAX(Instances!R3:Instances!R3),"diff", MAX(Instances!R3:Instances!R3)-MIN(Instances!R3:Instances!R3))} -> 0 | S3: =MIN($B3) -> 0 | T3: =MIN($C3) -> 0 | U3: =MIN($D3) -> 0 | V3: =MIN($E3) -> 0 | W3: =MIN($F3) -> 0 | X3: =MIN($G3) -> 0 | Y3: =MIN($H3) -> 0 | Z3: =MIN($I3) -> 0 | AA3: =MIN($J3) -> 0 | AB3: =MIN($K3) -> 0 | AC3: =MIN($M3) -> 0 | AD3: =MIN($N3) -> 0 | AE3: =MIN($P3) -> 0 | AF3: =MIN($Q3) -> 0 | AG3: =MIN($R3) -> 0 | AH3: =MEDIAN($B3) -> 0 | AI3: =MEDIAN($C3) -> 0 | AJ3: =MEDIAN($D3) -> 0 | AK3: =MEDIAN($E3) -> 0 | AL3: =MEDIAN($F3) -> 0 | AM3: =MEDIAN($G3) -> 0 | AN3: =MEDIAN($H3) -> 0 | AO3: =MEDIAN($I3) -> 0 | AP3: =MEDIAN($J3) -> 0 | AQ3: =MEDIAN($K3) -> 0 | AR3: =MEDIAN($M3) -> 0 | AS3: =MEDIAN($N3) -> 0 | AT3: =MEDIAN($P3) -> 0 | AU3: =MEDIAN($Q3) -> 0 | AV3: =MEDIAN($R3) -> 0 | AW3: =MAX($B3) -> 0 | AX3: =MAX($C3) -> 0 | AY3: =MAX($D3) -> 0 | AZ3: =MAX($E3) -> 0 | BA3: =MAX($F3) -> 0 | BB3: =MAX($G3) -> 0 | BC3: =MAX($H3) -> 0 | BD3: =MAX($I3) -> 0 | BE3: =MAX($J3) -> 0 | BF3: =MAX($K3) -> 0 | BG3: =MAX($M3) -> 0 | BH3: =MAX($N3) -> 0 | BI3: =MAX($P3) -> 0 | BJ3: =MAX($Q3) -> 0 | BK3: =MAX($R3) -> 0
A4: /Level_1 | B4: {=_xlfn.SWITCH($A$2,"average", AVERAGE(Instances!B4:Instances!B4),"median", MEDIAN(Instances!B4:Instances!B4),"min", MIN(Instances!B4:Instances!B4),"max", MAX(Instances!B4:Instances!B4),"diff", MAX(Instances!B4:Instances!B4)-MIN(Instances!B4:Instances!B4))} -> 0 | C4: {=_xlfn.SWITCH($A$2,"average", AVERAGE(Instances!C4:Instances!C4),"median", MEDIAN(Instances!C4:Instances!C4),"min", MIN(Instances!C4:Instances!C4),"max", MAX(Instances!C4:Instances!C4),"diff", MAX(Instances!C4:Instances!C4)-MIN(Instances!C4:Instances!C4))} -> 0 | D4: {=_xlfn.SWITCH($A$2,"average", AVERAGE(Instances!D4:Instances!D4),"median", MEDIAN(Instances!D4:Instances!D4),"min", MIN(Instances!D4:Instances!D4),"max", MAX(Instances!D4:Instances!D4),"diff", MAX(Instances!D4:Instances!D4)-MIN(Instances!D4:Instances!D4))} -> 0 | E4: {=_xlfn.SWITCH($A$2,"average", AVERAGE(Instances!E4:Instances!E4),"median", MEDIAN(Instances!E4:Instances!E4),"min", MIN(Instances!E4:Instances!E4),"max", MAX(Instances!E4:Instances!E4),"diff", MAX(Instances!E4:Instances!E4)-MIN(Instances!E4:Instances!E4))} -> 0 | F4: {=_xlfn.SWITCH($A$2,"average", AVERAGE(Instances!F4:Instances!F4),"median", MEDIAN(Instances!F4:Instances!F4),"min", MIN(Instances!F4:Instances!F4),"max", MAX(Instances!F4:Instances!F4),"diff", MAX(Instances!F4:Instances!F4)-MIN(Instances!F4:Instances!F4))} -> 0 | G4: {=_xlfn.SWITCH($A$2,"average", AVERAGE(Instances!G4:Instances!G4),"median", MEDIAN(Instances!G4:Instances!G4),"min", MIN(Instances!G4:Instances!G4),"max", MAX(Instances!G4:Instances!G4),"diff", MAX(Instances!G4:Instances!G4)-MIN(Instances!G4:Instances!G4))} -> 0 | H4: {=_xlfn.SWITCH($A$2,"average", AVERAGE(Instances!H4:Instances!H4),"median", MEDIAN(Instances!H4:Instances!H4),"min", MIN(Instances!H4:Instances!H4),"max", MAX(Instances!H4:Instances!H4),"diff", MAX(Instances!H4:Instances!H4)-MIN(Instances!H4:Instances!H4))} -> 0 | I4: {=_xlfn.SWITCH($A$2,"average", AVERAGE(Instances!I4:Instances!I4),"median", MEDIAN(Instances!I4:Instances!I4),"min", MIN(Instances!I4:Instances!I4),"max", MAX(Instances!I4:Instances!I4),"diff", MAX(Instances!I4:Instances!I4)-MIN(Instances!I4:Instances!I4))} -> 0 | ... K4: {=_xlfn.SWITCH($A$2,"average", AVERAGE(Instances!K4:Instances!K4),"median", MEDIAN(Instances!K4:Instances!K4),"min", MIN(Instances!K4:Instances!K4),"max", MAX(Instances!K4:Instances!K4),"diff", MAX(Instances!K4:Instances!K4)-MIN(Instances!K4:Instances!K4))} -> 0 | M4: {=_xlfn.SWITCH($A$2,"average", AVERAGE(Instances!M4:Instances!M4),"median", MEDIAN(Instances!M4:Instances!M4),"min", MIN(Instances!M4:Instances!M4),"max", MAX(Instances!M4:Instances!M4),"diff", MAX(Instances!M4:Instances!M4)-MIN(Instances!M4:Instances!M4))} -> 0 | N4: {=_xlfn.SWITCH($A$2,"average", AVERAGE(Instances!N4:Instances!N4),"median", MEDIAN(Instances!N4:Instances!N4),"min", MIN(Instances!N4:Instances!N4),"max", MAX(Instances!N4:Instances!N4),"diff", MAX(Instances!N4:Instances!N4)-MIN(Instances!N4:Instances!N4))} -> 0 | P4: {=_xlfn.SWITCH($A$2,"average", AVERAGE(Instances!P4:Instances!P4),"median", MEDIAN(Instances!P4:Instances!P4),"min", MIN(Instances!P4:Instances!P4),"max", MAX(Instances!P4:Instances!P4),"diff", MAX(Instances!P4:Instances!P4)-MIN(Instances!P4:Instances!P4))} -> 0 | Q4: {=_xlfn.SWITCH($A$2,"average", AVERAGE(Instances!Q4:Instances!Q4),"median", MEDIAN(Instances!Q4:Instances!Q4),"min", MIN(Instances!Q4:Instances!Q4),"max", MAX(Instances!Q4:Instances!Q4),"diff", MAX(Instances!Q4:Instances!Q4)-MIN(Instances!Q4:Instances!Q4))} -> 0 | R4: {=_xlfn.SWITCH($A$2,"average", AVERAGE(Instances!R4:Instances!R4),"median", MEDIAN(Instances!R4:Instances!R4),"min", MIN(Instances!R4:Instances!R4),"max", MAX(Instances!R4:Instances!R4),"diff", MAX(Instances!R4:Instances!R4)-MIN(Instances!R4:Instances!R4))} -> 0 | S4: =MIN($B4) -> 0 | T4: =MIN($C4) -> 0 | U4: =MIN($D4) -> 0 | V4: =MIN($E4) -> 0 | W4: =MIN($F4) -> 0 | X4: =MIN($G4) -> 0 | Y4: =MIN($H4) -> 0 | Z4: =MIN($I4) -> 0 | AA4: =MIN($J4) -> 0 | AB4: =MIN($K4) -> 0 | AC4: =MIN($M4) -> 0 | AD4: =MIN($N4) -> 0 | AE4: =MIN($P4) -> 0 | AF4: =MIN($Q4) -> 0 | AG4: =MIN($R4) -> 0 | AH4: =MEDIAN($B4) -> 0 | AI4: =MEDIAN($C4) -> 0 | AJ4: =MEDIAN($D4) -> 0 | AK4: =MEDIAN($E4) -> 0 | AL4: =MEDIAN($F4) -> 0 | AM4: =MEDIAN($G4) -> 0 | AN4: =MEDIAN($H4) -> 0 | AO4: =MEDIAN($I4) -> 0 | AP4: =MEDIAN($J4) -> 0 | AQ4: =MEDIAN($K4) -> 0 | AR4: =MEDIAN($M4) -> 0 | AS4: =MEDIAN($N4) -> 0 | AT4: =MEDIAN($P4) -> 0 | AU4: =MEDIAN($Q4) -> 0 | AV4: =MEDIAN($R4) -> 0 | AW4: =MAX($B4) -> 0 | AX4: =MAX($C4) -> 0 | AY4: =MAX($D4) -> 0 | AZ4: =MAX($E4) -> 0 | BA4: =MAX($F4) -> 0 | BB4: =MAX($G4) -> 0 | BC4: =MAX($H4) -> 0 | BD4: =MAX($I4) -> 0 | BE4: =MAX($J4) -> 0 | BF4: =MAX($K4) -> 0 | BG4: =MAX($M4) -> 0 | BH4: =MAX($N4) -> 0 | BI4: =MAX($P4) -> 0 | BJ4: =MAX($Q4) -> 0 | BK4: =MAX($R4) -> 0
A5: /Level_2 | E5: {=_xlfn.SWITCH($A$2,"average", AVERAGE(Instances!E5:Instances!E5),"median", MEDIAN(Instances!E5:Instances!E5),"min", MIN(Instances!E5:Instances!E5),"max", MAX(Instances!E5:Instances!E5),"diff", MAX(Instances!E5:Instances!E5)-MIN(Instances!E5:Instances!E5))} -> 0 | F5: {=_xlfn.SWITCH($A$2,"average", AVERAGE(Instances!F5:Instances!F5),"median", MEDIAN(Instances!F5:Instances!F5),"min", MIN(Instances!F5:Instances!F5),"max", MAX(Instances!F5:Instances!F5),"diff", MAX(Instances!F5:Instances!F5)-MIN(Instances!F5:Instances!F5))} -> 0 | G5: {=_xlfn.SWITCH($A$2,"average", AVERAGE(Instances!G5:Instances!G5),"median", MEDIAN(Instances!G5:Instances!G5),"min", MIN(Instances!G5:Instances!G5),"max", MAX(Instances!G5:Instances!G5),"diff", MAX(Instances!G5:Instances!G5)-MIN(Instances!G5:Instances!G5))} -> 0 | J5: {=_xlfn.SWITCH($A$2,"average", AVERAGE(Instances!J5:Instances!J5),"median", MEDIAN(Instances!J5:Instances!J5),"min", MIN(Instances!J5:Instances!J5),"max", MAX(Instances!J5:Instances!J5),"diff", MAX(Instances!J5:Instances!J5)-MIN(Instances!J5:Instances!J5))} -> 0 | P5: {=_xlfn.SWITCH($A$2,"average", AVERAGE(Instances!P5:Instances!P5),"median", MEDIAN(Instances!P5:Instances!P5),"min", MIN(Instances!P5:Instances!P5),"max", MAX(Instances!P5:Instances!P5),"diff", MAX(Instances!P5:Instances!P5)-MIN(Instances!P5:Instances!P5))} -> 0 | Q5: {=_xlfn.SWITCH($A$2,"average", AVERAGE(Instances!Q5:Instances!Q5),"median", MEDIAN(Instances!Q5:Instances!Q5),"min", MIN(Instances!Q5:Instances!Q5),"max", MAX(Instances!Q5:Instances!Q5),"diff", MAX(Instances!Q5:Instances!Q5)-MIN(Instances!Q5:Instances!Q5))} -> 0 | V5: =MIN($E5) -> 0 | W5: =MIN($F5) -> 0 | X5: =MIN($G5) -> 0 | AA5: =MIN($J5) -> 0 | AE5: =MIN($P5) -> 0 | AF5: =MIN($Q5) -> 0 | AK5: =MEDIAN($E5) -> 0 | AL5: =MEDIAN($F5) -> 0 | AM5: =MEDIAN($G5) -> 0 | AP5: =MEDIAN($J5) -> 0 | AT5: =MEDIAN($P5) -> 0 | AU5: =MEDIAN($Q5) -> 0 | AZ5: =MAX($E5) -> 0 | BA5: =MAX($F5) -> 0 | BB5: =MAX($G5) -> 0 | BE5: =MAX($J5) -> 0 | BI5: =MAX($P5) -> 0 | BJ5: =MAX($Q5) -> 0
A6: /Level_3 | E6: {=_xlfn.SWITCH($A$2,"average", AVERAGE(Instances!E6:Instances!E6),"median", MEDIAN(Instances!E6:Instances!E6),"min", MIN(Instances!E6:Instances!E6),"max", MAX(Instances!E6:Instances!E6),"diff", MAX(Instances!E6:Instances!E6)-MIN(Instances!E6:Instances!E6))} -> 0 | F6: {=_xlfn.SWITCH($A$2,"average", AVERAGE(Instances!F6:Instances!F6),"median", MEDIAN(Instances!F6:Instances!F6),"min", MIN(Instances!F6:Instances!F6),"max", MAX(Instances!F6:Instances!F6),"diff", MAX(Instances!F6:Instances!F6)-MIN(Instances!F6:Instances!F6))} -> 0 | G6: {=_xlfn.SWITCH($A$2,"average", AVERAGE(Instances!G6:Instances!G6),"median", MEDIAN(Instances!G6:Instances!G6),"min", MIN(Instances!G6:Instances!G6),"max", MAX(Instances!G6:Instances!G6),"diff", MAX(Instances!G6:Instances!G6)-MIN(Instances!G6:Instances!G6))} -> 0 | J6: {=_xlfn.SWITCH($A$2,"average", AVERAGE(Instances!J6:Instances!J6),"median", MEDIAN(Instances!J6:Instances!J6),"min", MIN(Instances!J6:Instances!J6),"max", MAX(Instances!J6:Instances!J6),"diff", MAX(Instances!J6:Instances!J6)-MIN(Instances!J6:Instances!J6))} -> 0 | P6: {=_xlfn.SWITCH($A$2,"average", AVERAGE(Instances!P6:Instances!P6),"median", MEDIAN(Instances!P6:Instances!P6),"min", MIN(Instances!P6:Instances!P6),"max", MAX(Instances!P6:Instances!P6),"diff", MAX(Instances!P6:Instances!P6)-MIN(Instances!P6:Instances!P6))} -> 0 | Q6: {=_xlfn.SWITCH($A$2,"average", AVERAGE(Instances!Q6:Instances!Q6),"median", MEDIAN(Instances!Q6:Instances!Q6),"min", MIN(Instances!Q6:Instances!Q6),"max", MAX(Instances!Q6:Instances!Q6),"diff", MAX(Instances!Q6:Instances!Q6)-MIN(Instances!Q6:Instances!Q6))} -> 0 | V6: =MIN($E6) -> 0 | W6: =MIN($F6) -> 0 | X6: =MIN($G6) -> 0 | AA6: =MIN($J6) -> 0 | AE6: =MIN($P6) -> 0 | AF6: =MIN($Q6) -> 0 | AK6: =MEDIAN($E6) -> 0 | AL6: =MEDIAN($F6) -> 0 | AM6: =MEDIAN($G6) -> 0 | AP6: =MEDIAN($J6) -> 0 | AT6: =MEDIAN($P6) -> 0 | AU6: =MEDIAN($Q6) -> 0 | AZ6: =MAX($E6) -> 0 | BA6: =MAX($F6) -> 0 | BB6: =MAX($G6) -> 0 | BE6: =MAX($J6) -> 0 | BI6: =MAX($P6) -> 0 | BJ6: =MAX($Q6) -> 0
A7: /Level_4 | B7: {=_xlfn.SWITCH($A$2,"average", AVERAGE(Instances!B7:Instances!B7),"median", MEDIAN(Instances!B7:Instances!B7),"min", MIN(Instances!B7:Instances!B7),"max", MAX(Instances!B7:Instances!B7),"diff", MAX(Instances!B7:Instances!B7)-MIN(Instances!B7:Instances!B7))} -> 0 | C7: {=_xlfn.SWITCH($A$2,"average", AVERAGE(Instances!C7:Instances!C7),"median", MEDIAN(Instances!C7:Instances!C7),"min", MIN(Instances!C7:Instances!C7),"max", MAX(Instances!C7:Instances!C7),"diff", MAX(Instances!C7:Instances!C7)-MIN(Instances!C7:Instances!C7))} -> 0 | D7: {=_xlfn.SWITCH($A$2,"average", AVERAGE(Instances!D7:Instances!D7),"median", MEDIAN(Instances!D7:Instances!D7),"min", MIN(Instances!D7:Instances!D7),"max", MAX(Instances!D7:Instances!D7),"diff", MAX(Instances!D7:Instances!D7)-MIN(Instances!D7:Instances!D7))} -> 0 | E7: {=_xlfn.SWITCH($A$2,"average", AVERAGE(Instances!E7:Instances!E7),"median", MEDIAN(Instances!E7:Instances!E7),"min", MIN(Instances!E7:Instances!E7),"max", MAX(Instances!E7:Instances!E7),"diff", MAX(Instances!E7:Instances!E7)-MIN(Instances!E7:Instances!E7))} -> 0 | F7: {=_xlfn.SWITCH($A$2,"average", AVERAGE(Instances!F7:Instances!F7),"median", MEDIAN(Instances!F7:Instances!F7),"min", MIN(Instances!F7:Instances!F7),"max", MAX(Instances!F7:Instances!F7),"diff", MAX(Instances!F7:Instances!F7)-MIN(Instances!F7:Instances!F7))} -> 0 | G7: {=_xlfn.SWITCH($A$2,"average", AVERAGE(Instances!G7:Instances!G7),"median", MEDIAN(Instances!G7:Instances!G7),"min", MIN(Instances!G7:Instances!G7),"max", MAX(Instances!G7:Instances!G7),"diff", MAX(Instances!G7:Instances!G7)-MIN(Instances!G7:Instances!G7))} -> 0 | H7: {=_xlfn.SWITCH($A$2,"average", AVERAGE(Instances!H7:Instances!H7),"median", MEDIAN(Instances!H7:Instances!H7),"min", MIN(Instances!H7:Instances!H7),"max", MAX(Instances!H7:Instances!H7),"diff", MAX(Instances!H7:Instances!H7)-MIN(Instances!H7:Instances!H7))} -> 0 | I7: {=_xlfn.SWITCH($A$2,"average", AVERAGE(Instances!I7:Instances!I7),"median", MEDIAN(Instances!I7:Instances!I7),"min", MIN(Instances!I7:Instances!I7),"max", MAX(Instances!I7:Instances!I7),"diff", MAX(Instances!I7:Instances!I7)-MIN(Instances!I7:Instances!I7))} -> 0 | ... K7: {=_xlfn.SWITCH($A$2,"average", AVERAGE(Instances!K7:Instances!K7),"median", MEDIAN(Instances!K7:Instances!K7),"min", MIN(Instances!K7:Instances!K7),"max", MAX(Instances!K7:Instances!K7),"diff", MAX(Instances!K7:Instances!K7)-MIN(Instances!K7:Instances!K7))} -> 0 | M7: {=_xlfn.SWITCH($A$2,"average", AVERAGE(Instances!M7:Instances!M7),"median", MEDIAN(Instances!M7:Instances!M7),"min", MIN(Instances!M7:Instances!M7),"max", MAX(Instances!M7:Instances!M7),"diff", MAX(Instances!M7:Instances!M7)-MIN(Instances!M7:Instances!M7))} -> 0 | N7: {=_xlfn.SWITCH($A$2,"average", AVERAGE(Instances!N7:Instances!N7),"median", MEDIAN(Instances!N7:Instances!N7),"min", MIN(Instances!N7:Instances!N7),"max", MAX(Instances!N7:Instances!N7),"diff", MAX(Instances!N7:Instances!N7)-MIN(Instances!N7:Instances!N7))} -> 0 | P7: {=_xlfn.SWITCH($A$2,"average", AVERAGE(Instances!P7:Instances!P7),"median", MEDIAN(Instances!P7:Instances!P7),"min", MIN(Instances!P7:Instances!P7),"max", MAX(Instances!P7:Instances!P7),"diff", MAX(Instances!P7:Instances!P7)-MIN(Instances!P7:Instances!P7))} -> 0 | Q7: {=_xlfn.SWITCH($A$2,"average", AVERAGE(Instances!Q7:Instances!Q7),"median", MEDIAN(Instances!Q7:Instances!Q7),"min", MIN(Instances!Q7:Instances!Q7),"max", MAX(Instances!Q7:Instances!Q7),"diff", MAX(Instances!Q7:Instances!Q7)-MIN(Instances!Q7:Instances!Q7))} -> 0 | R7: {=_xlfn.SWITCH($A$2,"average", AVERAGE(Instances!R7:Instances!R7),"median", MEDIAN(Instances!R7:Instances!R7),"min", MIN(Instances!R7:Instances!R7),"max", MAX(Instances!R7:Instances!R7),"diff", MAX(Instances!R7:Instances!R7)-MIN(Instances!R7:Instances!R7))} -> 0 | S7: =MIN($B7) -> 0 | T7: =MIN($C7) -> 0 | U7: =MIN($D7) -> 0 | V7: =MIN($E7) -> 0 | W7: =MIN($F7) -> 0 | X7: =MIN($G7) -> 0 | Y7: =MIN($H7) -> 0 | Z7: =MIN($I7) -> 0 | AA7: =MIN($J7) -> 0 | AB7: =MIN($K7) -> 0 | AC7: =MIN($M7) -> 0 | AD7: =MIN($N7) -> 0 | AE7: =MIN($P7) -> 0 | AF7: =MIN($Q7) -> 0 | AG7: =MIN($R7) -> 0 | AH7: =MEDIAN($B7) -> 0 | AI7: =MEDIAN($C7) -> 0 | AJ7: =MEDIAN($D7) -> 0 | AK7: =MEDIAN($E7) -> 0 | AL7: =MEDIAN($F7) -> 0 | AM7: =MEDIAN($G7) -> 0 | AN7: =MEDIAN($H7) -> 0 | AO7: =MEDIAN($I7) -> 0 | AP7: =MEDIAN($J7) -> 0 | AQ7: =MEDIAN($K7) -> 0 | AR7: =MEDIAN($M7) -> 0 | AS7: =MEDIAN($N7) -> 0 | AT7: =MEDIAN($P7) -> 0 | AU7: =MEDIAN($Q7) -> 0 | AV7: =MEDIAN($R7) -> 0 | AW7: =MAX($B7) -> 0 | AX7: =MAX($C7) -> 0 | AY7: =MAX($D7) -> 0 | AZ7: =MAX($E7) -> 0 | BA7: =MAX($F7) -> 0 | BB7: =MAX($G7) -> 0 | BC7: =MAX($H7) -> 0 | BD7: =MAX($I7) -> 0 | BE7: =MAX($J7) -> 0 | BF7: =MAX($K7) -> 0 | BG7: =MAX($M7) -> 0 | BH7: =MAX($N7) -> 0 | BI7: =MAX($P7) -> 0 | BJ7: =MAX($Q7) -> 0 | BK7: =MAX($R7) -> 0
A8: /Level_5 | B8: {=_xlfn.SWITCH($A$2,"average", AVERAGE(Instances!B8:Instances!B8),"median", MEDIAN(Instances!B8:Instances!B8),"min", MIN(Instances!B8:Instances!B8),"max", MAX(Instances!B8:Instances!B8),"diff", MAX(Instances!B8:Instances!B8)-MIN(Instances!B8:Instances!B8))} -> 0 | C8: {=_xlfn.SWITCH($A$2,"average", AVERAGE(Instances!C8:Instances!C8),"median", MEDIAN(Instances!C8:Instances!C8),"min", MIN(Instances!C8:Instances!C8),"max", MAX(Instances!C8:Instances!C8),"diff", MAX(Instances!C8:Instances!C8)-MIN(Instances!C8:Instances!C8))} -> 0 | D8: {=_xlfn.SWITCH($A$2,"average", AVERAGE(Instances!D8:Instances!D8),"median", MEDIAN(Instances!D8:Instances!D8),"min", MIN(Instances!D8:Instances!D8),"max", MAX(Instances!D8:Instances!D8),"diff", MAX(Instances!D8:Instances!D8)-MIN(Instances!D8:Instances!D8))} -> 0 | E8: {=_xlfn.SWITCH($A$2,"average", AVERAGE(Instances!E8:Instances!E8),"median", MEDIAN(Instances!E8:Instances!E8),"min", MIN(Instances!E8:Instances!E8),"max", MAX(Instances!E8:Instances!E8),"diff", MAX(Instances!E8:Instances!E8)-MIN(Instances!E8:Instances!E8))} -> 0 | F8: {=_xlfn.SWITCH($A$2,"average", AVERAGE(Instances!F8:Instances!F8),"median", MEDIAN(Instances!F8:Instances!F8),"min", MIN(Instances!F8:Instances!F8),"max", MAX(Instances!F8:Instances!F8),"diff", MAX(Instances!F8:Instances!F8)-MIN(Instances!F8:Instances!F8))} -> 0 | G8: {=_xlfn.SWITCH($A$2,"average", AVERAGE(Instances!G8:Instances!G8),"median", MEDIAN(Instances!G8:Instances!G8),"min", MIN(Instances!G8:Instances!G8),"max", MAX(Instances!G8:Instances!G8),"diff", MAX(Instances!G8:Instances!G8)-MIN(Instances!G8:Instances!G8))} -> 0 | H8: {=_xlfn.SWITCH($A$2,"average", AVERAGE(Instances!H8:Instances!H8),"median", MEDIAN(Instances!H8:Instances!H8),"min", MIN(Instances!H8:Instances!H8),"max", MAX(Instances!H8:Instances!H8),"diff", MAX(Instances!H8:Instances!H8)-MIN(Instances!H8:Instances!H8))} -> 0 | I8: {=_xlfn.SWITCH($A$2,"average", AVERAGE(Instances!I8:Instances!I8),"median", MEDIAN(Instances!I8:Instances!I8),"min", MIN(Instances!I8:Instances!I8),"max", MAX(Instances!I8:Instances!I8),"diff", MAX(Instances!I8:Instances!I8)-MIN(Instances!I8:Instances!I8))} -> 0 | ... K8: {=_xlfn.SWITCH($A$2,"average", AVERAGE(Instances!K8:Instances!K8),"median", MEDIAN(Instances!K8:Instances!K8),"min", MIN(Instances!K8:Instances!K8),"max", MAX(Instances!K8:Instances!K8),"diff", MAX(Instances!K8:Instances!K8)-MIN(Instances!K8:Instances!K8))} -> 0 | M8: {=_xlfn.SWITCH($A$2,"average", AVERAGE(Instances!M8:Instances!M8),"median", MEDIAN(Instances!M8:Instances!M8),"min", MIN(Instances!M8:Instances!M8),"max", MAX(Instances!M8:Instances!M8),"diff", MAX(Instances!M8:Instances!M8)-MIN(Instances!M8:Instances!M8))} -> 0 | N8: {=_xlfn.SWITCH($A$2,"average", AVERAGE(Instances!N8:Instances!N8),"median", MEDIAN(Instances!N8:Instances!N8),"min", MIN(Instances!N8:Instances!N8),"max", MAX(Instances!N8:Instances!N8),"diff", MAX(Instances!N8:Instances!N8)-MIN(Instances!N8:Instances!N8))} -> 0 | P8: {=_xlfn.SWITCH($A$2,"average", AVERAGE(Instances!P8:Instances!P8),"median", MEDIAN(Instances!P8:Instances!P8),"min", MIN(Instances!P8:Instances!P8),"max", MAX(Instances!P8:Instances!P8),"diff", MAX(Instances!P8:Instances!P8)-MIN(Instances!P8:Instances!P8))} -> 0 | Q8: {=_xlfn.SWITCH($A$2,"average", AVERAGE(Instances!Q8:Instances!Q8),"median", MEDIAN(Instances!Q8:Instances!Q8),"min", MIN(Instances!Q8:Instances!Q8),"max", MAX(Instances!Q8:Instances!Q8),"diff", MAX(Instances!Q8:Instances!Q8)-MIN(Instances!Q8:Instances!Q8))} -> 0 | R8: {=_xlfn.SWITCH($A$2,"average", AVERAGE(Instances!R8:Instances!R8),"median", MEDIAN(Instances!R8:Instances!R8),"min", MIN(Instances!R8:Instances!R8),"max", MAX(Instances!R8:Instances!R8),"diff", MAX(Instances!R8:Instances!R8)-MIN(Instances!R8:Instances!R8))} -> 0 | S8: =MIN($B8) -> 0 | T8: =MIN($C8) -> 0 | U8: =MIN($D8) -> 0 | V8: =MIN($E8) -> 0 | W8: =MIN($F8) -> 0 | X8: =MIN($G8) -> 0 | Y8: =MIN($H8) -> 0 | Z8: =MIN($I8) -> 0 | AA8: =MIN($J8) -> 0 | AB8: =MIN($K8) -> 0 | AC8: =MIN($M8) -> 0 | AD8: =MIN($N8) -> 0 | AE8: =MIN($P8) -> 0 | AF8: =MIN($Q8) -> 0 | AG8: =MIN($R8) -> 0 | AH8: =MEDIAN($B8) -> 0 | AI8: =MEDIAN($C8) -> 0 | AJ8: =MEDIAN($D8) -> 0 | AK8: =MEDIAN($E8) -> 0 | AL8: =MEDIAN($F8) -> 0 | AM8: =MEDIAN($G8) -> 0 | AN8: =MEDIAN($H8) -> 0 | AO8: =MEDIAN($I8) -> 0 | AP8: =MEDIAN($J8) -> 0 | AQ8: =MEDIAN($K8) -> 0 | AR8: =MEDIAN($M8) -> 0 | AS8: =MEDIAN($N8) -> 0 | AT8: =MEDIAN($P8) -> 0 | AU8: =MEDIAN($Q8) -> 0 | AV8: =MEDIAN($R8) -> 0 | AW8: =MAX($B8) -> 0 | AX8: =MAX($C8) -> 0 | AY8: =MAX($D8) -> 0 | AZ8: =MAX($E8) -> 0 | BA8: =MAX($F8) -> 0 | BB8: =MAX($G8) -> 0 | BC8: =MAX($H8) -> 0 | BD8: =MAX($I8) -> 0 | BE8: =MAX($J8) -> 0 | BF8: =MAX($K8) -> 0 | BG8: =MAX($M8) -> 0 | BH8: =MAX($N8) -> 0 | BI8: =MAX($P8) -> 0 | BJ8: =MAX($Q8) -> 0 | BK8: =MAX($R8) -> 0
A9: /Level_6 | B9: {=_xlfn.SWITCH($A$2,"average", AVERAGE(Instances!B9:Instances!B9),"median", MEDIAN(Instances!B9:Instances!B9),"min", MIN(Instances!B9:Instances!B9),"max", MAX(Instances!B9:Instances!B9),"diff", MAX(Instances!B9:Instances!B9)-MIN(Instances!B9:Instances!B9))} -> 0 | C9: {=_xlfn.SWITCH($A$2,"average", AVERAGE(Instances!C9:Instances!C9),"median", MEDIAN(Instances!C9:Instances!C9),"min", MIN(Instances!C9:Instances!C9),"max", MAX(Instances!C9:Instances!C9),"diff", MAX(Instances!C9:Instances!C9)-MIN(Instances!C9:Instances!C9))} -> 0 | D9: {=_xlfn.SWITCH($A$2,"average", AVERAGE(Instances!D9:Instances!D9),"median", MEDIAN(Instances!D9:Instances!D9),"min", MIN(Instances!D9:Instances!D9),"max", MAX(Instances!D9:Instances!D9),"diff", MAX(Instances!D9:Instances!D9)-MIN(Instances!D9:Instances!D9))} -> 0 | E9: {=_xlfn.SWITCH($A$2,"average", AVERAGE(Instances!E9:Instances!E9),"median", MEDIAN(Instances!E9:Instances!E9),"min", MIN(Instances!E9:Instances!E9),"max", MAX(Instances!E9:Instances!E9),"diff", MAX(Instances!E9:Instances!E9)-MIN(Instances!E9:Instances!E9))} -> 0 | F9: {=_xlfn.SWITCH($A$2,"average", AVERAGE(Instances!F9:Instances!F9),"median", MEDIAN(Instances!F9:Instances!F9),"min", MIN(Instances!F9:Instances!F9),"max", MAX(Instances!F9:Instances!F9),"diff", MAX(Instances!F9:Instances!F9)-MIN(Instances!F9:Instances!F9))} -> 0 | G9: {=_xlfn.SWITCH($A$2,"average", AVERAGE(Instances!G9:Instances!G9),"median", MEDIAN(Instances!G9:Instances!G9),"min", MIN(Instances!G9:Instances!G9),"max", MAX(Instances!G9:Instances!G9),"diff", MAX(Instances!G9:Instances!G9)-MIN(Instances!G9:Instances!G9))} -> 0 | H9: {=_xlfn.SWITCH($A$2,"average", AVERAGE(Instances!H9:Instances!H9),"median", MEDIAN(Instances!H9:Instances!H9),"min", MIN(Instances!H9:Instances!H9),"max", MAX(Instances!H9:Instances!H9),"diff", MAX(Instances!H9:Instances!H9)-MIN(Instances!H9:Instances!H9))} -> 0 | I9: {=_xlfn.SWITCH($A$2,"average", AVERAGE(Instances!I9:Instances!I9),"median", MEDIAN(Instances!I9:Instances!I9),"min", MIN(Instances!I9:Instances!I9),"max", MAX(Instances!I9:Instances!I9),"diff", MAX(Instances!I9:Instances!I9)-MIN(Instances!I9:Instances!I9))} -> 0 | ... K9: {=_xlfn.SWITCH($A$2,"average", AVERAGE(Instances!K9:Instances!K9),"median", MEDIAN(Instances!K9:Instances!K9),"min", MIN(Instances!K9:Instances!K9),"max", MAX(Instances!K9:Instances!K9),"diff", MAX(Instances!K9:Instances!K9)-MIN(Instances!K9:Instances!K9))} -> 0 | M9: {=_xlfn.SWITCH($A$2,"average", AVERAGE(Instances!M9:Instances!M9),"median", MEDIAN(Instances!M9:Instances!M9),"min", MIN(Instances!M9:Instances!M9),"max", MAX(Instances!M9:Instances!M9),"diff", MAX(Instances!M9:Instances!M9)-MIN(Instances!M9:Instances!M9))} -> 0 | N9: {=_xlfn.SWITCH($A$2,"average", AVERAGE(Instances!N9:Instances!N9),"median", MEDIAN(Instances!N9:Instances!N9),"min", MIN(Instances!N9:Instances!N9),"max", MAX(Instances!N9:Instances!N9),"diff", MAX(Instances!N9:Instances!N9)-MIN(Instances!N9:Instances!N9))} -> 0 | P9: {=_xlfn.SWITCH($A$2,"average", AVERAGE(Instances!P9:Instances!P9),"median", MEDIAN(Instances!P9:Instances!P9),"min", MIN(Instances!P9:Instances!P9),"max", MAX(Instances!P9:Instances!P9),"diff", MAX(Instances!P9:Instances!P9)-MIN(Instances!P9:Instances!P9))} -> 0 | Q9: {=_xlfn.SWITCH($A$2,"average", AVERAGE(Instances!Q9:Instances!Q9),"median", MEDIAN(Instances!Q9:Instances!Q9),"min", MIN(Instances!Q9:Instances!Q9),"max", MAX(Instances!Q9:Instances!Q9),"diff", MAX(Instances!Q9:Instances!Q9)-MIN(Instances!Q9:Instances!Q9))} -> 0 | R9: {=_xlfn.SWITCH($A$2,"average", AVERAGE(Instances!R9:Instances!R9),"median", MEDIAN(Instances!R9:Instances!R9),"min", MIN(Instances!R9:Instances!R9),"max", MAX(Instances!R9:Instances!R9),"diff", MAX(Instances!R9:Instances!R9)-MIN(Instances!R9:Instances!R9))} -> 0 | S9: =MIN($B9) -> 0 | T9: =MIN($C9) -> 0 | U9: =MIN($D9) -> 0 | V9: =MIN($E9) -> 0 | W9: =MIN($F9) -> 0 | X9: =MIN($G9) -> 0 | Y9: =MIN($H9) -> 0 | Z9: =MIN($I9) -> 0 | AA9: =MIN($J9) -> 0 | AB9: =MIN($K9) -> 0 | AC9: =MIN($M9) -> 0 | AD9: =MIN($N9) -> 0 | AE9: =MIN($P9) -> 0 | AF9: =MIN($Q9) -> 0 | AG9: =MIN($R9) -> 0 | AH9: =MEDIAN($B9) -> 0 | AI9: =MEDIAN($C9) -> 0 | AJ9: =MEDIAN($D9) -> 0 | AK9: =MEDIAN($E9) -> 0 | AL9: =MEDIAN($F9) -> 0 | AM9: =MEDIAN($G9) -> 0 | AN9: =MEDIAN($H9) -> 0 | AO9: =MEDIAN($I9) -> 0 | AP9: =MEDIAN($J9) -> 0 | AQ9: =MEDIAN($K9) -> 0 | AR9: =MEDIAN($M9) -> 0 | AS9: =MEDIAN($N9) -> 0 | AT9: =MEDIAN($P9) -> 0 | AU9: =MEDIAN($Q9) -> 0 | AV9: =MEDIAN($R9) -> 0 | AW9: =MAX($B9) -> 0 | AX9: =MAX($C9) -> 0 | AY9: =MAX($D9) -> 0 | AZ9: =MAX($E9) -> 0 | BA9: =MAX($F9) -> 0 | BB9: =MAX($G9) -> 0 | BC9: =MAX($H9) -> 0 | BD9: =MAX($I9) -> 0 | BE9: =MAX($J9) -> 0 | BF9: =MAX($K9) -> 0 | BG9: =MAX($M9) -> 0 | BH9: =MAX($N9) -> 0 | BI9: =MAX($P9) -> 0 | BJ9: =MAX($Q9) -> 0 | BK9: =MAX($R9) -> 0
