Workbook

Sheet Instances
B1: clingo-5.8.0/one-as
B2: choices | C2: conflicts | D2: constraints | E2: error | F2: mem | G2: memout | H2: models | I2: overall-time | J2: par2 | K2: restarts | L2: rstatus | M2: rules | N2: solving-time | O2: status | P2: time | Q2: timeout | R2: variables
A3: Level_0/2-0000101 | B3: 839 | C3: 0 | D3: 108042 | E3: 0 | F3: 179 | G3: 0 | H3: 1 | I3: 2.397 | J3: 2.46 | K3: 0 | L3: ok | M3: 477481 | N3: 0.01 | O3: SATISFIABLE | P3: 2.46 | Q3: 0 | R3: 179096
A4: Level_0/2-0000110 | B4: 1112 | C4: 0 | D4: 138673 | E4: 0 | F4: 223 | G4: 0 | H4: 1 | I4: 2.85 | J4: 2.93 | K4: 0 | L4: ok | M4: 572593 | N4: 0.02 | O4: SATISFIABLE | P4: 2.93 | Q4: 0 | R4: 215132
A5: Level_0/2-0001001 | B5: 523 | C5: 0 | D5: 106237 | E5: 0 | F5: 190 | G5: 0 | H5: 1 | I5: 2.548 | J5: 2.62 | K5: 0 | L5: ok | M5: 531500 | N5: 0.01 | O5: SATISFIABLE | P5: 2.62 | Q5: 0 | R5: 190873
A6: Level_0/2-0001010 | B6: 1464 | C6: 1 | D6: 227403 | E6: 0 | F6: 299 | G6: 0 | H6: 1 | I6: 3.949 | J6: 4.06 | K6: 0 | L6: ok | M6: 861548 | N6: 0.03 | O6: SATISFIABLE | P6: 4.06 | Q6: 0 | R6: 306887
A7: Level_0/2-0001100 | B7: 767 | C7: 0 | D7: 127626 | E7: 0 | F7: 202 | G7: 0 | H7: 1 | I7: 2.534 | J7: 2.61 | K7: 0 | L7: ok | M7: 525049 | N7: 0.01 | O7: SATISFIABLE | P7: 2.61 | Q7: 0 | R7: 198752
A8: Level_0/2-0100001 | B8: 515 | C8: 0 | D8: 86065 | E8: 0 | F8: 140 | G8: 0 | H8: 1 | I8: 1.906 | J8: 1.96 | K8: 0 | L8: ok | M8: 395956 | N8: 0.01 | O8: SATISFIABLE | P8: 1.96 | Q8: 0 | R8: 143835
A9: Level_0/2-0100100 | B9: 658 | C9: 0 | D9: 151526 | E9: 0 | F9: 151 | G9: 0 | H9: 1 | I9: 1.93 | J9: 1.98 | K9: 0 | L9: ok | M9: 410085 | N9: 0.01 | O9: SATISFIABLE | P9: 1.98 | Q9: 0 | R9: 150890
A10: Level_0/3-0001101 | B10: 1095 | C10: 0 | D10: 199280 | E10: 0 | F10: 318 | G10: 0 | H10: 1 | I10: 4.314 | J10: 4.43 | K10: 0 | L10: ok | M10: 933041 | N10: 0.02 | O10: SATISFIABLE | P10: 4.43 | Q10: 0 | R10: 318496
A11: Level_0/3-0001110 | B11: 1145 | C11: 0 | D11: 242876 | E11: 0 | F11: 367 | G11: 0 | H11: 1 | I11: 4.916 | J11: 5.05 | K11: 0 | L11: ok | M11: 1078748 | N11: 0.03 | O11: SATISFIABLE | P11: 5.05 | Q11: 0 | R11: 365407
A12: Level_0/3-0101001 | B12: 621 | C12: 0 | D12: 135579 | E12: 0 | F12: 245 | G12: 0 | H12: 1 | I12: 3.269 | J12: 3.43 | K12: 0 | L12: ok | M12: 726092 | N12: 0.02 | O12: SATISFIABLE | P12: 3.43 | Q12: 0 | R12: 242780
A13: Level_0/3-1011000 | B13: 1152 | C13: 0 | D13: 337701 | E13: 0 | F13: 458 | G13: 0 | H13: 1 | I13: 6.324 | J13: 6.49 | K13: 0 | L13: ok | M13: 1412233 | N13: 0.04 | O13: SATISFIABLE | P13: 6.49 | Q13: 0 | R13: 456718
A14: Level_0/3-1100010 | B14: 1203 | C14: 0 | D14: 377109 | E14: 0 | F14: 411 | G14: 0 | H14: 1 | I14: 5.662 | J14: 5.81 | K14: 0 | L14: ok | M14: 1240754 | N14: 0.03 | O14: SATISFIABLE | P14: 5.81 | Q14: 0 | R14: 409026
... A362: Level_9/7-1111111 | B362: 362447 | C362: 1191 | D362: 2564050 | E362: 0 | F362: 1353 | G362: 0 | H362: 1 | I362: 28.601 | J362: 29.05 | K362: 6 | L362: ok | M362: 5155200 | N362: 7.26 | O362: SATISFIABLE | P362: 29.05 | Q362: 0 | R362: 1337115
A364: SUM | B364: =SUM(B$3:B$362) -> 0 | C364: =SUM(C$3:C$362) -> 0 | D364: =SUM(D$3:D$362) -> 0 | E364: =SUM(E$3:E$362) -> 0 | F364: =SUM(F$3:F$362) -> 0 | G364: =SUM(G$3:G$362) -> 0 | H364: =SUM(H$3:H$362) -> 0 | I364: =SUM(I$3:I$362) -> 0 | ... K364: =SUM(K$3:K$362) -> 0 | M364: =SUM(M$3:M$362) -> 0 | N364: =SUM(N$3:N$362) -> 0 | P364: =SUM(P$3:P$362) -> 0 | Q364: =SUM(Q$3:Q$362) -> 0 | R364: =SUM(R$3:R$362) -> 0
A365: AVG | B365: =AVERAGE(B$3:B$362) -> 0 | C365: =AVERAGE(C$3:C$362) -> 0 | D365: =AVERAGE(D$3:D$362) -> 0 | E365: =AVERAGE(E$3:E$362) -> 0 | F365: =AVERAGE(F$3:F$362) -> 0 | G365: =AVERAGE(G$3:G$362) -> 0 | H365: =AVERAGE(H$3:H$362) -> 0 | I365: =AVERAGE(I$3:I$362) -> 0 | ... K365: =AVERAGE(K$3:K$362) -> 0 | M365: =AVERAGE(M$3:M$362) -> 0 | N365: =AVERAGE(N$3:N$362) -> 0 | P365: =AVERAGE(P$3:P$362) -> 0 | Q365: =AVERAGE(Q$3:Q$362) -> 0 | R365: =AVERAGE(R$3:R$362) -> 0
A366: DEV | B366: =STDEV(B$3:B$362) -> 0 | C366: =STDEV(C$3:C$362) -> 0 | D366: =STDEV(D$3:D$362) -> 0 | E366: =STDEV(E$3:E$362) -> 0 | F366: =STDEV(F$3:F$362) -> 0 | G366: =STDEV(G$3:G$362) -> 0 | H366: =STDEV(H$3:H$362) -> 0 | I366: =STDEV(I$3:I$362) -> 0 | ... K366: =STDEV(K$3:K$362) -> 0 | M366: =STDEV(M$3:M$362) -> 0 | N366: =STDEV(N$3:N$362) -> 0 | P366: =STDEV(P$3:P$362) -> 0 | Q366: =STDEV(Q$3:Q$362) -> 0 | R366: =STDEV(R$3:R$362) -> 0
A367: DST | B367: =SUMPRODUCT(--(B$3:B$362-$S$3:$S$362)^2)^0.5 -> 890538.29 | C367: =SUMPRODUCT(--(C$3:C$362-$T$3:$T$362)^2)^0.5 -> 19886.944 | D367: =SUMPRODUCT(--(D$3:D$362-$U$3:$U$362)^2)^0.5 -> 18909096 | E367: =SUMPRODUCT(--(E$3:E$362-$V$3:$V$362)^2)^0.5 -> 0 | F367: =SUMPRODUCT(--(F$3:F$362-$W$3:$W$362)^2)^0.5 -> 11838.061 | G367: =SUMPRODUCT(--(G$3:G$362-$X$3:$X$362)^2)^0.5 -> 0 | H367: =SUMPRODUCT(--(H$3:H$362-$Y$3:$Y$362)^2)^0.5 -> 18.973666 | I367: =SUMPRODUCT(--(I$3:I$362-$Z$3:$Z$362)^2)^0.5 -> 193.30555 | J367: =SUMPRODUCT(--(J$3:J$362-$AA$3:$AA$362)^2)^0.5 -> 197.43293 | K367: =SUMPRODUCT(--(K$3:K$362-$AB$3:$AB$362)^2)^0.5 -> 100.005 | M367: =SUMPRODUCT(--(M$3:M$362-$AC$3:$AC$362)^2)^0.5 -> 41597476 | N367: =SUMPRODUCT(--(N$3:N$362-$AD$3:$AD$362)^2)^0.5 -> 35.638746 | P367: =SUMPRODUCT(--(P$3:P$362-$AE$3:$AE$362)^2)^0.5 -> 197.43293 | Q367: =SUMPRODUCT(--(Q$3:Q$362-$AF$3:$AF$362)^2)^0.5 -> 0 | R367: =SUMPRODUCT(--(R$3:R$362-$AG$3:$AG$362)^2)^0.5 -> 11884305
A368: BEST | B368: =SUMPRODUCT(NOT(ISBLANK(B$3:B$362))*(B$3:B$362=$S$3:$S$362)) -> 0 | C368: =SUMPRODUCT(NOT(ISBLANK(C$3:C$362))*(C$3:C$362=$T$3:$T$362)) -> 112 | D368: =SUMPRODUCT(NOT(ISBLANK(D$3:D$362))*(D$3:D$362=$U$3:$U$362)) -> 0 | E368: =SUMPRODUCT(NOT(ISBLANK(E$3:E$362))*(E$3:E$362=$V$3:$V$362)) -> 360 | F368: =SUMPRODUCT(NOT(ISBLANK(F$3:F$362))*(F$3:F$362=$W$3:$W$362)) -> 0 | G368: =SUMPRODUCT(NOT(ISBLANK(G$3:G$362))*(G$3:G$362=$X$3:$X$362)) -> 360 | H368: =SUMPRODUCT(NOT(ISBLANK(H$3:H$362))*(H$3:H$362=$Y$3:$Y$362)) -> 0 | I368: =SUMPRODUCT(NOT(ISBLANK(I$3:I$362))*(I$3:I$362=$Z$3:$Z$362)) -> 0 | J368: =SUMPRODUCT(NOT(ISBLANK(J$3:J$362))*(J$3:J$362=$AA$3:$AA$362)) -> 0 | K368: =SUMPRODUCT(NOT(ISBLANK(K$3:K$362))*(K$3:K$362=$AB$3:$AB$362)) -> 276 | M368: =SUMPRODUCT(NOT(ISBLANK(M$3:M$362))*(M$3:M$362=$AC$3:$AC$362)) -> 0 | N368: =SUMPRODUCT(NOT(ISBLANK(N$3:N$362))*(N$3:N$362=$AD$3:$AD$362)) -> 0 | P368: =SUMPRODUCT(NOT(ISBLANK(P$3:P$362))*(P$3:P$362=$AE$3:$AE$362)) -> 0 | Q368: =SUMPRODUCT(NOT(ISBLANK(Q$3:Q$362))*(Q$3:Q$362=$AF$3:$AF$362)) -> 360 | R368: =SUMPRODUCT(NOT(ISBLANK(R$3:R$362))*(R$3:R$362=$AG$3:$AG$362)) -> 0
A369: BETTER | B369: =SUMPRODUCT(NOT(ISBLANK(B$3:B$362))*(B$3:B$362<$AH$3:$AH$362)) -> 0 | C369: =SUMPRODUCT(NOT(ISBLANK(C$3:C$362))*(C$3:C$362<$AI$3:$AI$362)) -> 0 | D369: =SUMPRODUCT(NOT(ISBLANK(D$3:D$362))*(D$3:D$362<$AJ$3:$AJ$362)) -> 0 | E369: =SUMPRODUCT(NOT(ISBLANK(E$3:E$362))*(E$3:E$362<$AK$3:$AK$362)) -> 0 | F369: =SUMPRODUCT(NOT(ISBLANK(F$3:F$362))*(F$3:F$362<$AL$3:$AL$362)) -> 0 | G369: =SUMPRODUCT(NOT(ISBLANK(G$3:G$362))*(G$3:G$362<$AM$3:$AM$362)) -> 0 | H369: =SUMPRODUCT(NOT(ISBLANK(H$3:H$362))*(H$3:H$362<$AN$3:$AN$362)) -> 0 | I369: =SUMPRODUCT(NOT(ISBLANK(I$3:I$362))*(I$3:I$362<$AO$3:$AO$362)) -> 0 | J369: =SUMPRODUCT(NOT(ISBLANK(J$3:J$362))*(J$3:J$362<$AP$3:$AP$362)) -> 0 | K369: =SUMPRODUCT(NOT(ISBLANK(K$3:K$362))*(K$3:K$362<$AQ$3:$AQ$362)) -> 0 | M369: =SUMPRODUCT(NOT(ISBLANK(M$3:M$362))*(M$3:M$362<$AR$3:$AR$362)) -> 0 | N369: =SUMPRODUCT(NOT(ISBLANK(N$3:N$362))*(N$3:N$362<$AS$3:$AS$362)) -> 0 | P369: =SUMPRODUCT(NOT(ISBLANK(P$3:P$362))*(P$3:P$362<$AT$3:$AT$362)) -> 0 | Q369: =SUMPRODUCT(NOT(ISBLANK(Q$3:Q$362))*(Q$3:Q$362<$AU$3:$AU$362)) -> 0 | R369: =SUMPRODUCT(NOT(ISBLANK(R$3:R$362))*(R$3:R$362<$AV$3:$AV$362)) -> 0
A370: WORSE | B370: =SUMPRODUCT((NOT(ISBLANK(B$3:B$362))*(B$3:B$362>$AH$3:$AH$362))+ISBLANK(B$3:B$362)) -> 360 | C370: =SUMPRODUCT((NOT(ISBLANK(C$3:C$362))*(C$3:C$362>$AI$3:$AI$362))+ISBLANK(C$3:C$362)) -> 248 | D370: =SUMPRODUCT((NOT(ISBLANK(D$3:D$362))*(D$3:D$362>$AJ$3:$AJ$362))+ISBLANK(D$3:D$362)) -> 360 | E370: =SUMPRODUCT((NOT(ISBLANK(E$3:E$362))*(E$3:E$362>$AK$3:$AK$362))+ISBLANK(E$3:E$362)) -> 0 | F370: =SUMPRODUCT((NOT(ISBLANK(F$3:F$362))*(F$3:F$362>$AL$3:$AL$362))+ISBLANK(F$3:F$362)) -> 360 | G370: =SUMPRODUCT((NOT(ISBLANK(G$3:G$362))*(G$3:G$362>$AM$3:$AM$362))+ISBLANK(G$3:G$362)) -> 0 | H370: =SUMPRODUCT((NOT(ISBLANK(H$3:H$362))*(H$3:H$362>$AN$3:$AN$362))+ISBLANK(H$3:H$362)) -> 360 | I370: =SUMPRODUCT((NOT(ISBLANK(I$3:I$362))*(I$3:I$362>$AO$3:$AO$362))+ISBLANK(I$3:I$362)) -> 360 | J370: =SUMPRODUCT((NOT(ISBLANK(J$3:J$362))*(J$3:J$362>$AP$3:$AP$362))+ISBLANK(J$3:J$362)) -> 360 | K370: =SUMPRODUCT((NOT(ISBLANK(K$3:K$362))*(K$3:K$362>$AQ$3:$AQ$362))+ISBLANK(K$3:K$362)) -> 84 | M370: =SUMPRODUCT((NOT(ISBLANK(M$3:M$362))*(M$3:M$362>$AR$3:$AR$362))+ISBLANK(M$3:M$362)) -> 360 | N370: =SUMPRODUCT((NOT(ISBLANK(N$3:N$362))*(N$3:N$362>$AS$3:$AS$362))+ISBLANK(N$3:N$362)) -> 360 | P370: =SUMPRODUCT((NOT(ISBLANK(P$3:P$362))*(P$3:P$362>$AT$3:$AT$362))+ISBLANK(P$3:P$362)) -> 360 | Q370: =SUMPRODUCT((NOT(ISBLANK(Q$3:Q$362))*(Q$3:Q$362>$AU$3:$AU$362))+ISBLANK(Q$3:Q$362)) -> 0 | R370: =SUMPRODUCT((NOT(ISBLANK(R$3:R$362))*(R$3:R$362>$AV$3:$AV$362))+ISBLANK(R$3:R$362)) -> 360
A371: WORST | B371: =SUMPRODUCT((NOT(ISBLANK(B$3:B$362))*(B$3:B$362=$AW$3:$AW$362))+ISBLANK(B$3:B$362)) -> 0 | C371: =SUMPRODUCT((NOT(ISBLANK(C$3:C$362))*(C$3:C$362=$AX$3:$AX$362))+ISBLANK(C$3:C$362)) -> 112 | D371: =SUMPRODUCT((NOT(ISBLANK(D$3:D$362))*(D$3:D$362=$AY$3:$AY$362))+ISBLANK(D$3:D$362)) -> 0 | E371: =SUMPRODUCT((NOT(ISBLANK(E$3:E$362))*(E$3:E$362=$AZ$3:$AZ$362))+ISBLANK(E$3:E$362)) -> 360 | F371: =SUMPRODUCT((NOT(ISBLANK(F$3:F$362))*(F$3:F$362=$BA$3:$BA$362))+ISBLANK(F$3:F$362)) -> 0 | G371: =SUMPRODUCT((NOT(ISBLANK(G$3:G$362))*(G$3:G$362=$BB$3:$BB$362))+ISBLANK(G$3:G$362)) -> 360 | H371: =SUMPRODUCT((NOT(ISBLANK(H$3:H$362))*(H$3:H$362=$BC$3:$BC$362))+ISBLANK(H$3:H$362)) -> 0 | I371: =SUMPRODUCT((NOT(ISBLANK(I$3:I$362))*(I$3:I$362=$BD$3:$BD$362))+ISBLANK(I$3:I$362)) -> 0 | J371: =SUMPRODUCT((NOT(ISBLANK(J$3:J$362))*(J$3:J$362=$BE$3:$BE$362))+ISBLANK(J$3:J$362)) -> 0 | K371: =SUMPRODUCT((NOT(ISBLANK(K$3:K$362))*(K$3:K$362=$BF$3:$BF$362))+ISBLANK(K$3:K$362)) -> 276 | M371: =SUMPRODUCT((NOT(ISBLANK(M$3:M$362))*(M$3:M$362=$BG$3:$BG$362))+ISBLANK(M$3:M$362)) -> 0 | N371: =SUMPRODUCT((NOT(ISBLANK(N$3:N$362))*(N$3:N$362=$BH$3:$BH$362))+ISBLANK(N$3:N$362)) -> 0 | P371: =SUMPRODUCT((NOT(ISBLANK(P$3:P$362))*(P$3:P$362=$BI$3:$BI$362))+ISBLANK(P$3:P$362)) -> 0 | Q371: =SUMPRODUCT((NOT(ISBLANK(Q$3:Q$362))*(Q$3:Q$362=$BJ$3:$BJ$362))+ISBLANK(Q$3:Q$362)) -> 360 | R371: =SUMPRODUCT((NOT(ISBLANK(R$3:R$362))*(R$3:R$362=$BK$3:$BK$362))+ISBLANK(R$3:R$362)) -> 0

Sheet Merged Runs
A1: Merge criteria: | B1: clingo-5.8.0/one-as | S1: min | AH1: median | AW1: max
A2: median | B2: choices | C2: conflicts | D2: constraints | E2: error | F2: mem | G2: memout | H2: models | I2: overall-time | J2: par2 | K2: restarts | L2: rstatus | M2: rules | N2: solving-time | O2: status | P2: time | Q2: timeout | R2: variables | S2: choices | T2: conflicts | U2: constraints | V2: error | W2: mem | X2: memout | Y2: models | Z2: overall-time | AA2: par2 | AB2: restarts | AC2: rules | AD2: solving-time | AE2: time | AF2: timeout | AG2: variables | AH2: choices | AI2: conflicts | AJ2: constraints | AK2: error | AL2: mem | AM2: memout | AN2: models | AO2: overall-time | AP2: par2 | AQ2: restarts | AR2: rules | AS2: solving-time | AT2: time | AU2: timeout | AV2: variables | AW2: choices | AX2: conflicts | AY2: constraints | AZ2: error | BA2: mem | BB2: memout | BC2: models | BD2: overall-time | BE2: par2 | BF2: restarts | BG2: rules | BH2: solving-time | BI2: time | BJ2: timeout | BK2: variables
A3: Level_0/2-0000101 | B3: {=_xlfn.SWITCH($A$2,"average", AVERAGE(Instances!B3:B3),"median", MEDIAN(Instances!B3:B3),"min", MIN(Instances!B3:B3),"max", MAX(Instances!B3:B3),"diff", MAX(Instances!B3:B3)-MIN(Instances!B3:B3))} -> 839 | C3: {=_xlfn.SWITCH($A$2,"average", AVERAGE(Instances!C3:C3),"median", MEDIAN(Instances!C3:C3),"min", MIN(Instances!C3:C3),"max", MAX(Instances!C3:C3),"diff", MAX(Instances!C3:C3)-MIN(Instances!C3:C3))} -> 0 | D3: {=_xlfn.SWITCH($A$2,"average", AVERAGE(Instances!D3:D3),"median", MEDIAN(Instances!D3:D3),"min", MIN(Instances!D3:D3),"max", MAX(Instances!D3:D3),"diff", MAX(Instances!D3:D3)-MIN(Instances!D3:D3))} -> 108042 | E3: {=_xlfn.SWITCH($A$2,"average", AVERAGE(Instances!E3:E3),"median", MEDIAN(Instances!E3:E3),"min", MIN(Instances!E3:E3),"max", MAX(Instances!E3:E3),"diff", MAX(Instances!E3:E3)-MIN(Instances!E3:E3))} -> 0 | F3: {=_xlfn.SWITCH($A$2,"average", AVERAGE(Instances!F3:F3),"median", MEDIAN(Instances!F3:F3),"min", MIN(Instances!F3:F3),"max", MAX(Instances!F3:F3),"diff", MAX(Instances!F3:F3)-MIN(Instances!F3:F3))} -> 179 | G3: {=_xlfn.SWITCH($A$2,"average", AVERAGE(Instances!G3:G3),"median", MEDIAN(Instances!G3:G3),"min", MIN(Instances!G3:G3),"max", MAX(Instances!G3:G3),"diff", MAX(Instances!G3:G3)-MIN(Instances!G3:G3))} -> 0 | H3: {=_xlfn.SWITCH($A$2,"average", AVERAGE(Instances!H3:H3),"median", MEDIAN(Instances!H3:H3),"min", MIN(Instances!H3:H3),"max", MAX(Instances!H3:H3),"diff", MAX(Instances!H3:H3)-MIN(Instances!H3:H3))} -> 1 | I3: {=_xlfn.SWITCH($A$2,"average", AVERAGE(Instances!I3:I3),"median", MEDIAN(Instances!I3:I3),"min", MIN(Instances!I3:I3),"max", MAX(Instances!I3:I3),"diff", MAX(Instances!I3:I3)-MIN(Instances!I3:I3))} -> 2.397 | ... K3: {=_xlfn.SWITCH($A$2,"average", AVERAGE(Instances!K3:K3),"median", MEDIAN(Instances!K3:K3),"min", MIN(Instances!K3:K3),"max", MAX(Instances!K3:K3),"diff", MAX(Instances!K3:K3)-MIN(Instances!K3:K3))} -> 0 | M3: {=_xlfn.SWITCH($A$2,"average", AVERAGE(Instances!M3:M3),"median", MEDIAN(Instances!M3:M3),"min", MIN(Instances!M3:M3),"max", MAX(Instances!M3:M3),"diff", MAX(Instances!M3:M3)-MIN(Instances!M3:M3))} -> 477481 | N3: {=_xlfn.SWITCH($A$2,"average", AVERAGE(Instances!N3:N3),"median", MEDIAN(Instances!N3:N3),"min", MIN(Instances!N3:N3),"max", MAX(Instances!N3:N3),"diff", MAX(Instances!N3:N3)-MIN(Instances!N3:N3))} -> 0.01 | P3: {=_xlfn.SWITCH($A$2,"average", AVERAGE(Instances!P3:P3),"median", MEDIAN(Instances!P3:P3),"min", MIN(Instances!P3:P3),"max", MAX(Instances!P3:P3),"diff", MAX(Instances!P3:P3)-MIN(Instances!P3:P3))} -> 2.46 | Q3: {=_xlfn.SWITCH($A$2,"average", AVERAGE(Instances!Q3:Q3),"median", MEDIAN(Instances!Q3:Q3),"min", MIN(Instances!Q3:Q3),"max", MAX(Instances!Q3:Q3),"diff", MAX(Instances!Q3:Q3)-MIN(Instances!Q3:Q3))} -> 0 | R3: {=_xlfn.SWITCH($A$2,"average", AVERAGE(Instances!R3:R3),"median", MEDIAN(Instances!R3:R3),"min", MIN(Instances!R3:R3),"max", MAX(Instances!R3:R3),"diff", MAX(Instances!R3:R3)-MIN(Instances!R3:R3))} -> 179096 | S3: =MIN($B3) -> 839 | T3: =MIN($C3) -> 0 | U3: =MIN($D3) -> 108042 | V3: =MIN($E3) -> 0 | W3: =MIN($F3) -> 179 | X3: =MIN($G3) -> 0 | Y3: =MIN($H3) -> 1 | Z3: =MIN($I3) -> 2.397 | AA3: =MIN($J3) -> 2.46 | AB3: =MIN($K3) -> 0 | AC3: =MIN($M3) -> 477481 | AD3: =MIN($N3) -> 0.01 | AE3: =MIN($P3) -> 2.46 | AF3: =MIN($Q3) -> 0 | AG3: =MIN($R3) -> 179096 | AH3: =MEDIAN($B3) -> 839 | AI3: =MEDIAN($C3) -> 0 | AJ3: =MEDIAN($D3) -> 108042 | AK3: =MEDIAN($E3) -> 0 | AL3: =MEDIAN($F3) -> 179 | AM3: =MEDIAN($G3) -> 0 | AN3: =MEDIAN($H3) -> 1 | AO3: =MEDIAN($I3) -> 2.397 | AP3: =MEDIAN($J3) -> 2.46 | AQ3: =MEDIAN($K3) -> 0 | AR3: =MEDIAN($M3) -> 477481 | AS3: =MEDIAN($N3) -> 0.01 | AT3: =MEDIAN($P3) -> 2.46 | AU3: =MEDIAN($Q3) -> 0 | AV3: =MEDIAN($R3) -> 179096 | AW3: =MAX($B3) -> 839 | AX3: =MAX($C3) -> 0 | AY3: =MAX($D3) -> 108042 | AZ3: =MAX($E3) -> 0 | BA3: =MAX($F3) -> 179 | BB3: =MAX($G3) -> 0 | BC3: =MAX($H3) -> 1 | BD3: =MAX($I3) -> 2.397 | BE3: =MAX($J3) -> 2.46 | BF3: =MAX($K3) -> 0 | BG3: =MAX($M3) -> 477481 | BH3: =MAX($N3) -> 0.01 | BI3: =MAX($P3) -> 2.46 | BJ3: =MAX($Q3) -> 0 | BK3: =MAX($R3) -> 179096
A4: Level_0/2-0000110 | B4: {=_xlfn.SWITCH($A$2,"average", AVERAGE(Instances!B4:B4),"median", MEDIAN(Instances!B4:B4),"min", MIN(Instances!B4:B4),"max", MAX(Instances!B4:B4),"diff", MAX(Instances!B4:B4)-MIN(Instances!B4:B4))} -> 1112 | C4: {=_xlfn.SWITCH($A$2,"average", AVERAGE(Instances!C4:C4),"median", MEDIAN(Instances!C4:C4),"min", MIN(Instances!C4:C4),"max", MAX(Instances!C4:C4),"diff", MAX(Instances!C4:C4)-MIN(Instances!C4:C4))} -> 0 | D4: {=_xlfn.SWITCH($A$2,"average", AVERAGE(Instances!D4:D4),"median", MEDIAN(Instances!D4:D4),"min", MIN(Instances!D4:D4),"max", MAX(Instances!D4:D4),"diff", MAX(Instances!D4:D4)-MIN(Instances!D4:D4))} -> 138673 | E4: {=_xlfn.SWITCH($A$2,"average", AVERAGE(Instances!E4:E4),"median", MEDIAN(Instances!E4:E4),"min", MIN(Instances!E4:E4),"max", MAX(Instances!E4:E4),"diff", MAX(Instances!E4:E4)-MIN(Instances!E4:E4))} -> 0 | F4: {=_xlfn.SWITCH($A$2,"average", AVERAGE(Instances!F4:F4),"median", MEDIAN(Instances!F4:F4),"min", MIN(Instances!F4:F4),"max", MAX(Instances!F4:F4),"diff", MAX(Instances!F4:F4)-MIN(Instances!F4:F4))} -> 223 | G4: {=_xlfn.SWITCH($A$2,"average", AVERAGE(Instances!G4:G4),"median", MEDIAN(Instances!G4:G4),"min", MIN(Instances!G4:G4),"max", MAX(Instances!G4:G4),"diff", MAX(Instances!G4:G4)-MIN(Instances!G4:G4))} -> 0 | H4: {=_xlfn.SWITCH($A$2,"average", AVERAGE(Instances!H4:H4),"median", MEDIAN(Instances!H4:H4),"min", MIN(Instances!H4:H4),"max", MAX(Instances!H4:H4),"diff", MAX(Instances!H4:H4)-MIN(Instances!H4:H4))} -> 1 | I4: {=_xlfn.SWITCH($A$2,"average", AVERAGE(Instances!I4:I4),"median", MEDIAN(Instances!I4:I4),"min", MIN(Instances!I4:I4),"max", MAX(Instances!I4:I4),"diff", MAX(Instances!I4:I4)-MIN(Instances!I4:I4))} -> 2.85 | ... K4: {=_xlfn.SWITCH($A$2,"average", AVERAGE(Instances!K4:K4),"median", MEDIAN(Instances!K4:K4),"min", MIN(Instances!K4:K4),"max", MAX(Instances!K4:K4),"diff", MAX(Instances!K4:K4)-MIN(Instances!K4:K4))} -> 0 | M4: {=_xlfn.SWITCH($A$2,"average", AVERAGE(Instances!M4:M4),"median", MEDIAN(Instances!M4:M4),"min", MIN(Instances!M4:M4),"max", MAX(Instances!M4:M4),"diff", MAX(Instances!M4:M4)-MIN(Instances!M4:M4))} -> 572593 | N4: {=_xlfn.SWITCH($A$2,"average", AVERAGE(Instances!N4:N4),"median", MEDIAN(Instances!N4:N4),"min", MIN(Instances!N4:N4),"max", MAX(Instances!N4:N4),"diff", MAX(Instances!N4:N4)-MIN(Instances!N4:N4))} -> 0.02 | P4: {=_xlfn.SWITCH($A$2,"average", AVERAGE(Instances!P4:P4),"median", MEDIAN(Instances!P4:P4),"min", MIN(Instances!P4:P4),"max", MAX(Instances!P4:P4),"diff", MAX(Instances!P4:P4)-MIN(Instances!P4:P4))} -> 2.93 | Q4: {=_xlfn.SWITCH($A$2,"average", AVERAGE(Instances!Q4:Q4),"median", MEDIAN(Instances!Q4:Q4),"min", MIN(Instances!Q4:Q4),"max", MAX(Instances!Q4:Q4),"diff", MAX(Instances!Q4:Q4)-MIN(Instances!Q4:Q4))} -> 0 | R4: {=_xlfn.SWITCH($A$2,"average", AVERAGE(Instances!R4:R4),"median", MEDIAN(Instances!R4:R4),"min", MIN(Instances!R4:R4),"max", MAX(Instances!R4:R4),"diff", MAX(Instances!R4:R4)-MIN(Instances!R4:R4))} -> 215132 | S4: =MIN($B4) -> 1112 | T4: =MIN($C4) -> 0 | U4: =MIN($D4) -> 138673 | V4: =MIN($E4) -> 0 | W4: =MIN($F4) -> 223 | X4: =MIN($G4) -> 0 | Y4: =MIN($H4) -> 1 | Z4: =MIN($I4) -> 2.85 | AA4: =MIN($J4) -> 2.93 | AB4: =MIN($K4) -> 0 | AC4: =MIN($M4) -> 572593 | AD4: =MIN($N4) -> 0.02 | AE4: =MIN($P4) -> 2.93 | AF4: =MIN($Q4) -> 0 | AG4: =MIN($R4) -> 215132 | AH4: =MEDIAN($B4) -> 1112 | AI4: =MEDIAN($C4) -> 0 | AJ4: =MEDIAN($D4) -> 138673 | AK4: =MEDIAN($E4) -> 0 | AL4: =MEDIAN($F4) -> 223 | AM4: =MEDIAN($G4) -> 0 | AN4: =MEDIAN($H4) -> 1 | AO4: =MEDIAN($I4) -> 2.85 | AP4: =MEDIAN($J4) -> 2.93 | AQ4: =MEDIAN($K4) -> 0 | AR4: =MEDIAN($M4) -> 572593 | AS4: =MEDIAN($N4) -> 0.02 | AT4: =MEDIAN($P4) -> 2.93 | AU4: =MEDIAN($Q4) -> 0 | AV4: =MEDIAN($R4) -> 215132 | AW4: =MAX($B4) -> 1112 | AX4: =MAX($C4) -> 0 | AY4: =MAX($D4) -> 138673 | AZ4: =MAX($E4) -> 0 | BA4: =MAX($F4) -> 223 | BB4: =MAX($G4) -> 0 | BC4: =MAX($H4) -> 1 | BD4: =MAX($I4) -> 2.85 | BE4: =MAX($J4) -> 2.93 | BF4: =MAX($K4) -> 0 | BG4: =MAX($M4) -> 572593 | BH4: =MAX($N4) -> 0.02 | BI4: =MAX($P4) -> 2.93 | BJ4: =MAX($Q4) -> 0 | BK4: =MAX($R4) -> 215132
A5: Level_0/2-0001001 | B5: {=_xlfn.SWITCH($A$2,"average", AVERAGE(Instances!B5:B5),"median", MEDIAN(Instances!B5:B5),"min", MIN(Instances!B5:B5),"max", MAX(Instances!B5:B5),"diff", MAX(Instances!B5:B5)-MIN(Instances!B5:B5))} -> 523 | C5: {=_xlfn.SWITCH($A$2,"average", AVERAGE(Instances!C5:C5),"median", MEDIAN(Instances!C5:C5),"min", MIN(Instances!C5:C5),"max", MAX(Instances!C5:C5),"diff", MAX(Instances!C5:C5)-MIN(Instances!C5:C5))} -> 0 | D5: {=_xlfn.SWITCH($A$2,"average", AVERAGE(Instances!D5:D5),"median", MEDIAN(Instances!D5:D5),"min", MIN(Instances!D5:D5),"max", MAX(Instances!D5:D5),"diff", MAX(Instances!D5:D5)-MIN(Instances!D5:D5))} -> 106237 | E5: {=_xlfn.SWITCH($A$2,"average", AVERAGE(Instances!E5:E5),"median", MEDIAN(Instances!E5:E5),"min", MIN(Instances!E5:E5),"max", MAX(Instances!E5:E5),"diff", MAX(Instances!E5:E5)-MIN(Instances!E5:E5))} -> 0 | F5: {=_xlfn.SWITCH($A$2,"average", AVERAGE(Instances!F5:F5),"median", MEDIAN(Instances!F5:F5),"min", MIN(Instances!F5:F5),"max", MAX(Instances!F5:F5),"diff", MAX(Instances!F5:F5)-MIN(Instances!F5:F5))} -> 190 | G5: {=_xlfn.SWITCH($A$2,"average", AVERAGE(Instances!G5:G5),"median", MEDIAN(Instances!G5:G5),"min", MIN(Instances!G5:G5),"max", MAX(Instances!G5:G5),"diff", MAX(Instances!G5:G5)-MIN(Instances!G5:G5))} -> 0 | H5: {=_xlfn.SWITCH($A$2,"average", AVERAGE(Instances!H5:H5),"median", MEDIAN(Instances!H5:H5),"min", MIN(Instances!H5:H5),"max", MAX(Instances!H5:H5),"diff", MAX(Instances!H5:H5)-MIN(Instances!H5:H5))} -> 1 | I5: {=_xlfn.SWITCH($A$2,"average", AVERAGE(Instances!I5:I5),"median", MEDIAN(Instances!I5:I5),"min", MIN(Instances!I5:I5),"max", MAX(Instances!I5:I5),"diff", MAX(Instances!I5:I5)-MIN(Instances!I5:I5))} -> 2.548 | ... K5: {=_xlfn.SWITCH($A$2,"average", AVERAGE(Instances!K5:K5),"median", MEDIAN(Instances!K5:K5),"min", MIN(Instances!K5:K5),"max", MAX(Instances!K5:K5),"diff", MAX(Instances!K5:K5)-MIN(Instances!K5:K5))} -> 0 | M5: {=_xlfn.SWITCH($A$2,"average", AVERAGE(Instances!M5:M5),"median", MEDIAN(Instances!M5:M5),"min", MIN(Instances!M5:M5),"max", MAX(Instances!M5:M5),"diff", MAX(Instances!M5:M5)-MIN(Instances!M5:M5))} -> 531500 | N5: {=_xlfn.SWITCH($A$2,"average", AVERAGE(Instances!N5:N5),"median", MEDIAN(Instances!N5:N5),"min", MIN(Instances!N5:N5),"max", MAX(Instances!N5:N5),"diff", MAX(Instances!N5:N5)-MIN(Instances!N5:N5))} -> 0.01 | P5: {=_xlfn.SWITCH($A$2,"average", AVERAGE(Instances!P5:P5),"median", MEDIAN(Instances!P5:P5),"min", MIN(Instances!P5:P5),"max", MAX(Instances!P5:P5),"diff", MAX(Instances!P5:P5)-MIN(Instances!P5:P5))} -> 2.62 | Q5: {=_xlfn.SWITCH($A$2,"average", AVERAGE(Instances!Q5:Q5),"median", MEDIAN(Instances!Q5:Q5),"min", MIN(Instances!Q5:Q5),"max", MAX(Instances!Q5:Q5),"diff", MAX(Instances!Q5:Q5)-MIN(Instances!Q5:Q5))} -> 0 | R5: {=_xlfn.SWITCH($A$2,"average", AVERAGE(Instances!R5:R5),"median", MEDIAN(Instances!R5:R5),"min", MIN(Instances!R5:R5),"max", MAX(Instances!R5:R5),"diff", MAX(Instances!R5:R5)-MIN(Instances!R5:R5))} -> 190873 | S5: =MIN($B5) -> 523 | T5: =MIN($C5) -> 0 | U5: =MIN($D5) -> 106237 | V5: =MIN($E5) -> 0 | W5: =MIN($F5) -> 190 | X5: =MIN($G5) -> 0 | Y5: =MIN($H5) -> 1 | Z5: =MIN($I5) -> 2.548 | AA5: =MIN($J5) -> 2.62 | AB5: =MIN($K5) -> 0 | AC5: =MIN($M5) -> 531500 | AD5: =MIN($N5) -> 0.01 | AE5: =MIN($P5) -> 2.62 | AF5: =MIN($Q5) -> 0 | AG5: =MIN($R5) -> 190873 | AH5: =MEDIAN($B5) -> 523 | AI5: =MEDIAN($C5) -> 0 | AJ5: =MEDIAN($D5) -> 106237 | AK5: =MEDIAN($E5) -> 0 | AL5: =MEDIAN($F5) -> 190 | AM5: =MEDIAN($G5) -> 0 | AN5: =MEDIAN($H5) -> 1 | AO5: =MEDIAN($I5) -> 2.548 | AP5: =MEDIAN($J5) -> 2.62 | AQ5: =MEDIAN($K5) -> 0 | AR5: =MEDIAN($M5) -> 531500 | AS5: =MEDIAN($N5) -> 0.01 | AT5: =MEDIAN($P5) -> 2.62 | AU5: =MEDIAN($Q5) -> 0 | AV5: =MEDIAN($R5) -> 190873 | AW5: =MAX($B5) -> 523 | AX5: =MAX($C5) -> 0 | AY5: =MAX($D5) -> 106237 | AZ5: =MAX($E5) -> 0 | BA5: =MAX($F5) -> 190 | BB5: =MAX($G5) -> 0 | BC5: =MAX($H5) -> 1 | BD5: =MAX($I5) -> 2.548 | BE5: =MAX($J5) -> 2.62 | BF5: =MAX($K5) -> 0 | BG5: =MAX($M5) -> 531500 | BH5: =MAX($N5) -> 0.01 | BI5: =MAX($P5) -> 2.62 | BJ5: =MAX($Q5) -> 0 | BK5: =MAX($R5) -> 190873
A6: Level_0/2-0001010 | B6: {=_xlfn.SWITCH($A$2,"average", AVERAGE(Instances!B6:B6),"median", MEDIAN(Instances!B6:B6),"min", MIN(Instances!B6:B6),"max", MAX(Instances!B6:B6),"diff", MAX(Instances!B6:B6)-MIN(Instances!B6:B6))} -> 1464 | C6: {=_xlfn.SWITCH($A$2,"average", AVERAGE(Instances!C6:C6),"median", MEDIAN(Instances!C6:C6),"min", MIN(Instances!C6:C6),"max", MAX(Instances!C6:C6),"diff", MAX(Instances!C6:C6)-MIN(Instances!C6:C6))} -> 1 | D6: {=_xlfn.SWITCH($A$2,"average", AVERAGE(Instances!D6:D6),"median", MEDIAN(Instances!D6:D6),"min", MIN(Instances!D6:D6),"max", MAX(Instances!D6:D6),"diff", MAX(Instances!D6:D6)-MIN(Instances!D6:D6))} -> 227403 | E6: {=_xlfn.SWITCH($A$2,"average", AVERAGE(Instances!E6:E6),"median", MEDIAN(Instances!E6:E6),"min", MIN(Instances!E6:E6),"max", MAX(Instances!E6:E6),"diff", MAX(Instances!E6:E6)-MIN(Instances!E6:E6))} -> 0 | F6: {=_xlfn.SWITCH($A$2,"average", AVERAGE(Instances!F6:F6),"median", MEDIAN(Instances!F6:F6),"min", MIN(Instances!F6:F6),"max", MAX(Instances!F6:F6),"diff", MAX(Instances!F6:F6)-MIN(Instances!F6:F6))} -> 299 | G6: {=_xlfn.SWITCH($A$2,"average", AVERAGE(Instances!G6:G6),"median", MEDIAN(Instances!G6:G6),"min", MIN(Instances!G6:G6),"max", MAX(Instances!G6:G6),"diff", MAX(Instances!G6:G6)-MIN(Instances!G6:G6))} -> 0 | H6: {=_xlfn.SWITCH($A$2,"average", AVERAGE(Instances!H6:H6),"median", MEDIAN(Instances!H6:H6),"min", MIN(Instances!H6:H6),"max", MAX(Instances!H6:H6),"diff", MAX(Instances!H6:H6)-MIN(Instances!H6:H6))} -> 1 | I6: {=_xlfn.SWITCH($A$2,"average", AVERAGE(Instances!I6:I6),"median", MEDIAN(Instances!I6:I6),"min", MIN(Instances!I6:I6),"max", MAX(Instances!I6:I6),"diff", MAX(Instances!I6:I6)-MIN(Instances!I6:I6))} -> 3.949 | ... K6: {=_xlfn.SWITCH($A$2,"average", AVERAGE(Instances!K6:K6),"median", MEDIAN(Instances!K6:K6),"min", MIN(Instances!K6:K6),"max", MAX(Instances!K6:K6),"diff", MAX(Instances!K6:K6)-MIN(Instances!K6:K6))} -> 0 | M6: {=_xlfn.SWITCH($A$2,"average", AVERAGE(Instances!M6:M6),"median", MEDIAN(Instances!M6:M6),"min", MIN(Instances!M6:M6),"max", MAX(Instances!M6:M6),"diff", MAX(Instances!M6:M6)-MIN(Instances!M6:M6))} -> 861548 | N6: {=_xlfn.SWITCH($A$2,"average", AVERAGE(Instances!N6:N6),"median", MEDIAN(Instances!N6:N6),"min", MIN(Instances!N6:N6),"max", MAX(Instances!N6:N6),"diff", MAX(Instances!N6:N6)-MIN(Instances!N6:N6))} -> 0.03 | P6: {=_xlfn.SWITCH($A$2,"average", AVERAGE(Instances!P6:P6),"median", MEDIAN(Instances!P6:P6),"min", MIN(Instances!P6:P6),"max", MAX(Instances!P6:P6),"diff", MAX(Instances!P6:P6)-MIN(Instances!P6:P6))} -> 4.06 | Q6: {=_xlfn.SWITCH($A$2,"average", AVERAGE(Instances!Q6:Q6),"median", MEDIAN(Instances!Q6:Q6),"min", MIN(Instances!Q6:Q6),"max", MAX(Instances!Q6:Q6),"diff", MAX(Instances!Q6:Q6)-MIN(Instances!Q6:Q6))} -> 0 | R6: {=_xlfn.SWITCH($A$2,"average", AVERAGE(Instances!R6:R6),"median", MEDIAN(Instances!R6:R6),"min", MIN(Instances!R6:R6),"max", MAX(Instances!R6:R6),"diff", MAX(Instances!R6:R6)-MIN(Instances!R6:R6))} -> 306887 | S6: =MIN($B6) -> 1464 | T6: =MIN($C6) -> 1 | U6: =MIN($D6) -> 227403 | V6: =MIN($E6) -> 0 | W6: =MIN($F6) -> 299 | X6: =MIN($G6) -> 0 | Y6: =MIN($H6) -> 1 | Z6: =MIN($I6) -> 3.949 | AA6: =MIN($J6) -> 4.06 | AB6: =MIN($K6) -> 0 | AC6: =MIN($M6) -> 861548 | AD6: =MIN($N6) -> 0.03 | AE6: =MIN($P6) -> 4.06 | AF6: =MIN($Q6) -> 0 | AG6: =MIN($R6) -> 306887 | AH6: =MEDIAN($B6) -> 1464 | AI6: =MEDIAN($C6) -> 1 | AJ6: =MEDIAN($D6) -> 227403 | AK6: =MEDIAN($E6) -> 0 | AL6: =MEDIAN($F6) -> 299 | AM6: =MEDIAN($G6) -> 0 | AN6: =MEDIAN($H6) -> 1 | AO6: =MEDIAN($I6) -> 3.949 | AP6: =MEDIAN($J6) -> 4.06 | AQ6: =MEDIAN($K6) -> 0 | AR6: =MEDIAN($M6) -> 861548 | AS6: =MEDIAN($N6) -> 0.03 | AT6: =MEDIAN($P6) -> 4.06 | AU6: =MEDIAN($Q6) -> 0 | AV6: =MEDIAN($R6) -> 306887 | AW6: =MAX($B6) -> 1464 | AX6: =MAX($C6) -> 1 | AY6: =MAX($D6) -> 227403 | AZ6: =MAX($E6) -> 0 | BA6: =MAX($F6) -> 299 | BB6: =MAX($G6) -> 0 | BC6: =MAX($H6) -> 1 | BD6: =MAX($I6) -> 3.949 | BE6: =MAX($J6) -> 4.06 | BF6: =MAX($K6) -> 0 | BG6: =MAX($M6) -> 861548 | BH6: =MAX($N6) -> 0.03 | BI6: =MAX($P6) -> 4.06 | BJ6: =MAX($Q6) -> 0 | BK6: =MAX($R6) -> 306887
A7: Level_0/2-0001100 | B7: {=_xlfn.SWITCH($A$2,"average", AVERAGE(Instances!B7:B7),"median", MEDIAN(Instances!B7:B7),"min", MIN(Instances!B7:B7),"max", MAX(Instances!B7:B7),"diff", MAX(Instances!B7:B7)-MIN(Instances!B7:B7))} -> 767 | C7: {=_xlfn.SWITCH($A$2,"average", AVERAGE(Instances!C7:C7),"median", MEDIAN(Instances!C7:C7),"min", MIN(Instances!C7:C7),"max", MAX(Instances!C7:C7),"diff", MAX(Instances!C7:C7)-MIN(Instances!C7:C7))} -> 0 | D7: {=_xlfn.SWITCH($A$2,"average", AVERAGE(Instances!D7:D7),"median", MEDIAN(Instances!D7:D7),"min", MIN(Instances!D7:D7),"max", MAX(Instances!D7:D7),"diff", MAX(Instances!D7:D7)-MIN(Instances!D7:D7))} -> 127626 | E7: {=_xlfn.SWITCH($A$2,"average", AVERAGE(Instances!E7:E7),"median", MEDIAN(Instances!E7:E7),"min", MIN(Instances!E7:E7),"max", MAX(Instances!E7:E7),"diff", MAX(Instances!E7:E7)-MIN(Instances!E7:E7))} -> 0 | F7: {=_xlfn.SWITCH($A$2,"average", AVERAGE(Instances!F7:F7),"median", MEDIAN(Instances!F7:F7),"min", MIN(Instances!F7:F7),"max", MAX(Instances!F7:F7),"diff", MAX(Instances!F7:F7)-MIN(Instances!F7:F7))} -> 202 | G7: {=_xlfn.SWITCH($A$2,"average", AVERAGE(Instances!G7:G7),"median", MEDIAN(Instances!G7:G7),"min", MIN(Instances!G7:G7),"max", MAX(Instances!G7:G7),"diff", MAX(Instances!G7:G7)-MIN(Instances!G7:G7))} -> 0 | H7: {=_xlfn.SWITCH($A$2,"average", AVERAGE(Instances!H7:H7),"median", MEDIAN(Instances!H7:H7),"min", MIN(Instances!H7:H7),"max", MAX(Instances!H7:H7),"diff", MAX(Instances!H7:H7)-MIN(Instances!H7:H7))} -> 1 | I7: {=_xlfn.SWITCH($A$2,"average", AVERAGE(Instances!I7:I7),"median", MEDIAN(Instances!I7:I7),"min", MIN(Instances!I7:I7),"max", MAX(Instances!I7:I7),"diff", MAX(Instances!I7:I7)-MIN(Instances!I7:I7))} -> 2.534 | ... K7: {=_xlfn.SWITCH($A$2,"average", AVERAGE(Instances!K7:K7),"median", MEDIAN(Instances!K7:K7),"min", MIN(Instances!K7:K7),"max", MAX(Instances!K7:K7),"diff", MAX(Instances!K7:K7)-MIN(Instances!K7:K7))} -> 0 | M7: {=_xlfn.SWITCH($A$2,"average", AVERAGE(Instances!M7:M7),"median", MEDIAN(Instances!M7:M7),"min", MIN(Instances!M7:M7),"max", MAX(Instances!M7:M7),"diff", MAX(Instances!M7:M7)-MIN(Instances!M7:M7))} -> 525049 | N7: {=_xlfn.SWITCH($A$2,"average", AVERAGE(Instances!N7:N7),"median", MEDIAN(Instances!N7:N7),"min", MIN(Instances!N7:N7),"max", MAX(Instances!N7:N7),"diff", MAX(Instances!N7:N7)-MIN(Instances!N7:N7))} -> 0.01 | P7: {=_xlfn.SWITCH($A$2,"average", AVERAGE(Instances!P7:P7),"median", MEDIAN(Instances!P7:P7),"min", MIN(Instances!P7:P7),"max", MAX(Instances!P7:P7),"diff", MAX(Instances!P7:P7)-MIN(Instances!P7:P7))} -> 2.61 | Q7: {=_xlfn.SWITCH($A$2,"average", AVERAGE(Instances!Q7:Q7),"median", MEDIAN(Instances!Q7:Q7),"min", MIN(Instances!Q7:Q7),"max", MAX(Instances!Q7:Q7),"diff", MAX(Instances!Q7:Q7)-MIN(Instances!Q7:Q7))} -> 0 | R7: {=_xlfn.SWITCH($A$2,"average", AVERAGE(Instances!R7:R7),"median", MEDIAN(Instances!R7:R7),"min", MIN(Instances!R7:R7),"max", MAX(Instances!R7:R7),"diff", MAX(Instances!R7:R7)-MIN(Instances!R7:R7))} -> 198752 | S7: =MIN($B7) -> 767 | T7: =MIN($C7) -> 0 | U7: =MIN($D7) -> 127626 | V7: =MIN($E7) -> 0 | W7: =MIN($F7) -> 202 | X7: =MIN($G7) -> 0 | Y7: =MIN($H7) -> 1 | Z7: =MIN($I7) -> 2.534 | AA7: =MIN($J7) -> 2.61 | AB7: =MIN($K7) -> 0 | AC7: =MIN($M7) -> 525049 | AD7: =MIN($N7) -> 0.01 | AE7: =MIN($P7) -> 2.61 | AF7: =MIN($Q7) -> 0 | AG7: =MIN($R7) -> 198752 | AH7: =MEDIAN($B7) -> 767 | AI7: =MEDIAN($C7) -> 0 | AJ7: =MEDIAN($D7) -> 127626 | AK7: =MEDIAN($E7) -> 0 | AL7: =MEDIAN($F7) -> 202 | AM7: =MEDIAN($G7) -> 0 | AN7: =MEDIAN($H7) -> 1 | AO7: =MEDIAN($I7) -> 2.534 | AP7: =MEDIAN($J7) -> 2.61 | AQ7: =MEDIAN($K7) -> 0 | AR7: =MEDIAN($M7) -> 525049 | AS7: =MEDIAN($N7) -> 0.01 | AT7: =MEDIAN($P7) -> 2.61 | AU7: =MEDIAN($Q7) -> 0 | AV7: =MEDIAN($R7) -> 198752 | AW7: =MAX($B7) -> 767 | AX7: =MAX($C7) -> 0 | AY7: =MAX($D7) -> 127626 | AZ7: =MAX($E7) -> 0 | BA7: =MAX($F7) -> 202 | BB7: =MAX($G7) -> 0 | BC7: =MAX($H7) -> 1 | BD7: =MAX($I7) -> 2.534 | BE7: =MAX($J7) -> 2.61 | BF7: =MAX($K7) -> 0 | BG7: =MAX($M7) -> 525049 | BH7: =MAX($N7) -> 0.01 | BI7: =MAX($P7) -> 2.61 | BJ7: =MAX($Q7) -> 0 | BK7: =MAX($R7) -> 198752
A8: Level_0/2-0100001 | B8: {=_xlfn.SWITCH($A$2,"average", AVERAGE(Instances!B8:B8),"median", MEDIAN(Instances!B8:B8),"min", MIN(Instances!B8:B8),"max", MAX(Instances!B8:B8),"diff", MAX(Instances!B8:B8)-MIN(Instances!B8:B8))} -> 515 | C8: {=_xlfn.SWITCH($A$2,"average", AVERAGE(Instances!C8:C8),"median", MEDIAN(Instances!C8:C8),"min", MIN(Instances!C8:C8),"max", MAX(Instances!C8:C8),"diff", MAX(Instances!C8:C8)-MIN(Instances!C8:C8))} -> 0 | D8: {=_xlfn.SWITCH($A$2,"average", AVERAGE(Instances!D8:D8),"median", MEDIAN(Instances!D8:D8),"min", MIN(Instances!D8:D8),"max", MAX(Instances!D8:D8),"diff", MAX(Instances!D8:D8)-MIN(Instances!D8:D8))} -> 86065 | E8: {=_xlfn.SWITCH($A$2,"average", AVERAGE(Instances!E8:E8),"median", MEDIAN(Instances!E8:E8),"min", MIN(Instances!E8:E8),"max", MAX(Instances!E8:E8),"diff", MAX(Instances!E8:E8)-MIN(Instances!E8:E8))} -> 0 | F8: {=_xlfn.SWITCH($A$2,"average", AVERAGE(Instances!F8:F8),"median", MEDIAN(Instances!F8:F8),"min", MIN(Instances!F8:F8),"max", MAX(Instances!F8:F8),"diff", MAX(Instances!F8:F8)-MIN(Instances!F8:F8))} -> 140 | G8: {=_xlfn.SWITCH($A$2,"average", AVERAGE(Instances!G8:G8),"median", MEDIAN(Instances!G8:G8),"min", MIN(Instances!G8:G8),"max", MAX(Instances!G8:G8),"diff", MAX(Instances!G8:G8)-MIN(Instances!G8:G8))} -> 0 | H8: {=_xlfn.SWITCH($A$2,"average", AVERAGE(Instances!H8:H8),"median", MEDIAN(Instances!H8:H8),"min", MIN(Instances!H8:H8),"max", MAX(Instances!H8:H8),"diff", MAX(Instances!H8:H8)-MIN(Instances!H8:H8))} -> 1 | I8: {=_xlfn.SWITCH($A$2,"average", AVERAGE(Instances!I8:I8),"median", MEDIAN(Instances!I8:I8),"min", MIN(Instances!I8:I8),"max", MAX(Instances!I8:I8),"diff", MAX(Instances!I8:I8)-MIN(Instances!I8:I8))} -> 1.906 | ... K8: {=_xlfn.SWITCH($A$2,"average", AVERAGE(Instances!K8:K8),"median", MEDIAN(Instances!K8:K8),"min", MIN(Instances!K8:K8),"max", MAX(Instances!K8:K8),"diff", MAX(Instances!K8:K8)-MIN(Instances!K8:K8))} -> 0 | M8: {=_xlfn.SWITCH($A$2,"average", AVERAGE(Instances!M8:M8),"median", MEDIAN(Instances!M8:M8),"min", MIN(Instances!M8:M8),"max", MAX(Instances!M8:M8),"diff", MAX(Instances!M8:M8)-MIN(Instances!M8:M8))} -> 395956 | N8: {=_xlfn.SWITCH($A$2,"average", AVERAGE(Instances!N8:N8),"median", MEDIAN(Instances!N8:N8),"min", MIN(Instances!N8:N8),"max", MAX(Instances!N8:N8),"diff", MAX(Instances!N8:N8)-MIN(Instances!N8:N8))} -> 0.01 | P8: {=_xlfn.SWITCH($A$2,"average", AVERAGE(Instances!P8:P8),"median", MEDIAN(Instances!P8:P8),"min", MIN(Instances!P8:P8),"max", MAX(Instances!P8:P8),"diff", MAX(Instances!P8:P8)-MIN(Instances!P8:P8))} -> 1.96 | Q8: {=_xlfn.SWITCH($A$2,"average", AVERAGE(Instances!Q8:Q8),"median", MEDIAN(Instances!Q8:Q8),"min", MIN(Instances!Q8:Q8),"max", MAX(Instances!Q8:Q8),"diff", MAX(Instances!Q8:Q8)-MIN(Instances!Q8:Q8))} -> 0 | R8: {=_xlfn.SWITCH($A$2,"average", AVERAGE(Instances!R8:R8),"median", MEDIAN(Instances!R8:R8),"min", MIN(Instances!R8:R8),"max", MAX(Instances!R8:R8),"diff", MAX(Instances!R8:R8)-MIN(Instances!R8:R8))} -> 143835 | S8: =MIN($B8) -> 515 | T8: =MIN($C8) -> 0 | U8: =MIN($D8) -> 86065 | V8: =MIN($E8) -> 0 | W8: =MIN($F8) -> 140 | X8: =MIN($G8) -> 0 | Y8: =MIN($H8) -> 1 | Z8: =MIN($I8) -> 1.906 | AA8: =MIN($J8) -> 1.96 | AB8: =MIN($K8) -> 0 | AC8: =MIN($M8) -> 395956 | AD8: =MIN($N8) -> 0.01 | AE8: =MIN($P8) -> 1.96 | AF8: =MIN($Q8) -> 0 | AG8: =MIN($R8) -> 143835 | AH8: =MEDIAN($B8) -> 515 | AI8: =MEDIAN($C8) -> 0 | AJ8: =MEDIAN($D8) -> 86065 | AK8: =MEDIAN($E8) -> 0 | AL8: =MEDIAN($F8) -> 140 | AM8: =MEDIAN($G8) -> 0 | AN8: =MEDIAN($H8) -> 1 | AO8: =MEDIAN($I8) -> 1.906 | AP8: =MEDIAN($J8) -> 1.96 | AQ8: =MEDIAN($K8) -> 0 | AR8: =MEDIAN($M8) -> 395956 | AS8: =MEDIAN($N8) -> 0.01 | AT8: =MEDIAN($P8) -> 1.96 | AU8: =MEDIAN($Q8) -> 0 | AV8: =MEDIAN($R8) -> 143835 | AW8: =MAX($B8) -> 515 | AX8: =MAX($C8) -> 0 | AY8: =MAX($D8) -> 86065 | AZ8: =MAX($E8) -> 0 | BA8: =MAX($F8) -> 140 | BB8: =MAX($G8) -> 0 | BC8: =MAX($H8) -> 1 | BD8: =MAX($I8) -> 1.906 | BE8: =MAX($J8) -> 1.96 | BF8: =MAX($K8) -> 0 | BG8: =MAX($M8) -> 395956 | BH8: =MAX($N8) -> 0.01 | BI8: =MAX($P8) -> 1.96 | BJ8: =MAX($Q8) -> 0 | BK8: =MAX($R8) -> 143835
A9: Level_0/2-0100100 | B9: {=_xlfn.SWITCH($A$2,"average", AVERAGE(Instances!B9:B9),"median", MEDIAN(Instances!B9:B9),"min", MIN(Instances!B9:B9),"max", MAX(Instances!B9:B9),"diff", MAX(Instances!B9:B9)-MIN(Instances!B9:B9))} -> 658 | C9: {=_xlfn.SWITCH($A$2,"average", AVERAGE(Instances!C9:C9),"median", MEDIAN(Instances!C9:C9),"min", MIN(Instances!C9:C9),"max", MAX(Instances!C9:C9),"diff", MAX(Instances!C9:C9)-MIN(Instances!C9:C9))} -> 0 | D9: {=_xlfn.SWITCH($A$2,"average", AVERAGE(Instances!D9:D9),"median", MEDIAN(Instances!D9:D9),"min", MIN(Instances!D9:D9),"max", MAX(Instances!D9:D9),"diff", MAX(Instances!D9:D9)-MIN(Instances!D9:D9))} -> 151526 | E9: {=_xlfn.SWITCH($A$2,"average", AVERAGE(Instances!E9:E9),"median", MEDIAN(Instances!E9:E9),"min", MIN(Instances!E9:E9),"max", MAX(Instances!E9:E9),"diff", MAX(Instances!E9:E9)-MIN(Instances!E9:E9))} -> 0 | F9: {=_xlfn.SWITCH($A$2,"average", AVERAGE(Instances!F9:F9),"median", MEDIAN(Instances!F9:F9),"min", MIN(Instances!F9:F9),"max", MAX(Instances!F9:F9),"diff", MAX(Instances!F9:F9)-MIN(Instances!F9:F9))} -> 151 | G9: {=_xlfn.SWITCH($A$2,"average", AVERAGE(Instances!G9:G9),"median", MEDIAN(Instances!G9:G9),"min", MIN(Instances!G9:G9),"max", MAX(Instances!G9:G9),"diff", MAX(Instances!G9:G9)-MIN(Instances!G9:G9))} -> 0 | H9: {=_xlfn.SWITCH($A$2,"average", AVERAGE(Instances!H9:H9),"median", MEDIAN(Instances!H9:H9),"min", MIN(Instances!H9:H9),"max", MAX(Instances!H9:H9),"diff", MAX(Instances!H9:H9)-MIN(Instances!H9:H9))} -> 1 | I9: {=_xlfn.SWITCH($A$2,"average", AVERAGE(Instances!I9:I9),"median", MEDIAN(Instances!I9:I9),"min", MIN(Instances!I9:I9),"max", MAX(Instances!I9:I9),"diff", MAX(Instances!I9:I9)-MIN(Instances!I9:I9))} -> 1.93 | ... K9: {=_xlfn.SWITCH($A$2,"average", AVERAGE(Instances!K9:K9),"median", MEDIAN(Instances!K9:K9),"min", MIN(Instances!K9:K9),"max", MAX(Instances!K9:K9),"diff", MAX(Instances!K9:K9)-MIN(Instances!K9:K9))} -> 0 | M9: {=_xlfn.SWITCH($A$2,"average", AVERAGE(Instances!M9:M9),"median", MEDIAN(Instances!M9:M9),"min", MIN(Instances!M9:M9),"max", MAX(Instances!M9:M9),"diff", MAX(Instances!M9:M9)-MIN(Instances!M9:M9))} -> 410085 | N9: {=_xlfn.SWITCH($A$2,"average", AVERAGE(Instances!N9:N9),"median", MEDIAN(Instances!N9:N9),"min", MIN(Instances!N9:N9),"max", MAX(Instances!N9:N9),"diff", MAX(Instances!N9:N9)-MIN(Instances!N9:N9))} -> 0.01 | P9: {=_xlfn.SWITCH($A$2,"average", AVERAGE(Instances!P9:P9),"median", MEDIAN(Instances!P9:P9),"min", MIN(Instances!P9:P9),"max", MAX(Instances!P9:P9),"diff", MAX(Instances!P9:P9)-MIN(Instances!P9:P9))} -> 1.98 | Q9: {=_xlfn.SWITCH($A$2,"average", AVERAGE(Instances!Q9:Q9),"median", MEDIAN(Instances!Q9:Q9),"min", MIN(Instances!Q9:Q9),"max", MAX(Instances!Q9:Q9),"diff", MAX(Instances!Q9:Q9)-MIN(Instances!Q9:Q9))} -> 0 | R9: {=_xlfn.SWITCH($A$2,"average", AVERAGE(Instances!R9:R9),"median", MEDIAN(Instances!R9:R9),"min", MIN(Instances!R9:R9),"max", MAX(Instances!R9:R9),"diff", MAX(Instances!R9:R9)-MIN(Instances!R9:R9))} -> 150890 | S9: =MIN($B9) -> 658 | T9: =MIN($C9) -> 0 | U9: =MIN($D9) -> 151526 | V9: =MIN($E9) -> 0 | W9: =MIN($F9) -> 151 | X9: =MIN($G9) -> 0 | Y9: =MIN($H9) -> 1 | Z9: =MIN($I9) -> 1.93 | AA9: =MIN($J9) -> 1.98 | AB9: =MIN($K9) -> 0 | AC9: =MIN($M9) -> 410085 | AD9: =MIN($N9) -> 0.01 | AE9: =MIN($P9) -> 1.98 | AF9: =MIN($Q9) -> 0 | AG9: =MIN($R9) -> 150890 | AH9: =MEDIAN($B9) -> 658 | AI9: =MEDIAN($C9) -> 0 | AJ9: =MEDIAN($D9) -> 151526 | AK9: =MEDIAN($E9) -> 0 | AL9: =MEDIAN($F9) -> 151 | AM9: =MEDIAN($G9) -> 0 | AN9: =MEDIAN($H9) -> 1 | AO9: =MEDIAN($I9) -> 1.93 | AP9: =MEDIAN($J9) -> 1.98 | AQ9: =MEDIAN($K9) -> 0 | AR9: =MEDIAN($M9) -> 410085 | AS9: =MEDIAN($N9) -> 0.01 | AT9: =MEDIAN($P9) -> 1.98 | AU9: =MEDIAN($Q9) -> 0 | AV9: =MEDIAN($R9) -> 150890 | AW9: =MAX($B9) -> 658 | AX9: =MAX($C9) -> 0 | AY9: =MAX($D9) -> 151526 | AZ9: =MAX($E9) -> 0 | BA9: =MAX($F9) -> 151 | BB9: =MAX($G9) -> 0 | BC9: =MAX($H9) -> 1 | BD9: =MAX($I9) -> 1.93 | BE9: =MAX($J9) -> 1.98 | BF9: =MAX($K9) -> 0 | BG9: =MAX($M9) -> 410085 | BH9: =MAX($N9) -> 0.01 | BI9: =MAX($P9) -> 1.98 | BJ9: =MAX($Q9) -> 0 | BK9: =MAX($R9) -> 150890
A10: Level_0/3-0001101 | B10: {=_xlfn.SWITCH($A$2,"average", AVERAGE(Instances!B10:B10),"median", MEDIAN(Instances!B10:B10),"min", MIN(Instances!B10:B10),"max", MAX(Instances!B10:B10),"diff", MAX(Instances!B10:B10)-MIN(Instances!B10:B10))} -> 1095 | C10: {=_xlfn.SWITCH($A$2,"average", AVERAGE(Instances!C10:C10),"median", MEDIAN(Instances!C10:C10),"min", MIN(Instances!C10:C10),"max", MAX(Instances!C10:C10),"diff", MAX(Instances!C10:C10)-MIN(Instances!C10:C10))} -> 0 | D10: {=_xlfn.SWITCH($A$2,"average", AVERAGE(Instances!D10:D10),"median", MEDIAN(Instances!D10:D10),"min", MIN(Instances!D10:D10),"max", MAX(Instances!D10:D10),"diff", MAX(Instances!D10:D10)-MIN(Instances!D10:D10))} -> 199280 | E10: {=_xlfn.SWITCH($A$2,"average", AVERAGE(Instances!E10:E10),"median", MEDIAN(Instances!E10:E10),"min", MIN(Instances!E10:E10),"max", MAX(Instances!E10:E10),"diff", MAX(Instances!E10:E10)-MIN(Instances!E10:E10))} -> 0 | F10: {=_xlfn.SWITCH($A$2,"average", AVERAGE(Instances!F10:F10),"median", MEDIAN(Instances!F10:F10),"min", MIN(Instances!F10:F10),"max", MAX(Instances!F10:F10),"diff", MAX(Instances!F10:F10)-MIN(Instances!F10:F10))} -> 318 | G10: {=_xlfn.SWITCH($A$2,"average", AVERAGE(Instances!G10:G10),"median", MEDIAN(Instances!G10:G10),"min", MIN(Instances!G10:G10),"max", MAX(Instances!G10:G10),"diff", MAX(Instances!G10:G10)-MIN(Instances!G10:G10))} -> 0 | H10: {=_xlfn.SWITCH($A$2,"average", AVERAGE(Instances!H10:H10),"median", MEDIAN(Instances!H10:H10),"min", MIN(Instances!H10:H10),"max", MAX(Instances!H10:H10),"diff", MAX(Instances!H10:H10)-MIN(Instances!H10:H10))} -> 1 | I10: {=_xlfn.SWITCH($A$2,"average", AVERAGE(Instances!I10:I10),"median", MEDIAN(Instances!I10:I10),"min", MIN(Instances!I10:I10),"max", MAX(Instances!I10:I10),"diff", MAX(Instances!I10:I10)-MIN(Instances!I10:I10))} -> 4.314 | ... K10: {=_xlfn.SWITCH($A$2,"average", AVERAGE(Instances!K10:K10),"median", MEDIAN(Instances!K10:K10),"min", MIN(Instances!K10:K10),"max", MAX(Instances!K10:K10),"diff", MAX(Instances!K10:K10)-MIN(Instances!K10:K10))} -> 0 | M10: {=_xlfn.SWITCH($A$2,"average", AVERAGE(Instances!M10:M10),"median", MEDIAN(Instances!M10:M10),"min", MIN(Instances!M10:M10),"max", MAX(Instances!M10:M10),"diff", MAX(Instances!M10:M10)-MIN(Instances!M10:M10))} -> 933041 | N10: {=_xlfn.SWITCH($A$2,"average", AVERAGE(Instances!N10:N10),"median", MEDIAN(Instances!N10:N10),"min", MIN(Instances!N10:N10),"max", MAX(Instances!N10:N10),"diff", MAX(Instances!N10:N10)-MIN(Instances!N10:N10))} -> 0.02 | P10: {=_xlfn.SWITCH($A$2,"average", AVERAGE(Instances!P10:P10),"median", MEDIAN(Instances!P10:P10),"min", MIN(Instances!P10:P10),"max", MAX(Instances!P10:P10),"diff", MAX(Instances!P10:P10)-MIN(Instances!P10:P10))} -> 4.43 | Q10: {=_xlfn.SWITCH($A$2,"average", AVERAGE(Instances!Q10:Q10),"median", MEDIAN(Instances!Q10:Q10),"min", MIN(Instances!Q10:Q10),"max", MAX(Instances!Q10:Q10),"diff", MAX(Instances!Q10:Q10)-MIN(Instances!Q10:Q10))} -> 0 | R10: {=_xlfn.SWITCH($A$2,"average", AVERAGE(Instances!R10:R10),"median", MEDIAN(Instances!R10:R10),"min", MIN(Instances!R10:R10),"max", MAX(Instances!R10:R10),"diff", MAX(Instances!R10:R10)-MIN(Instances!R10:R10))} -> 318496 | S10: =MIN($B10) -> 1095 | T10: =MIN($C10) -> 0 | U10: =MIN($D10) -> 199280 | V10: =MIN($E10) -> 0 | W10: =MIN($F10) -> 318 | X10: =MIN($G10) -> 0 | Y10: =MIN($H10) -> 1 | Z10: =MIN($I10) -> 4.314 | AA10: =MIN($J10) -> 4.43 | AB10: =MIN($K10) -> 0 | AC10: =MIN($M10) -> 933041 | AD10: =MIN($N10) -> 0.02 | AE10: =MIN($P10) -> 4.43 | AF10: =MIN($Q10) -> 0 | AG10: =MIN($R10) -> 318496 | AH10: =MEDIAN($B10) -> 1095 | AI10: =MEDIAN($C10) -> 0 | AJ10: =MEDIAN($D10) -> 199280 | AK10: =MEDIAN($E10) -> 0 | AL10: =MEDIAN($F10) -> 318 | AM10: =MEDIAN($G10) -> 0 | AN10: =MEDIAN($H10) -> 1 | AO10: =MEDIAN($I10) -> 4.314 | AP10: =MEDIAN($J10) -> 4.43 | AQ10: =MEDIAN($K10) -> 0 | AR10: =MEDIAN($M10) -> 933041 | AS10: =MEDIAN($N10) -> 0.02 | AT10: =MEDIAN($P10) -> 4.43 | AU10: =MEDIAN($Q10) -> 0 | AV10: =MEDIAN($R10) -> 318496 | AW10: =MAX($B10) -> 1095 | AX10: =MAX($C10) -> 0 | AY10: =MAX($D10) -> 199280 | AZ10: =MAX($E10) -> 0 | BA10: =MAX($F10) -> 318 | BB10: =MAX($G10) -> 0 | BC10: =MAX($H10) -> 1 | BD10: =MAX($I10) -> 4.314 | BE10: =MAX($J10) -> 4.43 | BF10: =MAX($K10) -> 0 | BG10: =MAX($M10) -> 933041 | BH10: =MAX($N10) -> 0.02 | BI10: =MAX($P10) -> 4.43 | BJ10: =MAX($Q10) -> 0 | BK10: =MAX($R10) -> 318496
A11: Level_0/3-0001110 | B11: {=_xlfn.SWITCH($A$2,"average", AVERAGE(Instances!B11:B11),"median", MEDIAN(Instances!B11:B11),"min", MIN(Instances!B11:B11),"max", MAX(Instances!B11:B11),"diff", MAX(Instances!B11:B11)-MIN(Instances!B11:B11))} -> 1145 | C11: {=_xlfn.SWITCH($A$2,"average", AVERAGE(Instances!C11:C11),"median", MEDIAN(Instances!C11:C11),"min", MIN(Instances!C11:C11),"max", MAX(Instances!C11:C11),"diff", MAX(Instances!C11:C11)-MIN(Instances!C11:C11))} -> 0 | D11: {=_xlfn.SWITCH($A$2,"average", AVERAGE(Instances!D11:D11),"median", MEDIAN(Instances!D11:D11),"min", MIN(Instances!D11:D11),"max", MAX(Instances!D11:D11),"diff", MAX(Instances!D11:D11)-MIN(Instances!D11:D11))} -> 242876 | E11: {=_xlfn.SWITCH($A$2,"average", AVERAGE(Instances!E11:E11),"median", MEDIAN(Instances!E11:E11),"min", MIN(Instances!E11:E11),"max", MAX(Instances!E11:E11),"diff", MAX(Instances!E11:E11)-MIN(Instances!E11:E11))} -> 0 | F11: {=_xlfn.SWITCH($A$2,"average", AVERAGE(Instances!F11:F11),"median", MEDIAN(Instances!F11:F11),"min", MIN(Instances!F11:F11),"max", MAX(Instances!F11:F11),"diff", MAX(Instances!F11:F11)-MIN(Instances!F11:F11))} -> 367 | G11: {=_xlfn.SWITCH($A$2,"average", AVERAGE(Instances!G11:G11),"median", MEDIAN(Instances!G11:G11),"min", MIN(Instances!G11:G11),"max", MAX(Instances!G11:G11),"diff", MAX(Instances!G11:G11)-MIN(Instances!G11:G11))} -> 0 | H11: {=_xlfn.SWITCH($A$2,"average", AVERAGE(Instances!H11:H11),"median", MEDIAN(Instances!H11:H11),"min", MIN(Instances!H11:H11),"max", MAX(Instances!H11:H11),"diff", MAX(Instances!H11:H11)-MIN(Instances!H11:H11))} -> 1 | I11: {=_xlfn.SWITCH($A$2,"average", AVERAGE(Instances!I11:I11),"median", MEDIAN(Instances!I11:I11),"min", MIN(Instances!I11:I11),"max", MAX(Instances!I11:I11),"diff", MAX(Instances!I11:I11)-MIN(Instances!I11:I11))} -> 4.916 | ... K11: {=_xlfn.SWITCH($A$2,"average", AVERAGE(Instances!K11:K11),"median", MEDIAN(Instances!K11:K11),"min", MIN(Instances!K11:K11),"max", MAX(Instances!K11:K11),"diff", MAX(Instances!K11:K11)-MIN(Instances!K11:K11))} -> 0 | M11: {=_xlfn.SWITCH($A$2,"average", AVERAGE(Instances!M11:M11),"median", MEDIAN(Instances!M11:M11),"min", MIN(Instances!M11:M11),"max", MAX(Instances!M11:M11),"diff", MAX(Instances!M11:M11)-MIN(Instances!M11:M11))} -> 1078748 | N11: {=_xlfn.SWITCH($A$2,"average", AVERAGE(Instances!N11:N11),"median", MEDIAN(Instances!N11:N11),"min", MIN(Instances!N11:N11),"max", MAX(Instances!N11:N11),"diff", MAX(Instances!N11:N11)-MIN(Instances!N11:N11))} -> 0.03 | P11: {=_xlfn.SWITCH($A$2,"average", AVERAGE(Instances!P11:P11),"median", MEDIAN(Instances!P11:P11),"min", MIN(Instances!P11:P11),"max", MAX(Instances!P11:P11),"diff", MAX(Instances!P11:P11)-MIN(Instances!P11:P11))} -> 5.05 | Q11: {=_xlfn.SWITCH($A$2,"average", AVERAGE(Instances!Q11:Q11),"median", MEDIAN(Instances!Q11:Q11),"min", MIN(Instances!Q11:Q11),"max", MAX(Instances!Q11:Q11),"diff", MAX(Instances!Q11:Q11)-MIN(Instances!Q11:Q11))} -> 0 | R11: {=_xlfn.SWITCH($A$2,"average", AVERAGE(Instances!R11:R11),"median", MEDIAN(Instances!R11:R11),"min", MIN(Instances!R11:R11),"max", MAX(Instances!R11:R11),"diff", MAX(Instances!R11:R11)-MIN(Instances!R11:R11))} -> 365407 | S11: =MIN($B11) -> 1145 | T11: =MIN($C11) -> 0 | U11: =MIN($D11) -> 242876 | V11: =MIN($E11) -> 0 | W11: =MIN($F11) -> 367 | X11: =MIN($G11) -> 0 | Y11: =MIN($H11) -> 1 | Z11: =MIN($I11) -> 4.916 | AA11: =MIN($J11) -> 5.05 | AB11: =MIN($K11) -> 0 | AC11: =MIN($M11) -> 1078748 | AD11: =MIN($N11) -> 0.03 | AE11: =MIN($P11) -> 5.05 | AF11: =MIN($Q11) -> 0 | AG11: =MIN($R11) -> 365407 | AH11: =MEDIAN($B11) -> 1145 | AI11: =MEDIAN($C11) -> 0 | AJ11: =MEDIAN($D11) -> 242876 | AK11: =MEDIAN($E11) -> 0 | AL11: =MEDIAN($F11) -> 367 | AM11: =MEDIAN($G11) -> 0 | AN11: =MEDIAN($H11) -> 1 | AO11: =MEDIAN($I11) -> 4.916 | AP11: =MEDIAN($J11) -> 5.05 | AQ11: =MEDIAN($K11) -> 0 | AR11: =MEDIAN($M11) -> 1078748 | AS11: =MEDIAN($N11) -> 0.03 | AT11: =MEDIAN($P11) -> 5.05 | AU11: =MEDIAN($Q11) -> 0 | AV11: =MEDIAN($R11) -> 365407 | AW11: =MAX($B11) -> 1145 | AX11: =MAX($C11) -> 0 | AY11: =MAX($D11) -> 242876 | AZ11: =MAX($E11) -> 0 | BA11: =MAX($F11) -> 367 | BB11: =MAX($G11) -> 0 | BC11: =MAX($H11) -> 1 | BD11: =MAX($I11) -> 4.916 | BE11: =MAX($J11) -> 5.05 | BF11: =MAX($K11) -> 0 | BG11: =MAX($M11) -> 1078748 | BH11: =MAX($N11) -> 0.03 | BI11: =MAX($P11) -> 5.05 | BJ11: =MAX($Q11) -> 0 | BK11: =MAX($R11) -> 365407
A12: Level_0/3-0101001 | B12: {=_xlfn.SWITCH($A$2,"average", AVERAGE(Instances!B12:B12),"median", MEDIAN(Instances!B12:B12),"min", MIN(Instances!B12:B12),"max", MAX(Instances!B12:B12),"diff", MAX(Instances!B12:B12)-MIN(Instances!B12:B12))} -> 621 | C12: {=_xlfn.SWITCH($A$2,"average", AVERAGE(Instances!C12:C12),"median", MEDIAN(Instances!C12:C12),"min", MIN(Instances!C12:C12),"max", MAX(Instances!C12:C12),"diff", MAX(Instances!C12:C12)-MIN(Instances!C12:C12))} -> 0 | D12: {=_xlfn.SWITCH($A$2,"average", AVERAGE(Instances!D12:D12),"median", MEDIAN(Instances!D12:D12),"min", MIN(Instances!D12:D12),"max", MAX(Instances!D12:D12),"diff", MAX(Instances!D12:D12)-MIN(Instances!D12:D12))} -> 135579 | E12: {=_xlfn.SWITCH($A$2,"average", AVERAGE(Instances!E12:E12),"median", MEDIAN(Instances!E12:E12),"min", MIN(Instances!E12:E12),"max", MAX(Instances!E12:E12),"diff", MAX(Instances!E12:E12)-MIN(Instances!E12:E12))} -> 0 | F12: {=_xlfn.SWITCH($A$2,"average", AVERAGE(Instances!F12:F12),"median", MEDIAN(Instances!F12:F12),"min", MIN(Instances!F12:F12),"max", MAX(Instances!F12:F12),"diff", MAX(Instances!F12:F12)-MIN(Instances!F12:F12))} -> 245 | G12: {=_xlfn.SWITCH($A$2,"average", AVERAGE(Instances!G12:G12),"median", MEDIAN(Instances!G12:G12),"min", MIN(Instances!G12:G12),"max", MAX(Instances!G12:G12),"diff", MAX(Instances!G12:G12)-MIN(Instances!G12:G12))} -> 0 | H12: {=_xlfn.SWITCH($A$2,"average", AVERAGE(Instances!H12:H12),"median", MEDIAN(Instances!H12:H12),"min", MIN(Instances!H12:H12),"max", MAX(Instances!H12:H12),"diff", MAX(Instances!H12:H12)-MIN(Instances!H12:H12))} -> 1 | I12: {=_xlfn.SWITCH($A$2,"average", AVERAGE(Instances!I12:I12),"median", MEDIAN(Instances!I12:I12),"min", MIN(Instances!I12:I12),"max", MAX(Instances!I12:I12),"diff", MAX(Instances!I12:I12)-MIN(Instances!I12:I12))} -> 3.269 | ... K12: {=_xlfn.SWITCH($A$2,"average", AVERAGE(Instances!K12:K12),"median", MEDIAN(Instances!K12:K12),"min", MIN(Instances!K12:K12),"max", MAX(Instances!K12:K12),"diff", MAX(Instances!K12:K12)-MIN(Instances!K12:K12))} -> 0 | M12: {=_xlfn.SWITCH($A$2,"average", AVERAGE(Instances!M12:M12),"median", MEDIAN(Instances!M12:M12),"min", MIN(Instances!M12:M12),"max", MAX(Instances!M12:M12),"diff", MAX(Instances!M12:M12)-MIN(Instances!M12:M12))} -> 726092 | N12: {=_xlfn.SWITCH($A$2,"average", AVERAGE(Instances!N12:N12),"median", MEDIAN(Instances!N12:N12),"min", MIN(Instances!N12:N12),"max", MAX(Instances!N12:N12),"diff", MAX(Instances!N12:N12)-MIN(Instances!N12:N12))} -> 0.02 | P12: {=_xlfn.SWITCH($A$2,"average", AVERAGE(Instances!P12:P12),"median", MEDIAN(Instances!P12:P12),"min", MIN(Instances!P12:P12),"max", MAX(Instances!P12:P12),"diff", MAX(Instances!P12:P12)-MIN(Instances!P12:P12))} -> 3.43 | Q12: {=_xlfn.SWITCH($A$2,"average", AVERAGE(Instances!Q12:Q12),"median", MEDIAN(Instances!Q12:Q12),"min", MIN(Instances!Q12:Q12),"max", MAX(Instances!Q12:Q12),"diff", MAX(Instances!Q12:Q12)-MIN(Instances!Q12:Q12))} -> 0 | R12: {=_xlfn.SWITCH($A$2,"average", AVERAGE(Instances!R12:R12),"median", MEDIAN(Instances!R12:R12),"min", MIN(Instances!R12:R12),"max", MAX(Instances!R12:R12),"diff", MAX(Instances!R12:R12)-MIN(Instances!R12:R12))} -> 242780 | S12: =MIN($B12) -> 621 | T12: =MIN($C12) -> 0 | U12: =MIN($D12) -> 135579 | V12: =MIN($E12) -> 0 | W12: =MIN($F12) -> 245 | X12: =MIN($G12) -> 0 | Y12: =MIN($H12) -> 1 | Z12: =MIN($I12) -> 3.269 | AA12: =MIN($J12) -> 3.43 | AB12: =MIN($K12) -> 0 | AC12: =MIN($M12) -> 726092 | AD12: =MIN($N12) -> 0.02 | AE12: =MIN($P12) -> 3.43 | AF12: =MIN($Q12) -> 0 | AG12: =MIN($R12) -> 242780 | AH12: =MEDIAN($B12) -> 621 | AI12: =MEDIAN($C12) -> 0 | AJ12: =MEDIAN($D12) -> 135579 | AK12: =MEDIAN($E12) -> 0 | AL12: =MEDIAN($F12) -> 245 | AM12: =MEDIAN($G12) -> 0 | AN12: =MEDIAN($H12) -> 1 | AO12: =MEDIAN($I12) -> 3.269 | AP12: =MEDIAN($J12) -> 3.43 | AQ12: =MEDIAN($K12) -> 0 | AR12: =MEDIAN($M12) -> 726092 | AS12: =MEDIAN($N12) -> 0.02 | AT12: =MEDIAN($P12) -> 3.43 | AU12: =MEDIAN($Q12) -> 0 | AV12: =MEDIAN($R12) -> 242780 | AW12: =MAX($B12) -> 621 | AX12: =MAX($C12) -> 0 | AY12: =MAX($D12) -> 135579 | AZ12: =MAX($E12) -> 0 | BA12: =MAX($F12) -> 245 | BB12: =MAX($G12) -> 0 | BC12: =MAX($H12) -> 1 | BD12: =MAX($I12) -> 3.269 | BE12: =MAX($J12) -> 3.43 | BF12: =MAX($K12) -> 0 | BG12: =MAX($M12) -> 726092 | BH12: =MAX($N12) -> 0.02 | BI12: =MAX($P12) -> 3.43 | BJ12: =MAX($Q12) -> 0 | BK12: =MAX($R12) -> 242780
A13: Level_0/3-1011000 | B13: {=_xlfn.SWITCH($A$2,"average", AVERAGE(Instances!B13:B13),"median", MEDIAN(Instances!B13:B13),"min", MIN(Instances!B13:B13),"max", MAX(Instances!B13:B13),"diff", MAX(Instances!B13:B13)-MIN(Instances!B13:B13))} -> 1152 | C13: {=_xlfn.SWITCH($A$2,"average", AVERAGE(Instances!C13:C13),"median", MEDIAN(Instances!C13:C13),"min", MIN(Instances!C13:C13),"max", MAX(Instances!C13:C13),"diff", MAX(Instances!C13:C13)-MIN(Instances!C13:C13))} -> 0 | D13: {=_xlfn.SWITCH($A$2,"average", AVERAGE(Instances!D13:D13),"median", MEDIAN(Instances!D13:D13),"min", MIN(Instances!D13:D13),"max", MAX(Instances!D13:D13),"diff", MAX(Instances!D13:D13)-MIN(Instances!D13:D13))} -> 337701 | E13: {=_xlfn.SWITCH($A$2,"average", AVERAGE(Instances!E13:E13),"median", MEDIAN(Instances!E13:E13),"min", MIN(Instances!E13:E13),"max", MAX(Instances!E13:E13),"diff", MAX(Instances!E13:E13)-MIN(Instances!E13:E13))} -> 0 | F13: {=_xlfn.SWITCH($A$2,"average", AVERAGE(Instances!F13:F13),"median", MEDIAN(Instances!F13:F13),"min", MIN(Instances!F13:F13),"max", MAX(Instances!F13:F13),"diff", MAX(Instances!F13:F13)-MIN(Instances!F13:F13))} -> 458 | G13: {=_xlfn.SWITCH($A$2,"average", AVERAGE(Instances!G13:G13),"median", MEDIAN(Instances!G13:G13),"min", MIN(Instances!G13:G13),"max", MAX(Instances!G13:G13),"diff", MAX(Instances!G13:G13)-MIN(Instances!G13:G13))} -> 0 | H13: {=_xlfn.SWITCH($A$2,"average", AVERAGE(Instances!H13:H13),"median", MEDIAN(Instances!H13:H13),"min", MIN(Instances!H13:H13),"max", MAX(Instances!H13:H13),"diff", MAX(Instances!H13:H13)-MIN(Instances!H13:H13))} -> 1 | I13: {=_xlfn.SWITCH($A$2,"average", AVERAGE(Instances!I13:I13),"median", MEDIAN(Instances!I13:I13),"min", MIN(Instances!I13:I13),"max", MAX(Instances!I13:I13),"diff", MAX(Instances!I13:I13)-MIN(Instances!I13:I13))} -> 6.324 | ... K13: {=_xlfn.SWITCH($A$2,"average", AVERAGE(Instances!K13:K13),"median", MEDIAN(Instances!K13:K13),"min", MIN(Instances!K13:K13),"max", MAX(Instances!K13:K13),"diff", MAX(Instances!K13:K13)-MIN(Instances!K13:K13))} -> 0 | M13: {=_xlfn.SWITCH($A$2,"average", AVERAGE(Instances!M13:M13),"median", MEDIAN(Instances!M13:M13),"min", MIN(Instances!M13:M13),"max", MAX(Instances!M13:M13),"diff", MAX(Instances!M13:M13)-MIN(Instances!M13:M13))} -> 1412233 | N13: {=_xlfn.SWITCH($A$2,"average", AVERAGE(Instances!N13:N13),"median", MEDIAN(Instances!N13:N13),"min", MIN(Instances!N13:N13),"max", MAX(Instances!N13:N13),"diff", MAX(Instances!N13:N13)-MIN(Instances!N13:N13))} -> 0.04 | P13: {=_xlfn.SWITCH($A$2,"average", AVERAGE(Instances!P13:P13),"median", MEDIAN(Instances!P13:P13),"min", MIN(Instances!P13:P13),"max", MAX(Instances!P13:P13),"diff", MAX(Instances!P13:P13)-MIN(Instances!P13:P13))} -> 6.49 | Q13: {=_xlfn.SWITCH($A$2,"average", AVERAGE(Instances!Q13:Q13),"median", MEDIAN(Instances!Q13:Q13),"min", MIN(Instances!Q13:Q13),"max", MAX(Instances!Q13:Q13),"diff", MAX(Instances!Q13:Q13)-MIN(Instances!Q13:Q13))} -> 0 | R13: {=_xlfn.SWITCH($A$2,"average", AVERAGE(Instances!R13:R13),"median", MEDIAN(Instances!R13:R13),"min", MIN(Instances!R13:R13),"max", MAX(Instances!R13:R13),"diff", MAX(Instances!R13:R13)-MIN(Instances!R13:R13))} -> 456718 | S13: =MIN($B13) -> 1152 | T13: =MIN($C13) -> 0 | U13: =MIN($D13) -> 337701 | V13: =MIN($E13) -> 0 | W13: =MIN($F13) -> 458 | X13: =MIN($G13) -> 0 | Y13: =MIN($H13) -> 1 | Z13: =MIN($I13) -> 6.324 | AA13: =MIN($J13) -> 6.49 | AB13: =MIN($K13) -> 0 | AC13: =MIN($M13) -> 1412233 | AD13: =MIN($N13) -> 0.04 | AE13: =MIN($P13) -> 6.49 | AF13: =MIN($Q13) -> 0 | AG13: =MIN($R13) -> 456718 | AH13: =MEDIAN($B13) -> 1152 | AI13: =MEDIAN($C13) -> 0 | AJ13: =MEDIAN($D13) -> 337701 | AK13: =MEDIAN($E13) -> 0 | AL13: =MEDIAN($F13) -> 458 | AM13: =MEDIAN($G13) -> 0 | AN13: =MEDIAN($H13) -> 1 | AO13: =MEDIAN($I13) -> 6.324 | AP13: =MEDIAN($J13) -> 6.49 | AQ13: =MEDIAN($K13) -> 0 | AR13: =MEDIAN($M13) -> 1412233 | AS13: =MEDIAN($N13) -> 0.04 | AT13: =MEDIAN($P13) -> 6.49 | AU13: =MEDIAN($Q13) -> 0 | AV13: =MEDIAN($R13) -> 456718 | AW13: =MAX($B13) -> 1152 | AX13: =MAX($C13) -> 0 | AY13: =MAX($D13) -> 337701 | AZ13: =MAX($E13) -> 0 | BA13: =MAX($F13) -> 458 | BB13: =MAX($G13) -> 0 | BC13: =MAX($H13) -> 1 | BD13: =MAX($I13) -> 6.324 | BE13: =MAX($J13) -> 6.49 | BF13: =MAX($K13) -> 0 | BG13: =MAX($M13) -> 1412233 | BH13: =MAX($N13) -> 0.04 | BI13: =MAX($P13) -> 6.49 | BJ13: =MAX($Q13) -> 0 | BK13: =MAX($R13) -> 456718
