Workbook

Sheet torsten-full
C1: MAPF
A2: trains | B2: instances | C2: grounding | D2: global | E2: timeouts | F2: rules | G2: variables | H2: constraints
A3: 2 | B3: 70 | C3: 3.0722714 | D3: 8.9388429 | E3: 0 | F3: 801516.01 | G3: 298687.54 | H3: 767748.01
A4: 3 | B4: 70 | C4: 4.4996857 | D4: 81.091971 | E4: 0 | F4: 1189087.6 | G4: 427171.29 | H4: 1130506.9
A5: 4 | B5: 70 | C5: 6.0040429 | D5: 483.93604 | E5: 8 | F5: 1600793.6 | G5: 547377.56 | H5: 1484530
A6: 5 | B6: 70 | C6: 7.5078 | D6: 1069.2141 | E6: 31 | F6: 2011069.8 | G6: 644632.44 | H6: 1774884.8
A7: 6 | B7: 70 | C7: 9.3255 | D7: 1378.0986 | E7: 56 | F7: 2462364.3 | G7: 755469.03 | H7: 2118716.2
A8: 7 | B8: 10 | C8: 10.3695 | D8: 1500.0055 | E8: 10 | F8: 2486712.8 | G8: 845792.5 | H8: 2223014
C10: drive-map-edge-functions
A11: trains | B11: instances | C11: grounding | D11: global | E11: timeouts | F11: rules | G11: variables | H11: constraints
A12: 2 | B12: 70 | C12: 10.000743 | D12: 15.641314 | E12: 0 | F12: 3020970.5 | G12: 1091278.1 | H12: 5218774.2
A13: 3 | B13: 70 | C13: 17.583543 | D13: 54.621543 | E13: 0 | F13: 4956314.8 | G13: 1869342 | H13: 8975610.1
A14: 4 | B14: 70 | C14: 25.271771 | D14: 246.72306 | E14: 2 | F14: 6953861.1 | G14: 2690112.6 | H14: 12838514
A15: 5 | B15: 70 | C15: 32.499557 | D15: 527.98784 | E15: 14 | F15: 8661939 | G15: 3294762.8 | H15: 15816693
A16: 6 | B16: 70 | C16: 40.404914 | D16: 829.43663 | E16: 29 | F16: 10568134 | G16: 4045741.8 | H16: 19431036
A17: 7 | B17: 10 | C17: 47.4136 | D17: 950.6386 | E17: 6 | F17: 12280008 | G17: 4745241.7 | H17: 22704465
C19: drive-map-subnodes
A20: trains | B20: instances | C20: grounding | D20: global | E20: timeouts | F20: rules | G20: variables | H20: constraints
A21: 2 | B21: 70 | C21: 2.6108571 | D21: 3.0971429 | E21: 0 | F21: 524526.33 | G21: 441113 | H21: 1592668.3
A22: 3 | B22: 70 | C22: 4.2572714 | D22: 6.1957 | E22: 0 | F22: 884535.6 | G22: 744848.04 | H22: 2722272.1
A23: 4 | B23: 70 | C23: 6.1961 | D23: 49.048529 | E23: 0 | F23: 1295830.1 | G23: 1084734.9 | H23: 4026163.8
A24: 5 | B24: 70 | C24: 7.8511571 | D24: 165.03987 | E24: 2 | F24: 1634663.5 | G24: 1354134.2 | H24: 5055473.1
A25: 6 | B25: 70 | C25: 9.5979857 | D25: 330.95613 | E25: 9 | F25: 2004184 | G25: 1633916.9 | H25: 6138409.4
A26: 7 | B26: 10 | C26: 11.4207 | D26: 694.0527 | E26: 4 | F26: 2284295.1 | G26: 1914095.5 | H26: 7141526.3
C28: drive-map-hypergraph
A29: trains | B29: instances | C29: grounding | D29: global | E29: timeouts | F29: rules | G29: variables | H29: constraints
A30: 2 | B30: 70 | C30: 9.4373714 | D30: 14.191371 | E30: 0 | F30: 2558790.9 | G30: 979289.84 | H30: 4273248.2
A31: 3 | B31: 70 | C31: 15.916929 | D31: 53.312786 | E31: 0 | F31: 4259748.9 | G31: 1710945.5 | H31: 7468507.8
A32: 4 | B32: 70 | C32: 22.922529 | D32: 242.80839 | E32: 1 | F32: 5945828.4 | G32: 2442968.6 | H32: 10685375
A33: 5 | B33: 70 | C33: 29.168286 | D33: 660.29971 | E33: 19 | F33: 7424659.5 | G33: 2999246.3 | H33: 13176417
A34: 6 | B34: 70 | C34: 36.190514 | D34: 826.85694 | E34: 32 | F34: 9058220.1 | G34: 3678640.8 | H34: 16200769
A35: 7 | B35: 10 | C35: 42.3793 | D35: 1084.6923 | E35: 6 | F35: 10534561 | G35: 4320872.4 | H35: 18945501
C37: clingo-dl
A38: trains | B38: instances | C38: grounding | D38: global | E38: timeouts | F38: rules | G38: variables | H38: constraints
A39: 2 | B39: 70 | C39: 2.0976714 | D39: 2.1719571 | E39: 0 | F39: 377044.01 | G39: 287745.4 | H39: 1001913.2
A40: 3 | B40: 70 | C40: 6.1814143 | D40: 6.6189857 | E40: 0 | F40: 1163337.7 | G40: 938139.51 | H40: 3313619.7
A41: 4 | B41: 70 | C41: 13.070929 | D41: 13.709929 | E41: 0 | F41: 2402399.2 | G41: 1973697.9 | H41: 7014289.2
A42: 5 | B42: 70 | C42: 22.375286 | D42: 23.588 | E42: 0 | F42: 4031384.1 | G42: 3356750.2 | H42: 11966142
A43: 6 | B43: 70 | C43: 34.290486 | D43: 36.592486 | E43: 0 | F43: 6023328 | G43: 5020314.9 | H43: 17905315
A44: 7 | B44: 10 | C44: 49.4721 | D44: 51.9971 | E44: 0 | F44: 8436900.9 | G44: 7051733.3 | H44: 25170500

Sheet torsten-half
C1: MAPF
A2: trains | B2: instances | C2: grounding | D2: global | E2: timeouts
A3: 2 | B3: 70 | C3: 3.0722714 | D3: 8.9388429 | E3: 0
A4: 3 | B4: 70 | C4: 4.4996857 | D4: 81.091971 | E4: 0
A5: 4 | B5: 70 | C5: 6.0040429 | D5: 483.93604 | E5: 8
A6: 5 | B6: 70 | C6: 7.5078 | D6: 1069.2141 | E6: 31
A7: 6 | B7: 70 | C7: 9.3255 | D7: 1378.0986 | E7: 56
A8: 7 | B8: 10 | C8: 10.3695 | D8: 1500.0055 | E8: 10
C10: drive-map-edge-functions
A11: trains | B11: instances | C11: grounding | D11: global | E11: timeouts
A12: 2 | B12: 70 | C12: 10.000743 | D12: 15.641314 | E12: 0
A13: 3 | B13: 70 | C13: 17.583543 | D13: 54.621543 | E13: 0
A14: 4 | B14: 70 | C14: 25.271771 | D14: 246.72306 | E14: 2
A15: 5 | B15: 70 | C15: 32.499557 | D15: 527.98784 | E15: 14
A16: 6 | B16: 70 | C16: 40.404914 | D16: 829.43663 | E16: 29
A17: 7 | B17: 10 | C17: 47.4136 | D17: 950.6386 | E17: 6
C19: drive-map-subnodes
A20: trains | B20: instances | C20: grounding | D20: global | E20: timeouts
A21: 2 | B21: 70 | C21: 2.6108571 | D21: 3.0971429 | E21: 0
A22: 3 | B22: 70 | C22: 4.2572714 | D22: 6.1957 | E22: 0
A23: 4 | B23: 70 | C23: 6.1961 | D23: 49.048529 | E23: 0
A24: 5 | B24: 70 | C24: 7.8511571 | D24: 165.03987 | E24: 2
A25: 6 | B25: 70 | C25: 9.5979857 | D25: 330.95613 | E25: 9
A26: 7 | B26: 10 | C26: 11.4207 | D26: 694.0527 | E26: 4
C28: drive-map-hypergraph
A29: trains | B29: instances | C29: grounding | D29: global | E29: timeouts
A30: 2 | B30: 70 | C30: 9.4373714 | D30: 14.191371 | E30: 0
A31: 3 | B31: 70 | C31: 15.916929 | D31: 53.312786 | E31: 0
A32: 4 | B32: 70 | C32: 22.922529 | D32: 242.80839 | E32: 1
A33: 5 | B33: 70 | C33: 29.168286 | D33: 660.29971 | E33: 19
A34: 6 | B34: 70 | C34: 36.190514 | D34: 826.85694 | E34: 32
A35: 7 | B35: 10 | C35: 42.3793 | D35: 1084.6923 | E35: 6
C37: clingo-dl
A38: trains | B38: instances | C38: grounding | D38: global | E38: timeouts
A39: 2 | B39: 70 | C39: 2.0976714 | D39: 2.1719571 | E39: 0
A40: 3 | B40: 70 | C40: 6.1814143 | D40: 6.6189857 | E40: 0
A41: 4 | B41: 70 | C41: 13.070929 | D41: 13.709929 | E41: 0
A42: 5 | B42: 70 | C42: 22.375286 | D42: 23.588 | E42: 0
A43: 6 | B43: 70 | C43: 34.290486 | D43: 36.592486 | E43: 0
A44: 7 | B44: 10 | C44: 49.4721 | D44: 51.9971 | E44: 0

Sheet Helper
A2: choices | B2: 1 | E2: =VLOOKUP(Charts!$F$3,A2:B16,2,FALSE) -> #REF! | K2: =E2 -> #REF! | Q2: =VLOOKUP(Charts!$F$3,A2:B16,2,FALSE) -> #REF!
A3: conflicts | B3: 2 | D3: data | E3: =#REF! -> #REF! | J3: data | K3: =E3 -> #REF! | Q3: =#REF! -> #REF!
A4: constraints | B4: 3 | D4: index | E4: values | F4: sorted | H4: aggregated | J4: index | K4: values | L4: sorted | N4: aggregated | P4: plot | Q4: index | R4: sorted | S4: index | T4: aggregated
A5: error | B5: 4 | D5: 1 | E5: =IF(INDIRECT(ADDRESS($D5+2,E$2+1,,,"Instances"))="","",INDIRECT(ADDRESS($D5+2,E$2+1,,,"Instances"))) -> #REF! | F5: =IFERROR(SMALL(E5:E364,ROW()-ROW($F$5)+1),"") | H5: =IFERROR(SUM(F5),"") -> 0 | J5: 1 | K5: {=SWITCH(Charts!$B$3,"average", AVERAGE(INDIRECT(ADDRESS(0+3,K$2+1,,,"Instances") & ":" & ADDRESS(0+3,K$2+1))),"median", MEDIAN(INDIRECT(ADDRESS(0+3,K$2+1,,,"Instances") & ":" & ADDRESS(0+3,K$2+1))),"min", MIN(INDIRECT(ADDRESS(0+3,K$2+1,,,"Instances") & ":" & ADDRESS(0+3,K$2+1))),"max", MAX(INDIRECT(ADDRESS(0+3,K$2+1,,,"Instances") & ":" & ADDRESS(0+3,K$2+1))),"diff", MAX(INDIRECT(ADDRESS(0+3,K$2+1,,,"Instances") & ":" & ADDRESS(0+3,K$2+1)))-MIN(INDIRECT(ADDRESS(0+3,K$2+1,,,"Instances") & ":" & ADDRESS(0+3,K$2+1))))} -> #REF! | L5: =IFERROR(SMALL(K5:K364,ROW()-ROW($L$5)+1),"") | N5: =IFERROR(SUM(L5),"") -> 0 | Q5: =IF(Charts!$B$3="none",E1812,IF(K1812="",NA(),K1812)) -> #REF! | R5: =IF(Charts!$B$3="none",F1812,IF(L1812="",NA(),L1812)) -> #REF! | S5: =IF(Charts!$B$3="none",G1812,IF(M1812="",NA(),M1812)) -> #REF! | T5: =IF(Charts!$B$3="none",H1812,IF(N1812="",NA(),N1812)) -> #REF!
A6: mem | B6: 5 | D6: 2 | E6: =IF(INDIRECT(ADDRESS($D6+2,E$2+1,,,"Instances"))="","",INDIRECT(ADDRESS($D6+2,E$2+1,,,"Instances"))) -> #REF! | F6: =IFERROR(SMALL(E5:E364,ROW()-ROW($F$5)+1),"") | H6: =IFERROR(SUM(F5:F6),"") -> 0 | J6: 2 | K6: {=SWITCH(Charts!$B$3,"average", AVERAGE(INDIRECT(ADDRESS(1+3,K$2+1,,,"Instances") & ":" & ADDRESS(1+3,K$2+1))),"median", MEDIAN(INDIRECT(ADDRESS(1+3,K$2+1,,,"Instances") & ":" & ADDRESS(1+3,K$2+1))),"min", MIN(INDIRECT(ADDRESS(1+3,K$2+1,,,"Instances") & ":" & ADDRESS(1+3,K$2+1))),"max", MAX(INDIRECT(ADDRESS(1+3,K$2+1,,,"Instances") & ":" & ADDRESS(1+3,K$2+1))),"diff", MAX(INDIRECT(ADDRESS(1+3,K$2+1,,,"Instances") & ":" & ADDRESS(1+3,K$2+1)))-MIN(INDIRECT(ADDRESS(1+3,K$2+1,,,"Instances") & ":" & ADDRESS(1+3,K$2+1))))} -> #REF! | L6: =IFERROR(SMALL(K5:K364,ROW()-ROW($L$5)+1),"") | N6: =IFERROR(SUM(L5:L6),"") -> 0 | Q6: =IF(Charts!$B$3="none",E1813,IF(K1813="",NA(),K1813)) -> #REF! | R6: =IF(Charts!$B$3="none",F1813,IF(L1813="",NA(),L1813)) -> #REF! | S6: =IF(Charts!$B$3="none",G1813,IF(M1813="",NA(),M1813)) -> #REF! | T6: =IF(Charts!$B$3="none",H1813,IF(N1813="",NA(),N1813)) -> #REF!
A7: memout | B7: 6 | D7: 3 | E7: =IF(INDIRECT(ADDRESS($D7+2,E$2+1,,,"Instances"))="","",INDIRECT(ADDRESS($D7+2,E$2+1,,,"Instances"))) -> #REF! | F7: =IFERROR(SMALL(E5:E364,ROW()-ROW($F$5)+1),"") | H7: =IFERROR(SUM(F5:F7),"") -> 0 | J7: 3 | K7: {=SWITCH(Charts!$B$3,"average", AVERAGE(INDIRECT(ADDRESS(2+3,K$2+1,,,"Instances") & ":" & ADDRESS(2+3,K$2+1))),"median", MEDIAN(INDIRECT(ADDRESS(2+3,K$2+1,,,"Instances") & ":" & ADDRESS(2+3,K$2+1))),"min", MIN(INDIRECT(ADDRESS(2+3,K$2+1,,,"Instances") & ":" & ADDRESS(2+3,K$2+1))),"max", MAX(INDIRECT(ADDRESS(2+3,K$2+1,,,"Instances") & ":" & ADDRESS(2+3,K$2+1))),"diff", MAX(INDIRECT(ADDRESS(2+3,K$2+1,,,"Instances") & ":" & ADDRESS(2+3,K$2+1)))-MIN(INDIRECT(ADDRESS(2+3,K$2+1,,,"Instances") & ":" & ADDRESS(2+3,K$2+1))))} -> #REF! | L7: =IFERROR(SMALL(K5:K364,ROW()-ROW($L$5)+1),"") | N7: =IFERROR(SUM(L5:L7),"") -> 0 | Q7: =IF(Charts!$B$3="none",E1814,IF(K1814="",NA(),K1814)) -> #REF! | R7: =IF(Charts!$B$3="none",F1814,IF(L1814="",NA(),L1814)) -> #REF! | S7: =IF(Charts!$B$3="none",G1814,IF(M1814="",NA(),M1814)) -> #REF! | T7: =IF(Charts!$B$3="none",H1814,IF(N1814="",NA(),N1814)) -> #REF!
A8: models | B8: 7 | D8: 4 | E8: =IF(INDIRECT(ADDRESS($D8+2,E$2+1,,,"Instances"))="","",INDIRECT(ADDRESS($D8+2,E$2+1,,,"Instances"))) -> #REF! | F8: =IFERROR(SMALL(E5:E364,ROW()-ROW($F$5)+1),"") | H8: =IFERROR(SUM(F5:F8),"") -> 0 | J8: 4 | K8: {=SWITCH(Charts!$B$3,"average", AVERAGE(INDIRECT(ADDRESS(3+3,K$2+1,,,"Instances") & ":" & ADDRESS(3+3,K$2+1))),"median", MEDIAN(INDIRECT(ADDRESS(3+3,K$2+1,,,"Instances") & ":" & ADDRESS(3+3,K$2+1))),"min", MIN(INDIRECT(ADDRESS(3+3,K$2+1,,,"Instances") & ":" & ADDRESS(3+3,K$2+1))),"max", MAX(INDIRECT(ADDRESS(3+3,K$2+1,,,"Instances") & ":" & ADDRESS(3+3,K$2+1))),"diff", MAX(INDIRECT(ADDRESS(3+3,K$2+1,,,"Instances") & ":" & ADDRESS(3+3,K$2+1)))-MIN(INDIRECT(ADDRESS(3+3,K$2+1,,,"Instances") & ":" & ADDRESS(3+3,K$2+1))))} -> #REF! | L8: =IFERROR(SMALL(K5:K364,ROW()-ROW($L$5)+1),"") | N8: =IFERROR(SUM(L5:L8),"") -> 0 | Q8: =IF(Charts!$B$3="none",E1815,IF(K1815="",NA(),K1815)) -> #REF! | R8: =IF(Charts!$B$3="none",F1815,IF(L1815="",NA(),L1815)) -> #REF! | S8: =IF(Charts!$B$3="none",G1815,IF(M1815="",NA(),M1815)) -> #REF! | T8: =IF(Charts!$B$3="none",H1815,IF(N1815="",NA(),N1815)) -> #REF!
A9: overall-time | B9: 8 | D9: 5 | E9: =IF(INDIRECT(ADDRESS($D9+2,E$2+1,,,"Instances"))="","",INDIRECT(ADDRESS($D9+2,E$2+1,,,"Instances"))) -> #REF! | F9: =IFERROR(SMALL(E5:E364,ROW()-ROW($F$5)+1),"") | H9: =IFERROR(SUM(F5:F9),"") -> 0 | J9: 5 | K9: {=SWITCH(Charts!$B$3,"average", AVERAGE(INDIRECT(ADDRESS(4+3,K$2+1,,,"Instances") & ":" & ADDRESS(4+3,K$2+1))),"median", MEDIAN(INDIRECT(ADDRESS(4+3,K$2+1,,,"Instances") & ":" & ADDRESS(4+3,K$2+1))),"min", MIN(INDIRECT(ADDRESS(4+3,K$2+1,,,"Instances") & ":" & ADDRESS(4+3,K$2+1))),"max", MAX(INDIRECT(ADDRESS(4+3,K$2+1,,,"Instances") & ":" & ADDRESS(4+3,K$2+1))),"diff", MAX(INDIRECT(ADDRESS(4+3,K$2+1,,,"Instances") & ":" & ADDRESS(4+3,K$2+1)))-MIN(INDIRECT(ADDRESS(4+3,K$2+1,,,"Instances") & ":" & ADDRESS(4+3,K$2+1))))} -> #REF! | L9: =IFERROR(SMALL(K5:K364,ROW()-ROW($L$5)+1),"") | N9: =IFERROR(SUM(L5:L9),"") -> 0 | Q9: =IF(Charts!$B$3="none",E1816,IF(K1816="",NA(),K1816)) -> #REF! | R9: =IF(Charts!$B$3="none",F1816,IF(L1816="",NA(),L1816)) -> #REF! | S9: =IF(Charts!$B$3="none",G1816,IF(M1816="",NA(),M1816)) -> #REF! | T9: =IF(Charts!$B$3="none",H1816,IF(N1816="",NA(),N1816)) -> #REF!
A10: par2 | B10: 9 | D10: 6 | E10: =IF(INDIRECT(ADDRESS($D10+2,E$2+1,,,"Instances"))="","",INDIRECT(ADDRESS($D10+2,E$2+1,,,"Instances"))) -> #REF! | F10: =IFERROR(SMALL(E5:E364,ROW()-ROW($F$5)+1),"") | H10: =IFERROR(SUM(F5:F10),"") -> 0 | J10: 6 | K10: {=SWITCH(Charts!$B$3,"average", AVERAGE(INDIRECT(ADDRESS(5+3,K$2+1,,,"Instances") & ":" & ADDRESS(5+3,K$2+1))),"median", MEDIAN(INDIRECT(ADDRESS(5+3,K$2+1,,,"Instances") & ":" & ADDRESS(5+3,K$2+1))),"min", MIN(INDIRECT(ADDRESS(5+3,K$2+1,,,"Instances") & ":" & ADDRESS(5+3,K$2+1))),"max", MAX(INDIRECT(ADDRESS(5+3,K$2+1,,,"Instances") & ":" & ADDRESS(5+3,K$2+1))),"diff", MAX(INDIRECT(ADDRESS(5+3,K$2+1,,,"Instances") & ":" & ADDRESS(5+3,K$2+1)))-MIN(INDIRECT(ADDRESS(5+3,K$2+1,,,"Instances") & ":" & ADDRESS(5+3,K$2+1))))} -> #REF! | L10: =IFERROR(SMALL(K5:K364,ROW()-ROW($L$5)+1),"") | N10: =IFERROR(SUM(L5:L10),"") -> 0 | Q10: =IF(Charts!$B$3="none",E1817,IF(K1817="",NA(),K1817)) -> #REF! | R10: =IF(Charts!$B$3="none",F1817,IF(L1817="",NA(),L1817)) -> #REF! | S10: =IF(Charts!$B$3="none",G1817,IF(M1817="",NA(),M1817)) -> #REF! | T10: =IF(Charts!$B$3="none",H1817,IF(N1817="",NA(),N1817)) -> #REF!
A11: restarts | B11: 10 | D11: 7 | E11: =IF(INDIRECT(ADDRESS($D11+2,E$2+1,,,"Instances"))="","",INDIRECT(ADDRESS($D11+2,E$2+1,,,"Instances"))) -> #REF! | F11: =IFERROR(SMALL(E5:E364,ROW()-ROW($F$5)+1),"") | H11: =IFERROR(SUM(F5:F11),"") -> 0 | J11: 7 | K11: {=SWITCH(Charts!$B$3,"average", AVERAGE(INDIRECT(ADDRESS(6+3,K$2+1,,,"Instances") & ":" & ADDRESS(6+3,K$2+1))),"median", MEDIAN(INDIRECT(ADDRESS(6+3,K$2+1,,,"Instances") & ":" & ADDRESS(6+3,K$2+1))),"min", MIN(INDIRECT(ADDRESS(6+3,K$2+1,,,"Instances") & ":" & ADDRESS(6+3,K$2+1))),"max", MAX(INDIRECT(ADDRESS(6+3,K$2+1,,,"Instances") & ":" & ADDRESS(6+3,K$2+1))),"diff", MAX(INDIRECT(ADDRESS(6+3,K$2+1,,,"Instances") & ":" & ADDRESS(6+3,K$2+1)))-MIN(INDIRECT(ADDRESS(6+3,K$2+1,,,"Instances") & ":" & ADDRESS(6+3,K$2+1))))} -> #REF! | L11: =IFERROR(SMALL(K5:K364,ROW()-ROW($L$5)+1),"") | N11: =IFERROR(SUM(L5:L11),"") -> 0 | Q11: =IF(Charts!$B$3="none",E1818,IF(K1818="",NA(),K1818)) -> #REF! | R11: =IF(Charts!$B$3="none",F1818,IF(L1818="",NA(),L1818)) -> #REF! | S11: =IF(Charts!$B$3="none",G1818,IF(M1818="",NA(),M1818)) -> #REF! | T11: =IF(Charts!$B$3="none",H1818,IF(N1818="",NA(),N1818)) -> #REF!
A12: rules | B12: 12 | D12: 8 | E12: =IF(INDIRECT(ADDRESS($D12+2,E$2+1,,,"Instances"))="","",INDIRECT(ADDRESS($D12+2,E$2+1,,,"Instances"))) -> #REF! | F12: =IFERROR(SMALL(E5:E364,ROW()-ROW($F$5)+1),"") | H12: =IFERROR(SUM(F5:F12),"") -> 0 | J12: 8 | K12: {=SWITCH(Charts!$B$3,"average", AVERAGE(INDIRECT(ADDRESS(7+3,K$2+1,,,"Instances") & ":" & ADDRESS(7+3,K$2+1))),"median", MEDIAN(INDIRECT(ADDRESS(7+3,K$2+1,,,"Instances") & ":" & ADDRESS(7+3,K$2+1))),"min", MIN(INDIRECT(ADDRESS(7+3,K$2+1,,,"Instances") & ":" & ADDRESS(7+3,K$2+1))),"max", MAX(INDIRECT(ADDRESS(7+3,K$2+1,,,"Instances") & ":" & ADDRESS(7+3,K$2+1))),"diff", MAX(INDIRECT(ADDRESS(7+3,K$2+1,,,"Instances") & ":" & ADDRESS(7+3,K$2+1)))-MIN(INDIRECT(ADDRESS(7+3,K$2+1,,,"Instances") & ":" & ADDRESS(7+3,K$2+1))))} -> #REF! | L12: =IFERROR(SMALL(K5:K364,ROW()-ROW($L$5)+1),"") | N12: =IFERROR(SUM(L5:L12),"") -> 0 | Q12: =IF(Charts!$B$3="none",E1819,IF(K1819="",NA(),K1819)) -> #REF! | R12: =IF(Charts!$B$3="none",F1819,IF(L1819="",NA(),L1819)) -> #REF! | S12: =IF(Charts!$B$3="none",G1819,IF(M1819="",NA(),M1819)) -> #REF! | T12: =IF(Charts!$B$3="none",H1819,IF(N1819="",NA(),N1819)) -> #REF!
A13: solving-time | B13: 13 | D13: 9 | E13: =IF(INDIRECT(ADDRESS($D13+2,E$2+1,,,"Instances"))="","",INDIRECT(ADDRESS($D13+2,E$2+1,,,"Instances"))) -> #REF! | F13: =IFERROR(SMALL(E5:E364,ROW()-ROW($F$5)+1),"") | H13: =IFERROR(SUM(F5:F13),"") -> 0 | J13: 9 | K13: {=SWITCH(Charts!$B$3,"average", AVERAGE(INDIRECT(ADDRESS(8+3,K$2+1,,,"Instances") & ":" & ADDRESS(8+3,K$2+1))),"median", MEDIAN(INDIRECT(ADDRESS(8+3,K$2+1,,,"Instances") & ":" & ADDRESS(8+3,K$2+1))),"min", MIN(INDIRECT(ADDRESS(8+3,K$2+1,,,"Instances") & ":" & ADDRESS(8+3,K$2+1))),"max", MAX(INDIRECT(ADDRESS(8+3,K$2+1,,,"Instances") & ":" & ADDRESS(8+3,K$2+1))),"diff", MAX(INDIRECT(ADDRESS(8+3,K$2+1,,,"Instances") & ":" & ADDRESS(8+3,K$2+1)))-MIN(INDIRECT(ADDRESS(8+3,K$2+1,,,"Instances") & ":" & ADDRESS(8+3,K$2+1))))} -> #REF! | L13: =IFERROR(SMALL(K5:K364,ROW()-ROW($L$5)+1),"") | N13: =IFERROR(SUM(L5:L13),"") -> 0 | Q13: =IF(Charts!$B$3="none",E1820,IF(K1820="",NA(),K1820)) -> #REF! | R13: =IF(Charts!$B$3="none",F1820,IF(L1820="",NA(),L1820)) -> #REF! | S13: =IF(Charts!$B$3="none",G1820,IF(M1820="",NA(),M1820)) -> #REF! | T13: =IF(Charts!$B$3="none",H1820,IF(N1820="",NA(),N1820)) -> #REF!
A14: time | B14: 15 | D14: 10 | E14: =IF(INDIRECT(ADDRESS($D14+2,E$2+1,,,"Instances"))="","",INDIRECT(ADDRESS($D14+2,E$2+1,,,"Instances"))) -> #REF! | F14: =IFERROR(SMALL(E5:E364,ROW()-ROW($F$5)+1),"") | H14: =IFERROR(SUM(F5:F14),"") -> 0 | J14: 10 | K14: {=SWITCH(Charts!$B$3,"average", AVERAGE(INDIRECT(ADDRESS(9+3,K$2+1,,,"Instances") & ":" & ADDRESS(9+3,K$2+1))),"median", MEDIAN(INDIRECT(ADDRESS(9+3,K$2+1,,,"Instances") & ":" & ADDRESS(9+3,K$2+1))),"min", MIN(INDIRECT(ADDRESS(9+3,K$2+1,,,"Instances") & ":" & ADDRESS(9+3,K$2+1))),"max", MAX(INDIRECT(ADDRESS(9+3,K$2+1,,,"Instances") & ":" & ADDRESS(9+3,K$2+1))),"diff", MAX(INDIRECT(ADDRESS(9+3,K$2+1,,,"Instances") & ":" & ADDRESS(9+3,K$2+1)))-MIN(INDIRECT(ADDRESS(9+3,K$2+1,,,"Instances") & ":" & ADDRESS(9+3,K$2+1))))} -> #REF! | L14: =IFERROR(SMALL(K5:K364,ROW()-ROW($L$5)+1),"") | N14: =IFERROR(SUM(L5:L14),"") -> 0 | Q14: =IF(Charts!$B$3="none",E1821,IF(K1821="",NA(),K1821)) -> #REF! | R14: =IF(Charts!$B$3="none",F1821,IF(L1821="",NA(),L1821)) -> #REF! | S14: =IF(Charts!$B$3="none",G1821,IF(M1821="",NA(),M1821)) -> #REF! | T14: =IF(Charts!$B$3="none",H1821,IF(N1821="",NA(),N1821)) -> #REF!
A15: timeout | B15: 16 | D15: 11 | E15: =IF(INDIRECT(ADDRESS($D15+2,E$2+1,,,"Instances"))="","",INDIRECT(ADDRESS($D15+2,E$2+1,,,"Instances"))) -> #REF! | F15: =IFERROR(SMALL(E5:E364,ROW()-ROW($F$5)+1),"") | H15: =IFERROR(SUM(F5:F15),"") -> 0 | J15: 11 | K15: {=SWITCH(Charts!$B$3,"average", AVERAGE(INDIRECT(ADDRESS(10+3,K$2+1,,,"Instances") & ":" & ADDRESS(10+3,K$2+1))),"median", MEDIAN(INDIRECT(ADDRESS(10+3,K$2+1,,,"Instances") & ":" & ADDRESS(10+3,K$2+1))),"min", MIN(INDIRECT(ADDRESS(10+3,K$2+1,,,"Instances") & ":" & ADDRESS(10+3,K$2+1))),"max", MAX(INDIRECT(ADDRESS(10+3,K$2+1,,,"Instances") & ":" & ADDRESS(10+3,K$2+1))),"diff", MAX(INDIRECT(ADDRESS(10+3,K$2+1,,,"Instances") & ":" & ADDRESS(10+3,K$2+1)))-MIN(INDIRECT(ADDRESS(10+3,K$2+1,,,"Instances") & ":" & ADDRESS(10+3,K$2+1))))} -> #REF! | L15: =IFERROR(SMALL(K5:K364,ROW()-ROW($L$5)+1),"") | N15: =IFERROR(SUM(L5:L15),"") -> 0 | Q15: =IF(Charts!$B$3="none",E1822,IF(K1822="",NA(),K1822)) -> #REF! | R15: =IF(Charts!$B$3="none",F1822,IF(L1822="",NA(),L1822)) -> #REF! | S15: =IF(Charts!$B$3="none",G1822,IF(M1822="",NA(),M1822)) -> #REF! | T15: =IF(Charts!$B$3="none",H1822,IF(N1822="",NA(),N1822)) -> #REF!
A16: variables | B16: 17 | D16: 12 | E16: =IF(INDIRECT(ADDRESS($D16+2,E$2+1,,,"Instances"))="","",INDIRECT(ADDRESS($D16+2,E$2+1,,,"Instances"))) -> #REF! | F16: =IFERROR(SMALL(E5:E364,ROW()-ROW($F$5)+1),"") | H16: =IFERROR(SUM(F5:F16),"") -> 0 | J16: 12 | K16: {=SWITCH(Charts!$B$3,"average", AVERAGE(INDIRECT(ADDRESS(11+3,K$2+1,,,"Instances") & ":" & ADDRESS(11+3,K$2+1))),"median", MEDIAN(INDIRECT(ADDRESS(11+3,K$2+1,,,"Instances") & ":" & ADDRESS(11+3,K$2+1))),"min", MIN(INDIRECT(ADDRESS(11+3,K$2+1,,,"Instances") & ":" & ADDRESS(11+3,K$2+1))),"max", MAX(INDIRECT(ADDRESS(11+3,K$2+1,,,"Instances") & ":" & ADDRESS(11+3,K$2+1))),"diff", MAX(INDIRECT(ADDRESS(11+3,K$2+1,,,"Instances") & ":" & ADDRESS(11+3,K$2+1)))-MIN(INDIRECT(ADDRESS(11+3,K$2+1,,,"Instances") & ":" & ADDRESS(11+3,K$2+1))))} -> #REF! | L16: =IFERROR(SMALL(K5:K364,ROW()-ROW($L$5)+1),"") | N16: =IFERROR(SUM(L5:L16),"") -> 0 | Q16: =IF(Charts!$B$3="none",E1823,IF(K1823="",NA(),K1823)) -> #REF! | R16: =IF(Charts!$B$3="none",F1823,IF(L1823="",NA(),L1823)) -> #REF! | S16: =IF(Charts!$B$3="none",G1823,IF(M1823="",NA(),M1823)) -> #REF! | T16: =IF(Charts!$B$3="none",H1823,IF(N1823="",NA(),N1823)) -> #REF!
D17: 13 | E17: =IF(INDIRECT(ADDRESS($D17+2,E$2+1,,,"Instances"))="","",INDIRECT(ADDRESS($D17+2,E$2+1,,,"Instances"))) -> #REF! | F17: =IFERROR(SMALL(E5:E364,ROW()-ROW($F$5)+1),"") | H17: =IFERROR(SUM(F5:F17),"") -> 0 | J17: 13 | K17: {=SWITCH(Charts!$B$3,"average", AVERAGE(INDIRECT(ADDRESS(12+3,K$2+1,,,"Instances") & ":" & ADDRESS(12+3,K$2+1))),"median", MEDIAN(INDIRECT(ADDRESS(12+3,K$2+1,,,"Instances") & ":" & ADDRESS(12+3,K$2+1))),"min", MIN(INDIRECT(ADDRESS(12+3,K$2+1,,,"Instances") & ":" & ADDRESS(12+3,K$2+1))),"max", MAX(INDIRECT(ADDRESS(12+3,K$2+1,,,"Instances") & ":" & ADDRESS(12+3,K$2+1))),"diff", MAX(INDIRECT(ADDRESS(12+3,K$2+1,,,"Instances") & ":" & ADDRESS(12+3,K$2+1)))-MIN(INDIRECT(ADDRESS(12+3,K$2+1,,,"Instances") & ":" & ADDRESS(12+3,K$2+1))))} -> #REF! | L17: =IFERROR(SMALL(K5:K364,ROW()-ROW($L$5)+1),"") | N17: =IFERROR(SUM(L5:L17),"") -> 0 | Q17: =IF(Charts!$B$3="none",E1824,IF(K1824="",NA(),K1824)) -> #REF! | R17: =IF(Charts!$B$3="none",F1824,IF(L1824="",NA(),L1824)) -> #REF! | S17: =IF(Charts!$B$3="none",G1824,IF(M1824="",NA(),M1824)) -> #REF! | T17: =IF(Charts!$B$3="none",H1824,IF(N1824="",NA(),N1824)) -> #REF!
D18: 14 | E18: =IF(INDIRECT(ADDRESS($D18+2,E$2+1,,,"Instances"))="","",INDIRECT(ADDRESS($D18+2,E$2+1,,,"Instances"))) -> #REF! | F18: =IFERROR(SMALL(E5:E364,ROW()-ROW($F$5)+1),"") | H18: =IFERROR(SUM(F5:F18),"") -> 0 | J18: 14 | K18: {=SWITCH(Charts!$B$3,"average", AVERAGE(INDIRECT(ADDRESS(13+3,K$2+1,,,"Instances") & ":" & ADDRESS(13+3,K$2+1))),"median", MEDIAN(INDIRECT(ADDRESS(13+3,K$2+1,,,"Instances") & ":" & ADDRESS(13+3,K$2+1))),"min", MIN(INDIRECT(ADDRESS(13+3,K$2+1,,,"Instances") & ":" & ADDRESS(13+3,K$2+1))),"max", MAX(INDIRECT(ADDRESS(13+3,K$2+1,,,"Instances") & ":" & ADDRESS(13+3,K$2+1))),"diff", MAX(INDIRECT(ADDRESS(13+3,K$2+1,,,"Instances") & ":" & ADDRESS(13+3,K$2+1)))-MIN(INDIRECT(ADDRESS(13+3,K$2+1,,,"Instances") & ":" & ADDRESS(13+3,K$2+1))))} -> #REF! | L18: =IFERROR(SMALL(K5:K364,ROW()-ROW($L$5)+1),"") | N18: =IFERROR(SUM(L5:L18),"") -> 0 | Q18: =IF(Charts!$B$3="none",E1825,IF(K1825="",NA(),K1825)) -> #REF! | R18: =IF(Charts!$B$3="none",F1825,IF(L1825="",NA(),L1825)) -> #REF! | S18: =IF(Charts!$B$3="none",G1825,IF(M1825="",NA(),M1825)) -> #REF! | T18: =IF(Charts!$B$3="none",H1825,IF(N1825="",NA(),N1825)) -> #REF!
D19: 15 | E19: =IF(INDIRECT(ADDRESS($D19+2,E$2+1,,,"Instances"))="","",INDIRECT(ADDRESS($D19+2,E$2+1,,,"Instances"))) -> #REF! | F19: =IFERROR(SMALL(E5:E364,ROW()-ROW($F$5)+1),"") | H19: =IFERROR(SUM(F5:F19),"") -> 0 | J19: 15 | K19: {=SWITCH(Charts!$B$3,"average", AVERAGE(INDIRECT(ADDRESS(14+3,K$2+1,,,"Instances") & ":" & ADDRESS(14+3,K$2+1))),"median", MEDIAN(INDIRECT(ADDRESS(14+3,K$2+1,,,"Instances") & ":" & ADDRESS(14+3,K$2+1))),"min", MIN(INDIRECT(ADDRESS(14+3,K$2+1,,,"Instances") & ":" & ADDRESS(14+3,K$2+1))),"max", MAX(INDIRECT(ADDRESS(14+3,K$2+1,,,"Instances") & ":" & ADDRESS(14+3,K$2+1))),"diff", MAX(INDIRECT(ADDRESS(14+3,K$2+1,,,"Instances") & ":" & ADDRESS(14+3,K$2+1)))-MIN(INDIRECT(ADDRESS(14+3,K$2+1,,,"Instances") & ":" & ADDRESS(14+3,K$2+1))))} -> #REF! | L19: =IFERROR(SMALL(K5:K364,ROW()-ROW($L$5)+1),"") | N19: =IFERROR(SUM(L5:L19),"") -> 0 | Q19: =IF(Charts!$B$3="none",E1826,IF(K1826="",NA(),K1826)) -> #REF! | R19: =IF(Charts!$B$3="none",F1826,IF(L1826="",NA(),L1826)) -> #REF! | S19: =IF(Charts!$B$3="none",G1826,IF(M1826="",NA(),M1826)) -> #REF! | T19: =IF(Charts!$B$3="none",H1826,IF(N1826="",NA(),N1826)) -> #REF!
D20: 16 | E20: =IF(INDIRECT(ADDRESS($D20+2,E$2+1,,,"Instances"))="","",INDIRECT(ADDRESS($D20+2,E$2+1,,,"Instances"))) -> #REF! | F20: =IFERROR(SMALL(E5:E364,ROW()-ROW($F$5)+1),"") | H20: =IFERROR(SUM(F5:F20),"") -> 0 | J20: 16 | K20: {=SWITCH(Charts!$B$3,"average", AVERAGE(INDIRECT(ADDRESS(15+3,K$2+1,,,"Instances") & ":" & ADDRESS(15+3,K$2+1))),"median", MEDIAN(INDIRECT(ADDRESS(15+3,K$2+1,,,"Instances") & ":" & ADDRESS(15+3,K$2+1))),"min", MIN(INDIRECT(ADDRESS(15+3,K$2+1,,,"Instances") & ":" & ADDRESS(15+3,K$2+1))),"max", MAX(INDIRECT(ADDRESS(15+3,K$2+1,,,"Instances") & ":" & ADDRESS(15+3,K$2+1))),"diff", MAX(INDIRECT(ADDRESS(15+3,K$2+1,,,"Instances") & ":" & ADDRESS(15+3,K$2+1)))-MIN(INDIRECT(ADDRESS(15+3,K$2+1,,,"Instances") & ":" & ADDRESS(15+3,K$2+1))))} -> #REF! | L20: =IFERROR(SMALL(K5:K364,ROW()-ROW($L$5)+1),"") | N20: =IFERROR(SUM(L5:L20),"") -> 0 | Q20: =IF(Charts!$B$3="none",E1827,IF(K1827="",NA(),K1827)) -> #REF! | R20: =IF(Charts!$B$3="none",F1827,IF(L1827="",NA(),L1827)) -> #REF! | S20: =IF(Charts!$B$3="none",G1827,IF(M1827="",NA(),M1827)) -> #REF! | T20: =IF(Charts!$B$3="none",H1827,IF(N1827="",NA(),N1827)) -> #REF!
D21: 17 | E21: =IF(INDIRECT(ADDRESS($D21+2,E$2+1,,,"Instances"))="","",INDIRECT(ADDRESS($D21+2,E$2+1,,,"Instances"))) -> #REF! | F21: =IFERROR(SMALL(E5:E364,ROW()-ROW($F$5)+1),"") | H21: =IFERROR(SUM(F5:F21),"") -> 0 | J21: 17 | K21: {=SWITCH(Charts!$B$3,"average", AVERAGE(INDIRECT(ADDRESS(16+3,K$2+1,,,"Instances") & ":" & ADDRESS(16+3,K$2+1))),"median", MEDIAN(INDIRECT(ADDRESS(16+3,K$2+1,,,"Instances") & ":" & ADDRESS(16+3,K$2+1))),"min", MIN(INDIRECT(ADDRESS(16+3,K$2+1,,,"Instances") & ":" & ADDRESS(16+3,K$2+1))),"max", MAX(INDIRECT(ADDRESS(16+3,K$2+1,,,"Instances") & ":" & ADDRESS(16+3,K$2+1))),"diff", MAX(INDIRECT(ADDRESS(16+3,K$2+1,,,"Instances") & ":" & ADDRESS(16+3,K$2+1)))-MIN(INDIRECT(ADDRESS(16+3,K$2+1,,,"Instances") & ":" & ADDRESS(16+3,K$2+1))))} -> #REF! | L21: =IFERROR(SMALL(K5:K364,ROW()-ROW($L$5)+1),"") | N21: =IFERROR(SUM(L5:L21),"") -> 0 | Q21: =IF(Charts!$B$3="none",E1828,IF(K1828="",NA(),K1828)) -> #REF! | R21: =IF(Charts!$B$3="none",F1828,IF(L1828="",NA(),L1828)) -> #REF! | S21: =IF(Charts!$B$3="none",G1828,IF(M1828="",NA(),M1828)) -> #REF! | T21: =IF(Charts!$B$3="none",H1828,IF(N1828="",NA(),N1828)) -> #REF!
D22: 18 | E22: =IF(INDIRECT(ADDRESS($D22+2,E$2+1,,,"Instances"))="","",INDIRECT(ADDRESS($D22+2,E$2+1,,,"Instances"))) -> #REF! | F22: =IFERROR(SMALL(E5:E364,ROW()-ROW($F$5)+1),"") | H22: =IFERROR(SUM(F5:F22),"") -> 0 | J22: 18 | K22: {=SWITCH(Charts!$B$3,"average", AVERAGE(INDIRECT(ADDRESS(17+3,K$2+1,,,"Instances") & ":" & ADDRESS(17+3,K$2+1))),"median", MEDIAN(INDIRECT(ADDRESS(17+3,K$2+1,,,"Instances") & ":" & ADDRESS(17+3,K$2+1))),"min", MIN(INDIRECT(ADDRESS(17+3,K$2+1,,,"Instances") & ":" & ADDRESS(17+3,K$2+1))),"max", MAX(INDIRECT(ADDRESS(17+3,K$2+1,,,"Instances") & ":" & ADDRESS(17+3,K$2+1))),"diff", MAX(INDIRECT(ADDRESS(17+3,K$2+1,,,"Instances") & ":" & ADDRESS(17+3,K$2+1)))-MIN(INDIRECT(ADDRESS(17+3,K$2+1,,,"Instances") & ":" & ADDRESS(17+3,K$2+1))))} -> #REF! | L22: =IFERROR(SMALL(K5:K364,ROW()-ROW($L$5)+1),"") | N22: =IFERROR(SUM(L5:L22),"") -> 0 | Q22: =IF(Charts!$B$3="none",E1829,IF(K1829="",NA(),K1829)) -> #REF! | R22: =IF(Charts!$B$3="none",F1829,IF(L1829="",NA(),L1829)) -> #REF! | S22: =IF(Charts!$B$3="none",G1829,IF(M1829="",NA(),M1829)) -> #REF! | T22: =IF(Charts!$B$3="none",H1829,IF(N1829="",NA(),N1829)) -> #REF!
D23: 19 | E23: =IF(INDIRECT(ADDRESS($D23+2,E$2+1,,,"Instances"))="","",INDIRECT(ADDRESS($D23+2,E$2+1,,,"Instances"))) -> #REF! | F23: =IFERROR(SMALL(E5:E364,ROW()-ROW($F$5)+1),"") | H23: =IFERROR(SUM(F5:F23),"") -> 0 | J23: 19 | K23: {=SWITCH(Charts!$B$3,"average", AVERAGE(INDIRECT(ADDRESS(18+3,K$2+1,,,"Instances") & ":" & ADDRESS(18+3,K$2+1))),"median", MEDIAN(INDIRECT(ADDRESS(18+3,K$2+1,,,"Instances") & ":" & ADDRESS(18+3,K$2+1))),"min", MIN(INDIRECT(ADDRESS(18+3,K$2+1,,,"Instances") & ":" & ADDRESS(18+3,K$2+1))),"max", MAX(INDIRECT(ADDRESS(18+3,K$2+1,,,"Instances") & ":" & ADDRESS(18+3,K$2+1))),"diff", MAX(INDIRECT(ADDRESS(18+3,K$2+1,,,"Instances") & ":" & ADDRESS(18+3,K$2+1)))-MIN(INDIRECT(ADDRESS(18+3,K$2+1,,,"Instances") & ":" & ADDRESS(18+3,K$2+1))))} -> #REF! | L23: =IFERROR(SMALL(K5:K364,ROW()-ROW($L$5)+1),"") | N23: =IFERROR(SUM(L5:L23),"") -> 0 | Q23: =IF(Charts!$B$3="none",E1830,IF(K1830="",NA(),K1830)) -> #REF! | R23: =IF(Charts!$B$3="none",F1830,IF(L1830="",NA(),L1830)) -> #REF! | S23: =IF(Charts!$B$3="none",G1830,IF(M1830="",NA(),M1830)) -> #REF! | T23: =IF(Charts!$B$3="none",H1830,IF(N1830="",NA(),N1830)) -> #REF!
D24: 20 | E24: =IF(INDIRECT(ADDRESS($D24+2,E$2+1,,,"Instances"))="","",INDIRECT(ADDRESS($D24+2,E$2+1,,,"Instances"))) -> #REF! | F24: =IFERROR(SMALL(E5:E364,ROW()-ROW($F$5)+1),"") | H24: =IFERROR(SUM(F5:F24),"") -> 0 | J24: 20 | K24: {=SWITCH(Charts!$B$3,"average", AVERAGE(INDIRECT(ADDRESS(19+3,K$2+1,,,"Instances") & ":" & ADDRESS(19+3,K$2+1))),"median", MEDIAN(INDIRECT(ADDRESS(19+3,K$2+1,,,"Instances") & ":" & ADDRESS(19+3,K$2+1))),"min", MIN(INDIRECT(ADDRESS(19+3,K$2+1,,,"Instances") & ":" & ADDRESS(19+3,K$2+1))),"max", MAX(INDIRECT(ADDRESS(19+3,K$2+1,,,"Instances") & ":" & ADDRESS(19+3,K$2+1))),"diff", MAX(INDIRECT(ADDRESS(19+3,K$2+1,,,"Instances") & ":" & ADDRESS(19+3,K$2+1)))-MIN(INDIRECT(ADDRESS(19+3,K$2+1,,,"Instances") & ":" & ADDRESS(19+3,K$2+1))))} -> #REF! | L24: =IFERROR(SMALL(K5:K364,ROW()-ROW($L$5)+1),"") | N24: =IFERROR(SUM(L5:L24),"") -> 0 | Q24: =IF(Charts!$B$3="none",E1831,IF(K1831="",NA(),K1831)) -> #REF! | R24: =IF(Charts!$B$3="none",F1831,IF(L1831="",NA(),L1831)) -> #REF! | S24: =IF(Charts!$B$3="none",G1831,IF(M1831="",NA(),M1831)) -> #REF! | T24: =IF(Charts!$B$3="none",H1831,IF(N1831="",NA(),N1831)) -> #REF!
D25: 21 | E25: =IF(INDIRECT(ADDRESS($D25+2,E$2+1,,,"Instances"))="","",INDIRECT(ADDRESS($D25+2,E$2+1,,,"Instances"))) -> #REF! | F25: =IFERROR(SMALL(E5:E364,ROW()-ROW($F$5)+1),"") | H25: =IFERROR(SUM(F5:F25),"") -> 0 | J25: 21 | K25: {=SWITCH(Charts!$B$3,"average", AVERAGE(INDIRECT(ADDRESS(20+3,K$2+1,,,"Instances") & ":" & ADDRESS(20+3,K$2+1))),"median", MEDIAN(INDIRECT(ADDRESS(20+3,K$2+1,,,"Instances") & ":" & ADDRESS(20+3,K$2+1))),"min", MIN(INDIRECT(ADDRESS(20+3,K$2+1,,,"Instances") & ":" & ADDRESS(20+3,K$2+1))),"max", MAX(INDIRECT(ADDRESS(20+3,K$2+1,,,"Instances") & ":" & ADDRESS(20+3,K$2+1))),"diff", MAX(INDIRECT(ADDRESS(20+3,K$2+1,,,"Instances") & ":" & ADDRESS(20+3,K$2+1)))-MIN(INDIRECT(ADDRESS(20+3,K$2+1,,,"Instances") & ":" & ADDRESS(20+3,K$2+1))))} -> #REF! | L25: =IFERROR(SMALL(K5:K364,ROW()-ROW($L$5)+1),"") | N25: =IFERROR(SUM(L5:L25),"") -> 0 | Q25: =IF(Charts!$B$3="none",E1832,IF(K1832="",NA(),K1832)) -> #REF! | R25: =IF(Charts!$B$3="none",F1832,IF(L1832="",NA(),L1832)) -> #REF! | S25: =IF(Charts!$B$3="none",G1832,IF(M1832="",NA(),M1832)) -> #REF! | T25: =IF(Charts!$B$3="none",H1832,IF(N1832="",NA(),N1832)) -> #REF!
D26: 22 | E26: =IF(INDIRECT(ADDRESS($D26+2,E$2+1,,,"Instances"))="","",INDIRECT(ADDRESS($D26+2,E$2+1,,,"Instances"))) -> #REF! | F26: =IFERROR(SMALL(E5:E364,ROW()-ROW($F$5)+1),"") | H26: =IFERROR(SUM(F5:F26),"") -> 0 | J26: 22 | K26: {=SWITCH(Charts!$B$3,"average", AVERAGE(INDIRECT(ADDRESS(21+3,K$2+1,,,"Instances") & ":" & ADDRESS(21+3,K$2+1))),"median", MEDIAN(INDIRECT(ADDRESS(21+3,K$2+1,,,"Instances") & ":" & ADDRESS(21+3,K$2+1))),"min", MIN(INDIRECT(ADDRESS(21+3,K$2+1,,,"Instances") & ":" & ADDRESS(21+3,K$2+1))),"max", MAX(INDIRECT(ADDRESS(21+3,K$2+1,,,"Instances") & ":" & ADDRESS(21+3,K$2+1))),"diff", MAX(INDIRECT(ADDRESS(21+3,K$2+1,,,"Instances") & ":" & ADDRESS(21+3,K$2+1)))-MIN(INDIRECT(ADDRESS(21+3,K$2+1,,,"Instances") & ":" & ADDRESS(21+3,K$2+1))))} -> #REF! | L26: =IFERROR(SMALL(K5:K364,ROW()-ROW($L$5)+1),"") | N26: =IFERROR(SUM(L5:L26),"") -> 0 | Q26: =IF(Charts!$B$3="none",E1833,IF(K1833="",NA(),K1833)) -> #REF! | R26: =IF(Charts!$B$3="none",F1833,IF(L1833="",NA(),L1833)) -> #REF! | S26: =IF(Charts!$B$3="none",G1833,IF(M1833="",NA(),M1833)) -> #REF! | T26: =IF(Charts!$B$3="none",H1833,IF(N1833="",NA(),N1833)) -> #REF!
D27: 23 | E27: =IF(INDIRECT(ADDRESS($D27+2,E$2+1,,,"Instances"))="","",INDIRECT(ADDRESS($D27+2,E$2+1,,,"Instances"))) -> #REF! | F27: =IFERROR(SMALL(E5:E364,ROW()-ROW($F$5)+1),"") | H27: =IFERROR(SUM(F5:F27),"") -> 0 | J27: 23 | K27: {=SWITCH(Charts!$B$3,"average", AVERAGE(INDIRECT(ADDRESS(22+3,K$2+1,,,"Instances") & ":" & ADDRESS(22+3,K$2+1))),"median", MEDIAN(INDIRECT(ADDRESS(22+3,K$2+1,,,"Instances") & ":" & ADDRESS(22+3,K$2+1))),"min", MIN(INDIRECT(ADDRESS(22+3,K$2+1,,,"Instances") & ":" & ADDRESS(22+3,K$2+1))),"max", MAX(INDIRECT(ADDRESS(22+3,K$2+1,,,"Instances") & ":" & ADDRESS(22+3,K$2+1))),"diff", MAX(INDIRECT(ADDRESS(22+3,K$2+1,,,"Instances") & ":" & ADDRESS(22+3,K$2+1)))-MIN(INDIRECT(ADDRESS(22+3,K$2+1,,,"Instances") & ":" & ADDRESS(22+3,K$2+1))))} -> #REF! | L27: =IFERROR(SMALL(K5:K364,ROW()-ROW($L$5)+1),"") | N27: =IFERROR(SUM(L5:L27),"") -> 0 | Q27: =IF(Charts!$B$3="none",E1834,IF(K1834="",NA(),K1834)) -> #REF! | R27: =IF(Charts!$B$3="none",F1834,IF(L1834="",NA(),L1834)) -> #REF! | S27: =IF(Charts!$B$3="none",G1834,IF(M1834="",NA(),M1834)) -> #REF! | T27: =IF(Charts!$B$3="none",H1834,IF(N1834="",NA(),N1834)) -> #REF!
D28: 24 | E28: =IF(INDIRECT(ADDRESS($D28+2,E$2+1,,,"Instances"))="","",INDIRECT(ADDRESS($D28+2,E$2+1,,,"Instances"))) -> #REF! | F28: =IFERROR(SMALL(E5:E364,ROW()-ROW($F$5)+1),"") | H28: =IFERROR(SUM(F5:F28),"") -> 0 | J28: 24 | K28: {=SWITCH(Charts!$B$3,"average", AVERAGE(INDIRECT(ADDRESS(23+3,K$2+1,,,"Instances") & ":" & ADDRESS(23+3,K$2+1))),"median", MEDIAN(INDIRECT(ADDRESS(23+3,K$2+1,,,"Instances") & ":" & ADDRESS(23+3,K$2+1))),"min", MIN(INDIRECT(ADDRESS(23+3,K$2+1,,,"Instances") & ":" & ADDRESS(23+3,K$2+1))),"max", MAX(INDIRECT(ADDRESS(23+3,K$2+1,,,"Instances") & ":" & ADDRESS(23+3,K$2+1))),"diff", MAX(INDIRECT(ADDRESS(23+3,K$2+1,,,"Instances") & ":" & ADDRESS(23+3,K$2+1)))-MIN(INDIRECT(ADDRESS(23+3,K$2+1,,,"Instances") & ":" & ADDRESS(23+3,K$2+1))))} -> #REF! | L28: =IFERROR(SMALL(K5:K364,ROW()-ROW($L$5)+1),"") | N28: =IFERROR(SUM(L5:L28),"") -> 0 | Q28: =IF(Charts!$B$3="none",E1835,IF(K1835="",NA(),K1835)) -> #REF! | R28: =IF(Charts!$B$3="none",F1835,IF(L1835="",NA(),L1835)) -> #REF! | S28: =IF(Charts!$B$3="none",G1835,IF(M1835="",NA(),M1835)) -> #REF! | T28: =IF(Charts!$B$3="none",H1835,IF(N1835="",NA(),N1835)) -> #REF!
D29: 25 | E29: =IF(INDIRECT(ADDRESS($D29+2,E$2+1,,,"Instances"))="","",INDIRECT(ADDRESS($D29+2,E$2+1,,,"Instances"))) -> #REF! | F29: =IFERROR(SMALL(E5:E364,ROW()-ROW($F$5)+1),"") | H29: =IFERROR(SUM(F5:F29),"") -> 0 | J29: 25 | K29: {=SWITCH(Charts!$B$3,"average", AVERAGE(INDIRECT(ADDRESS(24+3,K$2+1,,,"Instances") & ":" & ADDRESS(24+3,K$2+1))),"median", MEDIAN(INDIRECT(ADDRESS(24+3,K$2+1,,,"Instances") & ":" & ADDRESS(24+3,K$2+1))),"min", MIN(INDIRECT(ADDRESS(24+3,K$2+1,,,"Instances") & ":" & ADDRESS(24+3,K$2+1))),"max", MAX(INDIRECT(ADDRESS(24+3,K$2+1,,,"Instances") & ":" & ADDRESS(24+3,K$2+1))),"diff", MAX(INDIRECT(ADDRESS(24+3,K$2+1,,,"Instances") & ":" & ADDRESS(24+3,K$2+1)))-MIN(INDIRECT(ADDRESS(24+3,K$2+1,,,"Instances") & ":" & ADDRESS(24+3,K$2+1))))} -> #REF! | L29: =IFERROR(SMALL(K5:K364,ROW()-ROW($L$5)+1),"") | N29: =IFERROR(SUM(L5:L29),"") -> 0 | Q29: =IF(Charts!$B$3="none",E1836,IF(K1836="",NA(),K1836)) -> #REF! | R29: =IF(Charts!$B$3="none",F1836,IF(L1836="",NA(),L1836)) -> #REF! | S29: =IF(Charts!$B$3="none",G1836,IF(M1836="",NA(),M1836)) -> #REF! | T29: =IF(Charts!$B$3="none",H1836,IF(N1836="",NA(),N1836)) -> #REF!
D30: 26 | E30: =IF(INDIRECT(ADDRESS($D30+2,E$2+1,,,"Instances"))="","",INDIRECT(ADDRESS($D30+2,E$2+1,,,"Instances"))) -> #REF! | F30: =IFERROR(SMALL(E5:E364,ROW()-ROW($F$5)+1),"") | H30: =IFERROR(SUM(F5:F30),"") -> 0 | J30: 26 | K30: {=SWITCH(Charts!$B$3,"average", AVERAGE(INDIRECT(ADDRESS(25+3,K$2+1,,,"Instances") & ":" & ADDRESS(25+3,K$2+1))),"median", MEDIAN(INDIRECT(ADDRESS(25+3,K$2+1,,,"Instances") & ":" & ADDRESS(25+3,K$2+1))),"min", MIN(INDIRECT(ADDRESS(25+3,K$2+1,,,"Instances") & ":" & ADDRESS(25+3,K$2+1))),"max", MAX(INDIRECT(ADDRESS(25+3,K$2+1,,,"Instances") & ":" & ADDRESS(25+3,K$2+1))),"diff", MAX(INDIRECT(ADDRESS(25+3,K$2+1,,,"Instances") & ":" & ADDRESS(25+3,K$2+1)))-MIN(INDIRECT(ADDRESS(25+3,K$2+1,,,"Instances") & ":" & ADDRESS(25+3,K$2+1))))} -> #REF! | L30: =IFERROR(SMALL(K5:K364,ROW()-ROW($L$5)+1),"") | N30: =IFERROR(SUM(L5:L30),"") -> 0 | Q30: =IF(Charts!$B$3="none",E1837,IF(K1837="",NA(),K1837)) -> #REF! | R30: =IF(Charts!$B$3="none",F1837,IF(L1837="",NA(),L1837)) -> #REF! | S30: =IF(Charts!$B$3="none",G1837,IF(M1837="",NA(),M1837)) -> #REF! | T30: =IF(Charts!$B$3="none",H1837,IF(N1837="",NA(),N1837)) -> #REF!
D31: 27 | E31: =IF(INDIRECT(ADDRESS($D31+2,E$2+1,,,"Instances"))="","",INDIRECT(ADDRESS($D31+2,E$2+1,,,"Instances"))) -> #REF! | F31: =IFERROR(SMALL(E5:E364,ROW()-ROW($F$5)+1),"") | H31: =IFERROR(SUM(F5:F31),"") -> 0 | J31: 27 | K31: {=SWITCH(Charts!$B$3,"average", AVERAGE(INDIRECT(ADDRESS(26+3,K$2+1,,,"Instances") & ":" & ADDRESS(26+3,K$2+1))),"median", MEDIAN(INDIRECT(ADDRESS(26+3,K$2+1,,,"Instances") & ":" & ADDRESS(26+3,K$2+1))),"min", MIN(INDIRECT(ADDRESS(26+3,K$2+1,,,"Instances") & ":" & ADDRESS(26+3,K$2+1))),"max", MAX(INDIRECT(ADDRESS(26+3,K$2+1,,,"Instances") & ":" & ADDRESS(26+3,K$2+1))),"diff", MAX(INDIRECT(ADDRESS(26+3,K$2+1,,,"Instances") & ":" & ADDRESS(26+3,K$2+1)))-MIN(INDIRECT(ADDRESS(26+3,K$2+1,,,"Instances") & ":" & ADDRESS(26+3,K$2+1))))} -> #REF! | L31: =IFERROR(SMALL(K5:K364,ROW()-ROW($L$5)+1),"") | N31: =IFERROR(SUM(L5:L31),"") -> 0 | Q31: =IF(Charts!$B$3="none",E1838,IF(K1838="",NA(),K1838)) -> #REF! | R31: =IF(Charts!$B$3="none",F1838,IF(L1838="",NA(),L1838)) -> #REF! | S31: =IF(Charts!$B$3="none",G1838,IF(M1838="",NA(),M1838)) -> #REF! | T31: =IF(Charts!$B$3="none",H1838,IF(N1838="",NA(),N1838)) -> #REF!
D32: 28 | E32: =IF(INDIRECT(ADDRESS($D32+2,E$2+1,,,"Instances"))="","",INDIRECT(ADDRESS($D32+2,E$2+1,,,"Instances"))) -> #REF! | F32: =IFERROR(SMALL(E5:E364,ROW()-ROW($F$5)+1),"") | H32: =IFERROR(SUM(F5:F32),"") -> 0 | J32: 28 | K32: {=SWITCH(Charts!$B$3,"average", AVERAGE(INDIRECT(ADDRESS(27+3,K$2+1,,,"Instances") & ":" & ADDRESS(27+3,K$2+1))),"median", MEDIAN(INDIRECT(ADDRESS(27+3,K$2+1,,,"Instances") & ":" & ADDRESS(27+3,K$2+1))),"min", MIN(INDIRECT(ADDRESS(27+3,K$2+1,,,"Instances") & ":" & ADDRESS(27+3,K$2+1))),"max", MAX(INDIRECT(ADDRESS(27+3,K$2+1,,,"Instances") & ":" & ADDRESS(27+3,K$2+1))),"diff", MAX(INDIRECT(ADDRESS(27+3,K$2+1,,,"Instances") & ":" & ADDRESS(27+3,K$2+1)))-MIN(INDIRECT(ADDRESS(27+3,K$2+1,,,"Instances") & ":" & ADDRESS(27+3,K$2+1))))} -> #REF! | L32: =IFERROR(SMALL(K5:K364,ROW()-ROW($L$5)+1),"") | N32: =IFERROR(SUM(L5:L32),"") -> 0 | Q32: =IF(Charts!$B$3="none",E1839,IF(K1839="",NA(),K1839)) -> #REF! | R32: =IF(Charts!$B$3="none",F1839,IF(L1839="",NA(),L1839)) -> #REF! | S32: =IF(Charts!$B$3="none",G1839,IF(M1839="",NA(),M1839)) -> #REF! | T32: =IF(Charts!$B$3="none",H1839,IF(N1839="",NA(),N1839)) -> #REF!
D33: 29 | E33: =IF(INDIRECT(ADDRESS($D33+2,E$2+1,,,"Instances"))="","",INDIRECT(ADDRESS($D33+2,E$2+1,,,"Instances"))) -> #REF! | F33: =IFERROR(SMALL(E5:E364,ROW()-ROW($F$5)+1),"") | H33: =IFERROR(SUM(F5:F33),"") -> 0 | J33: 29 | K33: {=SWITCH(Charts!$B$3,"average", AVERAGE(INDIRECT(ADDRESS(28+3,K$2+1,,,"Instances") & ":" & ADDRESS(28+3,K$2+1))),"median", MEDIAN(INDIRECT(ADDRESS(28+3,K$2+1,,,"Instances") & ":" & ADDRESS(28+3,K$2+1))),"min", MIN(INDIRECT(ADDRESS(28+3,K$2+1,,,"Instances") & ":" & ADDRESS(28+3,K$2+1))),"max", MAX(INDIRECT(ADDRESS(28+3,K$2+1,,,"Instances") & ":" & ADDRESS(28+3,K$2+1))),"diff", MAX(INDIRECT(ADDRESS(28+3,K$2+1,,,"Instances") & ":" & ADDRESS(28+3,K$2+1)))-MIN(INDIRECT(ADDRESS(28+3,K$2+1,,,"Instances") & ":" & ADDRESS(28+3,K$2+1))))} -> #REF! | L33: =IFERROR(SMALL(K5:K364,ROW()-ROW($L$5)+1),"") | N33: =IFERROR(SUM(L5:L33),"") -> 0 | Q33: =IF(Charts!$B$3="none",E1840,IF(K1840="",NA(),K1840)) -> #REF! | R33: =IF(Charts!$B$3="none",F1840,IF(L1840="",NA(),L1840)) -> #REF! | S33: =IF(Charts!$B$3="none",G1840,IF(M1840="",NA(),M1840)) -> #REF! | T33: =IF(Charts!$B$3="none",H1840,IF(N1840="",NA(),N1840)) -> #REF!
D34: 30 | E34: =IF(INDIRECT(ADDRESS($D34+2,E$2+1,,,"Instances"))="","",INDIRECT(ADDRESS($D34+2,E$2+1,,,"Instances"))) -> #REF! | F34: =IFERROR(SMALL(E5:E364,ROW()-ROW($F$5)+1),"") | H34: =IFERROR(SUM(F5:F34),"") -> 0 | J34: 30 | K34: {=SWITCH(Charts!$B$3,"average", AVERAGE(INDIRECT(ADDRESS(29+3,K$2+1,,,"Instances") & ":" & ADDRESS(29+3,K$2+1))),"median", MEDIAN(INDIRECT(ADDRESS(29+3,K$2+1,,,"Instances") & ":" & ADDRESS(29+3,K$2+1))),"min", MIN(INDIRECT(ADDRESS(29+3,K$2+1,,,"Instances") & ":" & ADDRESS(29+3,K$2+1))),"max", MAX(INDIRECT(ADDRESS(29+3,K$2+1,,,"Instances") & ":" & ADDRESS(29+3,K$2+1))),"diff", MAX(INDIRECT(ADDRESS(29+3,K$2+1,,,"Instances") & ":" & ADDRESS(29+3,K$2+1)))-MIN(INDIRECT(ADDRESS(29+3,K$2+1,,,"Instances") & ":" & ADDRESS(29+3,K$2+1))))} -> #REF! | L34: =IFERROR(SMALL(K5:K364,ROW()-ROW($L$5)+1),"") | N34: =IFERROR(SUM(L5:L34),"") -> 0 | Q34: =IF(Charts!$B$3="none",E1841,IF(K1841="",NA(),K1841)) -> #REF! | R34: =IF(Charts!$B$3="none",F1841,IF(L1841="",NA(),L1841)) -> #REF! | S34: =IF(Charts!$B$3="none",G1841,IF(M1841="",NA(),M1841)) -> #REF! | T34: =IF(Charts!$B$3="none",H1841,IF(N1841="",NA(),N1841)) -> #REF!
D35: 31 | E35: =IF(INDIRECT(ADDRESS($D35+2,E$2+1,,,"Instances"))="","",INDIRECT(ADDRESS($D35+2,E$2+1,,,"Instances"))) -> #REF! | F35: =IFERROR(SMALL(E5:E364,ROW()-ROW($F$5)+1),"") | H35: =IFERROR(SUM(F5:F35),"") -> 0 | J35: 31 | K35: {=SWITCH(Charts!$B$3,"average", AVERAGE(INDIRECT(ADDRESS(30+3,K$2+1,,,"Instances") & ":" & ADDRESS(30+3,K$2+1))),"median", MEDIAN(INDIRECT(ADDRESS(30+3,K$2+1,,,"Instances") & ":" & ADDRESS(30+3,K$2+1))),"min", MIN(INDIRECT(ADDRESS(30+3,K$2+1,,,"Instances") & ":" & ADDRESS(30+3,K$2+1))),"max", MAX(INDIRECT(ADDRESS(30+3,K$2+1,,,"Instances") & ":" & ADDRESS(30+3,K$2+1))),"diff", MAX(INDIRECT(ADDRESS(30+3,K$2+1,,,"Instances") & ":" & ADDRESS(30+3,K$2+1)))-MIN(INDIRECT(ADDRESS(30+3,K$2+1,,,"Instances") & ":" & ADDRESS(30+3,K$2+1))))} -> #REF! | L35: =IFERROR(SMALL(K5:K364,ROW()-ROW($L$5)+1),"") | N35: =IFERROR(SUM(L5:L35),"") -> 0 | Q35: =IF(Charts!$B$3="none",E1842,IF(K1842="",NA(),K1842)) -> #REF! | R35: =IF(Charts!$B$3="none",F1842,IF(L1842="",NA(),L1842)) -> #REF! | S35: =IF(Charts!$B$3="none",G1842,IF(M1842="",NA(),M1842)) -> #REF! | T35: =IF(Charts!$B$3="none",H1842,IF(N1842="",NA(),N1842)) -> #REF!
D36: 32 | E36: =IF(INDIRECT(ADDRESS($D36+2,E$2+1,,,"Instances"))="","",INDIRECT(ADDRESS($D36+2,E$2+1,,,"Instances"))) -> #REF! | F36: =IFERROR(SMALL(E5:E364,ROW()-ROW($F$5)+1),"") | H36: =IFERROR(SUM(F5:F36),"") -> 0 | J36: 32 | K36: {=SWITCH(Charts!$B$3,"average", AVERAGE(INDIRECT(ADDRESS(31+3,K$2+1,,,"Instances") & ":" & ADDRESS(31+3,K$2+1))),"median", MEDIAN(INDIRECT(ADDRESS(31+3,K$2+1,,,"Instances") & ":" & ADDRESS(31+3,K$2+1))),"min", MIN(INDIRECT(ADDRESS(31+3,K$2+1,,,"Instances") & ":" & ADDRESS(31+3,K$2+1))),"max", MAX(INDIRECT(ADDRESS(31+3,K$2+1,,,"Instances") & ":" & ADDRESS(31+3,K$2+1))),"diff", MAX(INDIRECT(ADDRESS(31+3,K$2+1,,,"Instances") & ":" & ADDRESS(31+3,K$2+1)))-MIN(INDIRECT(ADDRESS(31+3,K$2+1,,,"Instances") & ":" & ADDRESS(31+3,K$2+1))))} -> #REF! | L36: =IFERROR(SMALL(K5:K364,ROW()-ROW($L$5)+1),"") | N36: =IFERROR(SUM(L5:L36),"") -> 0 | Q36: =IF(Charts!$B$3="none",E1843,IF(K1843="",NA(),K1843)) -> #REF! | R36: =IF(Charts!$B$3="none",F1843,IF(L1843="",NA(),L1843)) -> #REF! | S36: =IF(Charts!$B$3="none",G1843,IF(M1843="",NA(),M1843)) -> #REF! | T36: =IF(Charts!$B$3="none",H1843,IF(N1843="",NA(),N1843)) -> #REF!
D37: 33 | E37: =IF(INDIRECT(ADDRESS($D37+2,E$2+1,,,"Instances"))="","",INDIRECT(ADDRESS($D37+2,E$2+1,,,"Instances"))) -> #REF! | F37: =IFERROR(SMALL(E5:E364,ROW()-ROW($F$5)+1),"") | H37: =IFERROR(SUM(F5:F37),"") -> 0 | J37: 33 | K37: {=SWITCH(Charts!$B$3,"average", AVERAGE(INDIRECT(ADDRESS(32+3,K$2+1,,,"Instances") & ":" & ADDRESS(32+3,K$2+1))),"median", MEDIAN(INDIRECT(ADDRESS(32+3,K$2+1,,,"Instances") & ":" & ADDRESS(32+3,K$2+1))),"min", MIN(INDIRECT(ADDRESS(32+3,K$2+1,,,"Instances") & ":" & ADDRESS(32+3,K$2+1))),"max", MAX(INDIRECT(ADDRESS(32+3,K$2+1,,,"Instances") & ":" & ADDRESS(32+3,K$2+1))),"diff", MAX(INDIRECT(ADDRESS(32+3,K$2+1,,,"Instances") & ":" & ADDRESS(32+3,K$2+1)))-MIN(INDIRECT(ADDRESS(32+3,K$2+1,,,"Instances") & ":" & ADDRESS(32+3,K$2+1))))} -> #REF! | L37: =IFERROR(SMALL(K5:K364,ROW()-ROW($L$5)+1),"") | N37: =IFERROR(SUM(L5:L37),"") -> 0 | Q37: =IF(Charts!$B$3="none",E1844,IF(K1844="",NA(),K1844)) -> #REF! | R37: =IF(Charts!$B$3="none",F1844,IF(L1844="",NA(),L1844)) -> #REF! | S37: =IF(Charts!$B$3="none",G1844,IF(M1844="",NA(),M1844)) -> #REF! | T37: =IF(Charts!$B$3="none",H1844,IF(N1844="",NA(),N1844)) -> #REF!
D38: 34 | E38: =IF(INDIRECT(ADDRESS($D38+2,E$2+1,,,"Instances"))="","",INDIRECT(ADDRESS($D38+2,E$2+1,,,"Instances"))) -> #REF! | F38: =IFERROR(SMALL(E5:E364,ROW()-ROW($F$5)+1),"") | H38: =IFERROR(SUM(F5:F38),"") -> 0 | J38: 34 | K38: {=SWITCH(Charts!$B$3,"average", AVERAGE(INDIRECT(ADDRESS(33+3,K$2+1,,,"Instances") & ":" & ADDRESS(33+3,K$2+1))),"median", MEDIAN(INDIRECT(ADDRESS(33+3,K$2+1,,,"Instances") & ":" & ADDRESS(33+3,K$2+1))),"min", MIN(INDIRECT(ADDRESS(33+3,K$2+1,,,"Instances") & ":" & ADDRESS(33+3,K$2+1))),"max", MAX(INDIRECT(ADDRESS(33+3,K$2+1,,,"Instances") & ":" & ADDRESS(33+3,K$2+1))),"diff", MAX(INDIRECT(ADDRESS(33+3,K$2+1,,,"Instances") & ":" & ADDRESS(33+3,K$2+1)))-MIN(INDIRECT(ADDRESS(33+3,K$2+1,,,"Instances") & ":" & ADDRESS(33+3,K$2+1))))} -> #REF! | L38: =IFERROR(SMALL(K5:K364,ROW()-ROW($L$5)+1),"") | N38: =IFERROR(SUM(L5:L38),"") -> 0 | Q38: =IF(Charts!$B$3="none",E1845,IF(K1845="",NA(),K1845)) -> #REF! | R38: =IF(Charts!$B$3="none",F1845,IF(L1845="",NA(),L1845)) -> #REF! | S38: =IF(Charts!$B$3="none",G1845,IF(M1845="",NA(),M1845)) -> #REF! | T38: =IF(Charts!$B$3="none",H1845,IF(N1845="",NA(),N1845)) -> #REF!
D39: 35 | E39: =IF(INDIRECT(ADDRESS($D39+2,E$2+1,,,"Instances"))="","",INDIRECT(ADDRESS($D39+2,E$2+1,,,"Instances"))) -> #REF! | F39: =IFERROR(SMALL(E5:E364,ROW()-ROW($F$5)+1),"") | H39: =IFERROR(SUM(F5:F39),"") -> 0 | J39: 35 | K39: {=SWITCH(Charts!$B$3,"average", AVERAGE(INDIRECT(ADDRESS(34+3,K$2+1,,,"Instances") & ":" & ADDRESS(34+3,K$2+1))),"median", MEDIAN(INDIRECT(ADDRESS(34+3,K$2+1,,,"Instances") & ":" & ADDRESS(34+3,K$2+1))),"min", MIN(INDIRECT(ADDRESS(34+3,K$2+1,,,"Instances") & ":" & ADDRESS(34+3,K$2+1))),"max", MAX(INDIRECT(ADDRESS(34+3,K$2+1,,,"Instances") & ":" & ADDRESS(34+3,K$2+1))),"diff", MAX(INDIRECT(ADDRESS(34+3,K$2+1,,,"Instances") & ":" & ADDRESS(34+3,K$2+1)))-MIN(INDIRECT(ADDRESS(34+3,K$2+1,,,"Instances") & ":" & ADDRESS(34+3,K$2+1))))} -> #REF! | L39: =IFERROR(SMALL(K5:K364,ROW()-ROW($L$5)+1),"") | N39: =IFERROR(SUM(L5:L39),"") -> 0 | Q39: =IF(Charts!$B$3="none",E1846,IF(K1846="",NA(),K1846)) -> #REF! | R39: =IF(Charts!$B$3="none",F1846,IF(L1846="",NA(),L1846)) -> #REF! | S39: =IF(Charts!$B$3="none",G1846,IF(M1846="",NA(),M1846)) -> #REF! | T39: =IF(Charts!$B$3="none",H1846,IF(N1846="",NA(),N1846)) -> #REF!
D40: 36 | E40: =IF(INDIRECT(ADDRESS($D40+2,E$2+1,,,"Instances"))="","",INDIRECT(ADDRESS($D40+2,E$2+1,,,"Instances"))) -> #REF! | F40: =IFERROR(SMALL(E5:E364,ROW()-ROW($F$5)+1),"") | H40: =IFERROR(SUM(F5:F40),"") -> 0 | J40: 36 | K40: {=SWITCH(Charts!$B$3,"average", AVERAGE(INDIRECT(ADDRESS(35+3,K$2+1,,,"Instances") & ":" & ADDRESS(35+3,K$2+1))),"median", MEDIAN(INDIRECT(ADDRESS(35+3,K$2+1,,,"Instances") & ":" & ADDRESS(35+3,K$2+1))),"min", MIN(INDIRECT(ADDRESS(35+3,K$2+1,,,"Instances") & ":" & ADDRESS(35+3,K$2+1))),"max", MAX(INDIRECT(ADDRESS(35+3,K$2+1,,,"Instances") & ":" & ADDRESS(35+3,K$2+1))),"diff", MAX(INDIRECT(ADDRESS(35+3,K$2+1,,,"Instances") & ":" & ADDRESS(35+3,K$2+1)))-MIN(INDIRECT(ADDRESS(35+3,K$2+1,,,"Instances") & ":" & ADDRESS(35+3,K$2+1))))} -> #REF! | L40: =IFERROR(SMALL(K5:K364,ROW()-ROW($L$5)+1),"") | N40: =IFERROR(SUM(L5:L40),"") -> 0 | Q40: =IF(Charts!$B$3="none",E1847,IF(K1847="",NA(),K1847)) -> #REF! | R40: =IF(Charts!$B$3="none",F1847,IF(L1847="",NA(),L1847)) -> #REF! | S40: =IF(Charts!$B$3="none",G1847,IF(M1847="",NA(),M1847)) -> #REF! | T40: =IF(Charts!$B$3="none",H1847,IF(N1847="",NA(),N1847)) -> #REF!
D41: 37 | E41: =IF(INDIRECT(ADDRESS($D41+2,E$2+1,,,"Instances"))="","",INDIRECT(ADDRESS($D41+2,E$2+1,,,"Instances"))) -> #REF! | F41: =IFERROR(SMALL(E5:E364,ROW()-ROW($F$5)+1),"") | H41: =IFERROR(SUM(F5:F41),"") -> 0 | J41: 37 | K41: {=SWITCH(Charts!$B$3,"average", AVERAGE(INDIRECT(ADDRESS(36+3,K$2+1,,,"Instances") & ":" & ADDRESS(36+3,K$2+1))),"median", MEDIAN(INDIRECT(ADDRESS(36+3,K$2+1,,,"Instances") & ":" & ADDRESS(36+3,K$2+1))),"min", MIN(INDIRECT(ADDRESS(36+3,K$2+1,,,"Instances") & ":" & ADDRESS(36+3,K$2+1))),"max", MAX(INDIRECT(ADDRESS(36+3,K$2+1,,,"Instances") & ":" & ADDRESS(36+3,K$2+1))),"diff", MAX(INDIRECT(ADDRESS(36+3,K$2+1,,,"Instances") & ":" & ADDRESS(36+3,K$2+1)))-MIN(INDIRECT(ADDRESS(36+3,K$2+1,,,"Instances") & ":" & ADDRESS(36+3,K$2+1))))} -> #REF! | L41: =IFERROR(SMALL(K5:K364,ROW()-ROW($L$5)+1),"") | N41: =IFERROR(SUM(L5:L41),"") -> 0 | Q41: =IF(Charts!$B$3="none",E1848,IF(K1848="",NA(),K1848)) -> #REF! | R41: =IF(Charts!$B$3="none",F1848,IF(L1848="",NA(),L1848)) -> #REF! | S41: =IF(Charts!$B$3="none",G1848,IF(M1848="",NA(),M1848)) -> #REF! | T41: =IF(Charts!$B$3="none",H1848,IF(N1848="",NA(),N1848)) -> #REF!
...
